Workbook

Sheet services_v2_10
A1: Evaluator | B1: Question | C1: status | D1: response_time | E1: answerability | F1: primary_kc_alignment | G1: secondary_kc_alignment | H1: synergy | I1: topic_alignment | J1: grade_alignment | K1: real_world_feasibility | L1: clarity | M1: conciseness_and_relevance | N1: language_quality | O1: content_appropriateness | P1: explanation
A2: TD | B2: Question 1 | C2: 0 | D2: 2.7569051 | E2: 1 | F2: 1 | G2: 1 | H2: 1 | I2: 1 | J2: 1 | K2: 1 | L2: 1 | M2: 1 | N2: 1 | O2: 1
A3: TD | B3: Question 2 | C3: 0 | D3: 9.2457919 | E3: 1 | F3: 1 | G3: 1 | H3: 1 | I3: 1 | J3: 1 | K3: 1 | L3: 1 | M3: 1 | N3: 1 | O3: 1
A4: TD | B4: Question 3 | C4: 0 | D4: 11.322627 | E4: 0 | F4: 'NA | G4: 'NA | H4: 'NA | I4: 'NA | J4: 'NA | K4: 'NA | L4: 'NA | M4: 'NA | N4: 'NA | O4: 'NA | P4: answerability: Final question asks to subtract 3 towels from 1 remaining towel (1-3=-2), creating impossible negative result. secondary_kc_alignment: The subtraction 1-3=-2 creates mathematically impossible scenario with negative towels. real_world_feasibility: Cannot wash 3 towels by hand when only 1 towel remains available.
A5: TD | B5: Question 4 | C5: 0 | D5: 5.4254258 | E5: 1 | F5: 1 | G5: 1 | H5: 1 | I5: 1 | J5: 0 | K5: 0 | L5: 1 | M5: 1 | N5: 1 | O5: 1 | P5: Grade Alignment: The problem requires multiplying 3-digit numbers (128, 153) by 1-digit numbers (7, 5), which is typically taught in Primary 4, not Primary 3. Primary 3 students typically work with 2-digit by 1-digit multiplication. Real-World Feasibility: Each cleaning staff cleaning 128-153 rooms per month is unrealistic - this would mean 4-5 rooms per day assuming 30 working days, which is not feasible for hotel room cleaning that requires thorough cleaning.
A6: TD | B6: Question 5 | C6: 0 | D6: 9.9993842 | E6: 1 | F6: 1 | G6: 1 | H6: 1 | I6: 1 | J6: 1 | K6: 1 | L6: 1 | M6: 1 | N6: 1 | O6: 1
A7: TD | B7: Question 6 | C7: 0 | D7: 2.7412577 | E7: 1 | F7: 1 | G7: 1 | H7: 1 | I7: 1 | J7: 1 | K7: 1 | L7: 1 | M7: 1 | N7: 1 | O7: 1
A8: TD | B8: Question 7 | C8: 0 | D8: 2.7019989 | E8: 1 | F8: 1 | G8: 1 | H8: 1 | I8: 1 | J8: 1 | K8: 1 | L8: 1 | M8: 1 | N8: 1 | O8: 1
A9: TD | B9: Question 8 | C9: 0 | D9: 2.7475965 | E9: 1 | F9: 1 | G9: 1 | H9: 1 | I9: 1 | J9: 1 | K9: 1 | L9: 1 | M9: 1 | N9: 1 | O9: 1
A10: TD | B10: Question 9 | C10: 0 | D10: 9.1578794 | E10: 1 | F10: 1 | G10: 1 | H10: 1 | I10: 1 | J10: 1 | K10: 1 | L10: 1 | M10: 1 | N10: 1 | O10: 1
A11: TD | B11: Question 10 | C11: 0 | D11: 8.9481184 | E11: 0 | F11: 'NA | G11: 'NA | H11: 'NA | I11: 'NA | J11: 'NA | K11: 'NA | L11: 'NA | M11: 'NA | N11: 'NA | O11: 'NA | P11: Answerability: Missing critical information - the number of teams is not specified, making the problem unsolvable. We know there are teams of 6 cleaners but not how many teams exist. Primary KC Alignment: Cannot perform the intended division operation (4-digit by 1-digit) because the divisor (number of teams) is unknown. The problem setup prevents demonstrating this knowledge component. Synergy: Since the primary division step cannot be completed due to missing information, the two knowledge components cannot work together as intended. Clarity: The problem statement is ambiguous about the total number of teams, creating confusion about what division operation should be performed.
A12: TD | B12: Question 11 | C12: 0 | D12: 5.5222678 | E12: 1 | F12: 1 | G12: 1 | H12: 0 | I12: 1 | J12: 1 | K12: 1 | L12: 1 | M12: 1 | N12: 1 | O12: 1 | P12: The two questions in the word problem are independent of each other. Question 1 asks for addition of fractions 3/4 + 2/3, while Question 2 asks for ordering the same fractions 3/4 and 2/3. The result from Question 1 (which would be 17/12 hours) is not used as input for Question 2. Both questions use the same given information independently, lacking the required connection where an early question's result serves as known information for a later question.
A13: TD | B13: Question 12 | C13: 0 | D13: 13.081812 | E13: 0 | F13: 'NA | G13: 'NA | H13: 'NA | I13: 'NA | J13: 'NA | K13: 'NA | L13: 'NA | M13: 'NA | N13: 'NA | O13: 'NA | P13: Answerability: The question 'What fraction of her allowance did Aisha spend on the streaming service compared to the cleaning supplies?' is ambiguous - could mean difference (5/8 - 1/3), ratio (5/8 / 1/3), or total (5/8 + 1/3). Primary KC Alignment: Due to ambiguous wording, it's unclear if subtraction of unlike fractions is required. Synergy: Primary and secondary knowledge components cannot work in tandem effectively when the primary operation is unclear. Clarity: The main question lacks clarity about which mathematical operation to perform.
A14: TD | B14: Question 13 | C14: 0 | D14: 2.7392824 | E14: 1 | F14: 1 | G14: 1 | H14: 1 | I14: 1 | J14: 1 | K14: 1 | L14: 1 | M14: 1 | N14: 1 | O14: 1
A15: TD | B15: Question 14 | C15: 0 | D15: 7.1983945 | E15: 1 | F15: 1 | G15: 1 | H15: 1 | I15: 1 | J15: 0 | K15: 1 | L15: 1 | M15: 1 | N15: 1 | O15: 1 | P15: Grade alignment fails because converting 3.35 to fraction form requires finding that 3.35 = 335/100, then simplifying 335/100 to 67/20 by finding GCD of 335 and 100. This level of fraction simplification with 3-digit numerators and finding GCD(335,100) = 5 exceeds typical Primary 4 expectations in Singapore math curriculum.
A16: TD | B16: Question 15 | C16: 0 | D16: 6.0542371 | E16: 1 | F16: 1 | G16: 0 | H16: 'NA | I16: 1 | J16: 1 | K16: 1 | L16: 1 | M16: 1 | N16: 1 | O16: 1 | P16: Secondary KC alignment: The subtraction of 25.75 - 18.60 = 7.15 results in a number with only 2 decimal places, but the secondary KC requires rounding decimals up to 3 decimal places. The result 7.15 does not have 3 decimal places to demonstrate the intended rounding skill. Synergy: The primary and secondary knowledge components are not used in tandem effectively since the subtraction result does not naturally require the full scope of the secondary KC (rounding up to 3 decimal places), making the rounding exercise feel artificial rather than integrated.
A17: TD | B17: Question 16 | C17: 0 | D17: 4.6215441 | E17: 1 | F17: 1 | G17: 1 | H17: 0 | I17: 1 | J17: 1 | K17: 1 | L17: 1 | M17: 1 | N17: 1 | O17: 1 | P17: Synergy: The two parts (a) and (b) are independent questions that do not require using the result from part (a) to solve part (b). Part (a) requires multiplying 4.75 x 3, while part (b) requires converting 4.75 to a fraction. These can be solved separately without any connection between the answers.
A18: TD | B18: Question 17 | C18: 0 | D18: 7.0889821 | E18: 1 | F18: 1 | G18: 1 | H18: 1 | I18: 1 | J18: 1 | K18: 1 | L18: 1 | M18: 1 | N18: 1 | O18: 1
A19: TD | B19: Question 18 | C19: 0 | D19: 2.5476983 | E19: 1 | F19: 1 | G19: 1 | H19: 1 | I19: 1 | J19: 1 | K19: 1 | L19: 1 | M19: 1 | N19: 1 | O19: 1
A20: TD | B20: Question 19 | C20: 0 | D20: 7.4159918 | E20: 1 | F20: 1 | G20: 0 | H20: 'NA | I20: 1 | J20: 1 | K20: 1 | L20: 1 | M20: 1 | N20: 1 | O20: 1 | P20: Secondary KC alignment: Problem requires decimal multiplication (3 x 7.60, 2 x 3.90) which is not the intended secondary KC of decimal addition. While decimal addition is used (22.80 + 7.80), it is not the primary computational challenge. Synergy: The primary KC (decimal division) and intended secondary KC (decimal addition) are not used in tandem since decimal multiplication dominates the problem complexity rather than decimal addition.
A21: TD | B21: Question 20 | C21: 0 | D21: 11.844131 | E21: 1 | F21: 1 | G21: 1 | H21: 1 | I21: 1 | J21: 1 | K21: 1 | L21: 0 | M21: 1 | N21: 1 | O21: 1 | P21: Part (b) is confusing and unclear. The phrase 'where should this day be placed in order compared to another day' is awkward. The question mentions 'more than 4 hours' but the actual total is 2 1/3 + 1 3/4 = 4 1/12 hours, which is only slightly more than 4. The wording makes it difficult to understand what exactly is being asked.
A22: TD | B22: Question 21 | C22: 0 | D22: 10.247955 | E22: 1 | F22: 1 | G22: 1 | H22: 0 | I22: 1 | J22: 1 | K22: 1 | L22: 1 | M22: 1 | N22: 1 | O22: 1 | P22: The two parts of the problem work independently rather than in tandem. Part (a) involves subtraction of mixed numbers while part (b) involves comparison and ordering, but the result from part (a) is not used in part (b). The questions are not connected such that early results inform later questions.
A23: TD | B23: Question 22 | C23: 0 | D23: 2.6843171 | E23: 1 | F23: 1 | G23: 1 | H23: 1 | I23: 1 | J23: 1 | K23: 1 | L23: 1 | M23: 1 | N23: 1 | O23: 1
A24: TD | B24: Question 23 | C24: 0 | D24: 2.7580295 | E24: 1 | F24: 1 | G24: 1 | H24: 1 | I24: 1 | J24: 1 | K24: 1 | L24: 1 | M24: 1 | N24: 1 | O24: 1
A25: TD | B25: Question 24 | C25: 0 | D25: 2.7695036 | E25: 1 | F25: 1 | G25: 1 | H25: 1 | I25: 1 | J25: 1 | K25: 1 | L25: 1 | M25: 1 | N25: 1 | O25: 1
A26: TD | B26: Question 25 | C26: 0 | D26: 4.93097 | E26: 0 | F26: 'NA | G26: 'NA | H26: 'NA | I26: 'NA | J26: 'NA | K26: 'NA | L26: 'NA | M26: 'NA | N26: 'NA | O26: 'NA | P26: Answerability: The problem states cleaning 9/4 rooms which equals 2.25 rooms or 2 and 1/4 rooms. This is unrealistic as you cannot clean a fractional part of a room in practical terms. Real-World Plausibility: Cleaning 9/4 = 2.25 rooms does not represent a realistic scenario as rooms are discrete units that cannot be partially cleaned in the context described.
A27: TD | B27: Question 26 | C27: 0 | D27: 4.0052609 | E27: 1 | F27: 0 | G27: 1 | H27: 'NA | I27: 1 | J27: 'NA | K27: 1 | L27: 1 | M27: 1 | N27: 1 | O27: 1 | P27: Primary KC alignment fails because the problem requires multiplying fraction by whole number (9/4 * 3 and 5/6 * 3), not multiplying two improper fractions as specified in the intended Primary Knowledge Component.
A28: TD | B28: Question 27 | C28: 0 | D28: 7.088975 | E28: 1 | F28: 1 | G28: 0 | H28: 'NA | I28: 1 | J28: 1 | K28: 1 | L28: 1 | M28: 1 | N28: 1 | O28: 1 | P28: Secondary KC alignment fails: The problem requires multiplying fractions (5/6 × 21/4) then subtracting, not direct fraction subtraction as specified in the intended Secondary Knowledge Component of subtracting fractions.
A29: TD | B29: Question 28 | C29: 0 | D29: 11.160343 | E29: 1 | F29: 1 | G29: 1 | H29: 1 | I29: 1 | J29: 1 | K29: 0 | L29: 1 | M29: 1 | N29: 1 | O29: 1 | P29: The problem lacks real-world plausibility because cleaning 8/5 rooms (1.6 rooms) is not realistic - you cannot clean a fractional portion of a room in typical cleaning operations.
A30: TD | B30: Question 29 | C30: 0 | D30: 11.237236 | E30: 0 | F30: 'NA | G30: 'NA | H30: 'NA | I30: 'NA | J30: 'NA | K30: 'NA | L30: 'NA | M30: 'NA | N30: 'NA | O30: 'NA | P30: Answerability: The problem has conflicting information. If each room requires 2 1/4 hours and she cleaned all 5 rooms, the minimum time needed is 5 * 2 1/4 = 11 1/4 hours. She cannot spend 1 1/2 hours less than this expected time while still completing all required work. Real-World Plausibility: The scenario is illogical - completing required work in less time than the stated requirement per room is impossible.
A31: TD | B31: Question 30 | C31: 0 | D31: 5.1581762 | E31: 1 | F31: 0 | G31: 1 | H31: 'NA | I31: 1 | J31: 'NA | K31: 1 | L31: 1 | M31: 1 | N31: 1 | O31: 1 | P31: Primary KC alignment fails because part (a) requires 3.75 x 12 = 45.00, which is simple decimal multiplication, not multiplication by 10, 100, 1000 or their multiples as specified. Synergy fails because the two parts are independent - part (a) calculates total cost while part (b) converts decimal to fraction, with no connection between the solutions.
A32: TD | B32: Question 31 | C32: 0 | D32: 6.8753588 | E32: 1 | F32: 0 | G32: 1 | H32: 'NA | I32: 1 | J32: 'NA | K32: 1 | L32: 1 | M32: 1 | N32: 1 | O32: 1 | P32: Primary KC alignment: The problem requires multiplying 3.850 by 140 and 3.850 by 1.4, but does not specifically require multiplying decimals by 10, 100, 1000 or their multiples as intended. The calculations are 3.850 x 140 and 3.850 x 1.4, which are general decimal multiplication, not the specific skill of multiplying by powers of 10. Synergy: While both primary and secondary knowledge components are present in the problem, they are not used in tandem effectively. The primary KC (multiplying by multiples of 10/100/1000) is not actually required, and the subtraction of decimals occurs independently rather than building upon the multiplication component meaningfully.
A33: TD | B33: Question 32 | C33: 0 | D33: 11.006899 | E33: 1 | F33: 0 | G33: 1 | H33: 'NA | I33: 1 | J33: 'NA | K33: 1 | L33: 1 | M33: 1 | N33: 1 | O33: 1 | P33: Primary KC alignment: Part (a) requires 123.456 / 1000 = 0.123456, but the instruction to give answer up to 3 decimal places requires rounding to 0.123, which involves rounding knowledge beyond the intended primary KC of pure division.
A34: TD | B34: Question 33 | C34: 0 | D34: 6.8771763 | E34: 0 | F34: 'NA | G34: 'NA | H34: 'NA | I34: 'NA | J34: 'NA | K34: 'NA | L34: 'NA | M34: 'NA | N34: 'NA | O34: 'NA | P34: Answerability: The problem contains conflicting information. The initial statement says charges are divided equally among all square metres, but then asks for cost per square metre using only the initial 1000 square metres (12.500/1000 = 0.0125), while the total cost calculation would use 1250 square metres (12.500/1250 = 0.01). This creates inconsistent pricing. Clarity: The decimal notation 12.500 is ambiguous - unclear if this represents 12.5 or 12500 dollars, creating confusion about the actual amount. Conciseness and Relevance: Questions (b) and (c) are redundant as they ask for the same information - the total cost of cleaning all areas, making one question unnecessary.
A35: TD | B35: Question 34 | C35: 0 | D35: 8.9349322 | E35: 1 | F35: 1 | G35: 1 | H35: 1 | I35: 1 | J35: 1 | K35: 1 | L35: 1 | M35: 1 | N35: 1 | O35: 1
A36: TD | B36: Question 35 | C36: 0 | D36: 9.6416333 | E36: 1 | F36: 1 | G36: 1 | H36: 1 | I36: 1 | J36: 1 | K36: 1 | L36: 1 | M36: 1 | N36: 1 | O36: 1
A37: TD | B37: Question 36 | C37: 0 | D37: 4.7240741 | E37: 1 | F37: 0 | G37: 1 | H37: 'NA | I37: 1 | J37: 'NA | K37: 1 | L37: 1 | M37: 1 | N37: 1 | O37: 1 | P37: Primary KC alignment fails because the problem requires finding the total cost given rate and quantity, not finding number of units given rate and total amount. The student needs to calculate: 6500g = 6.5kg, then 6.5 x 2.50 = 16.25. This involves finding total amount from rate and units, which is the opposite of the intended primary KC.
A38: TD | B38: Question 37 | C38: 0 | D38: 4.0054073 | E38: 1 | F38: 0 | G38: 1 | H38: 'NA | I38: 1 | J38: 'NA | K38: 1 | L38: 1 | M38: 1 | N38: 1 | O38: 1 | P38: primary_kc_alignment: The problem requires dividing fractions by fractions (3/4 ÷ 1/8 and 5/8 ÷ 1/8), not dividing a proper fraction by a whole number as specified in the intended Primary Knowledge Component.
A39: TD | B39: Question 38 | C39: 0 | D39: 9.6613545 | E39: 1 | F39: 1 | G39: 1 | H39: 1 | I39: 1 | J39: 1 | K39: 1 | L39: 1 | M39: 1 | N39: 1 | O39: 1
A40: TD | B40: Question 39 | C40: 0 | D40: 4.9915676 | E40: 1 | F40: 1 | G40: 0 | H40: 'NA | I40: 1 | J40: 1 | K40: 1 | L40: 1 | M40: 1 | N40: 1 | O40: 1 | P40: Secondary Knowledge Component Alignment: Part (b) requires adding fractions (5/6 + 1/2), not subtracting fractions as specified in the intended secondary knowledge component. Synergy: The two parts do not work in tandem - part (b) can be solved independently without using results from part (a). The connection between parts is weak as they address different aspects of the problem rather than building upon each other.
...

Sheet services_v2_6
A1: Evaluator | B1: Question | C1: status | D1: response_time | E1: answerability | F1: primary_kc_alignment | G1: secondary_kc_alignment | H1: synergy | I1: topic_alignment | J1: grade_alignment | K1: real_world_feasibility | L1: clarity | M1: conciseness_and_relevance | N1: language_quality | O1: content_appropriateness | P1: explanation
A2: TD | B2: Question 1 | C2: 0 | D2: 2.6852431 | E2: 1 | F2: 1 | G2: 1 | H2: 1 | I2: 1 | J2: 1 | K2: 1 | L2: 1 | M2: 1 | N2: 1 | O2: 1
A3: TD | B3: Question 2 | C3: 0 | D3: 10.58423 | E3: 1 | F3: 1 | G3: 1 | H3: 1 | I3: 1 | J3: 1 | K3: 1 | L3: 1 | M3: 1 | N3: 1 | O3: 1
A4: TD | B4: Question 3 | C4: 0 | D4: 2.833415 | E4: 1 | F4: 1 | G4: 1 | H4: 1 | I4: 1 | J4: 1 | K4: 1 | L4: 1 | M4: 1 | N4: 1 | O4: 1
A5: TD | B5: Question 4 | C5: 0 | D5: 5.9732535 | E5: 1 | F5: 1 | G5: 1 | H5: 1 | I5: 1 | J5: 0 | K5: 0 | L5: 1 | M5: 1 | N5: 1 | O5: 1 | P5: Grade alignment: The problem requires multiplying 3-digit numbers (128, 153) by 1-digit numbers (7, 5), which is typically introduced in Primary 4, not Primary 3. Primary 3 students typically work with 2-digit by 1-digit multiplication. Real-world feasibility: The numbers are unrealistic - 128 rooms per staff per month means about 4-5 rooms per day, but 153 rooms per staff per month means about 5-6 rooms per day. These rates are inconsistent and do not reflect typical hotel cleaning workloads where staff usually clean 10-15 rooms per day.
A6: TD | B6: Question 5 | C6: 0 | D6: 9.4653251 | E6: 1 | F6: 1 | G6: 1 | H6: 1 | I6: 1 | J6: 1 | K6: 1 | L6: 1 | M6: 1 | N6: 1 | O6: 1
A7: TD | B7: Question 6 | C7: 0 | D7: 2.7640405 | E7: 1 | F7: 1 | G7: 1 | H7: 1 | I7: 1 | J7: 1 | K7: 1 | L7: 1 | M7: 1 | N7: 1 | O7: 1
A8: TD | B8: Question 7 | C8: 0 | D8: 2.8201222 | E8: 1 | F8: 1 | G8: 1 | H8: 1 | I8: 1 | J8: 1 | K8: 1 | L8: 1 | M8: 1 | N8: 1 | O8: 1
A9: TD | B9: Question 8 | C9: 0 | D9: 2.9339297 | E9: 1 | F9: 1 | G9: 1 | H9: 1 | I9: 1 | J9: 1 | K9: 1 | L9: 1 | M9: 1 | N9: 1 | O9: 1
A10: TD | B10: Question 9 | C10: 0 | D10: 9.756686 | E10: 1 | F10: 1 | G10: 1 | H10: 1 | I10: 1 | J10: 1 | K10: 1 | L10: 1 | M10: 1 | N10: 1 | O10: 1
A11: TD | B11: Question 10 | C11: 0 | D11: 9.1482716 | E11: 0 | F11: 'NA | G11: 'NA | H11: 'NA | I11: 'NA | J11: 'NA | K11: 'NA | L11: 'NA | M11: 'NA | N11: 'NA | O11: 'NA | P11: Answerability: Missing critical information - number of teams is not specified, making the problem unsolvable. We know team size (6 cleaners) but not how many teams exist. Real-world feasibility: The logical structure is flawed - dividing total rooms by team size rather than number of teams does not represent realistic work allocation. Clarity: The problem setup is ambiguous about what division should be performed, leading to confusion about the solution method.
A12: TD | B12: Question 11 | C12: 0 | D12: 5.254674 | E12: 1 | F12: 1 | G12: 1 | H12: 0 | I12: 1 | J12: 1 | K12: 1 | L12: 1 | M12: 1 | N12: 1 | O12: 1 | P12: Synergy: The two questions are independent of each other. Question 1 asks for addition of fractions (3/4 + 2/3), while Question 2 asks for ordering the same fractions (3/4 and 2/3). The result from Question 1 (the sum 17/12 hours) is not used as input for Question 2. Question 2 can be solved entirely using the original given information without needing the answer from Question 1.
A13: TD | B13: Question 12 | C13: 0 | D13: 13.454622 | E13: 0 | F13: 'NA | G13: 'NA | H13: 'NA | I13: 'NA | J13: 'NA | K13: 'NA | L13: 'NA | M13: 'NA | N13: 'NA | O13: 'NA | P13: Answerability: The phrase 'compared to' is ambiguous - it could mean finding the difference (5/8 - 1/3) or the ratio (5/8 divided by 1/3), making the problem unclear. Clarity: The same ambiguity in 'compared to' makes the question unclear for Primary 4 students who need precise mathematical language.
A14: TD | B14: Question 13 | C14: 0 | D14: 2.8658512 | E14: 1 | F14: 1 | G14: 1 | H14: 1 | I14: 1 | J14: 1 | K14: 1 | L14: 1 | M14: 1 | N14: 1 | O14: 1
A15: TD | B15: Question 14 | C15: 0 | D15: 2.8743498 | E15: 1 | F15: 1 | G15: 1 | H15: 1 | I15: 1 | J15: 1 | K15: 1 | L15: 1 | M15: 1 | N15: 1 | O15: 1
A16: TD | B16: Question 15 | C16: 0 | D16: 11.307127 | E16: 1 | F16: 1 | G16: 0 | H16: 'NA | I16: 1 | J16: 1 | K16: 1 | L16: 1 | M16: 1 | N16: 1 | O16: 1 | P16: Secondary KC alignment fails because 25.75 - 18.60 = 7.15 already has 2 decimal places, so rounding to 2 decimal places is meaningless. Synergy fails because the rounding component does not add meaningful complexity when one of the three rounding tasks is redundant.
A17: TD | B17: Question 16 | C17: 0 | D17: 4.8262405 | E17: 1 | F17: 1 | G17: 1 | H17: 0 | I17: 1 | J17: 1 | K17: 1 | L17: 1 | M17: 1 | N17: 1 | O17: 1 | P17: Synergy: The two parts (a) and (b) are independent questions that do not require using the result from part (a) to solve part (b). Part (a) involves multiplying 4.75 x 3, while part (b) involves converting 4.75 to a fraction. These can be solved separately without connection between the questions.
A18: TD | B18: Question 17 | C18: 0 | D18: 2.7332907 | E18: 1 | F18: 1 | G18: 1 | H18: 1 | I18: 1 | J18: 1 | K18: 1 | L18: 1 | M18: 1 | N18: 1 | O18: 1
A19: TD | B19: Question 18 | C19: 0 | D19: 10.009708 | E19: 1 | F19: 1 | G19: 1 | H19: 1 | I19: 1 | J19: 1 | K19: 1 | L19: 1 | M19: 1 | N19: 1 | O19: 1
A20: TD | B20: Question 19 | C20: 0 | D20: 7.7084041 | E20: 1 | F20: 1 | G20: 0 | H20: 'NA | I20: 1 | J20: 1 | K20: 1 | L20: 1 | M20: 1 | N20: 1 | O20: 1 | P20: Secondary KC Alignment: The problem requires multiplying decimals by whole numbers (3 x 7.60 and 2 x 3.90) which is not the intended secondary KC of adding decimals. While decimal addition occurs (22.80 + 7.80), it is not a primary requirement since the multiplication steps dominate the complexity. Synergy: The primary KC (decimal division) and intended secondary KC (decimal addition) are not used in tandem because the actual secondary operation needed is decimal multiplication, not addition.
A21: TD | B21: Question 20 | C21: 0 | D21: 10.376223 | E21: 1 | F21: 1 | G21: 1 | H21: 1 | I21: 1 | J21: 1 | K21: 1 | L21: 0 | M21: 1 | N21: 1 | O21: 1 | P21: Part (b) is confusingly worded and difficult to understand. The phrasing 'where should this day be placed in order compared to another day' and the overall structure of the question lack clarity, making it hard for students to comprehend what is being asked.
A22: TD | B22: Question 21 | C22: 0 | D22: 2.8423467 | E22: 1 | F22: 1 | G22: 1 | H22: 1 | I22: 1 | J22: 1 | K22: 1 | L22: 1 | M22: 1 | N22: 1 | O22: 1
A23: TD | B23: Question 22 | C23: 0 | D23: 2.9086516 | E23: 1 | F23: 1 | G23: 1 | H23: 1 | I23: 1 | J23: 1 | K23: 1 | L23: 1 | M23: 1 | N23: 1 | O23: 1
A24: TD | B24: Question 23 | C24: 0 | D24: 9.4529357 | E24: 1 | F24: 1 | G24: 1 | H24: 1 | I24: 1 | J24: 1 | K24: 1 | L24: 1 | M24: 1 | N24: 1 | O24: 1
A25: TD | B25: Question 24 | C25: 0 | D25: 2.9156368 | E25: 1 | F25: 1 | G25: 1 | H25: 1 | I25: 1 | J25: 1 | K25: 1 | L25: 1 | M25: 1 | N25: 1 | O25: 1
A26: TD | B26: Question 25 | C26: 0 | D26: 5.1322038 | E26: 0 | F26: 'NA | G26: 'NA | H26: 'NA | I26: 'NA | J26: 'NA | K26: 'NA | L26: 'NA | M26: 'NA | N26: 'NA | O26: 'NA | P26: Answerability: The problem contains illogical information - cleaning 9/4 rooms means cleaning 2.25 rooms, which is not realistic as you cannot clean a fraction of a room in practical terms. Real-world feasibility: The scenario of cleaning 9/4 = 2.25 rooms is not plausible as rooms are discrete units that cannot be partially cleaned in the context described.
A27: TD | B27: Question 26 | C27: 0 | D27: 8.3418245 | E27: 1 | F27: 0 | G27: 1 | H27: 'NA | I27: 1 | J27: 'NA | K27: 1 | L27: 1 | M27: 1 | N27: 1 | O27: 1 | P27: Primary KC alignment fails because the intended Primary Knowledge Component is multiplying two improper fractions, but the problem only requires multiplying a whole number (3) by an improper fraction (9/4). There is no multiplication of two improper fractions in this problem.
A28: TD | B28: Question 27 | C28: 0 | D28: 7.8584189 | E28: 1 | F28: 1 | G28: 0 | H28: 'NA | I28: 1 | J28: 1 | K28: 1 | L28: 1 | M28: 1 | N28: 1 | O28: 1 | P28: Secondary KC Alignment: The second part requires multiplying 5/6 × 21/4 first, then subtracting from 21/4. This involves fraction multiplication as the primary operation, not fraction subtraction as intended. The subtraction is only the final step after the multiplication is completed.
A29: TD | B29: Question 28 | C29: 0 | D29: 11.094907 | E29: 1 | F29: 1 | G29: 1 | H29: 1 | I29: 1 | J29: 1 | K29: 0 | L29: 1 | M29: 1 | N29: 1 | O29: 1 | P29: Real-world feasibility fails because cleaning 8/5 rooms (1.6 rooms) is unrealistic - cleaning companies clean whole rooms, not fractional rooms in practice.
A30: TD | B30: Question 29 | C30: 0 | D30: 8.4552379 | E30: 0 | F30: 'NA | G30: 'NA | H30: 'NA | I30: 'NA | J30: 'NA | K30: 'NA | L30: 'NA | M30: 'NA | N30: 'NA | O30: 'NA | P30: Answerability: The problem has conflicting information. Question (a) asks for expected hours but this cannot be determined from given information. If each room requires 2 1/4 hours and there are 5 rooms, expected time would be 5 x 2 1/4 = 11 1/4 hours. However, question (b) asks for actual time, which would be 11 1/4 - 1 1/2 = 9 3/4 hours. But the problem states she spent 1 1/2 hours less than expected after cleaning all rooms, creating logical inconsistency about what the 2 1/4 hours per room represents. Real-World Feasibility: It is unrealistic that a professional cleaner would not know how long she actually spent cleaning rooms. The scenario where expected time per room is given but actual total time needs calculation is implausible. Clarity: The problem is ambiguous about whether 2 1/4 hours represents expected time per room or actual time per room, making it unclear what the 1 1/2 hours less refers to.
A31: TD | B31: Question 30 | C31: 0 | D31: 5.6199896 | E31: 1 | F31: 0 | G31: 1 | H31: 'NA | I31: 1 | J31: 'NA | K31: 1 | L31: 1 | M31: 1 | N31: 1 | O31: 1 | P31: Primary KC alignment: Part (a) requires 3.75 x 12 = 45.00, which is basic decimal multiplication, not specifically multiplying by 10, 100, 1000 or their multiples as intended. Synergy: The two parts are independent - part (a) calculates total cost while part (b) converts decimal to fraction. The result from part (a) is not used in part (b), so they do not work in tandem.
A32: TD | B32: Question 31 | C32: 0 | D32: 6.5976188 | E32: 1 | F32: 0 | G32: 1 | H32: 'NA | I32: 1 | J32: 'NA | K32: 1 | L32: 1 | M32: 1 | N32: 1 | O32: 1 | P32: Primary KC alignment: The problem requires multiplying 3.850 by 140 and 3.850 by 1.4, but these are not multiplication by 10, 100, 1000 or their multiples as specified in the intended primary KC. The calculations involve general decimal multiplication, not the specific skill of multiplying by powers of 10. Synergy: While both decimal multiplication and subtraction are used, they are not used in tandem as the primary KC (multiplying by 10/100/1000) is not actually required. The problem can be solved with general decimal operations without the specific primary KC skill.
A33: TD | B33: Question 32 | C33: 0 | D33: 2.8495309 | E33: 1 | F33: 1 | G33: 1 | H33: 1 | I33: 1 | J33: 1 | K33: 1 | L33: 1 | M33: 1 | N33: 1 | O33: 1
A34: TD | B34: Question 33 | C34: 0 | D34: 6.164221 | E34: 0 | F34: 'NA | G34: 'NA | H34: 'NA | I34: 'NA | J34: 'NA | K34: 'NA | L34: 'NA | M34: 'NA | N34: 'NA | O34: 'NA | P34: Answerability: The problem contains conflicting information - it states service charges are divided equally among all square metres cleaned, but then asks for cost per square metre using only the initial 1000 square metres rate, creating logical inconsistency. Clarity: The statement about charges being divided equally among all square metres cleaned creates ambiguity about which rate to use for calculations. Conciseness and Relevance: Question (b) asks for total cost of cleaning both areas separately, but this information is not needed to solve question (c) which asks for the total amount to pay, making question (b) redundant.
A35: TD | B35: Question 34 | C35: 0 | D35: 10.178117 | E35: 1 | F35: 1 | G35: 1 | H35: 1 | I35: 1 | J35: 1 | K35: 1 | L35: 1 | M35: 1 | N35: 1 | O35: 1
A36: TD | B36: Question 35 | C36: 0 | D36: 9.1334362 | E36: 1 | F36: 1 | G36: 1 | H36: 1 | I36: 1 | J36: 1 | K36: 1 | L36: 1 | M36: 1 | N36: 1 | O36: 1
A37: TD | B37: Question 36 | C37: 0 | D37: 4.8539279 | E37: 1 | F37: 0 | G37: 1 | H37: 'NA | I37: 1 | J37: 'NA | K37: 1 | L37: 1 | M37: 1 | N37: 1 | O37: 1 | P37: Primary KC alignment: The problem requires finding the total amount given rate and number of units, not finding number of units given rate and total amount. The rate is $2.50 per kg, units are 6.5 kg (converted from 6500g), and we calculate total amount = 2.50 * 6.5 = $16.25. This is the reverse of the intended primary KC.
A38: TD | B38: Question 37 | C38: 0 | D38: 4.4029164 | E38: 1 | F38: 0 | G38: 1 | H38: 'NA | I38: 1 | J38: 'NA | K38: 1 | L38: 1 | M38: 1 | N38: 1 | O38: 1 | P38: primary_kc_alignment: The problem requires dividing fractions by fractions (3/4 ÷ 1/8 and 5/8 ÷ 1/8), not dividing a proper fraction by a whole number as specified in the intended Primary Knowledge Component.
A39: TD | B39: Question 38 | C39: 0 | D39: 9.9044249 | E39: 1 | F39: 1 | G39: 1 | H39: 1 | I39: 1 | J39: 1 | K39: 1 | L39: 1 | M39: 1 | N39: 1 | O39: 1
A40: TD | B40: Question 39 | C40: 0 | D40: 5.5411067 | E40: 1 | F40: 1 | G40: 0 | H40: 'NA | I40: 1 | J40: 1 | K40: 1 | L40: 1 | M40: 1 | N40: 1 | O40: 1 | P40: Secondary KC Alignment: Part (a) requires division of whole number by fraction (12 ÷ 3/4) but does not require fraction subtraction. Part (b) requires addition of fractions (5/6 + 1/2) not subtraction as specified in secondary KC. Synergy: The two parts are not connected - part (b) does not use the result from part (a) as they address separate scenarios with different laundry amounts.
...

Sheet services_v2_7
A1: Evaluator | B1: Question | C1: status | D1: response_time | E1: answerability | F1: primary_kc_alignment | G1: secondary_kc_alignment | H1: synergy | I1: topic_alignment | J1: grade_alignment | K1: real_world_feasibility | L1: clarity | M1: conciseness_and_relevance | N1: language_quality | O1: content_appropriateness | P1: explanation
A2: TD | B2: Question 1 | C2: 0 | D2: 2.9567797 | E2: 1 | F2: 1 | G2: 1 | H2: 1 | I2: 1 | J2: 1 | K2: 1 | L2: 1 | M2: 1 | N2: 1 | O2: 1
A3: TD | B3: Question 2 | C3: 0 | D3: 9.3557088 | E3: 1 | F3: 1 | G3: 1 | H3: 1 | I3: 1 | J3: 1 | K3: 1 | L3: 1 | M3: 1 | N3: 1 | O3: 1
A4: TD | B4: Question 3 | C4: 0 | D4: 2.6899297 | E4: 1 | F4: 1 | G4: 1 | H4: 1 | I4: 1 | J4: 1 | K4: 1 | L4: 1 | M4: 1 | N4: 1 | O4: 1
A5: TD | B5: Question 4 | C5: 0 | D5: 11.316149 | E5: 1 | F5: 1 | G5: 1 | H5: 1 | I5: 1 | J5: 0 | K5: 1 | L5: 1 | M5: 1 | N5: 1 | O5: 1 | P5: Grade alignment issue: The problem requires 3-digit by 1-digit multiplication (128×7, 153×5) which is typically taught in Primary 4, not Primary 3. Primary 3 students usually work with 2-digit by 1-digit multiplication. The resulting numbers (896, 765) and calculations may be too advanced for Primary 3 level.
A6: TD | B6: Question 5 | C6: 0 | D6: 10.965541 | E6: 1 | F6: 1 | G6: 1 | H6: 0 | I6: 1 | J6: 1 | K6: 1 | L6: 1 | M6: 1 | N6: 1 | O6: 1 | P6: The division result from part (a) is not actually needed to solve parts (b) and (c). The comparison in parts (b) and (c) can be done directly using 288 and 245 without using the result 48 from the division.
A7: TD | B7: Question 6 | C7: 0 | D7: 2.9796932 | E7: 1 | F7: 1 | G7: 1 | H7: 1 | I7: 1 | J7: 1 | K7: 1 | L7: 1 | M7: 1 | N7: 1 | O7: 1
A8: TD | B8: Question 7 | C8: 0 | D8: 2.9824398 | E8: 1 | F8: 1 | G8: 1 | H8: 1 | I8: 1 | J8: 1 | K8: 1 | L8: 1 | M8: 1 | N8: 1 | O8: 1
A9: TD | B9: Question 8 | C9: 0 | D9: 2.8794115 | E9: 1 | F9: 1 | G9: 1 | H9: 1 | I9: 1 | J9: 1 | K9: 1 | L9: 1 | M9: 1 | N9: 1 | O9: 1
A10: TD | B10: Question 9 | C10: 0 | D10: 9.6901722 | E10: 1 | F10: 1 | G10: 1 | H10: 1 | I10: 1 | J10: 1 | K10: 1 | L10: 1 | M10: 1 | N10: 1 | O10: 1
A11: TD | B11: Question 10 | C11: 0 | D11: 10.342496 | E11: 0 | F11: 'NA | G11: 'NA | H11: 'NA | I11: 'NA | J11: 'NA | K11: 'NA | L11: 'NA | M11: 'NA | N11: 'NA | O11: 'NA | P11: Answerability: The problem cannot be solved because it does not specify the number of teams. To divide 2872 rooms among teams, we need to know how many teams there are. The problem mentions teams of 6 cleaners but does not give the total number of teams.
A12: TD | B12: Question 11 | C12: 0 | D12: 4.953521 | E12: 1 | F12: 1 | G12: 1 | H12: 0 | I12: 1 | J12: 1 | K12: 1 | L12: 1 | M12: 1 | N12: 1 | O12: 1 | P12: Synergy: The two questions are independent of each other. Question 1 requires adding 3/4 + 2/3, while Question 2 requires comparing 3/4 and 2/3. The result from Question 1 (total time = 17/12 hours) is not used as input for Question 2. The questions can be solved separately without connection.
A13: TD | B13: Question 12 | C13: 0 | D13: 11.589719 | E13: 0 | F13: 'NA | G13: 'NA | H13: 'NA | I13: 'NA | J13: 'NA | K13: 'NA | L13: 'NA | M13: 'NA | N13: 'NA | O13: 'NA | P13: The phrase 'What fraction of her allowance did Aisha spend on the streaming service compared to the cleaning supplies' is ambiguous. It could mean the difference (5/8 - 1/3), the ratio (5/8 divided by 1/3), or the total (5/8 + 1/3). This ambiguity makes the problem unclear and potentially unanswerable without additional clarification.
A14: TD | B14: Question 13 | C14: 0 | D14: 2.894984 | E14: 1 | F14: 1 | G14: 1 | H14: 1 | I14: 1 | J14: 1 | K14: 1 | L14: 1 | M14: 1 | N14: 1 | O14: 1
A15: TD | B15: Question 14 | C15: 0 | D15: 2.9831359 | E15: 1 | F15: 1 | G15: 1 | H15: 1 | I15: 1 | J15: 1 | K15: 1 | L15: 1 | M15: 1 | N15: 1 | O15: 1
A16: TD | B16: Question 15 | C16: 0 | D16: 10.365033 | E16: 1 | F16: 1 | G16: 0 | H16: 'NA | I16: 1 | J16: 1 | K16: 1 | L16: 1 | M16: 1 | N16: 1 | O16: 1 | P16: Secondary KC Alignment: The answer 7.15 already has 2 decimal places, so rounding to 2 decimal places produces the same result, making this rounding step meaningless and not properly demonstrating the intended rounding skill.
A17: TD | B17: Question 16 | C17: 0 | D17: 10.194513 | E17: 1 | F17: 1 | G17: 1 | H17: 0 | I17: 1 | J17: 1 | K17: 1 | L17: 1 | M17: 1 | N17: 1 | O17: 1 | P17: Synergy: The two questions operate independently. Part (b) asking to convert $4.75 to a fraction does not use the result from part (a) which calculates the total cost. The questions are not connected where one builds upon the other.
A18: TD | B18: Question 17 | C18: 0 | D18: 9.5279474 | E18: 1 | F18: 1 | G18: 1 | H18: 1 | I18: 1 | J18: 1 | K18: 1 | L18: 1 | M18: 1 | N18: 1 | O18: 1
A19: TD | B19: Question 18 | C19: 0 | D19: 2.8732562 | E19: 1 | F19: 1 | G19: 1 | H19: 1 | I19: 1 | J19: 1 | K19: 1 | L19: 1 | M19: 1 | N19: 1 | O19: 1
A20: TD | B20: Question 19 | C20: 0 | D20: 3.0203922 | E20: 1 | F20: 1 | G20: 1 | H20: 1 | I20: 1 | J20: 1 | K20: 1 | L20: 1 | M20: 1 | N20: 1 | O20: 1
A21: TD | B21: Question 20 | C21: 0 | D21: 10.966504 | E21: 1 | F21: 1 | G21: 1 | H21: 1 | I21: 1 | J21: 1 | K21: 1 | L21: 0 | M21: 1 | N21: 0 | O21: 1 | P21: Clarity: Part (b) is confusing and poorly worded - the question about which day they spent more than 4 hours is unclear since they spent 4 1/12 hours total, and the ordering question is unnecessarily complex. Language Quality: The sentence structure in part (b) has grammatical issues and creates confusion about what is being asked.
A22: TD | B22: Question 21 | C22: 0 | D22: 11.720196 | E22: 1 | F22: 1 | G22: 1 | H22: 0 | I22: 1 | J22: 1 | K22: 1 | L22: 1 | M22: 1 | N22: 1 | O22: 1 | P22: The two parts of the problem operate independently - part (a) calculates 3(2/5) - 2(4/5) = 3/5, while part (b) orders 2(4/5), 3(2/5), 3(1/2) from least to greatest. The result from part (a) is not used in part (b), lacking the required connection where early question results serve as known information for later questions.
A23: TD | B23: Question 22 | C23: 0 | D23: 2.9746659 | E23: 1 | F23: 1 | G23: 1 | H23: 1 | I23: 1 | J23: 1 | K23: 1 | L23: 1 | M23: 1 | N23: 1 | O23: 1
A24: TD | B24: Question 23 | C24: 0 | D24: 2.9665082 | E24: 1 | F24: 1 | G24: 1 | H24: 1 | I24: 1 | J24: 1 | K24: 1 | L24: 1 | M24: 1 | N24: 1 | O24: 1
A25: TD | B25: Question 24 | C25: 0 | D25: 2.8752787 | E25: 1 | F25: 1 | G25: 1 | H25: 1 | I25: 1 | J25: 1 | K25: 1 | L25: 1 | M25: 1 | N25: 1 | O25: 1
A26: TD | B26: Question 25 | C26: 0 | D26: 7.2034104 | E26: 1 | F26: 0 | G26: 1 | H26: 'NA | I26: 1 | J26: 'NA | K26: 0 | L26: 1 | M26: 1 | N26: 1 | O26: 1 | P26: Primary KC alignment: The intended primary KC is multiplying proper fraction by proper/improper fraction, but 5/8 (proper) × 9/4 (improper) does not match this specification exactly as stated. Real-world feasibility: Cleaning 9/4 = 2.25 rooms is unrealistic - cleaning companies typically clean whole rooms, not fractional portions like 0.25 of a room.
A27: TD | B27: Question 26 | C27: 0 | D27: 10.599792 | E27: 1 | F27: 0 | G27: 0 | H27: 'NA | I27: 1 | J27: 'NA | K27: 1 | L27: 1 | M27: 1 | N27: 1 | O27: 1 | P27: Primary KC: Problem requires multiplying whole numbers by fractions (3 x 9/4, 3 x 5/6), not multiplying two improper fractions as intended. Secondary KC: While fraction addition occurs, it is secondary to the multiplication steps rather than being a primary focus. Synergy: Cannot work in tandem since intended primary KC is not present in the problem.
A28: TD | B28: Question 27 | C28: 0 | D28: 8.8197243 | E28: 1 | F28: 1 | G28: 1 | H28: 1 | I28: 1 | J28: 1 | K28: 1 | L28: 1 | M28: 1 | N28: 1 | O28: 1
A29: TD | B29: Question 28 | C29: 0 | D29: 11.089425 | E29: 1 | F29: 1 | G29: 1 | H29: 1 | I29: 1 | J29: 1 | K29: 0 | L29: 1 | M29: 1 | N29: 1 | O29: 1 | P29: Real-world feasibility fails because cleaning 8/5 = 1.6 rooms is not realistic - you cannot meaningfully clean a fractional portion of a room in a professional cleaning context.
A30: TD | B30: Question 29 | C30: 0 | D30: 12.980158 | E30: 1 | F30: 1 | G30: 1 | H30: 1 | I30: 1 | J30: 1 | K30: 0 | L30: 1 | M30: 1 | N30: 1 | O30: 1 | P30: Real-world plausibility issue: The problem states Jenny was hired to clean rooms requiring 2+1/4 hours each, but then suggests she had different expectations about the time needed. This creates a logical inconsistency about whether the 2+1/4 hours represents the hiring specification or Jenny's personal expectation.
A31: TD | B31: Question 30 | C31: 0 | D31: 6.0309761 | E31: 1 | F31: 0 | G31: 1 | H31: 'NA | I31: 1 | J31: 'NA | K31: 1 | L31: 1 | M31: 1 | N31: 1 | O31: 1 | P31: Primary KC alignment: Part (a) requires 3.75 x 12 which is basic decimal multiplication, not specifically multiplying by 10, 100, 1000 or their multiples as stated in the intended primary KC. Synergy: The two parts are independent - part (b) can be solved without using the result from part (a), so the primary and secondary KCs are not used in tandem as required.
A32: TD | B32: Question 31 | C32: 0 | D32: 6.2696967 | E32: 1 | F32: 0 | G32: 1 | H32: 'NA | I32: 1 | J32: 'NA | K32: 1 | L32: 1 | M32: 1 | N32: 1 | O32: 1 | P32: Primary KC alignment: The problem requires multiplying 3.850 by 140 and 3.850 by 1.4, but does not specifically require multiplying decimals by 10, 100, 1000 or their multiples as stated in the intended primary KC. The calculations involve general decimal multiplication rather than the specific skill of multiplying by powers of 10. Synergy: While both decimal multiplication and subtraction are used, they are not used in tandem as the primary KC (multiplying by 10, 100, 1000) is not actually required. The problem uses general decimal operations but not the specific primary KC intended.
A33: TD | B33: Question 32 | C33: 0 | D33: 11.80816 | E33: 1 | F33: 0 | G33: 1 | H33: 'NA | I33: 1 | J33: 'NA | K33: 1 | L33: 1 | M33: 1 | N33: 1 | O33: 1 | P33: Primary KC alignment fails because the problem involves dividing a decimal (123.456) by an integer (1000), not dividing decimals by decimal multiples of 10/100/1000 as specified in the intended component.
A34: TD | B34: Question 33 | C34: 0 | D34: 7.3993216 | E34: 0 | F34: 'NA | G34: 'NA | H34: 'NA | I34: 'NA | J34: 'NA | K34: 'NA | L34: 'NA | M34: 'NA | N34: 'NA | O34: 'NA | P34: Answerability: The problem contains conflicting information. Part (a) asks for cost per square metre, part (b) asks for total cost of both areas, and part (c) asks what customer pays altogether. Parts (b) and (c) should have the same answer since the customer pays for all cleaning done, but they are presented as separate questions suggesting different answers. The problem states charges are divided equally among all square metres but then asks for costs as if calculated separately. Clarity: The relationship between parts (b) and (c) is unclear - if the customer gets both areas cleaned, the total cost and what they pay altogether should be identical, making one question redundant and confusing. Conciseness and Relevance: Part (c) is redundant since it asks the same thing as part (b) - the total amount the customer pays for cleaning both the original 1000 square metres and additional 250 square metres.
A35: TD | B35: Question 34 | C35: 0 | D35: 9.7738402 | E35: 1 | F35: 1 | G35: 1 | H35: 1 | I35: 1 | J35: 1 | K35: 1 | L35: 1 | M35: 1 | N35: 1 | O35: 1
A36: TD | B36: Question 35 | C36: 0 | D36: 2.8868771 | E36: 1 | F36: 1 | G36: 1 | H36: 1 | I36: 1 | J36: 1 | K36: 1 | L36: 1 | M36: 1 | N36: 1 | O36: 1
A37: TD | B37: Question 36 | C37: 0 | D37: 5.0062361 | E37: 1 | F37: 0 | G37: 1 | H37: 'NA | I37: 1 | J37: 'NA | K37: 1 | L37: 1 | M37: 1 | N37: 1 | O37: 1 | P37: Primary KC alignment: The problem requires finding the total cost given rate and quantity, not finding number of units given rate and total amount. The intended primary KC is about finding units when given rate and total, but this problem gives rate ($2.50/kg) and units (6.5 kg after conversion) to find total cost.
A38: TD | B38: Question 37 | C38: 0 | D38: 4.1251063 | E38: 1 | F38: 0 | G38: 1 | H38: 'NA | I38: 1 | J38: 'NA | K38: 1 | L38: 1 | M38: 1 | N38: 1 | O38: 1 | P38: primary_kc_alignment: The problem requires dividing fractions by fractions (3/4 ÷ 1/8 and 5/8 ÷ 1/8), not dividing a proper fraction by a whole number as specified in the intended Primary Knowledge Component.
A39: TD | B39: Question 38 | C39: 0 | D39: 8.7281647 | E39: 1 | F39: 1 | G39: 1 | H39: 1 | I39: 1 | J39: 1 | K39: 1 | L39: 1 | M39: 1 | N39: 1 | O39: 1
A40: TD | B40: Question 39 | C40: 0 | D40: 11.697304 | E40: 1 | F40: 1 | G40: 0 | H40: 'NA | I40: 1 | J40: 1 | K40: 1 | L40: 1 | M40: 1 | N40: 1 | O40: 1 | P40: Secondary Knowledge Component misalignment: Part (b) requires adding fractions (5/6 + 1/2) but the intended secondary KC is subtracting fractions. Synergy failure: Since part (b) does not use the intended secondary KC of fraction subtraction, the primary and secondary KCs are not used in tandem as required.
...

Sheet services_v2_8
A1: Evaluator | B1: Question | C1: status | D1: response_time | E1: answerability | F1: primary_kc_alignment | G1: secondary_kc_alignment | H1: synergy | I1: topic_alignment | J1: grade_alignment | K1: real_world_feasibility | L1: clarity | M1: conciseness_and_relevance | N1: language_quality | O1: content_appropriateness | P1: explanation
A2: TD | B2: Question 1 | C2: 0 | D2: 2.7721303 | E2: 1 | F2: 1 | G2: 1 | H2: 1 | I2: 1 | J2: 1 | K2: 1 | L2: 1 | M2: 1 | N2: 1 | O2: 1
A3: TD | B3: Question 2 | C3: 0 | D3: 10.241508 | E3: 1 | F3: 1 | G3: 1 | H3: 1 | I3: 1 | J3: 1 | K3: 1 | L3: 1 | M3: 1 | N3: 1 | O3: 1
A4: TD | B4: Question 3 | C4: 0 | D4: 2.6927347 | E4: 1 | F4: 1 | G4: 1 | H4: 1 | I4: 1 | J4: 1 | K4: 1 | L4: 1 | M4: 1 | N4: 1 | O4: 1
A5: TD | B5: Question 4 | C5: 0 | D5: 9.7683601 | E5: 1 | F5: 1 | G5: 1 | H5: 1 | I5: 1 | J5: 1 | K5: 1 | L5: 1 | M5: 1 | N5: 1 | O5: 1
A6: TD | B6: Question 5 | C6: 0 | D6: 10.422424 | E6: 1 | F6: 1 | G6: 1 | H6: 0 | I6: 1 | J6: 1 | K6: 1 | L6: 1 | M6: 1 | N6: 1 | O6: 1 | P6: Synergy: The questions are not properly connected. Parts (b) and (c) can be solved by directly comparing 288 and 245 without using the division result from part (a). The result from part (a) - 48 towels per machine - is not needed as known information for the later questions.
A7: TD | B7: Question 6 | C7: 0 | D7: 2.7081831 | E7: 1 | F7: 1 | G7: 1 | H7: 1 | I7: 1 | J7: 1 | K7: 1 | L7: 1 | M7: 1 | N7: 1 | O7: 1
A8: TD | B8: Question 7 | C8: 0 | D8: 2.6842921 | E8: 1 | F8: 1 | G8: 1 | H8: 1 | I8: 1 | J8: 1 | K8: 1 | L8: 1 | M8: 1 | N8: 1 | O8: 1
A9: TD | B9: Question 8 | C9: 0 | D9: 2.7195425 | E9: 1 | F9: 1 | G9: 1 | H9: 1 | I9: 1 | J9: 1 | K9: 1 | L9: 1 | M9: 1 | N9: 1 | O9: 1
A10: TD | B10: Question 9 | C10: 0 | D10: 9.3472028 | E10: 1 | F10: 1 | G10: 1 | H10: 1 | I10: 1 | J10: 1 | K10: 1 | L10: 1 | M10: 1 | N10: 1 | O10: 1
A11: TD | B11: Question 10 | C11: 0 | D11: 10.1264 | E11: 0 | F11: 'NA | G11: 'NA | H11: 'NA | I11: 'NA | J11: 'NA | K11: 'NA | L11: 'NA | M11: 'NA | N11: 'NA | O11: 'NA | P11: The problem is missing critical information - the number of teams. While it mentions teams of 6 cleaners, it does not specify how many teams exist, making it impossible to calculate 2872 divided by the unknown number of teams.
A12: TD | B12: Question 11 | C12: 0 | D12: 11.157178 | E12: 1 | F12: 1 | G12: 1 | H12: 0 | I12: 1 | J12: 1 | K12: 1 | L12: 1 | M12: 1 | N12: 1 | O12: 1 | P12: The two questions are independent - Question 2 does not use the result from Question 1. The total time (3/4 + 2/3 = 17/12 hours) is not needed for ordering 3/4 and 2/3, lacking the required connection between questions.
A13: TD | B13: Question 12 | C13: 0 | D13: 7.8492451 | E13: 1 | F13: 0 | G13: 1 | H13: 'NA | I13: 1 | J13: 'NA | K13: 1 | L13: 0 | M13: 1 | N13: 1 | O13: 1 | P13: Primary KC Alignment: The problem asks for comparison between fractions (5/8 compared to 1/3), which requires finding the difference 5/8 - 1/3, but this is not the main focus. The question What fraction of her allowance did Aisha spend on the streaming service compared to the cleaning supplies is ambiguous and does not clearly require subtraction of unlike fractions as the primary solution method. Synergy: The Primary KC (subtraction of unlike fractions) and Secondary KC (simplifying fractions) are not used in tandem effectively. The subtraction is not clearly the main operation needed, and simplifying may not be required depending on interpretation of compared to. Clarity: The phrase What fraction of her allowance did Aisha spend on the streaming service compared to the cleaning supplies is ambiguous. It could mean the difference (5/8 - 1/3), the ratio (5/8 divided by 1/3), or simply asking for both fractions separately.
A14: TD | B14: Question 13 | C14: 0 | D14: 2.7743421 | E14: 1 | F14: 1 | G14: 1 | H14: 1 | I14: 1 | J14: 1 | K14: 1 | L14: 1 | M14: 1 | N14: 1 | O14: 1
A15: TD | B15: Question 14 | C15: 0 | D15: 6.5698113 | E15: 1 | F15: 1 | G15: 1 | H15: 1 | I15: 1 | J15: 0 | K15: 1 | L15: 1 | M15: 1 | N15: 1 | O15: 1 | P15: Grade alignment fails because Primary 4 students typically learn basic fraction-decimal relationships like 0.5 = 1/2, but converting complex decimals like 3.35 to fractions (67/20) and determining simplest form requires knowledge of GCD/LCM concepts that are introduced in Primary 5-6. The complexity of this conversion exceeds Primary 4 expectations in Singapore math curriculum.
A16: TD | B16: Question 15 | C16: 0 | D16: 6.0532823 | E16: 1 | F16: 1 | G16: 0 | H16: 'NA | I16: 1 | J16: 1 | K16: 1 | L16: 1 | M16: 1 | N16: 1 | O16: 1 | P16: Secondary KC alignment: The subtraction result 25.75 - 18.60 = 7.15 already has only 2 decimal places, so rounding to 2 decimal places gives the same answer. The secondary knowledge component of rounding decimals up to 3 decimal places is not meaningfully applied since the result doesn't require rounding from 3 decimal places. Synergy: Since the secondary knowledge component is not properly utilized, the primary and secondary components do not work in tandem as intended. The rounding instruction becomes superficial rather than essential to solving the problem.
A17: TD | B17: Question 16 | C17: 0 | D17: 10.384726 | E17: 1 | F17: 1 | G17: 1 | H17: 0 | I17: 1 | J17: 1 | K17: 1 | L17: 1 | M17: 1 | N17: 1 | O17: 1 | P17: The two parts of the problem are not connected - part (b) does not use the result from part (a) as input, so they lack the required synergy where knowledge components work in tandem.
A18: TD | B18: Question 17 | C18: 0 | D18: 2.8108342 | E18: 1 | F18: 1 | G18: 1 | H18: 1 | I18: 1 | J18: 1 | K18: 1 | L18: 1 | M18: 1 | N18: 1 | O18: 1
A19: TD | B19: Question 18 | C19: 0 | D19: 9.282594 | E19: 1 | F19: 1 | G19: 1 | H19: 1 | I19: 1 | J19: 1 | K19: 1 | L19: 1 | M19: 1 | N19: 1 | O19: 1
A20: TD | B20: Question 19 | C20: 0 | D20: 7.3525038 | E20: 1 | F20: 1 | G20: 0 | H20: 'NA | I20: 1 | J20: 1 | K20: 1 | L20: 1 | M20: 1 | N20: 1 | O20: 1 | P20: Secondary KC alignment: Problem requires multiplication (3 × 7.60, 2 × 3.90) as primary operations before addition, making multiplication more prominent than the intended secondary KC of decimal addition. Synergy: The primary KC (decimal division) and secondary KC (decimal addition) are not used in tandem - they are sequential operations where addition feeds into division, but division does not enhance or work together with addition simultaneously.
A21: TD | B21: Question 20 | C21: 0 | D21: 11.982877 | E21: 0 | F21: 'NA | G21: 'NA | H21: 'NA | I21: 'NA | J21: 'NA | K21: 'NA | L21: 'NA | M21: 'NA | N21: 'NA | O21: 'NA | P21: Part (b) creates confusion by asking about a day with more than 4 hours instead of directly using the calculated total from part (a). The phrase 'this day' is ambiguous and the condition 'more than 4 hours' adds unnecessary complexity when the question should simply ask to compare 4 1/12 hours with 3 5/6 hours.
A22: TD | B22: Question 21 | C22: 0 | D22: 2.87549 | E22: 1 | F22: 1 | G22: 1 | H22: 1 | I22: 1 | J22: 1 | K22: 1 | L22: 1 | M22: 1 | N22: 1 | O22: 1
A23: TD | B23: Question 22 | C23: 0 | D23: 2.7190721 | E23: 1 | F23: 1 | G23: 1 | H23: 1 | I23: 1 | J23: 1 | K23: 1 | L23: 1 | M23: 1 | N23: 1 | O23: 1
A24: TD | B24: Question 23 | C24: 0 | D24: 9.7729228 | E24: 1 | F24: 1 | G24: 1 | H24: 1 | I24: 1 | J24: 1 | K24: 1 | L24: 1 | M24: 1 | N24: 1 | O24: 1
A25: TD | B25: Question 24 | C25: 0 | D25: 11.030297 | E25: 0 | F25: 'NA | G25: 'NA | H25: 'NA | I25: 'NA | J25: 'NA | K25: 'NA | L25: 'NA | M25: 'NA | N25: 'NA | O25: 'NA | P25: The problem has illogical relationship as the total work equals 11/10 of the mansion, meaning 110% which is impossible since you cannot clean more than 100% of a mansion. This makes the scenario unrealistic.
A26: TD | B26: Question 25 | C26: 0 | D26: 6.6835356 | E26: 1 | F26: 1 | G26: 1 | H26: 1 | I26: 1 | J26: 1 | K26: 0 | L26: 1 | M26: 1 | N26: 1 | O26: 1 | P26: Real-world feasibility: The scenario describes cleaning 9/4 = 2.25 rooms in a day, which means cleaning a quarter of a room. In reality, cleaning companies typically clean whole rooms or complete units, not fractional portions of rooms. This makes the scenario unrealistic as it does not mirror how cleaning services typically operate.
A27: TD | B27: Question 26 | C27: 0 | D27: 11.820546 | E27: 1 | F27: 0 | G27: 1 | H27: 'NA | I27: 1 | J27: 'NA | K27: 1 | L27: 1 | M27: 1 | N27: 1 | O27: 1 | P27: Primary KC alignment fails because the problem only requires multiplying whole numbers by fractions (3 x 9/4 and 3 x 5/6), not multiplying two improper fractions together as intended.
A28: TD | B28: Question 27 | C28: 0 | D28: 8.9201806 | E28: 1 | F28: 1 | G28: 1 | H28: 1 | I28: 1 | J28: 1 | K28: 1 | L28: 1 | M28: 1 | N28: 1 | O28: 1
A29: TD | B29: Question 28 | C29: 0 | D29: 10.476949 | E29: 1 | F29: 1 | G29: 1 | H29: 1 | I29: 1 | J29: 1 | K29: 0 | L29: 1 | M29: 1 | N29: 1 | O29: 1 | P29: Real-world plausibility fails because cleaning 8/5 rooms (1.6 rooms) is not realistic - you cannot clean a fraction of a room in a cleaning service context.
A30: TD | B30: Question 29 | C30: 0 | D30: 7.2338526 | E30: 0 | F30: 'NA | G30: 'NA | H30: 'NA | I30: 'NA | J30: 'NA | K30: 'NA | L30: 'NA | M30: 'NA | N30: 'NA | O30: 'NA | P30: Answerability: The problem contains conflicting information. If Jenny expected to spend 2 1/4 hours per room for 5 rooms (11 1/4 hours total), but actually spent 1 1/2 hours less (9 3/4 hours total), this means she was more efficient than expected. However, the problem setup suggests she realized she spent less time after cleaning, which creates logical inconsistency about whether the time per room was an expectation or actual measurement. Real-world feasibility: It is unrealistic for a professional cleaner to not know how long she actually spent cleaning rooms - she would track her time as she works, not realize afterward that she spent less time than expected. Clarity: The phrase 'Each room required 2 1/4 hours of cleaning' is ambiguous - it could mean this was the expected time or the actual time needed, creating confusion about what Jenny expected versus what actually happened.
A31: TD | B31: Question 30 | C31: 0 | D31: 5.4060376 | E31: 1 | F31: 0 | G31: 1 | H31: 'NA | I31: 1 | J31: 'NA | K31: 1 | L31: 1 | M31: 1 | N31: 1 | O31: 1 | P31: Primary KC alignment: Part (a) requires 3.75 * 12 which is basic decimal multiplication, not multiplication by 10/100/1000 or their multiples as specified in the intended primary KC. Synergy: The two parts (a) and (b) are independent questions that do not require each other's results - part (b) can be solved without using the answer from part (a), failing the synergy requirement.
A32: TD | B32: Question 31 | C32: 0 | D32: 6.3895786 | E32: 1 | F32: 0 | G32: 1 | H32: 'NA | I32: 1 | J32: 'NA | K32: 1 | L32: 1 | M32: 1 | N32: 1 | O32: 1 | P32: Primary KC alignment: The problem requires multiplying 3.850 by 140 and 3.850 by 1.4, but does not specifically require multiplying decimals by 10, 100, 1000 or their multiples as intended. The calculations involve general decimal multiplication, not the specific skill of multiplying by powers of 10. Synergy: While both knowledge components are used in the problem, they are not used in tandem effectively. The primary KC (multiplying by multiples of 10/100/1000) is not properly utilized, so the components do not work together as intended to solve the problem.
A33: TD | B33: Question 32 | C33: 0 | D33: 2.6909747 | E33: 1 | F33: 1 | G33: 1 | H33: 1 | I33: 1 | J33: 1 | K33: 1 | L33: 1 | M33: 1 | N33: 1 | O33: 1
A34: TD | B34: Question 33 | C34: 0 | D34: 6.4410024 | E34: 0 | F34: 'NA | G34: 'NA | H34: 'NA | I34: 'NA | J34: 'NA | K34: 'NA | L34: 'NA | M34: 'NA | N34: 'NA | O34: 'NA | P34: Answerability: The problem contains conflicting information about pricing structure. Initially states 12.500 for 1000 square metres, then states charges are divided equally among ALL square metres cleaned, creating ambiguity about whether the rate applies to original area only or total area. Clarity: The decimal notation 12.500 is ambiguous - unclear if this represents 12.5 or 12500 in standard notation. The pricing structure explanation creates confusion about how charges are calculated. Conciseness and Relevance: Questions (b) and (c) are redundant - both ask for the same total cost calculation, making one of these questions unnecessary.
A35: TD | B35: Question 34 | C35: 0 | D35: 9.4294014 | E35: 1 | F35: 1 | G35: 1 | H35: 1 | I35: 1 | J35: 1 | K35: 1 | L35: 1 | M35: 1 | N35: 1 | O35: 1
A36: TD | B36: Question 35 | C36: 0 | D36: 9.0323403 | E36: 1 | F36: 1 | G36: 1 | H36: 1 | I36: 1 | J36: 1 | K36: 1 | L36: 1 | M36: 1 | N36: 1 | O36: 1
A37: TD | B37: Question 36 | C37: 0 | D37: 4.5625811 | E37: 1 | F37: 0 | G37: 1 | H37: 'NA | I37: 1 | J37: 'NA | K37: 1 | L37: 1 | M37: 1 | N37: 1 | O37: 1 | P37: Primary KC alignment: The intended primary KC is 'finding number of units given rate and total amount' but the problem asks for total cost given rate and weight. The problem requires finding total amount (cost = rate x units) rather than finding number of units. This is the reverse operation of the intended primary KC.
A38: TD | B38: Question 37 | C38: 0 | D38: 4.8202665 | E38: 1 | F38: 0 | G38: 1 | H38: 'NA | I38: 1 | J38: 'NA | K38: 1 | L38: 1 | M38: 1 | N38: 1 | O38: 1 | P38: Primary KC alignment: The problem requires dividing fractions by fractions (3/4 ÷ 1/8 and 5/8 ÷ 1/8), not dividing a proper fraction by a whole number as intended. The intended primary KC would involve operations like 3/4 ÷ 2 or similar whole number divisors.
A39: TD | B39: Question 38 | C39: 0 | D39: 6.5712755 | E39: 1 | F39: 1 | G39: 1 | H39: 1 | I39: 1 | J39: 1 | K39: 1 | L39: 1 | M39: 0 | N39: 1 | O39: 1 | P39: The problem includes unnecessary information: mentioning 6 identical small rooms when only 1 room's solution amount is needed for the calculation. The number 6 is not used in solving either part (a) or part (b), making it irrelevant information that violates the conciseness requirement.
A40: TD | B40: Question 39 | C40: 0 | D40: 11.92199 | E40: 1 | F40: 1 | G40: 1 | H40: 0 | I40: 1 | J40: 1 | K40: 1 | L40: 1 | M40: 1 | N40: 1 | O40: 1 | P40: Synergy: The two questions are not properly connected. Part (b) provides 1/2 kg as given information rather than using the result from part (a) to determine remaining laundry. The questions can be solved independently without using results from earlier parts.
...

Sheet services_v2_9
A1: Evaluator | B1: Question | C1: status | D1: response_time | E1: answerability | F1: primary_kc_alignment | G1: secondary_kc_alignment | H1: synergy | I1: topic_alignment | J1: grade_alignment | K1: real_world_feasibility | L1: clarity | M1: conciseness_and_relevance | N1: language_quality | O1: content_appropriateness | P1: explanation
A2: TD | B2: Question 1 | C2: 0 | D2: 2.8541141 | E2: 1 | F2: 1 | G2: 1 | H2: 1 | I2: 1 | J2: 1 | K2: 1 | L2: 1 | M2: 1 | N2: 1 | O2: 1
A3: TD | B3: Question 2 | C3: 0 | D3: 11.201665 | E3: 1 | F3: 1 | G3: 1 | H3: 1 | I3: 1 | J3: 0 | K3: 1 | L3: 1 | M3: 1 | N3: 1 | O3: 1 | P3: Grade alignment issue: The problem requires 4-digit subtraction with regrouping (2501 - 1789), which is typically beyond Primary 3 level. Primary 3 students usually work with 3-digit numbers and simpler operations without complex regrouping.
A4: TD | B4: Question 3 | C4: 0 | D4: 2.7761278 | E4: 1 | F4: 1 | G4: 1 | H4: 1 | I4: 1 | J4: 1 | K4: 1 | L4: 1 | M4: 1 | N4: 1 | O4: 1
A5: TD | B5: Question 4 | C5: 0 | D5: 9.6568248 | E5: 1 | F5: 1 | G5: 1 | H5: 1 | I5: 1 | J5: 0 | K5: 1 | L5: 1 | M5: 1 | N5: 1 | O5: 1 | P5: Grade alignment fails because multiplying 3-digit numbers by 1-digit numbers (7×128, 5×153) requires carrying techniques typically taught in Primary 4 or higher, making it too advanced for Primary 3 students.
A6: TD | B6: Question 5 | C6: 0 | D6: 9.4693446 | E6: 1 | F6: 1 | G6: 1 | H6: 1 | I6: 1 | J6: 1 | K6: 1 | L6: 1 | M6: 1 | N6: 1 | O6: 1
A7: TD | B7: Question 6 | C7: 0 | D7: 2.7998908 | E7: 1 | F7: 1 | G7: 1 | H7: 1 | I7: 1 | J7: 1 | K7: 1 | L7: 1 | M7: 1 | N7: 1 | O7: 1
A8: TD | B8: Question 7 | C8: 0 | D8: 2.7304358 | E8: 1 | F8: 1 | G8: 1 | H8: 1 | I8: 1 | J8: 1 | K8: 1 | L8: 1 | M8: 1 | N8: 1 | O8: 1
A9: TD | B9: Question 8 | C9: 0 | D9: 2.8494666 | E9: 1 | F9: 1 | G9: 1 | H9: 1 | I9: 1 | J9: 1 | K9: 1 | L9: 1 | M9: 1 | N9: 1 | O9: 1
A10: TD | B10: Question 9 | C10: 0 | D10: 9.2154851 | E10: 1 | F10: 1 | G10: 1 | H10: 1 | I10: 1 | J10: 1 | K10: 1 | L10: 1 | M10: 1 | N10: 1 | O10: 1
A11: TD | B11: Question 10 | C11: 0 | D11: 10.232298 | E11: 0 | F11: 'NA | G11: 'NA | H11: 'NA | I11: 'NA | J11: 'NA | K11: 'NA | L11: 'NA | M11: 'NA | N11: 'NA | O11: 'NA | P11: The problem states there are teams of 6 cleaners but does not specify how many teams exist. Without knowing the number of teams, it is impossible to divide 2872 rooms among them. The problem needs to specify either the total number of teams or the total number of cleaners to be answerable.
