Workbook

Sheet recreation_v2_common_1
A1: Question | B1: status | C1: response_time | D1: answerability | E1: primary_kc_alignment | F1: secondary_kc_alignment | G1: synergy | H1: topic_alignment | I1: grade_alignment | J1: real_world_feasibility | K1: clarity | L1: conciseness_and_relevance | M1: language_quality | N1: content_appropriateness | O1: explanation
A2: Question 1 | B2: 0 | C2: 2.7279763 | D2: 1 | E2: 1 | F2: 1 | G2: 1 | H2: 1 | I2: 1 | J2: 1 | K2: 1 | L2: 1 | M2: 1 | N2: 1
A3: Question 2 | B3: 0 | C3: 10.523025 | D3: 0 | E3: 'NA | F3: 'NA | G3: 'NA | H3: 'NA | I3: 'NA | J3: 'NA | K3: 'NA | L3: 'NA | M3: 'NA | N3: 'NA | O3: Answerability: The problem contains contradictory instructions - Alvin cannot both divide time equally among 6 songs and spend 2/3 of total time on one song, creating logical conflict. Synergy: Parts (a) and (b) are disconnected due to this contradiction - equal division result from (a) cannot be used with the 2/3 allocation in (b). Real_world_feasibility: The scenario is unrealistic as it describes contradictory time allocation methods that no student would actually follow. Clarity: The contradictory instructions about time division create ambiguity about what Alvin actually does with his practice time.
A4: Question 3 | B4: 0 | C4: 7.3575993 | D4: 1 | E4: 1 | F4: 1 | G4: 1 | H4: 1 | I4: 1 | J4: 1 | K4: 1 | L4: 1 | M4: 1 | N4: 1
A5: Question 4 | B5: 0 | C5: 9.8658245 | D5: 1 | E5: 1 | F5: 1 | G5: 1 | H5: 1 | I5: 1 | J5: 1 | K5: 1 | L5: 1 | M5: 1 | N5: 1
A6: Question 5 | B6: 0 | C6: 2.77333 | D6: 1 | E6: 1 | F6: 1 | G6: 1 | H6: 1 | I6: 1 | J6: 1 | K6: 1 | L6: 1 | M6: 1 | N6: 1
A7: Question 6 | B7: 0 | C7: 10.815762 | D7: 1 | E7: 1 | F7: 1 | G7: 1 | H7: 1 | I7: 1 | J7: 1 | K7: 1 | L7: 1 | M7: 1 | N7: 1
A8: Question 7 | B8: 0 | C8: 2.7487135 | D8: 1 | E8: 1 | F8: 1 | G8: 1 | H8: 1 | I8: 1 | J8: 1 | K8: 1 | L8: 1 | M8: 1 | N8: 1
A9: Question 8 | B9: 0 | C9: 9.9748759 | D9: 1 | E9: 1 | F9: 1 | G9: 1 | H9: 1 | I9: 1 | J9: 1 | K9: 1 | L9: 1 | M9: 1 | N9: 1
A10: Question 9 | B10: 0 | C10: 5.1060007 | D10: 1 | E10: 1 | F10: 1 | G10: 0 | H10: 1 | I10: 0 | J10: 1 | K10: 1 | L10: 1 | M10: 1 | N10: 1 | O10: Synergy: The two parts (a) and (b) are independent questions that do not require using results from part (a) to solve part (b). They can be solved separately without connection. Grade_alignment: Finding percentiles/quartiles is typically introduced at upper secondary or pre-university level, which may be too advanced for Secondary O-level 2 students who would typically focus on basic measures like mean, median, mode.
A11: Question 10 | B11: 0 | C11: 2.6994808 | D11: 1 | E11: 1 | F11: 1 | G11: 1 | H11: 1 | I11: 1 | J11: 1 | K11: 1 | L11: 1 | M11: 1 | N11: 1
A12: Question 11 | B12: 0 | C12: 10.272939 | D12: 1 | E12: 0 | F12: 1 | G12: 'NA | H12: 1 | I12: 'NA | J12: 1 | K12: 1 | L12: 1 | M12: 1 | N12: 1 | O12: Primary KC alignment fails because the intended primary knowledge component is subtracting mixed numbers, but part (a) only requires addition of mixed numbers (4 2/3 + 1 5/6), and part (b) involves simple subtraction (8 1/2 - 6 1/2 = 2) rather than complex mixed number subtraction that should be the main focus.
A13: Question 12 | B13: 0 | C13: 4.657311 | D13: 1 | E13: 1 | F13: 1 | G13: 1 | H13: 1 | I13: 0 | J13: 1 | K13: 1 | L13: 1 | M13: 1 | N13: 1 | O13: Grade Alignment: The problem involves matrix operations which are typically introduced at A-level or pre-university level mathematics, not at O-level Secondary 3/4. O-level students at Secondary 3/4 grade typically work with basic algebra, geometry, and statistics, but matrix operations are beyond the standard O-level curriculum.
A14: Question 13 | B14: 0 | C14: 2.6687155 | D14: 1 | E14: 1 | F14: 1 | G14: 1 | H14: 1 | I14: 1 | J14: 1 | K14: 1 | L14: 1 | M14: 1 | N14: 1
A15: Question 14 | B15: 0 | C15: 9.9641955 | D15: 1 | E15: 1 | F15: 1 | G15: 1 | H15: 1 | I15: 1 | J15: 1 | K15: 1 | L15: 1 | M15: 1 | N15: 1
A16: Question 15 | B16: 0 | C16: 11.782847 | D16: 1 | E16: 0 | F16: 1 | G16: 'NA | H16: 1 | I16: 'NA | J16: 1 | K16: 1 | L16: 1 | M16: 1 | N16: 1 | O16: Primary KC alignment fails because the problem requires 3.275 * 20 which is general decimal multiplication, not multiplication by multiples of 10, 100, or 1000 as specified in the intended primary knowledge component.
A17: Question 16 | B17: 0 | C17: 11.199461 | D17: 1 | E17: 1 | F17: 1 | G17: 1 | H17: 1 | I17: 1 | J17: 1 | K17: 1 | L17: 1 | M17: 1 | N17: 1
A18: Question 17 | B18: 0 | C18: 8.2187405 | D18: 1 | E18: 1 | F18: 1 | G18: 1 | H18: 1 | I18: 1 | J18: 1 | K18: 1 | L18: 1 | M18: 1 | N18: 1
A19: Question 18 | B19: 0 | C19: 12.227212 | D19: 1 | E19: 1 | F19: 0 | G19: 'NA | H19: 1 | I19: 1 | J19: 1 | K19: 1 | L19: 1 | M19: 1 | N19: 1 | O19: Secondary KC alignment: Part (b) requires finding 2/5 of 12 and subtracting from total (12 - 4.8), but does not specifically require subtracting fractions in fractional form as intended.
A20: Question 19 | B20: 0 | C20: 9.4532199 | D20: 1 | E20: 1 | F20: 1 | G20: 1 | H20: 1 | I20: 1 | J20: 1 | K20: 1 | L20: 1 | M20: 1 | N20: 1
A21: Question 20 | B21: 0 | C21: 9.79392 | D21: 1 | E21: 1 | F21: 1 | G21: 1 | H21: 1 | I21: 1 | J21: 1 | K21: 1 | L21: 1 | M21: 1 | N21: 1
A22: Question 21 | B22: 0 | C22: 9.2166367 | D22: 1 | E22: 1 | F22: 1 | G22: 1 | H22: 1 | I22: 1 | J22: 1 | K22: 1 | L22: 1 | M22: 1 | N22: 1
A23: Question 22 | B23: 0 | C23: 4.5178807 | D23: 1 | E23: 1 | F23: 1 | G23: 1 | H23: 1 | I23: 0 | J23: 1 | K23: 1 | L23: 1 | M23: 1 | N23: 1 | O23: Grade Alignment: This problem is too simple for Secondary O-level 1 students. Finding 25% of 80 and multiplying by 15 are basic operations typically mastered in primary grades. Secondary O-level 1 students would need more complex percentage problems involving compound changes, algebraic manipulation, or multi-step reasoning beyond basic arithmetic.
A24: Question 23 | B24: 0 | C24: 11.331811 | D24: 1 | E24: 1 | F24: 1 | G24: 0 | H24: 1 | I24: 1 | J24: 1 | K24: 1 | L24: 1 | M24: 1 | N24: 1 | O24: The two questions are independent of each other. Part (a) result (1.42) is not used in part (b), and part (b) can be solved without solving part (a) first. True synergy requires questions to build upon each other sequentially.
A25: Question 24 | B25: 0 | C25: 10.970185 | D25: 1 | E25: 1 | F25: 1 | G25: 1 | H25: 1 | I25: 1 | J25: 1 | K25: 1 | L25: 1 | M25: 1 | N25: 1
A26: Question 25 | B26: 0 | C26: 9.9708791 | D26: 1 | E26: 0 | F26: 1 | G26: 'NA | H26: 1 | I26: 'NA | J26: 1 | K26: 1 | L26: 1 | M26: 1 | N26: 1 | O26: Primary KC alignment: The problem requires solving algebraic equations with variables (4x, 5x) and cross-multiplication, which goes beyond Primary 6 level ratio work of finding missing terms in simple equivalent ratios. Synergy: The addition component (adding 6 girls) is trivial and doesn't work in tandem with ratio concepts - it's just a setup step, not requiring meaningful integration of both knowledge components. Grade alignment: This problem requires algebraic thinking, variable manipulation, and cross-multiplication which are typically Secondary 1-2 concepts, not Primary 6 level mathematics.
A27: Question 26 | B27: 0 | C27: 9.3064461 | D27: 1 | E27: 1 | F27: 1 | G27: 1 | H27: 1 | I27: 1 | J27: 1 | K27: 1 | L27: 1 | M27: 1 | N27: 1
A28: Question 27 | B28: 0 | C28: 10.233713 | D28: 1 | E28: 1 | F28: 1 | G28: 0 | H28: 1 | I28: 1 | J28: 1 | K28: 1 | L28: 1 | M28: 1 | N28: 1 | O28: The problem lacks synergy between primary and secondary knowledge components. Parts (a) and (b) are independent calculations that do not build upon each other. Part (c) simply asks for addition of the results rather than requiring integrated use of both fraction multiplication and addition skills.
A29: Question 28 | B29: 0 | C29: 11.918844 | D29: 1 | E29: 1 | F29: 1 | G29: 0 | H29: 1 | I29: 1 | J29: 1 | K29: 1 | L29: 1 | M29: 1 | N29: 1 | O29: The two parts of the problem work independently rather than in tandem. Part (a) requires addition of 1234 + 956 + 1087 = 3277, while part (b) requires comparing 1234, 956, and 1087 to find 1234 is highest and 956 is lowest. The result from part (a) is not used in part (b), so the knowledge components are not used together to solve the problem.
A30: Question 29 | B30: 0 | C30: 10.594735 | D30: 0 | E30: 'NA | F30: 'NA | G30: 'NA | H30: 'NA | I30: 'NA | J30: 'NA | K30: 'NA | L30: 'NA | M30: 'NA | N30: 'NA | O30: Answerability: Conflicting information - 5/6 + 1/4 = 13/12 hours not 1 hour as stated. Synergy: Questions are independent rather than connected where one result feeds into the next question.
A31: Question 30 | B31: 0 | C31: 11.2432 | D31: 1 | E31: 1 | F31: 1 | G31: 0 | H31: 1 | I31: 1 | J31: 1 | K31: 1 | L31: 1 | M31: 1 | N31: 1 | O31: Synergy: The division result 246/3=82 boxes is not used in the subtraction step 246-18=228. The two knowledge components work independently rather than in tandem.
A32: Question 31 | B32: 0 | C32: 2.806071 | D32: 1 | E32: 1 | F32: 1 | G32: 1 | H32: 1 | I32: 1 | J32: 1 | K32: 1 | L32: 1 | M32: 1 | N32: 1
A33: Question 32 | B33: 0 | C33: 10.868348 | D33: 1 | E33: 1 | F33: 0 | G33: 'NA | H33: 1 | I33: 1 | J33: 1 | K33: 1 | L33: 1 | M33: 1 | N33: 1 | O33: Secondary KC alignment: The problem does not prominently feature multiplying whole numbers as a key skill - only basic multiplication like 4*18=72 is needed. Synergy: The secondary KC (multiplication of whole numbers) is not meaningfully integrated with the primary KC (inverse proportion) to add substantial complexity to the problem.
A34: Question 33 | B34: 0 | C34: 10.416202 | D34: 1 | E34: 1 | F34: 1 | G34: 1 | H34: 1 | I34: 1 | J34: 1 | K34: 1 | L34: 1 | M34: 1 | N34: 1
A35: Question 34 | B35: 0 | C35: 2.7544601 | D35: 1 | E35: 1 | F35: 1 | G35: 1 | H35: 1 | I35: 1 | J35: 1 | K35: 1 | L35: 1 | M35: 1 | N35: 1
A36: Question 35 | B36: 0 | C36: 12.341551 | D36: 1 | E36: 1 | F36: 1 | G36: 1 | H36: 1 | I36: 0 | J36: 1 | K36: 1 | L36: 1 | M36: 1 | N36: 1 | O36: Grade alignment issue: The problem requires understanding of arithmetic sequences and algebraic expressions with variables (finding nth term formula), which is typically taught in Secondary 2-3 level in Singapore math curriculum. This may be too advanced for Secondary O-level 1 students who are just beginning to learn basic algebraic concepts.
A37: Question 36 | B37: 0 | C37: 2.6710432 | D37: 1 | E37: 1 | F37: 1 | G37: 1 | H37: 1 | I37: 1 | J37: 1 | K37: 1 | L37: 1 | M37: 1 | N37: 1
A38: Question 37 | B38: 0 | C38: 12.524447 | D38: 0 | E38: 'NA | F38: 'NA | G38: 'NA | H38: 'NA | I38: 'NA | J38: 'NA | K38: 'NA | L38: 'NA | M38: 'NA | N38: 'NA | O38: The problem contains conflicting information. From ratio 2.5:1.5 with total 2 hours, free throws = 1.25 hours and dribbling = 0.75 hours, giving difference of 0.5 hours. But problem states difference is 0.8 hours. These constraints are incompatible, making the problem unsolvable.
A39: Question 38 | B39: 0 | C39: 12.123802 | D39: 1 | E39: 1 | F39: 1 | G39: 0 | H39: 1 | I39: 1 | J39: 1 | K39: 1 | L39: 1 | M39: 1 | N39: 1 | O39: The two questions are independent of each other. Part (b) can be solved without using the result from part (a), as it only requires adding the painting time on the last day (2 1/2 hours) with the sketching time (3/4 hour). True synergy would require part (b) to use the total painting time calculated in part (a).
A40: Question 39 | B40: 0 | C40: 4.7286177 | D40: 1 | E40: 1 | F40: 1 | G40: 1 | H40: 1 | I40: 0 | J40: 1 | K40: 1 | L40: 1 | M40: 1 | N40: 1 | O40: Grade alignment: The problem involves matrices operations (scalar multiplication and matrix addition) which are typically introduced at Secondary O-level 1/2 or earlier, making it too basic for Secondary O-level 3/4 students who would be expected to handle more advanced matrix concepts like matrix multiplication, determinants, or inverse matrices.
...

Sheet recreation_v2_common_2
A1: Question | B1: status | C1: response_time | D1: answerability | E1: primary_kc_alignment | F1: secondary_kc_alignment | G1: synergy | H1: topic_alignment | I1: grade_alignment | J1: real_world_feasibility | K1: clarity | L1: conciseness_and_relevance | M1: language_quality | N1: content_appropriateness | O1: explanation
A2: Question 1 | B2: 0 | C2: 2.7177205 | D2: 1 | E2: 1 | F2: 1 | G2: 1 | H2: 1 | I2: 1 | J2: 1 | K2: 1 | L2: 1 | M2: 1 | N2: 1
A3: Question 2 | B3: 0 | C3: 7.3437152 | D3: 0 | E3: 'NA | F3: 'NA | G3: 'NA | H3: 'NA | I3: 'NA | J3: 'NA | K3: 'NA | L3: 'NA | M3: 'NA | N3: 'NA | O3: Answerability: The problem contains conflicting information. The setup states Alvin divides his time equally among as many songs as possible, but then part (b) asks about spending 2/3 of practice time on the first song only, which contradicts equal division. Synergy: The two questions are not properly connected. Question (a) uses division of fractions 3/4 ÷ 1/8 = 6 songs, but question (b) uses multiplication 3/4 × 2/3 = 1/2 hour independently without using the result from part (a). Real-world feasibility: It is unrealistic for someone to first divide practice time equally among multiple songs and then decide to spend 2/3 of total time on just one song. Clarity: The problem statement is ambiguous about whether the 2/3 refers to the time allocated per song from equal division or 2/3 of the total 3/4 hour.
A4: Question 3 | B4: 0 | C4: 10.913837 | D4: 1 | E4: 1 | F4: 1 | G4: 1 | H4: 1 | I4: 1 | J4: 1 | K4: 1 | L4: 1 | M4: 1 | N4: 1
A5: Question 4 | B5: 0 | C5: 10.065275 | D5: 1 | E5: 1 | F5: 1 | G5: 1 | H5: 1 | I5: 1 | J5: 1 | K5: 1 | L5: 1 | M5: 1 | N5: 1
A6: Question 5 | B6: 0 | C6: 2.720664 | D6: 1 | E6: 1 | F6: 1 | G6: 1 | H6: 1 | I6: 1 | J6: 1 | K6: 1 | L6: 1 | M6: 1 | N6: 1
A7: Question 6 | B7: 0 | C7: 2.8154137 | D7: 1 | E7: 1 | F7: 1 | G7: 1 | H7: 1 | I7: 1 | J7: 1 | K7: 1 | L7: 1 | M7: 1 | N7: 1
A8: Question 7 | B8: 0 | C8: 8.529613 | D8: 1 | E8: 1 | F8: 1 | G8: 1 | H8: 1 | I8: 1 | J8: 1 | K8: 1 | L8: 1 | M8: 1 | N8: 1
A9: Question 8 | B9: 0 | C9: 9.1517496 | D9: 1 | E9: 1 | F9: 1 | G9: 1 | H9: 1 | I9: 1 | J9: 1 | K9: 1 | L9: 1 | M9: 1 | N9: 1
A10: Question 9 | B10: 0 | C10: 11.157462 | D10: 1 | E10: 1 | F10: 1 | G10: 0 | H10: 1 | I10: 0 | J10: 1 | K10: 1 | L10: 1 | M10: 1 | N10: 1 | O10: Synergy: The median and percentile calculations use the same dataset but do not build upon each other - part (a) result is not needed for part (b). Grade Alignment: Percentiles and quartiles are typically taught at higher secondary levels, not Secondary O-level 2 where basic statistics like mean and median are more appropriate.
A11: Question 10 | B11: 0 | C11: 2.7150619 | D11: 1 | E11: 1 | F11: 1 | G11: 1 | H11: 1 | I11: 1 | J11: 1 | K11: 1 | L11: 1 | M11: 1 | N11: 1
A12: Question 11 | B12: 0 | C12: 5.3452404 | D12: 1 | E12: 0 | F12: 1 | G12: 'NA | H12: 1 | I12: 'NA | J12: 1 | K12: 1 | L12: 1 | M12: 1 | N12: 1 | O12: Primary KC Alignment: The primary knowledge component is subtraction of mixed numbers, but part (a) only requires addition of mixed numbers (4 2/3 + 1 5/6), making addition the main focus rather than subtraction. Synergy: The two knowledge components are not used in tandem. Part (a) uses only addition of mixed numbers, while part (b) uses only subtraction of mixed numbers. The operations are sequential rather than integrated within the same problem-solving process.
A13: Question 12 | B13: 0 | C13: 4.5200787 | D13: 1 | E13: 1 | F13: 1 | G13: 1 | H13: 1 | I13: 0 | J13: 1 | K13: 1 | L13: 1 | M13: 1 | N13: 1 | O13: Grade Alignment: The problem involves matrix operations which are typically taught at Secondary O-level 4/5 or A-level, not Secondary O-level 3/4. Matrix subtraction and addition are advanced topics that exceed the mathematical knowledge expected for O-level 3/4 students in Singapore math syllabus.
A14: Question 13 | B14: 0 | C14: 2.7858157 | D14: 1 | E14: 1 | F14: 1 | G14: 1 | H14: 1 | I14: 1 | J14: 1 | K14: 1 | L14: 1 | M14: 1 | N14: 1
A15: Question 14 | B15: 0 | C15: 4.7111115 | D15: 1 | E15: 1 | F15: 0 | G15: 'NA | H15: 1 | I15: 1 | J15: 1 | K15: 1 | L15: 1 | M15: 1 | N15: 1 | O15: Secondary KC Alignment: The problem only requires division (70/250) and multiplication by 100 to convert to percentage. The intended secondary KC of whole number multiplication is not needed for solving this problem. Synergy: Since the secondary KC of whole number multiplication is not required, there is no synergy between the primary and secondary knowledge components in solving this problem.
A16: Question 15 | B16: 0 | C16: 10.94181 | D16: 1 | E16: 0 | F16: 1 | G16: 'NA | H16: 1 | I16: 'NA | J16: 1 | K16: 1 | L16: 1 | M16: 1 | N16: 1 | O16: Primary KC misalignment: The problem requires 3.275 x 20 which is general decimal multiplication, not specifically multiplying by multiples of 10, 100, or 1000 as intended. The calculation 3.275 x 20 does not align with the intended primary knowledge component.
A17: Question 16 | B17: 0 | C17: 10.532337 | D17: 1 | E17: 1 | F17: 1 | G17: 1 | H17: 1 | I17: 1 | J17: 1 | K17: 1 | L17: 1 | M17: 1 | N17: 1
A18: Question 17 | B18: 0 | C18: 10.893177 | D18: 1 | E18: 1 | F18: 1 | G18: 1 | H18: 1 | I18: 1 | J18: 1 | K18: 1 | L18: 1 | M18: 1 | N18: 1
A19: Question 18 | B19: 0 | C19: 12.670623 | D19: 1 | E19: 1 | F19: 0 | G19: 'NA | H19: 0 | I19: 1 | J19: 0 | K19: 1 | L19: 1 | M19: 1 | N19: 1 | O19: Secondary KC: Part b uses multiplication 2/5 * 12 and subtraction 12 - 4.8, not fraction subtraction. Topic: Making bookmarks is craft activity, not recreation like sports/games/music. Real-world: Result 7.2 bookmarks is unrealistic - cannot have fractional bookmarks.
A20: Question 19 | B20: 0 | C20: 9.7302074 | D20: 1 | E20: 1 | F20: 1 | G20: 1 | H20: 1 | I20: 1 | J20: 1 | K20: 1 | L20: 1 | M20: 1 | N20: 1
A21: Question 20 | B21: 0 | C21: 9.3709505 | D21: 1 | E21: 1 | F21: 1 | G21: 1 | H21: 1 | I21: 1 | J21: 1 | K21: 1 | L21: 1 | M21: 1 | N21: 1
A22: Question 21 | B22: 0 | C22: 2.6964796 | D22: 1 | E22: 1 | F22: 1 | G22: 1 | H22: 1 | I22: 1 | J22: 1 | K22: 1 | L22: 1 | M22: 1 | N22: 1
A23: Question 22 | B23: 0 | C23: 13.828212 | D23: 1 | E23: 1 | F23: 1 | G23: 1 | H23: 1 | I23: 0 | J23: 1 | K23: 1 | L23: 1 | M23: 1 | N23: 1 | O23: Grade Alignment: The problem involves basic percentage calculation (25% of 80) and simple multiplication (20 x 15), which are typically primary school level concepts. For Secondary O-level 1 students, the mathematical complexity should be significantly higher, involving more sophisticated percentage applications or multi-step problem solving.
A24: Question 23 | B24: 0 | C24: 11.815254 | D24: 1 | E24: 1 | F24: 1 | G24: 0 | H24: 1 | I24: 1 | J24: 1 | K24: 1 | L24: 1 | M24: 1 | N24: 1 | O24: Synergy: The two parts (a) and (b) can be solved independently. Part (a) uses 7.85 - 6.43 = 1.42, while part (b) orders all three values 6.43 < 7.802 < 7.85. The answer from part (a) is not needed to solve part (b), so the questions are not connected in tandem.
A25: Question 24 | B25: 0 | C25: 9.6581011 | D25: 1 | E25: 1 | F25: 1 | G25: 1 | H25: 1 | I25: 1 | J25: 1 | K25: 1 | L25: 1 | M25: 1 | N25: 1
A26: Question 25 | B26: 0 | C26: 10.424118 | D26: 1 | E26: 1 | F26: 1 | G26: 1 | H26: 1 | I26: 1 | J26: 1 | K26: 1 | L26: 1 | M26: 1 | N26: 1
A27: Question 26 | B27: 0 | C27: 2.7581527 | D27: 1 | E27: 1 | F27: 1 | G27: 1 | H27: 1 | I27: 1 | J27: 1 | K27: 1 | L27: 1 | M27: 1 | N27: 1
A28: Question 27 | B28: 0 | C28: 13.015867 | D28: 1 | E28: 1 | F28: 1 | G28: 1 | H28: 1 | I28: 1 | J28: 0 | K28: 1 | L28: 1 | M28: 1 | N28: 1 | O28: Real-world plausibility fails because playing 5/2 = 2.5 games of badminton is unrealistic. While incomplete games exist, expressing this as exactly 5/2 games does not mirror how people typically count games in reality.
A29: Question 28 | B29: 0 | C29: 11.536035 | D29: 1 | E29: 1 | F29: 1 | G29: 0 | H29: 1 | I29: 1 | J29: 1 | K29: 1 | L29: 1 | M29: 1 | N29: 1 | O29: The two parts of the problem work independently rather than in tandem. Part (a) involves addition while part (b) involves comparison, but the result from part (a) is not needed to solve part (b), and the comparison result is not used in the addition. The questions are not connected such that early results serve as input for later questions.
A30: Question 29 | B30: 0 | C30: 10.586619 | D30: 0 | E30: 'NA | F30: 'NA | G30: 'NA | H30: 'NA | I30: 'NA | J30: 'NA | K30: 'NA | L30: 'NA | M30: 'NA | N30: 'NA | O30: Answerability: Conflicting information - 5/6 + 1/4 = 13/12 = 1 1/12 hours, not 1 hour as stated. Synergy: Questions (a) and (b) are independent and do not require results from one to solve the other.
A31: Question 30 | B31: 0 | C31: 12.605166 | D31: 0 | E31: 'NA | F31: 'NA | G31: 'NA | H31: 'NA | I31: 'NA | J31: 'NA | K31: 'NA | L31: 'NA | M31: 'NA | N31: 'NA | O31: Answerability: The problem has unclear logic - if each box holds 3 balls and balls are packed equally into boxes, the relationship between 246 balls and the boxes is ambiguous. Synergy: The division and subtraction operations are not properly connected due to the unclear packing arrangement. Clarity: The packing process is ambiguously described, making it unclear whether 246/3 gives number of boxes or balls per box.
A32: Question 31 | B32: 0 | C32: 2.7717295 | D32: 1 | E32: 1 | F32: 1 | G32: 1 | H32: 1 | I32: 1 | J32: 1 | K32: 1 | L32: 1 | M32: 1 | N32: 1
A33: Question 32 | B33: 0 | C33: 12.547118 | D33: 1 | E33: 1 | F33: 0 | G33: 'NA | H33: 1 | I33: 0 | J33: 1 | K33: 1 | L33: 1 | M33: 1 | N33: 1 | O33: Secondary KC alignment fails because the problem primarily requires division (72/6, 72/8) rather than multiplication of whole numbers. Synergy fails because the two knowledge components do not work effectively together - inverse proportion is the dominant concept while multiplication is not prominently featured. Grade alignment fails because inverse proportion is typically taught at Primary 6 level in Singapore, making it too basic for Secondary O-level 2 students.
A34: Question 33 | B34: 0 | C34: 8.9250138 | D34: 1 | E34: 1 | F34: 1 | G34: 1 | H34: 1 | I34: 1 | J34: 1 | K34: 1 | L34: 1 | M34: 1 | N34: 1
A35: Question 34 | B35: 0 | C35: 2.6673152 | D35: 1 | E35: 1 | F35: 1 | G35: 1 | H35: 1 | I35: 1 | J35: 1 | K35: 1 | L35: 1 | M35: 1 | N35: 1
A36: Question 35 | B36: 0 | C36: 4.8393595 | D36: 1 | E36: 1 | F36: 1 | G36: 1 | H36: 1 | I36: 0 | J36: 1 | K36: 1 | L36: 1 | M36: 1 | N36: 1 | O36: Grade Alignment: This problem is too advanced for Secondary O-level 1 students. Finding algebraic expressions for nth terms of arithmetic sequences and using algebraic notation with variables like n is typically covered in higher secondary grades (O-level 2-3). Primary 1 students work with basic arithmetic operations and simple number patterns, not algebraic expressions.
A37: Question 36 | B37: 0 | C37: 10.259897 | D37: 1 | E37: 1 | F37: 1 | G37: 1 | H37: 1 | I37: 1 | J37: 1 | K37: 1 | L37: 1 | M37: 1 | N37: 1
A38: Question 37 | B38: 0 | C38: 11.632957 | D38: 0 | E38: 'NA | F38: 'NA | G38: 'NA | H38: 'NA | I38: 'NA | J38: 'NA | K38: 'NA | L38: 'NA | M38: 'NA | N38: 'NA | O38: Answerability: The given information creates conflicting constraints. From ratio 2.5:1.5 and total time 2 hours, the difference should be 0.5 hours, but problem states 0.8 hours difference. Secondary KC alignment: While 0.8 is a decimal, the actual solving process uses fraction arithmetic (5/3, 8/3) rather than decimal subtraction operations. The secondary knowledge component of decimal subtraction is not meaningfully engaged. Synergy: The ratio constraint and decimal difference constraint conflict rather than work together. The decimal information (0.8) cannot be properly integrated with the ratio-based solution. Grade alignment: This problem requires simultaneous equation solving and algebraic manipulation that exceeds typical Secondary O-level 1 capabilities, being more appropriate for higher secondary levels.
A39: Question 38 | B39: 0 | C39: 8.5646002 | D39: 1 | E39: 1 | F39: 1 | G39: 1 | H39: 1 | I39: 1 | J39: 1 | K39: 1 | L39: 1 | M39: 1 | N39: 1
A40: Question 39 | B40: 0 | C40: 4.5898228 | D40: 1 | E40: 1 | F40: 1 | G40: 1 | H40: 1 | I40: 0 | J40: 1 | K40: 1 | L40: 1 | M40: 1 | N40: 1 | O40: Grade alignment: This problem involves matrices operations (scalar multiplication and matrix addition) which are typically taught at higher secondary levels or pre-university mathematics, not at Primary grade levels. The intended grade appears to be Secondary O-level 3/4 but matrices are generally introduced in more advanced mathematics courses beyond primary education.
...

Sheet recreation_v2_common_3
A1: Question | B1: status | C1: response_time | D1: answerability | E1: primary_kc_alignment | F1: secondary_kc_alignment | G1: synergy | H1: topic_alignment | I1: grade_alignment | J1: real_world_feasibility | K1: clarity | L1: conciseness_and_relevance | M1: language_quality | N1: content_appropriateness | O1: explanation
A2: Question 1 | B2: 0 | C2: 2.7940016 | D2: 1 | E2: 1 | F2: 1 | G2: 1 | H2: 1 | I2: 1 | J2: 1 | K2: 1 | L2: 1 | M2: 1 | N2: 1
A3: Question 2 | B3: 0 | C3: 7.0621176 | D3: 0 | E3: 'NA | F3: 'NA | G3: 'NA | H3: 'NA | I3: 'NA | J3: 'NA | K3: 'NA | L3: 'NA | M3: 'NA | N3: 'NA | O3: Answerability: The problem contains conflicting information. It states Alvin divides time equally among songs, but then spends 2/3 of practice time on first song only, which contradicts equal division. Synergy: Part (a) uses division (3/4 ÷ 1/8 = 6 songs) but part (b) uses multiplication (3/4 × 2/3 = 1/2 hour) independently. The answer from part (a) is not needed for part (b), so questions are not connected. Real-world feasibility: It is unrealistic to spend 2/3 of total practice time on just one song when planning to practice 6 different songs equally. Clarity: The problem setup is ambiguous - unclear whether equal division applies before or after the 2/3 allocation to first song.
A4: Question 3 | B4: 0 | C4: 9.4372122 | D4: 1 | E4: 1 | F4: 1 | G4: 1 | H4: 1 | I4: 1 | J4: 1 | K4: 1 | L4: 1 | M4: 1 | N4: 1
A5: Question 4 | B5: 0 | C5: 2.690577 | D5: 1 | E5: 1 | F5: 1 | G5: 1 | H5: 1 | I5: 1 | J5: 1 | K5: 1 | L5: 1 | M5: 1 | N5: 1
A6: Question 5 | B6: 0 | C6: 2.5708678 | D6: 1 | E6: 1 | F6: 1 | G6: 1 | H6: 1 | I6: 1 | J6: 1 | K6: 1 | L6: 1 | M6: 1 | N6: 1
A7: Question 6 | B7: 0 | C7: 2.7724252 | D7: 1 | E7: 1 | F7: 1 | G7: 1 | H7: 1 | I7: 1 | J7: 1 | K7: 1 | L7: 1 | M7: 1 | N7: 1
A8: Question 7 | B8: 0 | C8: 10.689037 | D8: 1 | E8: 1 | F8: 1 | G8: 1 | H8: 1 | I8: 1 | J8: 1 | K8: 1 | L8: 1 | M8: 1 | N8: 1
A9: Question 8 | B9: 0 | C9: 12.651798 | D9: 1 | E9: 0 | F9: 1 | G9: 'NA | H9: 1 | I9: 'NA | J9: 1 | K9: 1 | L9: 1 | M9: 1 | N9: 1 | O9: Primary KC alignment fails because the multiplications required (135 x 7 and 248 x 6) are only 3-digit by 1-digit, which does not fully utilize the intended primary knowledge component that specifies up to 4 digits by 1 digit OR up to 3 digits by 2 digits.
A10: Question 9 | B10: 0 | C10: 10.584475 | D10: 1 | E10: 1 | F10: 1 | G10: 0 | H10: 1 | I10: 1 | J10: 1 | K10: 1 | L10: 1 | M10: 1 | N10: 1 | O10: The primary and secondary knowledge components operate independently on the same dataset rather than being used in tandem. The median calculation in part (a) does not inform or connect to the percentile calculations in part (b), lacking the required synergy where results from earlier questions should be used as known information for later questions.
A11: Question 10 | B11: 0 | C11: 2.7787445 | D11: 1 | E11: 1 | F11: 1 | G11: 1 | H11: 1 | I11: 1 | J11: 1 | K11: 1 | L11: 1 | M11: 1 | N11: 1
A12: Question 11 | B12: 0 | C12: 9.1818798 | D12: 1 | E12: 1 | F12: 1 | G12: 1 | H12: 1 | I12: 1 | J12: 1 | K12: 1 | L12: 1 | M12: 1 | N12: 1
A13: Question 12 | B13: 0 | C13: 4.4947371 | D13: 1 | E13: 1 | F13: 1 | G13: 1 | H13: 1 | I13: 0 | J13: 1 | K13: 1 | L13: 1 | M13: 1 | N13: 1 | O13: Grade Alignment: The problem involves matrix operations which are typically taught at upper secondary or pre-university level, not at Primary level. The Singapore Primary syllabus (Grades 1-6) does not include matrices as a topic. This problem would be more suitable for Secondary 3-4 or Junior College level students.
A14: Question 13 | B14: 0 | C14: 2.7859581 | D14: 1 | E14: 1 | F14: 1 | G14: 1 | H14: 1 | I14: 1 | J14: 1 | K14: 1 | L14: 1 | M14: 1 | N14: 1
A15: Question 14 | B15: 0 | C15: 11.403034 | D15: 1 | E15: 1 | F15: 0 | G15: 'NA | H15: 1 | I15: 1 | J15: 1 | K15: 1 | L15: 1 | M15: 1 | N15: 1 | O15: Secondary KC alignment: The problem does not require multiplying whole numbers as a separate mathematical concept - the solution uses division (70/250) and percentage conversion, not whole number multiplication. Synergy: Since the secondary KC is not present, there is no synergy between primary and secondary knowledge components.
A16: Question 15 | B16: 0 | C16: 12.001446 | D16: 1 | E16: 0 | F16: 1 | G16: 'NA | H16: 1 | I16: 'NA | J16: 1 | K16: 1 | L16: 1 | M16: 1 | N16: 1 | O16: Primary KC alignment: The problem requires 3.275 * 20, but the intended primary KC is specifically about multiplying decimals by 10, 100, 1000 and their multiples. While 20 is technically a multiple of 10, this multiplication does not demonstrate the key concept of decimal place movement that characterizes multiplying by powers of 10 and their multiples.
A17: Question 16 | B17: 0 | C17: 9.6668196 | D17: 1 | E17: 1 | F17: 1 | G17: 1 | H17: 1 | I17: 1 | J17: 1 | K17: 1 | L17: 1 | M17: 1 | N17: 1
A18: Question 17 | B18: 0 | C18: 13.051854 | D18: 1 | E18: 1 | F18: 1 | G18: 1 | H18: 1 | I18: 1 | J18: 1 | K18: 0 | L18: 1 | M18: 1 | N18: 1 | O18: Part (a) asks how many more km Jayden had left than Sarah, but Sarah actually had more remaining distance (1 1/6 km vs 1 1/3 km). This creates ambiguity about whether the answer should be negative or if the question intends the absolute difference.
A19: Question 18 | B19: 0 | C19: 8.1264899 | D19: 1 | E19: 1 | F19: 0 | G19: 'NA | H19: 0 | I19: 1 | J19: 0 | K19: 1 | L19: 1 | M19: 1 | N19: 1 | O19: Secondary KC alignment: Part (b) requires fraction multiplication (2/5 * 12) rather than fraction subtraction as intended. Synergy: The secondary KC (fraction subtraction) is not actually needed to solve the problem since part (b) uses multiplication and whole number subtraction instead. Topic alignment: Making bookmarks does not belong to recreation activities like sports, games, exercises, music, movies, dancing, painting, fishing - it is more of a craft/hobby activity. Real-world feasibility: Giving away 2/5 of 12 bookmarks results in 4.8 bookmarks, meaning giving away a fractional bookmark which is unrealistic.
A20: Question 19 | B20: 0 | C20: 8.7332776 | D20: 1 | E20: 1 | F20: 1 | G20: 1 | H20: 1 | I20: 1 | J20: 1 | K20: 1 | L20: 1 | M20: 1 | N20: 1
A21: Question 20 | B21: 0 | C21: 9.0387173 | D21: 1 | E21: 1 | F21: 1 | G21: 1 | H21: 1 | I21: 1 | J21: 1 | K21: 1 | L21: 1 | M21: 1 | N21: 1
A22: Question 21 | B22: 0 | C22: 9.3517365 | D22: 1 | E22: 1 | F22: 1 | G22: 1 | H22: 1 | I22: 1 | J22: 1 | K22: 1 | L22: 1 | M22: 1 | N22: 1
A23: Question 22 | B23: 0 | C23: 5.0306165 | D23: 1 | E23: 1 | F23: 1 | G23: 1 | H23: 1 | I23: 0 | J23: 1 | K23: 1 | L23: 1 | M23: 1 | N23: 1 | O23: Grade Alignment: This problem is too basic for Secondary O-level 1 students. Finding 25% of 80 (which equals 20) and multiplying 20 x 15 (which equals 300) are concepts typically mastered in primary grades 4-6. Secondary O-level 1 students would be expected to handle more complex percentage problems involving compound percentages, percentage profit/loss, or multi-step percentage calculations.
A24: Question 23 | B24: 0 | C24: 11.303157 | D24: 1 | E24: 1 | F24: 1 | G24: 0 | H24: 1 | I24: 1 | J24: 1 | K24: 1 | L24: 1 | M24: 1 | N24: 1 | O24: Synergy: The two parts of the problem use different knowledge components but do not build upon each other. Part (b) does not use the result from part (a) as input, so they work independently rather than in tandem.
A25: Question 24 | B25: 0 | C25: 9.8973794 | D25: 1 | E25: 1 | F25: 1 | G25: 1 | H25: 1 | I25: 1 | J25: 1 | K25: 1 | L25: 1 | M25: 1 | N25: 1
A26: Question 25 | B26: 0 | C26: 11.578887 | D26: 1 | E26: 1 | F26: 1 | G26: 1 | H26: 1 | I26: 1 | J26: 1 | K26: 1 | L26: 1 | M26: 1 | N26: 1
A27: Question 26 | B27: 0 | C27: 9.4541156 | D27: 1 | E27: 1 | F27: 1 | G27: 1 | H27: 1 | I27: 1 | J27: 1 | K27: 1 | L27: 1 | M27: 1 | N27: 1
A28: Question 27 | B28: 0 | C28: 9.9664359 | D28: 1 | E28: 1 | F28: 1 | G28: 0 | H28: 1 | I28: 1 | J28: 0 | K28: 1 | L28: 1 | M28: 1 | N28: 1 | O28: Synergy: Primary and secondary knowledge components are used separately in different parts rather than in tandem. Real-world feasibility: Each badminton game lasting 7/3 hours (about 2.33 hours) is unrealistic as typical badminton games last 30-60 minutes.
A29: Question 28 | B29: 0 | C29: 11.848651 | D29: 1 | E29: 1 | F29: 1 | G29: 0 | H29: 1 | I29: 1 | J29: 1 | K29: 1 | L29: 1 | M29: 1 | N29: 1 | O29: The two knowledge components work independently rather than in tandem. Part (a) uses addition while part (b) uses comparison, but the total from part (a) is not needed to solve part (b). The questions are not connected such that earlier results inform later questions.
A30: Question 29 | B30: 0 | C30: 8.1379664 | D30: 0 | E30: 'NA | F30: 'NA | G30: 'NA | H30: 'NA | I30: 'NA | J30: 'NA | K30: 'NA | L30: 'NA | M30: 'NA | N30: 'NA | O30: ANSWERABILITY: The problem contains conflicting information. It states Elaine spent 5/6 + 1/4 = 13/12 = 1 1/12 hours total, but also claims she spent exactly 1 hour total. These contradict each other (13/12 ≠ 12/12). CLARITY: The contradiction between calculated total time (13/12 hours) and stated total time (1 hour) creates ambiguity about which information is correct. CONCISENESS AND RELEVANCE: The statement about spending a total of 1 hour is irrelevant and contradictory information that confuses rather than helps solve the problem.
A31: Question 30 | B31: 0 | C31: 10.447739 | D31: 1 | E31: 1 | F31: 1 | G31: 0 | H31: 1 | I31: 0 | J31: 1 | K31: 1 | L31: 1 | M31: 1 | N31: 1 | O31: Synergy: The division (246/3=82) and subtraction (246-18=228) operations work independently rather than in tandem. The result of division is not used in the subtraction step. Grade Alignment: 3-digit by 1-digit division (246/3) is typically taught in Primary 4, not Primary 3. Primary 3 students usually work with simpler division problems.
A32: Question 31 | B32: 0 | C32: 2.7131121 | D32: 1 | E32: 1 | F32: 1 | G32: 1 | H32: 1 | I32: 1 | J32: 1 | K32: 1 | L32: 1 | M32: 1 | N32: 1
A33: Question 32 | B33: 0 | C33: 10.524487 | D33: 1 | E33: 1 | F33: 0 | G33: 'NA | H33: 1 | I33: 1 | J33: 1 | K33: 1 | L33: 1 | M33: 1 | N33: 1 | O33: Secondary KC alignment fails because while basic multiplication occurs in the solution (72/6=12, 72/8=9), the problem does not prominently feature multiplying whole numbers as a significant knowledge component that adds complexity to the problem solving process.
A34: Question 33 | B34: 0 | C34: 9.0910161 | D34: 1 | E34: 1 | F34: 1 | G34: 1 | H34: 1 | I34: 1 | J34: 1 | K34: 1 | L34: 1 | M34: 1 | N34: 1
A35: Question 34 | B35: 0 | C35: 10.531545 | D35: 1 | E35: 1 | F35: 1 | G35: 1 | H35: 1 | I35: 1 | J35: 1 | K35: 1 | L35: 1 | M35: 1 | N35: 1
A36: Question 35 | B36: 0 | C36: 9.6522086 | D36: 1 | E36: 1 | F36: 1 | G36: 1 | H36: 1 | I36: 1 | J36: 1 | K36: 1 | L36: 1 | M36: 1 | N36: 1
A37: Question 36 | B37: 0 | C37: 10.072319 | D37: 1 | E37: 1 | F37: 1 | G37: 1 | H37: 1 | I37: 1 | J37: 1 | K37: 1 | L37: 1 | M37: 1 | N37: 1
A38: Question 37 | B38: 0 | C38: 12.461843 | D38: 0 | E38: 'NA | F38: 'NA | G38: 'NA | H38: 'NA | I38: 'NA | J38: 'NA | K38: 'NA | L38: 'NA | M38: 'NA | N38: 'NA | O38: Answerability: The given conditions are contradictory. From ratio 2.5:1.5 with total 2 hours, free throws = 1.25 hours and dribbling = 0.75 hours, giving difference of 0.5 hours, but problem states difference is 0.8 hours. Synergy: Due to conflicting information, the primary and secondary knowledge components cannot work together to solve the problem properly.
A39: Question 38 | B39: 0 | C39: 8.9046466 | D39: 1 | E39: 1 | F39: 1 | G39: 1 | H39: 1 | I39: 1 | J39: 1 | K39: 1 | L39: 1 | M39: 1 | N39: 1
A40: Question 39 | B40: 0 | C40: 5.0285087 | D40: 1 | E40: 1 | F40: 1 | G40: 1 | H40: 1 | I40: 0 | J40: 1 | K40: 1 | L40: 1 | M40: 1 | N40: 1 | O40: Grade Alignment: This problem involves matrices operations (scalar multiplication and matrix addition) which are typically taught at Secondary 4/5 or Junior College level in Singapore, not at Primary level. The intended grade appears to be Primary 3/4 based on the format, but matrices are far beyond Primary school mathematics curriculum.
...

Sheet recreation_v2_common_4
A1: Question | B1: status | C1: response_time | D1: answerability | E1: primary_kc_alignment | F1: secondary_kc_alignment | G1: synergy | H1: topic_alignment | I1: grade_alignment | J1: real_world_feasibility | K1: clarity | L1: conciseness_and_relevance | M1: language_quality | N1: content_appropriateness | O1: explanation
A2: Question 1 | B2: 0 | C2: 2.7735593 | D2: 1 | E2: 1 | F2: 1 | G2: 1 | H2: 1 | I2: 1 | J2: 1 | K2: 1 | L2: 1 | M2: 1 | N2: 1
A3: Question 2 | B3: 0 | C3: 11.226758 | D3: 0 | E3: 'NA | F3: 'NA | G3: 'NA | H3: 'NA | I3: 'NA | J3: 'NA | K3: 'NA | L3: 'NA | M3: 'NA | N3: 'NA | O3: Answerability: The problem contains conflicting information - part (a) states time is divided equally among songs, but part (b) has 2/3 of total time spent on first song only, which contradicts equal division. Synergy: The two parts contradict each other logically, preventing proper connection between questions. Real-world feasibility: The contradiction makes the scenario unrealistic - cannot both divide time equally and spend 2/3 on one song.
A4: Question 3 | B4: 0 | C4: 9.6748328 | D4: 1 | E4: 1 | F4: 1 | G4: 1 | H4: 1 | I4: 1 | J4: 1 | K4: 1 | L4: 1 | M4: 1 | N4: 1
A5: Question 4 | B5: 0 | C5: 7.878248 | D5: 1 | E5: 1 | F5: 1 | G5: 1 | H5: 1 | I5: 1 | J5: 1 | K5: 1 | L5: 1 | M5: 1 | N5: 1
A6: Question 5 | B6: 0 | C6: 2.4598625 | D6: 1 | E6: 1 | F6: 1 | G6: 1 | H6: 1 | I6: 1 | J6: 1 | K6: 1 | L6: 1 | M6: 1 | N6: 1
A7: Question 6 | B7: 0 | C7: 9.360409 | D7: 1 | E7: 1 | F7: 1 | G7: 1 | H7: 1 | I7: 1 | J7: 1 | K7: 1 | L7: 1 | M7: 1 | N7: 1
A8: Question 7 | B8: 0 | C8: 10.928349 | D8: 1 | E8: 1 | F8: 1 | G8: 1 | H8: 1 | I8: 1 | J8: 1 | K8: 1 | L8: 1 | M8: 1 | N8: 1
A9: Question 8 | B9: 0 | C9: 2.7368925 | D9: 1 | E9: 1 | F9: 1 | G9: 1 | H9: 1 | I9: 1 | J9: 1 | K9: 1 | L9: 1 | M9: 1 | N9: 1
A10: Question 9 | B10: 0 | C10: 5.7621512 | D10: 1 | E10: 1 | F10: 1 | G10: 0 | H10: 1 | I10: 0 | J10: 1 | K10: 1 | L10: 1 | M10: 1 | N10: 1 | O10: Synergy: The two parts (a) and (b) are independent questions that do not require using results from part (a) to solve part (b). There is no connection between finding the median and finding quartiles in this problem structure. Grade_alignment: Finding percentiles and quartiles is typically introduced at Primary 6 level in Singapore math syllabus, making this problem too elementary for Secondary O-level 2 students who should be working with more advanced statistical concepts like standard deviation, probability distributions, or hypothesis testing.
A11: Question 10 | B11: 0 | C11: 2.7447343 | D11: 1 | E11: 1 | F11: 1 | G11: 1 | H11: 1 | I11: 1 | J11: 1 | K11: 1 | L11: 1 | M11: 1 | N11: 1
A12: Question 11 | B12: 0 | C12: 4.8526754 | D12: 1 | E12: 0 | F12: 1 | G12: 'NA | H12: 1 | I12: 'NA | J12: 1 | K12: 1 | L12: 1 | M12: 1 | N12: 1 | O12: Primary KC alignment fails because part (a) only requires addition of mixed numbers, not subtraction which is the intended primary KC. Synergy fails because the primary KC (subtraction) and secondary KC (addition) are not used in tandem - part (a) uses only addition, part (b) uses only subtraction, with no meaningful connection requiring both operations together to solve either question.
A13: Question 12 | B13: 0 | C13: 4.3163743 | D13: 1 | E13: 1 | F13: 1 | G13: 1 | H13: 1 | I13: 0 | J13: 1 | K13: 1 | L13: 1 | M13: 1 | N13: 1 | O13: Grade Alignment: The problem involves matrix operations which are typically taught at A-level or higher secondary mathematics, not at O-level 3/4. Matrix addition and subtraction are advanced topics that exceed the typical O-level mathematics curriculum which focuses more on basic algebra, geometry, and elementary functions.
A14: Question 13 | B14: 0 | C14: 2.7727604 | D14: 1 | E14: 1 | F14: 1 | G14: 1 | H14: 1 | I14: 1 | J14: 1 | K14: 1 | L14: 1 | M14: 1 | N14: 1
A15: Question 14 | B15: 0 | C15: 11.545491 | D15: 1 | E15: 1 | F15: 0 | G15: 'NA | H15: 1 | I15: 1 | J15: 1 | K15: 1 | L15: 1 | M15: 1 | N15: 1 | O15: Secondary KC alignment: Problem requires 70/250*100 = 28%, involving division and multiplication by 100 for percentage conversion, not multiplication of whole numbers as intended secondary KC. Synergy: Without proper secondary KC integration, no meaningful synergy between intended knowledge components exists.
A16: Question 15 | B16: 0 | C16: 11.276086 | D16: 1 | E16: 0 | F16: 1 | G16: 'NA | H16: 1 | I16: 'NA | J16: 1 | K16: 1 | L16: 1 | M16: 1 | N16: 1 | O16: Primary KC alignment fails because the problem requires calculating 3.275 * 20 = 65.5, which is standard decimal multiplication, not multiplication by 10, 100, 1000 or their multiples as specified in the intended Primary Knowledge Component.
A17: Question 16 | B17: 0 | C17: 10.276316 | D17: 1 | E17: 1 | F17: 1 | G17: 1 | H17: 1 | I17: 1 | J17: 1 | K17: 1 | L17: 1 | M17: 1 | N17: 1
A18: Question 17 | B18: 0 | C18: 10.180405 | D18: 1 | E18: 1 | F18: 1 | G18: 1 | H18: 1 | I18: 1 | J18: 1 | K18: 1 | L18: 1 | M18: 1 | N18: 1
A19: Question 18 | B19: 0 | C19: 10.788636 | D19: 1 | E19: 1 | F19: 0 | G19: 'NA | H19: 0 | I19: 1 | J19: 1 | K19: 1 | L19: 1 | M19: 1 | N19: 1 | O19: Secondary KC alignment: Part b requires 2/5 * 12 = 4.8 then 12 - 4.8 = 7.2, which involves subtracting decimals or whole numbers, not subtracting fractions as intended. Topic alignment: Making bookmarks is crafting/hobby activity, not recreation like sports, games, exercises, music, movies, dancing, painting, fishing.
A20: Question 19 | B20: 0 | C20: 9.7765841 | D20: 1 | E20: 1 | F20: 1 | G20: 1 | H20: 1 | I20: 1 | J20: 1 | K20: 1 | L20: 1 | M20: 1 | N20: 1
A21: Question 20 | B21: 0 | C21: 9.0327346 | D21: 1 | E21: 1 | F21: 1 | G21: 1 | H21: 1 | I21: 1 | J21: 1 | K21: 1 | L21: 1 | M21: 1 | N21: 1
A22: Question 21 | B22: 0 | C22: 9.5527074 | D22: 1 | E22: 1 | F22: 1 | G22: 1 | H22: 1 | I22: 1 | J22: 1 | K22: 1 | L22: 1 | M22: 1 | N22: 1
A23: Question 22 | B23: 0 | C23: 12.228829 | D23: 1 | E23: 1 | F23: 1 | G23: 1 | H23: 1 | I23: 0 | J23: 1 | K23: 1 | L23: 1 | M23: 1 | N23: 1 | O23: Grade Alignment: The problem involves basic 25% calculation and simple multiplication (20 * 15), which are Primary 5-6 level concepts, too elementary for Secondary O-level 1 students who should handle more complex percentage problems and multi-step calculations.
A24: Question 23 | B24: 0 | C24: 5.2399027 | D24: 1 | E24: 1 | F24: 1 | G24: 0 | H24: 1 | I24: 1 | J24: 1 | K24: 1 | L24: 1 | M24: 1 | N24: 1 | O24: synergy: The two parts (a) and (b) are independent questions that do not require using the result from part (a) to solve part (b). Part (a) involves decimal subtraction (7.85 - 6.43) while part (b) involves ordering all three given scores. The questions can be solved separately without connection, failing to demonstrate synergy between the primary and secondary knowledge components.
A25: Question 24 | B25: 0 | C25: 9.9740095 | D25: 1 | E25: 1 | F25: 1 | G25: 1 | H25: 1 | I25: 1 | J25: 1 | K25: 1 | L25: 1 | M25: 1 | N25: 1
A26: Question 25 | B26: 0 | C26: 12.030766 | D26: 1 | E26: 1 | F26: 1 | G26: 1 | H26: 1 | I26: 1 | J26: 1 | K26: 1 | L26: 1 | M26: 1 | N26: 1
A27: Question 26 | B27: 0 | C27: 8.8275437 | D27: 1 | E27: 1 | F27: 1 | G27: 1 | H27: 1 | I27: 1 | J27: 1 | K27: 1 | L27: 1 | M27: 1 | N27: 1
A28: Question 27 | B28: 0 | C28: 12.022637 | D28: 1 | E28: 1 | F28: 1 | G28: 1 | H28: 1 | I28: 1 | J28: 0 | K28: 1 | L28: 1 | M28: 1 | N28: 1 | O28: The scenario of playing 5/2 games (2.5 games) is unrealistic - it is unclear how one plays half a badminton game in practice, making the scenario implausible for real-world situations.
A29: Question 28 | B29: 0 | C29: 4.1480901 | D29: 1 | E29: 1 | F29: 1 | G29: 1 | H29: 1 | I29: 0 | J29: 1 | K29: 1 | L29: 1 | M29: 1 | N29: 1 | O29: Grade alignment issue: The problem uses 4-digit numbers (1234, 956, 1087) which are typically introduced in Primary 4, not Primary 3. Primary 3 students in Singapore math curriculum typically work with whole numbers up to 1000.
A30: Question 29 | B30: 0 | C30: 8.3827581 | D30: 0 | E30: 'NA | F30: 'NA | G30: 'NA | H30: 'NA | I30: 'NA | J30: 'NA | K30: 'NA | L30: 'NA | M30: 'NA | N30: 'NA | O30: Answerability: The problem contains conflicting information. It states Elaine spent 5/6 + 1/4 = 13/12 = 1 1/12 hours total, but also claims she spent exactly 1 hour total. This mathematical contradiction makes the problem logically inconsistent. Real-world feasibility: The contradictory time information makes this scenario implausible as actual times cannot simultaneously equal 1 1/12 hours and 1 hour. Clarity: The conflicting statements about total time create ambiguity about which information students should use. Conciseness and relevance: The statement about spending a total of 1 hour is unnecessary and contradictory information that confuses rather than helps solve the problem.
A31: Question 30 | B31: 0 | C31: 6.8951616 | D31: 1 | E31: 1 | F31: 1 | G31: 1 | H31: 1 | I31: 1 | J31: 1 | K31: 1 | L31: 1 | M31: 1 | N31: 1
A32: Question 31 | B32: 0 | C32: 9.462352 | D32: 1 | E32: 1 | F32: 1 | G32: 1 | H32: 1 | I32: 1 | J32: 1 | K32: 1 | L32: 1 | M32: 1 | N32: 1
A33: Question 32 | B33: 0 | C33: 13.949405 | D33: 1 | E33: 1 | F33: 0 | G33: 'NA | H33: 1 | I33: 0 | J33: 0 | K33: 1 | L33: 1 | M33: 1 | N33: 1 | O33: Secondary KC: Problem does not meaningfully target multiplication of whole numbers - only basic arithmetic like 4*18. Synergy: Parts (a) and (b) are independent - part (b) can be solved directly without using result from part (a). Grade alignment: Inverse proportion is too advanced for Secondary O-level 2. Real-world feasibility: More dancers typically increase rather than decrease total practice time due to coordination complexity.
A34: Question 33 | B34: 0 | C34: 9.6570816 | D34: 1 | E34: 1 | F34: 1 | G34: 1 | H34: 1 | I34: 1 | J34: 1 | K34: 1 | L34: 1 | M34: 1 | N34: 1
A35: Question 34 | B35: 0 | C35: 2.5225942 | D35: 1 | E35: 1 | F35: 1 | G35: 1 | H35: 1 | I35: 1 | J35: 1 | K35: 1 | L35: 1 | M35: 1 | N35: 1
A36: Question 35 | B36: 0 | C36: 12.243626 | D36: 1 | E36: 1 | F36: 1 | G36: 1 | H36: 1 | I36: 0 | J36: 1 | K36: 1 | L36: 1 | M36: 1 | N36: 1 | O36: Grade Alignment: The problem requires knowledge of arithmetic sequences and algebraic expression formulation that is typically taught in Secondary 2-3, not Secondary O-level 1. Secondary 1 students have not typically learned to derive nth term expressions for sequences.
A37: Question 36 | B37: 0 | C37: 9.0670693 | D37: 1 | E37: 1 | F37: 1 | G37: 1 | H37: 1 | I37: 1 | J37: 1 | K37: 1 | L37: 1 | M37: 1 | N37: 1
A38: Question 37 | B38: 0 | C38: 8.5239232 | D38: 0 | E38: 'NA | F38: 'NA | G38: 'NA | H38: 'NA | I38: 'NA | J38: 'NA | K38: 'NA | L38: 'NA | M38: 'NA | N38: 'NA | O38: The problem contains conflicting mathematical information. Using the ratio 2.5:1.5 with total time 2 hours gives free throw time = 1.25 hours and dribbling time = 0.75 hours. However, the difference is 1.25 - 0.75 = 0.5 hours, not 0.8 hours as stated in the problem. This mathematical inconsistency makes the problem unsolvable as written.
A39: Question 38 | B39: 0 | C39: 10.272482 | D39: 1 | E39: 1 | F39: 1 | G39: 0 | H39: 1 | I39: 1 | J39: 1 | K39: 1 | L39: 1 | M39: 1 | N39: 1 | O39: The primary and secondary knowledge components are used in separate independent questions rather than in tandem. Part a uses only mixed number multiplication while part b uses only fraction addition, without the result from part a being needed for part b.
A40: Question 39 | B40: 0 | C40: 5.1356039 | D40: 1 | E40: 1 | F40: 1 | G40: 1 | H40: 1 | I40: 0 | J40: 1 | K40: 1 | L40: 1 | M40: 1 | N40: 1 | O40: Grade alignment: This problem involves matrices operations including scalar multiplication and matrix addition, which are typically covered in Secondary O-level mathematics or higher. However, the specified grade is Secondary O-level 3/4, and matrix operations are generally introduced earlier in the O-level curriculum (around Secondary 1-2 level). The problem may be too advanced for the early secondary levels if matrices have not been introduced yet in the Singapore curriculum at that specific grade level.
...

Sheet recreation_v2_common_5
A1: Question | B1: status | C1: response_time | D1: answerability | E1: primary_kc_alignment | F1: secondary_kc_alignment | G1: synergy | H1: topic_alignment | I1: grade_alignment | J1: real_world_feasibility | K1: clarity | L1: conciseness_and_relevance | M1: language_quality | N1: content_appropriateness | O1: explanation
A2: Question 1 | B2: 0 | C2: 2.6639068 | D2: 1 | E2: 1 | F2: 1 | G2: 1 | H2: 1 | I2: 1 | J2: 1 | K2: 1 | L2: 1 | M2: 1 | N2: 1
A3: Question 2 | B3: 0 | C3: 8.1386747 | D3: 1 | E3: 1 | F3: 1 | G3: 0 | H3: 1 | I3: 1 | J3: 0 | K3: 0 | L3: 1 | M3: 1 | N3: 1 | O3: Synergy: The two parts can be solved independently. Part (a) uses 3/4 divided by 1/8, while part (b) uses 2/3 multiplied by 3/4. The result from part (a) is not needed for part (b). Real-world feasibility: The scenario is contradictory - Alvin cannot divide time equally among 6 songs and simultaneously spend 2/3 of total time on just the first song. This creates 6/6 + 2/3 = 1 + 2/3 = 5/3 of total time needed, which exceeds available time. Clarity: The problem setup is confusing as it describes two conflicting time allocation methods without clearly explaining the relationship between them.
A4: Question 3 | B4: 0 | C4: 9.8507729 | D4: 1 | E4: 1 | F4: 1 | G4: 1 | H4: 1 | I4: 1 | J4: 1 | K4: 1 | L4: 1 | M4: 1 | N4: 1
A5: Question 4 | B5: 0 | C5: 9.2473416 | D5: 1 | E5: 1 | F5: 1 | G5: 1 | H5: 1 | I5: 0 | J5: 1 | K5: 0 | L5: 1 | M5: 1 | N5: 1 | O5: Grade alignment: 1356 divides exactly by 4 with remainder 0, making comparison in part b trivial and potentially confusing for Primary 4 students who expect meaningful remainders in division problems. Clarity: Part b asks to explain answer but provides no clear guidance on what type of explanation is expected, creating ambiguity for Primary 4 students.
A6: Question 5 | B6: 0 | C6: 2.7540674 | D6: 1 | E6: 1 | F6: 1 | G6: 1 | H6: 1 | I6: 1 | J6: 1 | K6: 1 | L6: 1 | M6: 1 | N6: 1
A7: Question 6 | B7: 0 | C7: 2.6934965 | D7: 1 | E7: 1 | F7: 1 | G7: 1 | H7: 1 | I7: 1 | J7: 1 | K7: 1 | L7: 1 | M7: 1 | N7: 1
A8: Question 7 | B8: 0 | C8: 2.6977532 | D8: 1 | E8: 1 | F8: 1 | G8: 1 | H8: 1 | I8: 1 | J8: 1 | K8: 1 | L8: 1 | M8: 1 | N8: 1
A9: Question 8 | B9: 0 | C9: 9.9396858 | D9: 1 | E9: 1 | F9: 1 | G9: 1 | H9: 1 | I9: 1 | J9: 1 | K9: 1 | L9: 1 | M9: 1 | N9: 1
A10: Question 9 | B10: 0 | C10: 5.6511765 | D10: 1 | E10: 1 | F10: 1 | G10: 0 | H10: 1 | I10: 0 | J10: 1 | K10: 1 | L10: 1 | M10: 1 | N10: 1 | O10: Synergy: The two parts (a) and (b) are independent questions that do not require using results from part (a) to solve part (b). They can be solved separately without connection. Grade Alignment: Finding percentiles/quartiles is typically introduced at Primary 6 level in Singapore math syllabus, making this problem too easy for Secondary O-level 2 students who should be working with more advanced statistical concepts like standard deviation, probability distributions, or hypothesis testing.
A11: Question 10 | B11: 0 | C11: 2.7873759 | D11: 1 | E11: 1 | F11: 1 | G11: 1 | H11: 1 | I11: 1 | J11: 1 | K11: 1 | L11: 1 | M11: 1 | N11: 1
A12: Question 11 | B12: 0 | C12: 6.3578439 | D12: 1 | E12: 0 | F12: 1 | G12: 'NA | H12: 1 | I12: 'NA | J12: 1 | K12: 1 | L12: 1 | M12: 1 | N12: 1 | O12: Primary KC Alignment: The primary knowledge component is subtraction of mixed numbers, but part (a) only requires addition of mixed numbers (4 2/3 + 1 5/6). Part (b) requires subtraction (8 1/2 - sum from part a), but this makes addition the primary operation needed first. Synergy: The two knowledge components are not used in tandem. Part (a) uses only addition of fractions, while part (b) uses subtraction. They are sequential rather than synergistic - one could solve part (b) directly without doing part (a) by calculating 8 1/2 - 4 2/3 - 1 5/6.
A13: Question 12 | B13: 0 | C13: 4.0085497 | D13: 1 | E13: 1 | F13: 1 | G13: 1 | H13: 1 | I13: 0 | J13: 1 | K13: 1 | L13: 1 | M13: 1 | N13: 1 | O13: Grade Alignment: The problem involves matrix operations which are typically introduced at A-level mathematics or equivalent, not at O-level 3/4. O-level mathematics curriculum does not typically cover matrix addition and subtraction operations.
A14: Question 13 | B14: 0 | C14: 2.7205207 | D14: 1 | E14: 1 | F14: 1 | G14: 1 | H14: 1 | I14: 1 | J14: 1 | K14: 1 | L14: 1 | M14: 1 | N14: 1
A15: Question 14 | B15: 0 | C15: 4.880167 | D15: 1 | E15: 1 | F15: 0 | G15: 'NA | H15: 1 | I15: 1 | J15: 1 | K15: 1 | L15: 1 | M15: 1 | N15: 1 | O15: Secondary_kc_alignment: The problem only requires division (70/250) and multiplication by 100 to convert to percentage. No whole number multiplication beyond the conversion step is needed to solve the core problem. Synergy: Since the secondary knowledge component of whole number multiplication is not meaningfully integrated into the problem solving process, the primary and secondary components do not work in tandem to solve the problem.
A16: Question 15 | B16: 0 | C16: 10.00961 | D16: 1 | E16: 0 | F16: 1 | G16: 'NA | H16: 1 | I16: 'NA | J16: 1 | K16: 1 | L16: 1 | M16: 1 | N16: 1 | O16: Primary KC alignment fails because the problem requires multiplying 3.275 x 20, which is basic decimal multiplication, not specifically multiplying decimals by 10, 100, 1000 and their multiples as intended. The calculation 3.275 x 20 does not directly involve the intended primary knowledge component.
A17: Question 16 | B17: 0 | C17: 10.478716 | D17: 1 | E17: 1 | F17: 1 | G17: 1 | H17: 1 | I17: 1 | J17: 1 | K17: 1 | L17: 1 | M17: 0 | N17: 1 | O17: Language Quality: The text contains LaTeX formatting errors where 'textdollar15' appears instead of '15' in two places, making the problem difficult to read properly.
A18: Question 17 | B18: 0 | C18: 10.348738 | D18: 1 | E18: 1 | F18: 1 | G18: 1 | H18: 1 | I18: 1 | J18: 1 | K18: 1 | L18: 1 | M18: 1 | N18: 1
A19: Question 18 | B19: 0 | C19: 8.1482394 | D19: 1 | E19: 1 | F19: 0 | G19: 'NA | H19: 0 | I19: 1 | J19: 0 | K19: 1 | L19: 1 | M19: 1 | N19: 1 | O19: Secondary KC alignment: Part (b) requires multiplication of fractions (2/5 * 12) rather than subtraction of fractions. The calculation is 12 - (2/5 * 12) = 12 - 4.8 = 7.2, which involves fraction multiplication, not fraction subtraction. Synergy: Since part (b) does not use fraction subtraction as intended, the two knowledge components are not working in tandem as required. Topic alignment: Making bookmarks is a craft/art activity, not a recreation activity like sports, games, exercises, music, movies, dancing, painting, fishing. Real-world feasibility: The problem results in 7.2 bookmarks remaining, but you cannot have 0.2 of a bookmark in reality - bookmarks are discrete whole objects.
A20: Question 19 | B20: 0 | C20: 4.7998931 | D20: 1 | E20: 1 | F20: 0 | G20: 'NA | H20: 1 | I20: 1 | J20: 1 | K20: 1 | L20: 1 | M20: 1 | N20: 1 | O20: Secondary Knowledge Component Alignment: The problem does not require expressing a fraction in its simplest form. The multiplication 2 1/2 × 6 = 15, which is a whole number, not a fraction that needs simplification. Synergy: Since the secondary knowledge component (simplifying fractions) is not actually needed to solve this problem, the primary and secondary knowledge components do not work in tandem as required.
A21: Question 20 | B21: 0 | C21: 9.1245887 | D21: 1 | E21: 1 | F21: 1 | G21: 1 | H21: 1 | I21: 1 | J21: 1 | K21: 1 | L21: 1 | M21: 1 | N21: 1
A22: Question 21 | B22: 0 | C22: 2.6991065 | D22: 1 | E22: 1 | F22: 1 | G22: 1 | H22: 1 | I22: 1 | J22: 1 | K22: 1 | L22: 1 | M22: 1 | N22: 1
A23: Question 22 | B23: 0 | C23: 4.9887731 | D23: 1 | E23: 1 | F23: 1 | G23: 1 | H23: 1 | I23: 0 | J23: 1 | K23: 1 | L23: 1 | M23: 1 | N23: 1 | O23: Grade Alignment: This problem is too simple for Secondary O-level 1 students. Finding 25% increase (80 * 1.25 = 100, so 20 new members) and multiplying 20 * 15 = 300 are basic calculations more suitable for primary levels. Secondary O-level 1 students typically handle more complex percentage problems involving compound changes, algebraic representations, or multi-step reasoning.
A24: Question 23 | B24: 0 | C24: 4.7690439 | D24: 1 | E24: 1 | F24: 1 | G24: 0 | H24: 1 | I24: 1 | J24: 1 | K24: 1 | L24: 1 | M24: 1 | N24: 1 | O24: Synergy: The two parts (a) and (b) are independent questions that do not require using the result from part (a) to solve part (b). Part (a) involves decimal subtraction (7.85 - 6.43) while part (b) involves ordering all three scores. The questions can be solved separately without connection between them.
A25: Question 24 | B25: 0 | C25: 12.949323 | D25: 1 | E25: 1 | F25: 1 | G25: 1 | H25: 1 | I25: 0 | J25: 1 | K25: 1 | L25: 1 | M25: 1 | N25: 1 | O25: Grade Alignment: The numbers 3250 and 1875 are too large and complex for typical Primary 3 students. Primary 3 subtraction problems usually involve smaller numbers to build foundational skills before progressing to such large 4-digit calculations.
A26: Question 25 | B26: 0 | C26: 10.890895 | D26: 1 | E26: 1 | F26: 1 | G26: 1 | H26: 1 | I26: 1 | J26: 1 | K26: 1 | L26: 1 | M26: 1 | N26: 1
A27: Question 26 | B27: 0 | C27: 2.7016098 | D27: 1 | E27: 1 | F27: 1 | G27: 1 | H27: 1 | I27: 1 | J27: 1 | K27: 1 | L27: 1 | M27: 1 | N27: 1
A28: Question 27 | B28: 0 | C28: 9.8340316 | D28: 1 | E28: 1 | F28: 1 | G28: 1 | H28: 1 | I28: 1 | J28: 1 | K28: 1 | L28: 1 | M28: 1 | N28: 1
A29: Question 28 | B29: 0 | C29: 4.3127592 | D29: 1 | E29: 1 | F29: 1 | G29: 1 | H29: 1 | I29: 0 | J29: 1 | K29: 1 | L29: 1 | M29: 1 | N29: 1 | O29: Grade alignment: The problem involves 4-digit whole numbers (1234, 1087, 956) and their addition/comparison, which is typically beyond Primary 3 level. Primary 3 students usually work with numbers up to 1000 or smaller 3-digit numbers.
A30: Question 29 | B30: 0 | C30: 10.598396 | D30: 0 | E30: 'NA | F30: 'NA | G30: 'NA | H30: 'NA | I30: 'NA | J30: 'NA | K30: 'NA | L30: 'NA | M30: 'NA | N30: 'NA | O30: Answerability: Conflicting information - 5/6 + 1/4 = 13/12 = 1 1/12 hours, not 1 hour as stated. Synergy: Questions are not connected - part b does not use the result from part a.
A31: Question 30 | B31: 0 | C31: 6.3875835 | D31: 1 | E31: 1 | F31: 1 | G31: 0 | H31: 1 | I31: 1 | J31: 1 | K31: 1 | L31: 1 | M31: 1 | N31: 1 | O31: Synergy criterion not met: The division and subtraction operations work independently rather than in tandem. The division result (82 boxes) is not used in the subtraction calculation (246 - 18 = 228). The problem can be solved by performing 246 - 18 directly without needing the division step, indicating the knowledge components are not interconnected as required.
A32: Question 31 | B32: 0 | C32: 8.9352086 | D32: 1 | E32: 1 | F32: 1 | G32: 1 | H32: 1 | I32: 1 | J32: 1 | K32: 1 | L32: 1 | M32: 1 | N32: 1
A33: Question 32 | B33: 0 | C33: 10.669796 | D33: 1 | E33: 1 | F33: 1 | G33: 1 | H33: 1 | I33: 0 | J33: 1 | K33: 1 | L33: 1 | M33: 1 | N33: 1 | O33: Grade Alignment: Inverse proportion is typically taught at Primary 6 level in Singapore curriculum, making this content too elementary for Secondary O-level 2 students. The problem requires knowledge components below the intended grade level.
