Workbook

Sheet recreation_v2_10
A1: Evaluator | B1: Question | C1: status | D1: response_time | E1: answerability | F1: primary_kc_alignment | G1: secondary_kc_alignment | H1: synergy | I1: topic_alignment | J1: grade_alignment | K1: real_world_feasibility | L1: clarity | M1: conciseness_and_relevance | N1: language_quality | O1: content_appropriateness | P1: explanation
A2: TD | B2: Question 1 | C2: 0 | D2: 11.489272 | E2: 1 | F2: 1 | G2: 1 | H2: 1 | I2: 1 | J2: 0 | K2: 1 | L2: 1 | M2: 1 | N2: 1 | O2: 1 | P2: Grade Alignment: The problem uses 4-digit numbers (1562, 738) and requires multi-step operations that are typically beyond Primary 3 level. Primary 3 students usually work with 3-digit numbers and simpler single-step or two-step problems.
A3: TD | B3: Question 2 | C3: 0 | D3: 7.3595858 | E3: 0 | F3: 'NA | G3: 'NA | H3: 'NA | I3: 'NA | J3: 'NA | K3: 'NA | L3: 'NA | M3: 'NA | N3: 'NA | O3: 'NA | P3: Answerability: The problem cannot be solved as stated. To find average time per 10 metres, we need 202.457 / (500/10) = 202.457 / 50 = 4.04914 seconds. This requires division by 50, but the given information only allows division by whole numbers, not the result of 500/10. Primary KC Alignment: The problem requires 202.457 / 50 = 4.04914, which is division by 50. However, the intended primary KC is division by 10, 100, 1000 and their multiples. 50 is not 10, 100, 1000 or their multiples (multiples would be 20, 30, 200, 300, 2000, 3000, etc. but 50 is not among standard multiples typically covered).
A4: TD | B4: Question 3 | C4: 0 | D4: 5.4888599 | E4: 1 | F4: 0 | G4: 1 | H4: 'NA | I4: 1 | J4: 'NA | K4: 1 | L4: 1 | M4: 1 | N4: 1 | O4: 1 | P4: Primary KC Alignment: The problem requires dividing 12.000 by 10, but this is basic division by 10 which moves decimal point one place left. The intended primary KC specifies dividing decimals up to 3 decimal places by 10, 100, 1000 and their multiples, suggesting more complex operations with longer decimals or larger divisors. This problem only uses simple division by 10 with a result that has no decimal places after moving the decimal point.
A5: TD | B5: Question 4 | C5: 0 | D5: 2.7106245 | E5: 1 | F5: 1 | G5: 1 | H5: 1 | I5: 1 | J5: 1 | K5: 1 | L5: 1 | M5: 1 | N5: 1 | O5: 1
A6: TD | B6: Question 5 | C6: 0 | D6: 8.696775 | E6: 1 | F6: 1 | G6: 1 | H6: 1 | I6: 1 | J6: 1 | K6: 1 | L6: 1 | M6: 1 | N6: 1 | O6: 1
A7: TD | B7: Question 6 | C7: 0 | D7: 8.2287269 | E7: 1 | F7: 1 | G7: 1 | H7: 1 | I7: 1 | J7: 1 | K7: 1 | L7: 1 | M7: 1 | N7: 1 | O7: 1
A8: TD | B8: Question 7 | C8: 0 | D8: 7.4001384 | E8: 1 | F8: 1 | G8: 1 | H8: 1 | I8: 1 | J8: 1 | K8: 0 | L8: 1 | M8: 1 | N8: 1 | O8: 1 | P8: Real-world feasibility: The problem asks how many 45-minute dance routines can fit in 2 hours, which mathematically gives 2.67 routines. However, in reality, you cannot perform 2/3 of a dance routine - dance routines are complete performances that cannot be meaningfully fractioned. A dancer would only be able to perform 2 complete routines in 2 hours, making the mathematical answer unrealistic for the given context.
A9: TD | B9: Question 8 | C9: 0 | D9: 9.3756206 | E9: 1 | F9: 1 | G9: 1 | H9: 1 | I9: 1 | J9: 1 | K9: 1 | L9: 1 | M9: 1 | N9: 1 | O9: 1
A10: TD | B10: Question 9 | C10: 0 | D10: 5.9396985 | E10: 1 | F10: 1 | G10: 1 | H10: 1 | I10: 1 | J10: 0 | K10: 0 | L10: 1 | M10: 1 | N10: 1 | O10: 1 | P10: Grade Alignment: Matrix operations are typically introduced at A-level or equivalent advanced secondary level, not O-level 3/4. O-level students typically study basic algebra, geometry, and statistics. Real-World Plausibility: The impact factor matrix M with values like 0.5 and 0.8 as weightage for sports activities lacks clear real-world meaning. What does multiplying hours by these arbitrary factors represent in practical terms? The explanation of what C x M represents is not intuitive or realistic in a sports club context.
A11: TD | B11: Question 10 | C11: 0 | D11: 9.7642334 | E11: 1 | F11: 1 | G11: 1 | H11: 1 | I11: 1 | J11: 1 | K11: 1 | L11: 1 | M11: 1 | N11: 1 | O11: 1
A12: TD | B12: Question 11 | C12: 0 | D12: 9.7050951 | E12: 1 | F12: 1 | G12: 1 | H12: 1 | I12: 1 | J12: 1 | K12: 0 | L12: 1 | M12: 1 | N12: 1 | O12: 1 | P12: Real-world feasibility: Attending 5/3 sessions (approximately 1.67 sessions) is unrealistic - students typically attend complete sessions, not fractional portions of sessions.
A13: TD | B13: Question 12 | C13: 0 | D13: 4.4945402 | E13: 1 | F13: 1 | G13: 1 | H13: 1 | I13: 1 | J13: 0 | K13: 1 | L13: 1 | M13: 1 | N13: 1 | O13: 1 | P13: grade_alignment: The problem requires understanding of algebraic variables (x, n), algebraic expressions with variables, and algebraic manipulation which are typically introduced in Secondary 1/2 mathematics, not Primary 6. Primary 6 students in Singapore typically work with basic arithmetic and simple number patterns, not formal algebra with variables.
A14: TD | B14: Question 13 | C14: 0 | D14: 10.570142 | E14: 1 | F14: 1 | G14: 1 | H14: 1 | I14: 1 | J14: 0 | K14: 1 | L14: 1 | M14: 1 | N14: 1 | O14: 1 | P14: Grade Alignment: The calculation 5.30 / 4 = 1.325 results in a 3-decimal place answer, which is beyond Primary 4 level expectations for decimal precision.
A15: TD | B15: Question 14 | C15: 0 | D15: 10.282065 | E15: 1 | F15: 1 | G15: 1 | H15: 1 | I15: 1 | J15: 0 | K15: 1 | L15: 1 | M15: 1 | N15: 1 | O15: 1 | P15: Grade Alignment: The problem involves basic percentage calculation (15% increase) and simple subtraction, which are too elementary for Secondary O-level 1 students who should be working with advanced algebra, trigonometry, and complex mathematical concepts.
A16: TD | B16: Question 15 | C16: 0 | D16: 10.171179 | E16: 1 | F16: 1 | G16: 0 | H16: 'NA | I16: 1 | J16: 1 | K16: 1 | L16: 1 | M16: 1 | N16: 1 | O16: 1 | P16: The intended Secondary Knowledge Component is 'Finding mean deviation' which refers to calculating the average absolute deviation from the mean, but the problem only asks for calculating the mean in part (a). Mean deviation would require finding |xi - mean| for each value and then averaging those deviations.
A17: TD | B17: Question 16 | C17: 0 | D17: 10.177311 | E17: 0 | F17: 'NA | G17: 'NA | H17: 'NA | I17: 'NA | J17: 'NA | K17: 'NA | L17: 'NA | M17: 'NA | N17: 'NA | O17: 'NA | P17: Answerability: Logical inconsistency - if 2.35 points were wrongly added to 17.5 earned points, displayed score should be 19.85, not 17.5. Primary KC Alignment: Problem does not require multiplying decimals by 10/100/1000 or multiples - only decimal subtraction is needed. Synergy: Primary and secondary knowledge components cannot work in tandem since primary KC is not needed for solution.
A18: TD | B18: Question 17 | C18: 0 | D18: 10.726846 | E18: 0 | F18: 'NA | G18: 'NA | H18: 'NA | I18: 'NA | J18: 'NA | K18: 'NA | L18: 'NA | M18: 'NA | N18: 'NA | O18: 'NA | P18: The problem lacks essential information - the number of sessions Sarah attended last month is not provided. Without this information, it is impossible to calculate how many sessions she attended this month (5/3 times last month's sessions) and therefore impossible to determine the total paint used this month.
A19: TD | B19: Question 18 | C19: 0 | D19: 11.281861 | E19: 1 | F19: 1 | G19: 1 | H19: 1 | I19: 1 | J19: 1 | K19: 1 | L19: 1 | M19: 1 | N19: 1 | O19: 1
A20: TD | B20: Question 19 | C20: 0 | D20: 9.4469039 | E20: 1 | F20: 1 | G20: 1 | H20: 1 | I20: 1 | J20: 1 | K20: 1 | L20: 1 | M20: 1 | N20: 1 | O20: 1
A21: TD | B21: Question 20 | C21: 0 | D21: 7.7633095 | E21: 0 | F21: 'NA | G21: 'NA | H21: 'NA | I21: 'NA | J21: 'NA | K21: 'NA | L21: 'NA | M21: 'NA | N21: 'NA | O21: 'NA | P21: Answerability: The problem assumes painting completion is proportional to time spent without stating this relationship explicitly, creating ambiguity about how to solve it mathematically. Real-world feasibility: The assumption that painting progress is directly proportional to time spent is unrealistic - factors like complexity of different sections, drying time, and painting technique affect progress. Clarity: The connection between time spent and fraction of painting completed is not clearly established, making the problem ambiguous.
A22: TD | B22: Question 21 | C22: 0 | D22: 10.221833 | E22: 1 | F22: 1 | G22: 1 | H22: 1 | I22: 1 | J22: 1 | K22: 1 | L22: 1 | M22: 1 | N22: 1 | O22: 1
A23: TD | B23: Question 22 | C23: 0 | D23: 10.072337 | E23: 1 | F23: 0 | G23: 1 | H23: 'NA | I23: 1 | J23: 'NA | K23: 1 | L23: 1 | M23: 1 | N23: 1 | O23: 1 | P23: Primary KC alignment: Problem uses decimals with 3 decimal places (8.125, 8.085) but intended component specifies up to 2 decimal places only. Synergy: Part (a) calculates Mei's total score but this result is not used in part (b) which only compares final round scores - the two parts are independent rather than connected.
A24: TD | B24: Question 23 | C24: 0 | D24: 6.6962919 | E24: 0 | F24: 'NA | G24: 'NA | H24: 'NA | I24: 'NA | J24: 'NA | K24: 'NA | L24: 'NA | M24: 'NA | N24: 'NA | O24: 'NA | P24: Answerability: The problem is missing critical information - the number of practice days last month is not provided. Without this information, it is impossible to calculate the total hours each student spends practicing this month. The problem gives a ratio (9/5 times as many days) but no baseline number to multiply against.
A25: TD | B25: Question 24 | C25: 0 | D25: 11.906993 | E25: 1 | F25: 1 | G25: 1 | H25: 1 | I25: 1 | J25: 0 | K25: 0 | L25: 1 | M25: 1 | N25: 1 | O25: 1 | P25: Grade alignment: Direct proportion is too advanced for Secondary O-level 2 students. Real-world feasibility: The ratio of 6 mats for 8 participants (0.75 mats per person) is unrealistic - fitness classes typically use 1 mat per participant.
A26: TD | B26: Question 25 | C26: 0 | D26: 8.9400353 | E26: 1 | F26: 1 | G26: 1 | H26: 1 | I26: 1 | J26: 1 | K26: 1 | L26: 1 | M26: 1 | N26: 1 | O26: 1
A27: Minh | B27: Question 1 | C27: 0 | D27: 10.790107 | E27: 1 | F27: 0 | G27: 1 | H27: 'NA | I27: 1 | J27: 'NA | K27: 1 | L27: 1 | M27: 1 | N27: 1 | O27: 1 | P27: Primary KC specifies adding decimals up to 2 decimal places, but the problem includes 1.797 which has 3 decimal places, exceeding the specified limit.
A28: Minh | B28: Question 2 | C28: 0 | D28: 9.1472688 | E28: 1 | F28: 1 | G28: 1 | H28: 1 | I28: 1 | J28: 1 | K28: 1 | L28: 1 | M28: 1 | N28: 1 | O28: 1
A29: Minh | B29: Question 3 | C29: 0 | D29: 10.790239 | E29: 1 | F29: 1 | G29: 1 | H29: 1 | I29: 1 | J29: 1 | K29: 0 | L29: 1 | M29: 1 | N29: 1 | O29: 1 | P29: Real-world feasibility fails because 0.125 hours / 1000 students = 0.0001125 hours per student, which equals approximately 0.4 seconds. This duration is too brief for meaningful piano practice and does not represent a realistic educational scenario.
A30: Minh | B30: Question 4 | C30: 0 | D30: 12.334376 | E30: 1 | F30: 1 | G30: 1 | H30: 1 | I30: 1 | J30: 0 | K30: 1 | L30: 1 | M30: 1 | N30: 1 | O30: 1 | P30: Grade Alignment: Matrix operations including scalar multiplication and matrix subtraction are typically taught at A-level Secondary 5/6 in Singapore syllabus, not at O-level 3/4. O-level mathematics covers arithmetic, algebra, geometry and basic statistics but not matrix algebra.
A31: Minh | B31: Question 5 | C31: 0 | D31: 11.813534 | E31: 1 | F31: 1 | G31: 1 | H31: 1 | I31: 1 | J31: 1 | K31: 1 | L31: 1 | M31: 1 | N31: 1 | O31: 1
A32: Minh | B32: Question 6 | C32: 0 | D32: 9.7078769 | E32: 1 | F32: 1 | G32: 1 | H32: 1 | I32: 1 | J32: 1 | K32: 1 | L32: 1 | M32: 1 | N32: 1 | O32: 1
A33: Minh | B33: Question 7 | C33: 0 | D33: 9.7161987 | E33: 1 | F33: 1 | G33: 1 | H33: 1 | I33: 1 | J33: 1 | K33: 1 | L33: 1 | M33: 1 | N33: 1 | O33: 1
A34: Minh | B34: Question 8 | C34: 0 | D34: 9.9181993 | E34: 1 | F34: 1 | G34: 1 | H34: 1 | I34: 1 | J34: 1 | K34: 1 | L34: 1 | M34: 1 | N34: 1 | O34: 1
A35: Minh | B35: Question 9 | C35: 0 | D35: 9.9287775 | E35: 1 | F35: 1 | G35: 1 | H35: 1 | I35: 1 | J35: 1 | K35: 1 | L35: 1 | M35: 1 | N35: 1 | O35: 1
A36: Minh | B36: Question 10 | C36: 0 | D36: 4.5193596 | E36: 1 | F36: 1 | G36: 1 | H36: 1 | I36: 1 | J36: 0 | K36: 1 | L36: 1 | M36: 1 | N36: 1 | O36: 1 | P36: Grade Alignment: The problem uses terminology like lower quartile Q1, median Q2, upper quartile Q3, and interquartile range which are typically introduced at Primary 6 level in Singapore math syllabus, not Secondary O-level 3/4. The complexity and mathematical concepts required are below the intended grade level.
A37: Minh | B37: Question 11 | C37: 0 | D37: 2.7414355 | E37: 1 | F37: 1 | G37: 1 | H37: 1 | I37: 1 | J37: 1 | K37: 1 | L37: 1 | M37: 1 | N37: 1 | O37: 1
A38: Minh | B38: Question 12 | C38: 0 | D38: 12.432577 | E38: 0 | F38: 'NA | G38: 'NA | H38: 'NA | I38: 'NA | J38: 'NA | K38: 'NA | L38: 'NA | M38: 'NA | N38: 'NA | O38: 'NA | P38: Answerability: Problem contains conflicting information - using 5/6 ratio gives 20 painting students but using 3/4:2 ratio gives 9 painting students, making problem unsolvable. Secondary KC Alignment: Solution only requires fraction multiplication and ratio solving, not fraction division as intended. Synergy: Since secondary KC (fraction division) is not needed, primary and secondary KCs do not work in tandem. Grade Alignment: Complex ratio problem with conflicting constraints too advanced for Secondary O-level 1 students aged 13-14.
A39: Minh | B39: Question 13 | C39: 0 | D39: 11.611055 | E39: 1 | F39: 1 | G39: 1 | H39: 0 | I39: 1 | J39: 0 | K39: 1 | L39: 1 | M39: 1 | N39: 1 | O39: 1 | P39: Synergy: The two parts are not connected - part (b) does not use results from part (a), they are independent questions sharing only context. Grade Alignment: The problem involves basic inverse proportion (4*120=6*x) and simple division (36/6=6) which are too elementary for Secondary O-level 2 students who should handle more complex mathematical concepts.
A40: Minh | B40: Question 14 | C40: 0 | D40: 10.520213 | E40: 0 | F40: 'NA | G40: 'NA | H40: 'NA | I40: 'NA | J40: 'NA | K40: 'NA | L40: 'NA | M40: 'NA | N40: 'NA | O40: 'NA | P40: The problem is not answerable because 183 / 4 = 45.75, meaning 183 children cannot be divided equally into 4 groups with whole numbers of children per group.
...

Sheet recreation_v2_6
A1: Evaluator | B1: Question | C1: status | D1: response_time | E1: answerability | F1: primary_kc_alignment | G1: secondary_kc_alignment | H1: synergy | I1: topic_alignment | J1: grade_alignment | K1: real_world_feasibility | L1: clarity | M1: conciseness_and_relevance | N1: language_quality | O1: content_appropriateness | P1: explanation
A2: TD | B2: Question 1 | C2: 0 | D2: 10.966771 | E2: 1 | F2: 1 | G2: 1 | H2: 1 | I2: 1 | J2: 0 | K2: 1 | L2: 1 | M2: 1 | N2: 1 | O2: 1 | P2: Grade alignment: The problem uses 4-digit numbers (1562) which is typically beyond Primary 3 level. Primary 3 students usually work with 3-digit numbers, while 4-digit operations are introduced in Primary 4.
A3: TD | B3: Question 2 | C3: 0 | D3: 12.90036 | E3: 1 | F3: 0 | G3: 1 | H3: 'NA | I3: 1 | J3: 'NA | K3: 1 | L3: 1 | M3: 1 | N3: 1 | O3: 1 | P3: Primary KC alignment fails because the problem requires dividing 202.457 by 50, which is dividing a decimal by a whole number, not specifically by 10, 100, 1000 or their multiples as stated in the intended Primary Knowledge Component.
A4: TD | B4: Question 3 | C4: 0 | D4: 7.8134184 | E4: 1 | F4: 1 | G4: 1 | H4: 1 | I4: 1 | J4: 1 | K4: 0 | L4: 0 | M4: 0 | N4: 1 | O4: 1 | P4: Real-world feasibility: The scenario is unrealistic - Wei Lin swam only 2 days (Monday and Wednesday) but is asked to divide the distance among 10 days, which doesn't make practical sense for a training plan. Clarity: The problem is ambiguous about whether she should swim the average distance for 10 days total or as a daily routine, and the phrase 'that week' conflicts with the 10-day division. Conciseness: The phrase 'rounded to three decimal places' is unnecessary since 12.000/10 = 1.200 already has exactly 3 decimal places, and asking for rounding when no rounding is needed adds confusion.
A5: TD | B5: Question 4 | C5: 0 | D5: 2.885164 | E5: 1 | F5: 1 | G5: 1 | H5: 1 | I5: 1 | J5: 1 | K5: 1 | L5: 1 | M5: 1 | N5: 1 | O5: 1
A6: TD | B6: Question 5 | C6: 0 | D6: 2.7602148 | E6: 1 | F6: 1 | G6: 1 | H6: 1 | I6: 1 | J6: 1 | K6: 1 | L6: 1 | M6: 1 | N6: 1 | O6: 1
A7: TD | B7: Question 6 | C7: 0 | D7: 9.5751102 | E7: 1 | F7: 1 | G7: 1 | H7: 1 | I7: 1 | J7: 1 | K7: 1 | L7: 1 | M7: 1 | N7: 1 | O7: 1
A8: TD | B8: Question 7 | C8: 0 | D8: 7.8254948 | E8: 1 | F8: 1 | G8: 1 | H8: 1 | I8: 1 | J8: 1 | K8: 0 | L8: 1 | M8: 1 | N8: 1 | O8: 1 | P8: Real-world feasibility: The problem asks how many dance routines can be performed in 2 hours when each takes 3/4 hour. The mathematical answer is 8/3 = 2.67 routines, but in reality, you cannot perform 0.67 of a dance routine - you can only perform complete routines (2 full routines with 0.5 hours remaining). This creates a disconnect between the mathematical solution and real-world logic.
A9: TD | B9: Question 8 | C9: 0 | D9: 12.194606 | E9: 1 | F9: 1 | G9: 1 | H9: 1 | I9: 1 | J9: 0 | K9: 1 | L9: 1 | M9: 1 | N9: 1 | O9: 1 | P9: Grade Alignment: The problem uses 0.755 km which has 3 decimal places. Primary 4 students typically work with decimals up to 2 decimal places only. The subtraction 3.83 - 0.755 requires skills beyond typical Primary 4 level.
A10: TD | B10: Question 9 | C10: 0 | D10: 6.3747039 | E10: 1 | F10: 1 | G10: 1 | H10: 1 | I10: 1 | J10: 0 | K10: 0 | L10: 1 | M10: 1 | N10: 1 | O10: 1 | P10: Grade Alignment: Matrix operations including matrix multiplication are typically taught at A-level or higher education level, not at Secondary O-level 3/4 which typically covers basic algebra, geometry, and elementary statistics. Real-World Plausibility: The use of impact factor weightage matrix M with values like 0.5 and 0.8 for different sports activities is not how coaches typically analyze or plan training in reality. Coaches usually work with direct time allocations, percentages, or simple ratios rather than matrix multiplication with decimal weightage factors.
A11: TD | B11: Question 10 | C11: 0 | D11: 2.8708148 | E11: 1 | F11: 1 | G11: 1 | H11: 1 | I11: 1 | J11: 1 | K11: 1 | L11: 1 | M11: 1 | N11: 1 | O11: 1
A12: TD | B12: Question 11 | C12: 0 | D12: 9.4785137 | E12: 1 | F12: 1 | G12: 1 | H12: 1 | I12: 1 | J12: 1 | K12: 0 | L12: 1 | M12: 1 | N12: 1 | O12: 1 | P12: real_world_feasibility: Attending 5/3 sessions (approximately 1.67 sessions) is unrealistic as people typically attend complete sessions, not fractional parts of sessions.
A13: TD | B13: Question 12 | C13: 0 | D13: 4.7401688 | E13: 1 | F13: 1 | G13: 1 | H13: 1 | I13: 1 | J13: 0 | K13: 1 | L13: 1 | M13: 1 | N13: 1 | O13: 1 | P13: Grade Alignment: This problem requires algebraic expressions with variables (x, n) and algebraic manipulation which are typically introduced in Secondary 1-2, not Primary 6. Primary 6 students in Singapore typically work with basic algebra using simple letter representations but not complex algebraic expressions involving multiple variables and simplification at this level.
A14: TD | B14: Question 13 | C14: 0 | D14: 12.019702 | E14: 1 | F14: 1 | G14: 1 | H14: 1 | I14: 1 | J14: 0 | K14: 1 | L14: 1 | M14: 1 | N14: 1 | O14: 1 | P14: Grade Alignment: The division 5.30 / 4 = 1.325 produces a result with 3 decimal places, which exceeds the typical Primary 4 curriculum that works with decimals up to 2 decimal places only.
A15: TD | B15: Question 14 | C15: 0 | D15: 12.121318 | E15: 1 | F15: 1 | G15: 1 | H15: 1 | I15: 1 | J15: 0 | K15: 1 | L15: 1 | M15: 1 | N15: 1 | O15: 1 | P15: Grade Alignment: The problem difficulty is too low for Secondary O-level 1 students. Basic percentage increase (15%) and simple subtraction are typically mastered in primary grades 5-6. Secondary O-level 1 students require more complex percentage applications involving multiple steps, compound changes, or algebraic reasoning.
A16: TD | B16: Question 15 | C16: 0 | D16: 10.797413 | E16: 1 | F16: 1 | G16: 0 | H16: 'NA | I16: 1 | J16: 1 | K16: 1 | L16: 1 | M16: 1 | N16: 1 | O16: 1 | P16: The secondary KC specifies 'Finding mean deviation' but the problem only asks for calculating the mean, not the mean deviation. Mean deviation is a different statistical measure that involves finding the average of absolute deviations from the mean.
A17: TD | B17: Question 16 | C17: 0 | D17: 11.104954 | E17: 0 | F17: 'NA | G17: 'NA | H17: 'NA | I17: 'NA | J17: 'NA | K17: 'NA | L17: 'NA | M17: 'NA | N17: 'NA | O17: 'NA | P17: Answerability: There is conflicting information - if Siti earned 17.5 points and her display shows 17.5 points, then 0 points were wrongly added, contradicting the stated 2.35 wrongly added points. The display should show 17.5 + 2.35 = 19.85 if 2.35 were wrongly added. Primary KC Alignment: The problem requires multiplying 0.175 x 100, which uses 100 exactly, not a multiple of 100 as specified in the intended primary knowledge component about multiples of 10, 100, 1000.
A18: TD | B18: Question 17 | C18: 0 | D18: 10.181165 | E18: 0 | F18: 'NA | G18: 'NA | H18: 'NA | I18: 'NA | J18: 'NA | K18: 'NA | L18: 'NA | M18: 'NA | N18: 'NA | O18: 'NA | P18: Answerability: The problem cannot be solved because it lacks essential information - the number of sessions Sarah attended last month is not provided. Without knowing the baseline number of sessions, we cannot calculate 5/3 of that amount or determine the total paint used this month.
A19: TD | B19: Question 18 | C19: 0 | D19: 11.302904 | E19: 1 | F19: 1 | G19: 1 | H19: 1 | I19: 1 | J19: 1 | K19: 1 | L19: 1 | M19: 1 | N19: 1 | O19: 1
A20: TD | B20: Question 19 | C20: 0 | D20: 9.5451763 | E20: 1 | F20: 1 | G20: 1 | H20: 1 | I20: 1 | J20: 1 | K20: 1 | L20: 1 | M20: 1 | N20: 1 | O20: 1
A21: TD | B21: Question 20 | C21: 0 | D21: 12.942078 | E21: 0 | F21: 'NA | G21: 'NA | H21: 'NA | I21: 'NA | J21: 'NA | K21: 'NA | L21: 'NA | M21: 'NA | N21: 'NA | O21: 'NA | P21: Answerability: Problem requires assumption that painting completion is proportional to time spent, which is not explicitly stated. Real-world feasibility: The direct proportional relationship between time and painting completion is unrealistic as painting efficiency varies. Clarity: The relationship between time spent painting and fraction of painting completed is ambiguous.
A22: TD | B22: Question 21 | C22: 0 | D22: 2.8803875 | E22: 1 | F22: 1 | G22: 1 | H22: 1 | I22: 1 | J22: 1 | K22: 1 | L22: 1 | M22: 1 | N22: 1 | O22: 1
A23: TD | B23: Question 22 | C23: 0 | D23: 12.04306 | E23: 1 | F23: 0 | G23: 1 | H23: 'NA | I23: 1 | J23: 'NA | K23: 1 | L23: 1 | M23: 1 | N23: 1 | O23: 1 | P23: Primary KC alignment: Problem includes 3 decimal places (8.125, 8.085) but intended KC is up to 2 decimal places only. Synergy: Part (a) and (b) are independent - part (b) does not use results from part (a). Grade alignment: 3 decimal places may exceed Primary 4 level expectations in Singapore math curriculum.
A24: TD | B24: Question 23 | C24: 0 | D24: 7.68536 | E24: 0 | F24: 'NA | G24: 'NA | H24: 'NA | I24: 'NA | J24: 'NA | K24: 'NA | L24: 'NA | M24: 'NA | N24: 'NA | O24: 'NA | P24: The problem cannot be solved because critical information is missing - the number of practice days last month is not provided. To find total hours this month, we need: (7/4 hours per day) × (9/5 × days last month), but days last month is unknown. Without this information, the multiplication of fractions 7/4 × 9/5 can be performed but cannot yield the final answer requested.
A25: TD | B25: Question 24 | C25: 0 | D25: 10.481904 | E25: 1 | F25: 1 | G25: 1 | H25: 1 | I25: 1 | J25: 0 | K25: 1 | L25: 1 | M25: 1 | N25: 1 | O25: 1 | P25: Grade Alignment: Direct proportion is typically taught at Primary 6 level in Singapore math curriculum, making this problem too elementary for Secondary O-level 2 students who should be working with more advanced mathematical concepts.
A26: TD | B26: Question 25 | C26: 0 | D26: 2.8732784 | E26: 1 | F26: 1 | G26: 1 | H26: 1 | I26: 1 | J26: 1 | K26: 1 | L26: 1 | M26: 1 | N26: 1 | O26: 1
A27: Minh | B27: Question 1 | C27: 0 | D27: 12.361276 | E27: 1 | F27: 0 | G27: 1 | H27: 'NA | I27: 1 | J27: 'NA | K27: 1 | L27: 1 | M27: 1 | N27: 1 | O27: 1 | P27: Primary KC alignment: The intended primary KC specifies adding decimals up to 2 decimal places, but the problem includes 1.797 which has 3 decimal places, exceeding the specified limit. Grade alignment: Using 3-decimal place numbers like 1.797 may be beyond typical Primary 4 level where students usually work with decimals up to 2 decimal places.
A28: Minh | B28: Question 2 | C28: 0 | D28: 10.247757 | E28: 1 | F28: 1 | G28: 1 | H28: 1 | I28: 1 | J28: 1 | K28: 1 | L28: 1 | M28: 1 | N28: 1 | O28: 1
A29: Minh | B29: Question 3 | C29: 0 | D29: 10.909761 | E29: 1 | F29: 1 | G29: 1 | H29: 1 | I29: 1 | J29: 1 | K29: 0 | L29: 1 | M29: 1 | N29: 1 | O29: 1 | P29: Real-world feasibility: Dividing 0.125 hours (7.5 minutes) among 1000 students gives each student only 0.000125 hours (0.27 seconds) of practice time, which is unrealistic and impractical for actual music education.
A30: Minh | B30: Question 4 | C30: 0 | D30: 12.445494 | E30: 1 | F30: 1 | G30: 1 | H30: 1 | I30: 1 | J30: 0 | K30: 1 | L30: 1 | M30: 1 | N30: 1 | O30: 1 | P30: Grade Alignment: Matrix operations are too advanced for Primary 3/4 students who typically work with basic arithmetic on whole numbers, not matrices which are Secondary O-level concepts.
A31: Minh | B31: Question 5 | C31: 0 | D31: 9.3443689 | E31: 1 | F31: 1 | G31: 1 | H31: 1 | I31: 1 | J31: 1 | K31: 1 | L31: 1 | M31: 1 | N31: 1 | O31: 1
A32: Minh | B32: Question 6 | C32: 0 | D32: 2.8622868 | E32: 1 | F32: 1 | G32: 1 | H32: 1 | I32: 1 | J32: 1 | K32: 1 | L32: 1 | M32: 1 | N32: 1 | O32: 1
A33: Minh | B33: Question 7 | C33: 0 | D33: 11.546589 | E33: 1 | F33: 1 | G33: 1 | H33: 1 | I33: 1 | J33: 0 | K33: 1 | L33: 1 | M33: 1 | N33: 1 | O33: 1 | P33: Grade Alignment: The problem requires formal algebraic equation solving with variables, which is beyond Primary 6 level in Singapore curriculum. Primary 6 students typically solve such problems using arithmetic division (60 / 12 = 5) rather than algebraic methods with variables like n.
A34: Minh | B34: Question 8 | C34: 0 | D34: 9.621103 | E34: 1 | F34: 1 | G34: 1 | H34: 1 | I34: 1 | J34: 1 | K34: 1 | L34: 1 | M34: 1 | N34: 1 | O34: 1
A35: Minh | B35: Question 9 | C35: 0 | D35: 3.0815039 | E35: 1 | F35: 1 | G35: 1 | H35: 1 | I35: 1 | J35: 1 | K35: 1 | L35: 1 | M35: 1 | N35: 1 | O35: 1
A36: Minh | B36: Question 10 | C36: 0 | D36: 4.628762 | E36: 1 | F36: 1 | G36: 1 | H36: 1 | I36: 1 | J36: 0 | K36: 1 | L36: 1 | M36: 1 | N36: 1 | O36: 1 | P36: Grade Alignment: The problem is designed for Secondary O-level 3/4 but quartiles and interquartile range are typically introduced earlier in most Singapore math curricula, around Secondary 1-2 level. The complexity and mathematical rigor expected at O-level 3/4 would typically involve more advanced statistical concepts beyond basic quartile calculations.
A37: Minh | B37: Question 11 | C37: 0 | D37: 3.0786188 | E37: 1 | F37: 1 | G37: 1 | H37: 1 | I37: 1 | J37: 1 | K37: 1 | L37: 1 | M37: 1 | N37: 1 | O37: 1
A38: Minh | B38: Question 12 | C38: 0 | D38: 10.394073 | E38: 0 | F38: 'NA | G38: 'NA | H38: 'NA | I38: 'NA | J38: 'NA | K38: 'NA | L38: 'NA | M38: 'NA | N38: 'NA | O38: 'NA | P38: Answerability: The problem contains conflicting information. From ratio 3/4:2 with 24 dancing students gives 9 painting students, but condition 5/6 as many painting as dancing gives 20 painting students. Secondary KC: No fraction division is required - only fraction multiplication (3/4 divided by 2, then multiply by 24, and 5/6 multiply by 24). Synergy: Since secondary KC fraction division is not actually needed, primary and secondary KCs are not used in tandem. Conciseness: The two conditions (ratio and proportional relationship) provide redundant/conflicting information rather than both being necessary.
A39: Minh | B39: Question 13 | C39: 0 | D39: 6.3774529 | E39: 1 | F39: 1 | G39: 1 | H39: 0 | I39: 1 | J39: 0 | K39: 0 | L39: 1 | M39: 1 | N39: 1 | O39: 1 | P39: Synergy: The two parts (a) and (b) are independent problems that do not require results from part (a) to solve part (b). Part (a) uses inverse proportion while part (b) uses division, but they are not connected. Grade Alignment: This problem is too simple for Secondary O-level 2 students. Inverse proportion and basic division are typically covered in primary grades 5-6, not secondary level. Real-World Feasibility: Board games do not work with inverse proportion in reality. Adding more players typically increases game duration due to more turns and decisions, not decreases it proportionally as the problem suggests.
A40: Minh | B40: Question 14 | C40: 0 | D40: 12.405885 | E40: 0 | F40: 'NA | G40: 'NA | H40: 'NA | I40: 'NA | J40: 'NA | K40: 'NA | L40: 'NA | M40: 'NA | N40: 'NA | O40: 'NA | P40: Answerability: 183 / 4 = 45.75 children per group, which is impossible since you cannot have 0.75 of a child. Real-World Plausibility: Organizers would not attempt to divide children into fractional parts in real situations.
...

Sheet recreation_v2_7
A1: Evaluator | B1: Question | C1: status | D1: response_time | E1: answerability | F1: primary_kc_alignment | G1: secondary_kc_alignment | H1: synergy | I1: topic_alignment | J1: grade_alignment | K1: real_world_feasibility | L1: clarity | M1: conciseness_and_relevance | N1: language_quality | O1: content_appropriateness | P1: explanation
A2: TD | B2: Question 1 | C2: 0 | D2: 8.8292282 | E2: 1 | F2: 1 | G2: 1 | H2: 1 | I2: 1 | J2: 1 | K2: 1 | L2: 1 | M2: 1 | N2: 1 | O2: 1
A3: TD | B3: Question 2 | C3: 0 | D3: 10.586419 | E3: 1 | F3: 1 | G3: 1 | H3: 1 | I3: 1 | J3: 1 | K3: 1 | L3: 1 | M3: 1 | N3: 1 | O3: 1
A4: TD | B4: Question 3 | C4: 0 | D4: 4.7464764 | E4: 1 | F4: 0 | G4: 1 | H4: 'NA | I4: 1 | J4: 'NA | K4: 1 | L4: 1 | M4: 1 | N4: 1 | O4: 1 | P4: Primary KC alignment fails because the problem requires dividing 12.000 by 10, which is basic division by 10 (resulting in 1.200), not the intended more complex division of decimals by multiples of 10 that would demonstrate mastery of dividing decimals up to 3 decimal places by 10, 100, 1000 and their multiples.
A5: TD | B5: Question 4 | C5: 0 | D5: 2.9829743 | E5: 1 | F5: 1 | G5: 1 | H5: 1 | I5: 1 | J5: 1 | K5: 1 | L5: 1 | M5: 1 | N5: 1 | O5: 1
A6: TD | B6: Question 5 | C6: 0 | D6: 10.565943 | E6: 1 | F6: 1 | G6: 1 | H6: 1 | I6: 1 | J6: 1 | K6: 1 | L6: 1 | M6: 1 | N6: 1 | O6: 1
A7: TD | B7: Question 6 | C7: 0 | D7: 2.8882141 | E7: 1 | F7: 1 | G7: 1 | H7: 1 | I7: 1 | J7: 1 | K7: 1 | L7: 1 | M7: 1 | N7: 1 | O7: 1
A8: TD | B8: Question 7 | C8: 0 | D8: 3.1747651 | E8: 1 | F8: 1 | G8: 1 | H8: 1 | I8: 1 | J8: 1 | K8: 1 | L8: 1 | M8: 1 | N8: 1 | O8: 1
A9: TD | B9: Question 8 | C9: 0 | D9: 2.9812384 | E9: 1 | F9: 1 | G9: 1 | H9: 1 | I9: 1 | J9: 1 | K9: 1 | L9: 1 | M9: 1 | N9: 1 | O9: 1
A10: TD | B10: Question 9 | C10: 0 | D10: 5.3422201 | E10: 1 | F10: 1 | G10: 1 | H10: 1 | I10: 1 | J10: 0 | K10: 0 | L10: 1 | M10: 1 | N10: 1 | O10: 1 | P10: Grade alignment: Matrix operations are typically covered in Secondary 5/A-level or tertiary mathematics, not O-level 3/4. Real-world feasibility: The impact factor matrix M with values 1, 0.5, 0.8 and the resulting multiplication C x M producing weighted scores lacks clear real-world meaning in the sports club context. The scenario does not mirror typical sports club operations where such mathematical weightings would be applied.
A11: TD | B11: Question 10 | C11: 0 | D11: 9.1759417 | E11: 1 | F11: 1 | G11: 1 | H11: 1 | I11: 1 | J11: 1 | K11: 1 | L11: 1 | M11: 1 | N11: 1 | O11: 1
A12: TD | B12: Question 11 | C12: 0 | D12: 10.049004 | E12: 1 | F12: 1 | G12: 1 | H12: 1 | I12: 1 | J12: 1 | K12: 0 | L12: 1 | M12: 1 | N12: 1 | O12: 1 | P12: Real-world feasibility: Attending 5/3 sessions (approximately 1.67 sessions) is unrealistic as one cannot attend a partial session in practice.
A13: TD | B13: Question 12 | C13: 0 | D13: 5.1484213 | E13: 1 | F13: 1 | G13: 1 | H13: 1 | I13: 1 | J13: 0 | K13: 1 | L13: 1 | M13: 1 | N13: 1 | O13: 1 | P13: Grade Alignment: This problem requires algebraic expressions with variables (x, n) and algebraic manipulation which are typically introduced in Secondary 1-2, not Primary 6. Primary 6 students in Singapore math syllabus typically work with basic arithmetic and simple algebraic concepts but not complex variable expressions and simplification of linear expressions with multiple variables.
A14: TD | B14: Question 13 | C14: 0 | D14: 11.401763 | E14: 1 | F14: 1 | G14: 1 | H14: 1 | I14: 1 | J14: 0 | K14: 1 | L14: 1 | M14: 1 | N14: 1 | O14: 1 | P14: Grade alignment: The problem results in 1.325 m per person, which has 3 decimal places. This exceeds Primary 4 level expectations and the primary KC specification of up to 2 decimal places.
A15: TD | B15: Question 14 | C15: 0 | D15: 11.103193 | E15: 1 | F15: 1 | G15: 1 | H15: 1 | I15: 1 | J15: 0 | K15: 1 | L15: 1 | M15: 1 | N15: 1 | O15: 1 | P15: Grade Alignment: The problem is too simple for Secondary O-level 1 students. It involves basic percentage calculation (15% of 60 = 9) and simple subtraction (69 - 10 = 59), which are concepts typically mastered in primary school, not challenging enough for 15-16 year old students.
A16: TD | B16: Question 15 | C16: 0 | D16: 10.503006 | E16: 1 | F16: 1 | G16: 1 | H16: 1 | I16: 1 | J16: 1 | K16: 1 | L16: 1 | M16: 1 | N16: 1 | O16: 1
A17: TD | B17: Question 16 | C17: 0 | D17: 12.419333 | E17: 1 | F17: 0 | G17: 1 | H17: 'NA | I17: 1 | J17: 'NA | K17: 1 | L17: 1 | M17: 1 | N17: 1 | O17: 1 | P17: Primary KC alignment fails because the problem only requires basic multiplication of 0.175 * 100 = 17.5, which is straightforward decimal multiplication by 100. The intended primary KC specifically targets multiplying by multiples of 10, 100, 1000 (like 20, 300, 4000), which would be more complex and is not demonstrated in this problem.
A18: TD | B18: Question 17 | C18: 0 | D18: 8.2587128 | E18: 0 | F18: 'NA | G18: 'NA | H18: 'NA | I18: 'NA | J18: 'NA | K18: 'NA | L18: 'NA | M18: 'NA | N18: 'NA | O18: 'NA | P18: The problem is missing critical information - the number of sessions Sarah attended last month. Without this information, it is impossible to determine how many sessions she attended this month (5/3 times an unknown number) and therefore impossible to calculate the total paint used this month.
A19: TD | B19: Question 18 | C19: 0 | D19: 10.13975 | E19: 1 | F19: 1 | G19: 1 | H19: 1 | I19: 1 | J19: 1 | K19: 1 | L19: 1 | M19: 1 | N19: 1 | O19: 1
A20: TD | B20: Question 19 | C20: 0 | D20: 5.5768538 | E20: 0 | F20: 'NA | G20: 'NA | H20: 'NA | I20: 'NA | J20: 'NA | K20: 'NA | L20: 'NA | M20: 'NA | N20: 'NA | O20: 'NA | P20: Answerability: The problem contains ambiguous information about how the additional 1/8 watermelon is distributed. It states Sarah adds 1/8 to what each person already has, but it's unclear if this means 1/8 total is divided among all 5 people or if each of the 5 people gets 1/8 additional watermelon. Clarity: The distribution method for the additional 1/8 watermelon is not clearly specified, making the problem ambiguous to solve.
A21: TD | B21: Question 20 | C21: 0 | D21: 10.66585 | E21: 1 | F21: 1 | G21: 1 | H21: 1 | I21: 1 | J21: 1 | K21: 0 | L21: 1 | M21: 1 | N21: 1 | O21: 1 | P21: The problem assumes that spending 2/3 as much time painting directly results in completing 2/3 as much work. In reality, painting completion depends on factors beyond just time spent, such as painting complexity, technique, and efficiency. This creates an unrealistic direct proportional relationship between time and work output.
A22: TD | B22: Question 21 | C22: 0 | D22: 10.276766 | E22: 1 | F22: 1 | G22: 1 | H22: 0 | I22: 1 | J22: 0 | K22: 1 | L22: 1 | M22: 1 | N22: 1 | O22: 1 | P22: Synergy: The two knowledge components work independently rather than in tandem - converting 15% to decimal (0.15) is separate from finding original price from 85% = $102. Grade alignment: Reverse percentage problems are typically too advanced for Secondary O-level 1 students (ages 13-14) and usually taught at higher secondary levels.
A23: TD | B23: Question 22 | C23: 0 | D23: 11.924159 | E23: 1 | F23: 0 | G23: 1 | H23: 'NA | I23: 1 | J23: 'NA | K23: 1 | L23: 1 | M23: 1 | N23: 1 | O23: 1 | P23: Primary KC alignment: Problem uses 3 decimal places (8.125) but intended component specifies up to 2 decimal places only. Synergy: Part (b) does not use results from part (a) - the questions are independent rather than building upon each other. Grade alignment: 3 decimal place operations may exceed typical Primary 4 curriculum expectations.
A24: TD | B24: Question 23 | C24: 0 | D24: 11.008698 | E24: 0 | F24: 'NA | G24: 'NA | H24: 'NA | I24: 'NA | J24: 'NA | K24: 'NA | L24: 'NA | M24: 'NA | N24: 'NA | O24: 'NA | P24: The problem cannot be solved because it is missing critical information - the number of practice days last month is not provided. To find total hours this month, we need: (7/4 hours per day) * (9/5 * days last month) * (days last month), but the value for days last month is not given.
A25: TD | B25: Question 24 | C25: 0 | D25: 11.509672 | E25: 1 | F25: 1 | G25: 1 | H25: 1 | I25: 1 | J25: 0 | K25: 1 | L25: 1 | M25: 1 | N25: 1 | O25: 1 | P25: Grade Alignment: Direct proportion is typically taught at Primary 6 level in Singapore math curriculum, making this problem too easy for Secondary O-level 2 students who should be handling more advanced mathematical concepts.
A26: TD | B26: Question 25 | C26: 0 | D26: 9.2698736 | E26: 1 | F26: 1 | G26: 1 | H26: 1 | I26: 1 | J26: 1 | K26: 1 | L26: 1 | M26: 1 | N26: 1 | O26: 1
A27: Minh | B27: Question 1 | C27: 0 | D27: 12.207029 | E27: 1 | F27: 0 | G27: 1 | H27: 'NA | I27: 1 | J27: 'NA | K27: 1 | L27: 1 | M27: 1 | N27: 1 | O27: 1 | P27: Primary KC alignment: The distance 1.797 km has 3 decimal places, exceeding the intended 2 decimal places limit. Grade alignment: Using 3 decimal places (1.797) may be too advanced for Primary 4 students when the intended primary KC specifies up to 2 decimal places only.
A28: Minh | B28: Question 2 | C28: 0 | D28: 10.428056 | E28: 1 | F28: 1 | G28: 1 | H28: 1 | I28: 1 | J28: 1 | K28: 1 | L28: 1 | M28: 1 | N28: 1 | O28: 1
A29: Minh | B29: Question 3 | C29: 0 | D29: 11.258657 | E29: 1 | F29: 1 | G29: 1 | H29: 1 | I29: 1 | J29: 1 | K29: 0 | L29: 1 | M29: 1 | N29: 1 | O29: 1 | P29: Real-World Plausibility: Dividing 0.125 hours among 1000 students gives each student 0.0001125 hours or approximately 0.4 seconds, which is unrealistically short for piano practice.
A30: Minh | B30: Question 4 | C30: 0 | D30: 12.333076 | E30: 1 | F30: 1 | G30: 1 | H30: 1 | I30: 1 | J30: 0 | K30: 1 | L30: 1 | M30: 1 | N30: 1 | O30: 1 | P30: Grade alignment fails because matrix operations are typically taught at A-level or university level, not at Secondary O-level 3/4 where students are usually 15-16 years old and study basic algebra, geometry, and trigonometry.
A31: Minh | B31: Question 5 | C31: 0 | D31: 11.726676 | E31: 1 | F31: 1 | G31: 1 | H31: 1 | I31: 1 | J31: 1 | K31: 1 | L31: 1 | M31: 1 | N31: 1 | O31: 1
A32: Minh | B32: Question 6 | C32: 0 | D32: 11.085871 | E32: 1 | F32: 1 | G32: 1 | H32: 1 | I32: 1 | J32: 1 | K32: 1 | L32: 1 | M32: 1 | N32: 1 | O32: 1
A33: Minh | B33: Question 7 | C33: 0 | D33: 11.938291 | E33: 1 | F33: 1 | G33: 1 | H33: 1 | I33: 1 | J33: 0 | K33: 1 | L33: 1 | M33: 1 | N33: 1 | O33: 1 | P33: Grade Alignment: The problem requires formal algebraic methods with variables and equation solving that are typically taught in Secondary 1 of Singapore curriculum, not Primary 6. Primary 6 students typically solve such problems using arithmetic methods rather than algebraic equations with variables.
A34: Minh | B34: Question 8 | C34: 0 | D34: 11.074604 | E34: 1 | F34: 1 | G34: 1 | H34: 1 | I34: 1 | J34: 1 | K34: 1 | L34: 1 | M34: 1 | N34: 1 | O34: 1
A35: Minh | B35: Question 9 | C35: 0 | D35: 10.286548 | E35: 1 | F35: 1 | G35: 1 | H35: 1 | I35: 1 | J35: 1 | K35: 1 | L35: 1 | M35: 1 | N35: 1 | O35: 1
A36: Minh | B36: Question 10 | C36: 0 | D36: 4.8174362 | E36: 1 | F36: 1 | G36: 1 | H36: 1 | I36: 1 | J36: 0 | K36: 1 | L36: 1 | M36: 1 | N36: 1 | O36: 1 | P36: Grade Alignment: The problem is designed for Secondary O-level 3/4 but quartiles and interquartile range are typically introduced at Primary 6 or Secondary 1/2 level in Singapore math syllabus. This makes the problem too elementary for the intended grade level of Secondary O-level 3/4 students.
A37: Minh | B37: Question 11 | C37: 0 | D37: 2.9754205 | E37: 1 | F37: 1 | G37: 1 | H37: 1 | I37: 1 | J37: 1 | K37: 1 | L37: 1 | M37: 1 | N37: 1 | O37: 1
A38: Minh | B38: Question 12 | C38: 0 | D38: 14.602862 | E38: 0 | F38: 'NA | G38: 'NA | H38: 'NA | I38: 'NA | J38: 'NA | K38: 'NA | L38: 'NA | M38: 'NA | N38: 'NA | O38: 'NA | P38: Answerability: Problem has conflicting constraints - ratio 3/4:2 with 24 dancing students gives 9 painting students, but 5/6 * 24 = 20 painting students. Secondary KC: No fraction division is required, only fraction multiplication and ratios. Synergy: Conflicting constraints prevent knowledge components from working together. Grade alignment: Complex fraction ratios too advanced for Secondary O-level 1. Clarity: Conflicting mathematical information makes problem confusing.
A39: Minh | B39: Question 13 | C39: 0 | D39: 11.805742 | E39: 1 | F39: 1 | G39: 1 | H39: 0 | I39: 1 | J39: 0 | K39: 0 | L39: 1 | M39: 1 | N39: 1 | O39: 1 | P39: Synergy: The two parts are connected by context but do not require tandem use of both knowledge components - part (a) uses only inverse proportion, part (b) uses only division. Grade Alignment: The mathematical concepts (120/4*6 and 36/6) are too elementary for Secondary O-level 2 students who should handle advanced algebra, trigonometry, or calculus. Real-World Feasibility: Board games typically have fixed completion times regardless of player count - more players do not reduce game duration.
A40: Minh | B40: Question 14 | C40: 0 | D40: 7.7096441 | E40: 0 | F40: 'NA | G40: 'NA | H40: 'NA | I40: 'NA | J40: 'NA | K40: 'NA | L40: 'NA | M40: 'NA | N40: 'NA | O40: 'NA | P40: Answerability: The problem asks to divide 183 children equally into 4 groups, but 183 / 4 = 45 remainder 3, making equal division impossible. Real-world feasibility: An organizer would not expect to divide 183 children into exactly 4 equal groups as this is mathematically impossible, making the scenario unrealistic.
...

Sheet recreation_v2_8
A1: Evaluator | B1: Question | C1: status | D1: response_time | E1: answerability | F1: primary_kc_alignment | G1: secondary_kc_alignment | H1: synergy | I1: topic_alignment | J1: grade_alignment | K1: real_world_feasibility | L1: clarity | M1: conciseness_and_relevance | N1: language_quality | O1: content_appropriateness | P1: explanation
A2: TD | B2: Question 1 | C2: 0 | D2: 4.2545023 | E2: 1 | F2: 1 | G2: 1 | H2: 1 | I2: 1 | J2: 0 | K2: 1 | L2: 1 | M2: 1 | N2: 1 | O2: 1 | P2: Grade alignment: The problem involves 4-digit subtraction (1562 - 738) and 3-digit addition (824 + 247), which are typically taught in Primary 4, not Primary 3. Primary 3 students typically work with numbers up to 1000.
A3: TD | B3: Question 2 | C3: 0 | D3: 7.5306346 | E3: 1 | F3: 0 | G3: 1 | H3: 'NA | I3: 1 | J3: 'NA | K3: 1 | L3: 1 | M3: 1 | N3: 1 | O3: 1 | P3: Primary KC alignment fails because the problem requires dividing 202.457 by 50, but the intended primary KC is specifically about dividing decimals by 10, 100, 1000 and their multiples. The number 50 is not 10, 100, 1000 or their multiples (50 = 2 × 5 × 5, not 10^n × integer where the integer uses only factors of 10).
A4: TD | B4: Question 3 | C4: 0 | D4: 7.3835707 | E4: 1 | F4: 1 | G4: 1 | H4: 1 | I4: 1 | J4: 1 | K4: 0 | L4: 0 | M4: 0 | N4: 1 | O4: 1 | P4: Real-world feasibility: The problem states Wei Lin swam on Monday and Wednesday (2 days) but then asks to divide among 10 days for that week, which is illogical since a week has 7 days and she only swam 2 days. Clarity: The phrase 'that week' is ambiguous - it's unclear if this refers to the current week or a future training week. The connection between her actual swimming days and the 10-day division plan is confusing. Conciseness and relevance: The phrase 'rounded to three decimal places' is unnecessary since 12.000/10 = 1.200 exactly with no rounding needed, making this instruction irrelevant.
A5: TD | B5: Question 4 | C5: 0 | D5: 2.9632802 | E5: 1 | F5: 1 | G5: 1 | H5: 1 | I5: 1 | J5: 1 | K5: 1 | L5: 1 | M5: 1 | N5: 1 | O5: 1
A6: TD | B6: Question 5 | C6: 0 | D6: 9.1602857 | E6: 1 | F6: 1 | G6: 1 | H6: 1 | I6: 1 | J6: 1 | K6: 1 | L6: 1 | M6: 1 | N6: 1 | O6: 1
A7: TD | B7: Question 6 | C7: 0 | D7: 8.9367771 | E7: 1 | F7: 1 | G7: 1 | H7: 1 | I7: 1 | J7: 1 | K7: 1 | L7: 1 | M7: 1 | N7: 1 | O7: 1
A8: TD | B8: Question 7 | C8: 0 | D8: 2.9537668 | E8: 1 | F8: 1 | G8: 1 | H8: 1 | I8: 1 | J8: 1 | K8: 1 | L8: 1 | M8: 1 | N8: 1 | O8: 1
A9: TD | B9: Question 8 | C9: 0 | D9: 2.8304398 | E9: 1 | F9: 1 | G9: 1 | H9: 1 | I9: 1 | J9: 1 | K9: 1 | L9: 1 | M9: 1 | N9: 1 | O9: 1
A10: TD | B10: Question 9 | C10: 0 | D10: 5.7178175 | E10: 1 | F10: 1 | G10: 1 | H10: 1 | I10: 1 | J10: 0 | K10: 0 | L10: 1 | M10: 1 | N10: 1 | O10: 1 | P10: Grade Alignment: Matrix operations including matrix multiplication are typically covered at A-level or higher secondary mathematics, not O-level 3/4. O-level mathematics usually covers basic algebra, geometry, and statistics but not advanced matrix operations. Real-World Feasibility: The concept of multiplying a matrix of hours by impact factors to get weighted scores is not a realistic scenario in actual sports club operations. Sports clubs typically track total hours or performance metrics directly rather than applying mathematical weightage matrices to training hours.
A11: TD | B11: Question 10 | C11: 0 | D11: 9.8642569 | E11: 1 | F11: 1 | G11: 1 | H11: 1 | I11: 1 | J11: 1 | K11: 1 | L11: 1 | M11: 1 | N11: 1 | O11: 1
A12: TD | B12: Question 11 | C12: 0 | D12: 9.456778 | E12: 1 | F12: 1 | G12: 1 | H12: 1 | I12: 1 | J12: 1 | K12: 0 | L12: 1 | M12: 1 | N12: 1 | O12: 1 | P12: The scenario describes attending 5/3 sessions which equals 1.67 sessions. In reality you cannot attend a partial session - you either attend a complete session or you do not attend at all.
A13: TD | B13: Question 12 | C13: 0 | D13: 4.6168635 | E13: 1 | F13: 1 | G13: 1 | H13: 1 | I13: 1 | J13: 0 | K13: 1 | L13: 1 | M13: 1 | N13: 1 | O13: 1 | P13: Grade Alignment: This problem requires knowledge of algebraic expressions with variables (x, n) and algebraic manipulation which is typically introduced in Secondary 1-2, not Primary 6. Primary 6 students in Singapore typically work with basic arithmetic and simple pre-algebraic concepts but not formal algebraic expressions with multiple variables.
A14: TD | B14: Question 13 | C14: 0 | D14: 9.6671355 | E14: 1 | F14: 1 | G14: 1 | H14: 1 | I14: 1 | J14: 1 | K14: 1 | L14: 1 | M14: 1 | N14: 1 | O14: 1
A15: TD | B15: Question 14 | C15: 0 | D15: 11.507887 | E15: 1 | F15: 1 | G15: 1 | H15: 1 | I15: 1 | J15: 0 | K15: 1 | L15: 1 | M15: 1 | N15: 1 | O15: 1 | P15: Grade alignment issue: The problem involves basic percentage calculation (15% increase) and simple whole number subtraction, which are typically Primary 5-6 level concepts in Singapore curriculum. Secondary O-level 1 students require more advanced mathematical concepts like algebra, geometry, or trigonometry.
A16: TD | B16: Question 15 | C16: 0 | D16: 9.5587497 | E16: 1 | F16: 1 | G16: 1 | H16: 1 | I16: 1 | J16: 1 | K16: 1 | L16: 1 | M16: 1 | N16: 1 | O16: 1
A17: TD | B17: Question 16 | C17: 0 | D17: 12.023425 | E17: 0 | F17: 'NA | G17: 'NA | H17: 'NA | I17: 'NA | J17: 'NA | K17: 'NA | L17: 'NA | M17: 'NA | N17: 'NA | O17: 'NA | P17: Answerability: Logical inconsistency - if Siti earns 0.175 points per note for 100 notes, she should earn exactly 17.5 points, but the problem states 17.5 includes 2.35 wrongly added points. Primary KC: The problem requires decimal subtraction (17.5 - 2.35), not multiplying decimals by 10/100/1000. Synergy: Since primary KC is not used, there is no synergy between intended knowledge components.
A18: TD | B18: Question 17 | C18: 0 | D18: 11.198777 | E18: 0 | F18: 'NA | G18: 'NA | H18: 'NA | I18: 'NA | J18: 'NA | K18: 'NA | L18: 'NA | M18: 'NA | N18: 'NA | O18: 'NA | P18: Answerability: The problem cannot be solved because the number of sessions Sarah attended last month is not provided. Without this information, we cannot calculate how many sessions she attended this month (5/3 times an unknown number) or the total paint used. Conciseness and Relevance: The problem is missing essential information needed for solving, making it incomplete rather than concise.
A19: TD | B19: Question 18 | C19: 0 | D19: 2.7196012 | E19: 1 | F19: 1 | G19: 1 | H19: 1 | I19: 1 | J19: 1 | K19: 1 | L19: 1 | M19: 1 | N19: 1 | O19: 1
A20: TD | B20: Question 19 | C20: 0 | D20: 11.15262 | E20: 1 | F20: 1 | G20: 1 | H20: 1 | I20: 1 | J20: 1 | K20: 1 | L20: 1 | M20: 1 | N20: 1 | O20: 1
A21: TD | B21: Question 20 | C21: 0 | D21: 12.739032 | E21: 1 | F21: 1 | G21: 1 | H21: 1 | I21: 1 | J21: 1 | K21: 0 | L21: 1 | M21: 1 | N21: 1 | O21: 1 | P21: Real-world feasibility issue: The problem assumes that spending 2/3 as much time painting directly translates to completing 2/3 as much work, but this relationship is not established. In reality, painting completion depends on many factors beyond just time spent.
A22: TD | B22: Question 21 | C22: 0 | D22: 2.6960146 | E22: 1 | F22: 1 | G22: 1 | H22: 1 | I22: 1 | J22: 1 | K22: 1 | L22: 1 | M22: 1 | N22: 1 | O22: 1
A23: TD | B23: Question 22 | C23: 0 | D23: 6.2342091 | E23: 1 | F23: 0 | G23: 1 | H23: 'NA | I23: 1 | J23: 'NA | K23: 1 | L23: 1 | M23: 1 | N23: 1 | O23: 1 | P23: Primary KC alignment: The problem includes decimals with 3 decimal places (8.125, 8.085) which exceeds the intended primary KC of adding decimals up to 2 decimal places only. Synergy: Part (a) only requires decimal addition while part (b) only requires decimal comparison - the results from part (a) are not used in part (b), so the two knowledge components are not used in tandem. Grade alignment: Primary 4 students typically work with decimals up to 2 decimal places, but this problem includes 3 decimal places (8.125, 8.085) which may be beyond the grade level.
A24: TD | B24: Question 23 | C24: 0 | D24: 6.6957586 | E24: 0 | F24: 'NA | G24: 'NA | H24: 'NA | I24: 'NA | J24: 'NA | K24: 'NA | L24: 'NA | M24: 'NA | N24: 'NA | O24: 'NA | P24: Answerability: The problem is missing critical information - the number of practice days last month is not provided. Without this information, it is impossible to calculate the total hours each student practices this month. The problem states there are 9/5 times as many practice days this month compared to last month, but does not specify how many days last month had.
A25: TD | B25: Question 24 | C25: 0 | D25: 12.743428 | E25: 1 | F25: 1 | G25: 1 | H25: 1 | I25: 1 | J25: 0 | K25: 0 | L25: 1 | M25: 1 | N25: 1 | O25: 1 | P25: Grade alignment: The proportion calculation 6/8 * 30 = 22.5 mats creates fractional results that may be too complex for Secondary O-level 2 students in practical contexts. Real-world feasibility: Cannot have 22.5 physical exercise mats in reality - would need to round to whole number of mats.
A26: TD | B26: Question 25 | C26: 0 | D26: 9.8424313 | E26: 1 | F26: 1 | G26: 1 | H26: 1 | I26: 1 | J26: 1 | K26: 1 | L26: 1 | M26: 1 | N26: 1 | O26: 1
A27: Minh | B27: Question 1 | C27: 0 | D27: 9.9774241 | E27: 1 | F27: 0 | G27: 1 | H27: 'NA | I27: 1 | J27: 'NA | K27: 1 | L27: 1 | M27: 1 | N27: 1 | O27: 1 | P27: Primary KC alignment: The intended primary knowledge component specifies adding decimals up to 2 decimal places, but the problem includes 1.797 km which has 3 decimal places, exceeding the specified limit.
A28: Minh | B28: Question 2 | C28: 0 | D28: 9.9582582 | E28: 1 | F28: 1 | G28: 0 | H28: 'NA | I28: 1 | J28: 1 | K28: 1 | L28: 1 | M28: 1 | N28: 1 | O28: 1 | P28: Secondary Knowledge Component: The answer 3/4 / 3 = 1/4 is already in simplest form, so expressing a fraction in its simplest form is not actively required. Synergy: Since no simplification is needed, the primary and secondary knowledge components do not work together in solving the problem.
A29: Minh | B29: Question 3 | C29: 0 | D29: 10.278625 | E29: 1 | F29: 1 | G29: 1 | H29: 1 | I29: 1 | J29: 1 | K29: 0 | L29: 1 | M29: 1 | N29: 1 | O29: 1 | P29: Real-world feasibility: Dividing 0.125 hours among 1000 students gives each student 0.000125 hours = 0.45 seconds, which is not a realistic practice duration for music education.
A30: Minh | B30: Question 4 | C30: 0 | D30: 11.838459 | E30: 1 | F30: 1 | G30: 1 | H30: 1 | I30: 1 | J30: 0 | K30: 1 | L30: 1 | M30: 1 | N30: 1 | O30: 1 | P30: Grade Alignment: Matrix operations including scalar multiplication and matrix subtraction are typically taught at A-level or university level mathematics, not at Secondary O-level 3/4. This problem requires knowledge components that are too advanced for the intended grade level.
A31: Minh | B31: Question 5 | C31: 0 | D31: 11.456226 | E31: 1 | F31: 1 | G31: 1 | H31: 1 | I31: 1 | J31: 1 | K31: 1 | L31: 1 | M31: 1 | N31: 1 | O31: 1
A32: Minh | B32: Question 6 | C32: 0 | D32: 2.7895133 | E32: 1 | F32: 1 | G32: 1 | H32: 1 | I32: 1 | J32: 1 | K32: 1 | L32: 1 | M32: 1 | N32: 1 | O32: 1
A33: Minh | B33: Question 7 | C33: 0 | D33: 11.531544 | E33: 1 | F33: 1 | G33: 1 | H33: 1 | I33: 1 | J33: 0 | K33: 1 | L33: 1 | M33: 1 | N33: 1 | O33: 1 | P33: Grade alignment fails because algebraic equations with variables are not taught in Singapore Primary 6 curriculum. Primary 6 students typically solve problems using arithmetic methods rather than algebraic notation with variables like n.
A34: Minh | B34: Question 8 | C34: 0 | D34: 2.8079963 | E34: 1 | F34: 1 | G34: 1 | H34: 1 | I34: 1 | J34: 1 | K34: 1 | L34: 1 | M34: 1 | N34: 1 | O34: 1
A35: Minh | B35: Question 9 | C35: 0 | D35: 2.8056219 | E35: 1 | F35: 1 | G35: 1 | H35: 1 | I35: 1 | J35: 1 | K35: 1 | L35: 1 | M35: 1 | N35: 1 | O35: 1
A36: Minh | B36: Question 10 | C36: 0 | D36: 4.5168464 | E36: 1 | F36: 1 | G36: 1 | H36: 1 | I36: 1 | J36: 0 | K36: 1 | L36: 1 | M36: 1 | N36: 1 | O36: 1 | P36: Grade Alignment: The problem is designed for Secondary O-level 3/4 students but uses terminology and concepts (quartiles Q1, Q2, Q3, interquartile range) that are typically introduced in Primary 6 or Secondary 1/2 levels in Singapore math curriculum, making it too basic for the intended grade level.
A37: Minh | B37: Question 11 | C37: 0 | D37: 2.8709714 | E37: 1 | F37: 1 | G37: 1 | H37: 1 | I37: 1 | J37: 1 | K37: 1 | L37: 1 | M37: 1 | N37: 1 | O37: 1
A38: Minh | B38: Question 12 | C38: 0 | D38: 12.464845 | E38: 0 | F38: 'NA | G38: 'NA | H38: 'NA | I38: 'NA | J38: 'NA | K38: 'NA | L38: 'NA | M38: 'NA | N38: 'NA | O38: 'NA | P38: Answerability: The problem contains conflicting information. Given ratio 3/4 : 2 equals 3:8, but if dancing = 24 and painting = 5/6 * 24 = 20, then actual ratio is 20:24 = 5:6. These ratios 3:8 and 5:6 are inconsistent. Secondary KC Alignment: No fraction division operation is required to solve the problem. Synergy: Primary and secondary knowledge components do not work together since fraction division is not needed.
A39: Minh | B39: Question 13 | C39: 0 | D39: 11.00863 | E39: 1 | F39: 1 | G39: 1 | H39: 1 | I39: 1 | J39: 0 | K39: 1 | L39: 1 | M39: 1 | N39: 1 | O39: 1 | P39: Grade alignment issue: Inverse proportion problems requiring the conceptual understanding that gameplay time decreases as player count increases may be too advanced for Secondary O-level 2 students. This level of abstract proportional reasoning typically comes later in mathematical development.
A40: Minh | B40: Question 14 | C40: 0 | D40: 8.9232655 | E40: 0 | F40: 'NA | G40: 'NA | H40: 'NA | I40: 'NA | J40: 'NA | K40: 'NA | L40: 'NA | M40: 'NA | N40: 'NA | O40: 'NA | P40: ANSWERABILITY: The problem cannot be solved as stated because 183 ÷ 4 = 45.75, which is not a whole number of children. The problem asks for equal groups but this is mathematically impossible with the given numbers. GRADE_ALIGNMENT: Primary 3 students typically work with division problems that result in whole numbers. A problem requiring decimal answers (45.75) or understanding of remainders in this context exceeds Primary 3 expectations. REAL_WORLD_FEASIBILITY: In reality, workshop organizers would not create groups with fractional children (45.75 per group). They would either form unequal groups or adjust the number of groups, making the premise unrealistic.
...

Sheet recreation_v2_9
A1: Evaluator | B1: Question | C1: status | D1: response_time | E1: answerability | F1: primary_kc_alignment | G1: secondary_kc_alignment | H1: synergy | I1: topic_alignment | J1: grade_alignment | K1: real_world_feasibility | L1: clarity | M1: conciseness_and_relevance | N1: language_quality | O1: content_appropriateness | P1: explanation
A2: TD | B2: Question 1 | C2: 0 | D2: 4.3597925 | E2: 1 | F2: 1 | G2: 1 | H2: 1 | I2: 1 | J2: 0 | K2: 1 | L2: 1 | M2: 1 | N2: 1 | O2: 1 | P2: Grade alignment: The problem uses 4-digit numbers (1562, 738, 247) which are typically introduced in Primary 4 or higher. Primary 3 students typically work with 3-digit numbers or smaller. The computational complexity of subtracting and adding 4-digit numbers exceeds Primary 3 level expectations.
A3: TD | B3: Question 2 | C3: 0 | D3: 10.840834 | E3: 1 | F3: 0 | G3: 1 | H3: 'NA | I3: 1 | J3: 'NA | K3: 1 | L3: 1 | M3: 1 | N3: 1 | O3: 1 | P3: Primary KC alignment fails because the required calculation 202.457 / 50 cannot be solved using the intended method of dividing decimals by 10, 100, 1000 and their multiples. While 50 = 10 x 5, this division requires general decimal division algorithms rather than the place-value shifting method specific to powers of 10.
A4: TD | B4: Question 3 | C4: 0 | D4: 7.0765119 | E4: 1 | F4: 1 | G4: 1 | H4: 1 | I4: 1 | J4: 1 | K4: 1 | L4: 0 | M4: 1 | N4: 1 | O4: 1 | P4: The problem contains ambiguous language regarding the time frame. It states Wei Lin swam on Monday and Wednesday, then asks her to divide the total distance equally among 10 days as part of a training plan. It is unclear whether the 10 days refers to the current week (which would not make sense as a week has 7 days) or a future training period. This creates confusion about the context and timeline of the division task.
A5: TD | B5: Question 4 | C5: 0 | D5: 2.7348113 | E5: 1 | F5: 1 | G5: 1 | H5: 1 | I5: 1 | J5: 1 | K5: 1 | L5: 1 | M5: 1 | N5: 1 | O5: 1
A6: TD | B6: Question 5 | C6: 0 | D6: 11.202191 | E6: 1 | F6: 1 | G6: 1 | H6: 1 | I6: 1 | J6: 0 | K6: 1 | L6: 1 | M6: 1 | N6: 1 | O6: 1 | P6: Grade alignment failed because the problem uses 3.276 minutes which has 3 decimal places. Primary 4 students typically work with decimals up to 2 decimal places only according to Singapore math curriculum. The number 3.276 requires knowledge above Primary 4 level.
A7: TD | B7: Question 6 | C7: 0 | D7: 6.7938976 | E7: 1 | F7: 1 | G7: 1 | H7: 1 | I7: 1 | J7: 1 | K7: 1 | L7: 1 | M7: 1 | N7: 1 | O7: 1
A8: TD | B8: Question 7 | C8: 0 | D8: 2.7297006 | E8: 1 | F8: 1 | G8: 1 | H8: 1 | I8: 1 | J8: 1 | K8: 1 | L8: 1 | M8: 1 | N8: 1 | O8: 1
A9: TD | B9: Question 8 | C9: 0 | D9: 2.737859 | E9: 1 | F9: 1 | G9: 1 | H9: 1 | I9: 1 | J9: 1 | K9: 1 | L9: 1 | M9: 1 | N9: 1 | O9: 1
