Workbook

Sheet recreation_claude_v2_1
A1: Evaluator | B1: Question | C1: status | D1: response_time | E1: answerability | F1: primary_kc_alignment | G1: secondary_kc_alignment | H1: synergy | I1: topic_alignment | J1: grade_alignment | K1: real_world_feasibility | L1: clarity | M1: conciseness_and_relevance | N1: language_quality | O1: content_appropriateness | P1: explanation
A2: TD | B2: Question 1 | C2: 0 | D2: 11.105753 | E2: 1 | F2: 1 | G2: 1 | H2: 1 | I2: 1 | J2: 0 | K2: 1 | L2: 1 | M2: 1 | N2: 1 | O2: 1 | P2: Grade alignment issue: Problem requires 4-digit addition (1245+876, 987+1298, 1156+945) but Primary 3 students typically work with 3-digit numbers. 4-digit addition is usually taught in Primary 4.
A3: TD | B3: Question 2 | C3: 0 | D3: 9.6764731 | E3: 1 | F3: 1 | G3: 1 | H3: 1 | I3: 1 | J3: 1 | K3: 1 | L3: 1 | M3: 1 | N3: 1 | O3: 1
A4: TD | B4: Question 3 | C4: 0 | D4: 2.970257 | E4: 1 | F4: 1 | G4: 1 | H4: 1 | I4: 1 | J4: 1 | K4: 1 | L4: 1 | M4: 1 | N4: 1 | O4: 1
A5: TD | B5: Question 4 | C5: 0 | D5: 8.1421077 | E5: 1 | F5: 0 | G5: 1 | H5: 'NA | I5: 1 | J5: 'NA | K5: 1 | L5: 1 | M5: 1 | N5: 1 | O5: 1 | P5: Primary KC alignment: The problem requires multiplying 3-digit numbers (126, 148, 235) by 1-digit numbers (4, 3, 2), but the intended primary KC is specifically for multiplying whole numbers UP TO 3 digits by 1 digit, which typically means the multiplicand should be at most 3 digits. However, 126x4=504, 148x3=444, and 235x2=470 are all manageable calculations, but 235 is a 3-digit number that when multiplied results in complexity beyond typical Primary 3 expectations. Grade alignment: This problem involves 3-digit by 1-digit multiplication with numbers like 235x2, 148x3, and 126x4, which produces results in the hundreds. This level of multiplication complexity is typically introduced in Primary 4, not Primary 3 where students usually work with simpler 2-digit by 1-digit or very basic 3-digit by 1-digit multiplication.
A6: TD | B6: Question 5 | C6: 0 | D6: 3.0410473 | E6: 1 | F6: 1 | G6: 1 | H6: 1 | I6: 1 | J6: 1 | K6: 1 | L6: 1 | M6: 1 | N6: 1 | O6: 1
A7: TD | B7: Question 6 | C7: 0 | D7: 2.9441407 | E7: 1 | F7: 1 | G7: 1 | H7: 1 | I7: 1 | J7: 1 | K7: 1 | L7: 1 | M7: 1 | N7: 1 | O7: 1
A8: TD | B8: Question 7 | C8: 0 | D8: 10.786603 | E8: 1 | F8: 1 | G8: 1 | H8: 1 | I8: 1 | J8: 1 | K8: 1 | L8: 1 | M8: 1 | N8: 1 | O8: 1
A9: TD | B9: Question 8 | C9: 0 | D9: 10.350135 | E9: 1 | F9: 1 | G9: 1 | H9: 1 | I9: 1 | J9: 1 | K9: 1 | L9: 1 | M9: 1 | N9: 1 | O9: 1
A10: TD | B10: Question 9 | C10: 0 | D10: 2.9266968 | E10: 1 | F10: 1 | G10: 1 | H10: 1 | I10: 1 | J10: 1 | K10: 1 | L10: 1 | M10: 1 | N10: 1 | O10: 1
A11: TD | B11: Question 10 | C11: 0 | D11: 8.6437135 | E11: 1 | F11: 1 | G11: 1 | H11: 1 | I11: 1 | J11: 1 | K11: 1 | L11: 1 | M11: 1 | N11: 1 | O11: 1
A12: TD | B12: Question 11 | C12: 0 | D12: 11.651141 | E12: 0 | F12: 'NA | G12: 'NA | H12: 'NA | I12: 'NA | J12: 'NA | K12: 'NA | L12: 'NA | M12: 'NA | N12: 'NA | O12: 'NA | P12: Answerability: Questions (a) and (b) ask for totals but only provide single fractions - Sarah has 2/3 painting and 1/4 music, no second fractions to add. Primary KC Alignment: Problem does not require adding unlike fractions since each person has only one fraction per challenge type. Synergy: Primary and secondary knowledge components cannot work together effectively when primary component is not properly implemented.
A13: TD | B13: Question 12 | C13: 0 | D13: 2.9765003 | E13: 1 | F13: 1 | G13: 1 | H13: 1 | I13: 1 | J13: 1 | K13: 1 | L13: 1 | M13: 1 | N13: 1 | O13: 1
A14: TD | B14: Question 13 | C14: 0 | D14: 11.87017 | E14: 1 | F14: 0 | G14: 1 | H14: 'NA | I14: 1 | J14: 'NA | K14: 1 | L14: 1 | M14: 1 | N14: 1 | O14: 1 | P14: Primary KC alignment: Problem requires adding decimals up to 3 decimal places (1.142) but intended component specifies up to 2 decimal places only. Grade alignment: The use of 3 decimal places (1.142) may be too advanced for Primary 4 students who typically work with simpler decimal operations.
A15: TD | B15: Question 14 | C15: 0 | D15: 2.93716 | E15: 1 | F15: 1 | G15: 1 | H15: 1 | I15: 1 | J15: 1 | K15: 1 | L15: 1 | M15: 1 | N15: 1 | O15: 1
A16: TD | B16: Question 15 | C16: 0 | D16: 11.390833 | E16: 1 | F16: 1 | G16: 1 | H16: 1 | I16: 1 | J16: 0 | K16: 1 | L16: 1 | M16: 1 | N16: 1 | O16: 1 | P16: Grade alignment issue: The problem uses 2.486 km which has 3 decimal places (thousandths). Primary 4 students typically work with decimals up to 2 decimal places only. Working with 3 decimal places is usually introduced in Primary 5, making this problem too advanced for the intended grade level.
A17: TD | B17: Question 16 | C17: 0 | D17: 8.6064401 | E17: 1 | F17: 1 | G17: 1 | H17: 1 | I17: 1 | J17: 1 | K17: 1 | L17: 1 | M17: 1 | N17: 1 | O17: 1
A18: TD | B18: Question 17 | C18: 0 | D18: 9.417341 | E18: 1 | F18: 1 | G18: 1 | H18: 1 | I18: 1 | J18: 1 | K18: 1 | L18: 1 | M18: 1 | N18: 1 | O18: 1
A19: TD | B19: Question 18 | C19: 0 | D19: 2.9293506 | E19: 1 | F19: 1 | G19: 1 | H19: 1 | I19: 1 | J19: 1 | K19: 1 | L19: 1 | M19: 1 | N19: 1 | O19: 1
A20: TD | B20: Question 19 | C20: 0 | D20: 13.552191 | E20: 0 | F20: 'NA | G20: 'NA | H20: 'NA | I20: 'NA | J20: 'NA | K20: 'NA | L20: 'NA | M20: 'NA | N20: 'NA | O20: 'NA | P20: Answerability: The question 'total distance per lap over two days' is ambiguous and mathematically unclear. Primary KC Alignment: 5.24 / 3 = 1.7466... which exceeds 2 decimal places, violating the intended scope. Grade Alignment: Non-terminating decimals and ambiguous phrasing too complex for Primary 4. Real-world feasibility: Same pool having different lap distances on different days is unrealistic. Clarity: Final question phrasing is confusing and ambiguous.
A21: TD | B21: Question 20 | C21: 0 | D21: 8.9025273 | E21: 1 | F21: 1 | G21: 1 | H21: 1 | I21: 1 | J21: 1 | K21: 1 | L21: 1 | M21: 1 | N21: 1 | O21: 1
A22: TD | B22: Question 21 | C22: 0 | D22: 10.184599 | E22: 1 | F22: 1 | G22: 1 | H22: 1 | I22: 1 | J22: 1 | K22: 1 | L22: 1 | M22: 1 | N22: 1 | O22: 1
A23: TD | B23: Question 22 | C23: 0 | D23: 11.651554 | E23: 1 | F23: 1 | G23: 1 | H23: 1 | I23: 1 | J23: 1 | K23: 1 | L23: 1 | M23: 1 | N23: 1 | O23: 1
A24: TD | B24: Question 23 | C24: 0 | D24: 9.8399601 | E24: 1 | F24: 1 | G24: 1 | H24: 1 | I24: 1 | J24: 1 | K24: 1 | L24: 1 | M24: 1 | N24: 1 | O24: 1
A25: TD | B25: Question 24 | C25: 0 | D25: 11.518569 | E25: 1 | F25: 1 | G25: 1 | H25: 1 | I25: 1 | J25: 1 | K25: 1 | L25: 1 | M25: 1 | N25: 1 | O25: 1
A26: TD | B26: Question 25 | C26: 0 | D26: 10.433698 | E26: 1 | F26: 1 | G26: 1 | H26: 1 | I26: 1 | J26: 1 | K26: 1 | L26: 1 | M26: 1 | N26: 1 | O26: 1
A27: TD | B27: Question 26 | C27: 0 | D27: 11.149707 | E27: 1 | F27: 0 | G27: 1 | H27: 'NA | I27: 1 | J27: 'NA | K27: 1 | L27: 1 | M27: 1 | N27: 1 | O27: 1 | P27: Primary KC alignment: The problem only requires adding fractions (7/4 + 5/3, 9/5 + 8/7, and adding the sums). No multiplication of improper fractions is needed. Synergy: Cannot achieve synergy between primary and secondary KC when the primary KC (multiplying improper fractions) is not present in the problem.
A28: TD | B28: Question 27 | C28: 0 | D28: 6.3620174 | E28: 1 | F28: 0 | G28: 1 | H28: 'NA | I28: 1 | J28: 'NA | K28: 1 | L28: 1 | M28: 1 | N28: 1 | O28: 1 | P28: Primary KC alignment: The problem requires division of fractions (finding planned time when actual time is 2/3 of planned), not multiplication of two improper fractions. The main operation is (7/4 + 5/3 - 3/2) ÷ (2/3) which involves division as the primary operation. Synergy: The Primary KC (multiplication of improper fractions) and Secondary KC (subtraction of fractions) are not used in tandem. The problem primarily uses addition and subtraction of fractions, then division, but not multiplication of two improper fractions as required by the Primary KC.
A29: TD | B29: Question 28 | C29: 0 | D29: 10.531832 | E29: 1 | F29: 1 | G29: 1 | H29: 1 | I29: 1 | J29: 1 | K29: 1 | L29: 1 | M29: 1 | N29: 1 | O29: 1
A30: TD | B30: Question 29 | C30: 0 | D30: 10.047207 | E30: 1 | F30: 1 | G30: 0 | H30: 'NA | I30: 1 | J30: 1 | K30: 1 | L30: 1 | M30: 1 | N30: 1 | O30: 1 | P30: Secondary Knowledge Component misalignment: The problem requires subtracting whole numbers (22 - 19 = 3) rather than subtracting fractions as specified in the intended Secondary Knowledge Component.
A31: TD | B31: Question 30 | C31: 0 | D31: 12.467189 | E31: 1 | F31: 0 | G31: 1 | H31: 'NA | I31: 1 | J31: 'NA | K31: 1 | L31: 1 | M31: 1 | N31: 1 | O31: 1 | P31: Primary KC alignment: Problem requires 0.875 * 300 which is general decimal multiplication, not specifically multiplying by 10, 100, 1000 or their multiples as intended. Synergy: Since intended primary KC is not actually used, there is no synergistic relationship between the intended primary and secondary knowledge components.
A32: TD | B32: Question 31 | C32: 0 | D32: 6.1254821 | E32: 1 | F32: 0 | G32: 1 | H32: 'NA | I32: 1 | J32: 'NA | K32: 1 | L32: 1 | M32: 1 | N32: 1 | O32: 1 | P32: Primary KC alignment: The problem requires 0.125 * 400 which is decimal multiplication by a whole number, not specifically multiplying decimals by 10, 100, 1000 or their multiples as intended. Synergy: The two parts can be solved independently - the first part calculates distance (0.125 * 400 = 50), the second part subtracts (65.8 - 50 = 15.8). The primary and secondary knowledge components are not used in tandem as the multiplication result is not essential for the subtraction part.
A33: TD | B33: Question 32 | C33: 0 | D33: 11.520845 | E33: 1 | F33: 0 | G33: 1 | H33: 'NA | I33: 1 | J33: 'NA | K33: 1 | L33: 1 | M33: 1 | N33: 1 | O33: 1 | P33: Primary KC alignment fails because the problem requires dividing by 7, but the intended primary KC is dividing decimals by 10, 100, 1000 and their multiples. Since 7 is not a multiple of 10, 100, or 1000, this creates a fundamental misalignment with the intended knowledge component.
A34: TD | B34: Question 33 | C34: 0 | D34: 8.7761075 | E34: 0 | F34: 'NA | G34: 'NA | H34: 'NA | I34: 'NA | J34: 'NA | K34: 'NA | L34: 'NA | M34: 'NA | N34: 'NA | O34: 'NA | P34: Answerability: The problem contains illogical information - if Sarah swam 40000 meters total and the coach divides total time by 400, this does not give average time per 100 meters as stated. The calculation 40000/400=100, so dividing by 400 would give time per 100-meter segments, but the setup is mathematically inconsistent. Primary KC Alignment: The division required is by 400, not by 10, 100, 1000 or their multiples as specified in the intended knowledge component. 400 is not a multiple of 10, 100, or 1000 in the standard sense for this curriculum topic. Real-world Feasibility: Swimming 40000 meters (40 km) in 4 laps is unrealistic - this would mean each lap is 10 km, which is not feasible for a typical swimming practice session. Conciseness and Relevance: The 40000 meters information appears unnecessary and creates confusion since the actual calculation can be done by adding the times and dividing by 400 directly.
A35: TD | B35: Question 34 | C35: 0 | D35: 11.226322 | E35: 1 | F35: 1 | G35: 0 | H35: 'NA | I35: 1 | J35: 1 | K35: 1 | L35: 1 | M35: 1 | N35: 1 | O35: 1 | P35: Secondary KC alignment: Problem requires division (90/120) and multiplication by 100, not multiplication of whole numbers as intended. Synergy: No synergy exists since the intended secondary KC (whole number multiplication) is not actually needed to solve the problem.
A36: TD | B36: Question 35 | C36: 0 | D36: 6.2476168 | E36: 1 | F36: 1 | G36: 1 | H36: 1 | I36: 1 | J36: 1 | K36: 1 | L36: 1 | M36: 1 | N36: 1 | O36: 1
A37: TD | B37: Question 36 | C37: 0 | D37: 11.940733 | E37: 1 | F37: 1 | G37: 1 | H37: 1 | I37: 1 | J37: 1 | K37: 0 | L37: 1 | M37: 1 | N37: 1 | O37: 1 | P37: Real-world feasibility: 1.25 km/h is unrealistically slow for marathon training - this is slower than normal walking speed of 4-5 km/h and would not represent realistic training pace.
A38: TD | B38: Question 37 | C38: 0 | D38: 9.7374115 | E38: 1 | F38: 1 | G38: 1 | H38: 1 | I38: 1 | J38: 1 | K38: 1 | L38: 1 | M38: 1 | N38: 1 | O38: 1
A39: TD | B39: Question 38 | C39: 0 | D39: 2.8938303 | E39: 1 | F39: 1 | G39: 1 | H39: 1 | I39: 1 | J39: 1 | K39: 1 | L39: 1 | M39: 1 | N39: 1 | O39: 1
A40: TD | B40: Question 39 | C40: 0 | D40: 11.566289 | E40: 1 | F40: 1 | G40: 1 | H40: 1 | I40: 1 | J40: 1 | K40: 0 | L40: 1 | M40: 1 | N40: 1 | O40: 1 | P40: Real-world plausibility: The phrase 2/3 of the week refers to 4.67 days, which is not how people typically plan practice schedules in reality. Practice schedules are usually planned in whole days or specific days of the week.
...

Sheet recreation_claude_v2_2
A1: Evaluator | B1: Question | C1: status | D1: response_time | E1: answerability | F1: primary_kc_alignment | G1: secondary_kc_alignment | H1: synergy | I1: topic_alignment | J1: grade_alignment | K1: real_world_feasibility | L1: clarity | M1: conciseness_and_relevance | N1: language_quality | O1: content_appropriateness | P1: explanation
A2: TD | B2: Question 1 | C2: 0 | D2: 4.6345649 | E2: 1 | F2: 1 | G2: 1 | H2: 1 | I2: 1 | J2: 0 | K2: 1 | L2: 1 | M2: 1 | N2: 1 | O2: 1 | P2: Grade alignment: Primary 3 students typically work with 3-digit numbers, but this problem uses 4-digit numbers (1245, 1298, 1156) which is typically introduced in Primary 4. The addition of 4-digit numbers exceeds the expected mathematical complexity for Primary 3 students.
A3: TD | B3: Question 2 | C3: 0 | D3: 9.7286408 | E3: 1 | F3: 1 | G3: 1 | H3: 1 | I3: 1 | J3: 1 | K3: 1 | L3: 1 | M3: 1 | N3: 1 | O3: 1
A4: TD | B4: Question 3 | C4: 0 | D4: 10.642204 | E4: 1 | F4: 1 | G4: 1 | H4: 1 | I4: 1 | J4: 1 | K4: 1 | L4: 1 | M4: 1 | N4: 1 | O4: 1
A5: TD | B5: Question 4 | C5: 0 | D5: 5.6356914 | E5: 1 | F5: 0 | G5: 1 | H5: 'NA | I5: 1 | J5: 'NA | K5: 1 | L5: 1 | M5: 1 | N5: 1 | O5: 1 | P5: Primary KC alignment: Problem requires multiplying 3-digit numbers by 1-digit numbers (126x4, 148x3, 235x2), but Primary 3 students typically learn multiplication of 2-digit by 1-digit numbers. Grade alignment: The multiplication operations involve 3-digit by 1-digit multiplication which exceeds typical Primary 3 curriculum expectations where students usually work with simpler multiplication facts and 2-digit by 1-digit operations.
A6: TD | B6: Question 5 | C6: 0 | D6: 2.9623332 | E6: 1 | F6: 1 | G6: 1 | H6: 1 | I6: 1 | J6: 1 | K6: 1 | L6: 1 | M6: 1 | N6: 1 | O6: 1
A7: TD | B7: Question 6 | C7: 0 | D7: 3.0652823 | E7: 1 | F7: 1 | G7: 1 | H7: 1 | I7: 1 | J7: 1 | K7: 1 | L7: 1 | M7: 1 | N7: 1 | O7: 1
A8: TD | B8: Question 7 | C8: 0 | D8: 11.272932 | E8: 1 | F8: 1 | G8: 1 | H8: 1 | I8: 1 | J8: 1 | K8: 1 | L8: 1 | M8: 1 | N8: 1 | O8: 1
A9: TD | B9: Question 8 | C9: 0 | D9: 8.3822763 | E9: 1 | F9: 1 | G9: 1 | H9: 1 | I9: 1 | J9: 1 | K9: 1 | L9: 1 | M9: 1 | N9: 1 | O9: 1
A10: TD | B10: Question 9 | C10: 0 | D10: 2.8803325 | E10: 1 | F10: 1 | G10: 1 | H10: 1 | I10: 1 | J10: 1 | K10: 1 | L10: 1 | M10: 1 | N10: 1 | O10: 1
A11: TD | B11: Question 10 | C11: 0 | D11: 7.7712424 | E11: 1 | F11: 1 | G11: 1 | H11: 1 | I11: 1 | J11: 1 | K11: 1 | L11: 0 | M11: 1 | N11: 1 | O11: 1 | P11: Clarity: The problem contains the phrase 'clarity' appears twice in the JSON structure which creates ambiguity in the evaluation framework. Additionally, while the problem context is clear, the transition between the two mathematical operations could be more explicitly connected in the problem statement.
A12: TD | B12: Question 11 | C12: 0 | D12: 13.712001 | E12: 0 | F12: 'NA | G12: 'NA | H12: 'NA | I12: 'NA | J12: 'NA | K12: 'NA | L12: 'NA | M12: 'NA | N12: 'NA | O12: 'NA | P12: Answerability: Questions (a) and (b) ask for totals when only single fractions are given per person per challenge, making them unanswerable as intended. Primary KC Alignment: Questions (a) and (b) do not require adding fractions - they only restate given information. The primary knowledge component is not properly targeted. Synergy: Primary and secondary knowledge components are not used together - questions (a) and (b) need no addition, and question (c) can be solved independently. Clarity: Questions (a) and (b) are ambiguous since they ask what fraction Sarah completed in total when only one fraction per challenge type is provided.
A13: TD | B13: Question 12 | C13: 0 | D13: 2.9679828 | E13: 1 | F13: 1 | G13: 1 | H13: 1 | I13: 1 | J13: 1 | K13: 1 | L13: 1 | M13: 1 | N13: 1 | O13: 1
A14: TD | B14: Question 13 | C14: 0 | D14: 11.611817 | E14: 1 | F14: 0 | G14: 1 | H14: 'NA | I14: 1 | J14: 'NA | K14: 1 | L14: 1 | M14: 1 | N14: 1 | O14: 1 | P14: Primary KC alignment: The intended primary component specifies adding decimals up to 2 decimal places, but the problem includes 1.142 which has 3 decimal places, exceeding the intended scope.
A15: TD | B15: Question 14 | C15: 0 | D15: 10.927273 | E15: 1 | F15: 0 | G15: 1 | H15: 'NA | I15: 1 | J15: 'NA | K15: 1 | L15: 1 | M15: 1 | N15: 1 | O15: 1 | P15: Primary KC alignment fails because the problem directly states Wednesday practice was 0.25 hours less than Monday, so no decimal subtraction calculation is needed - students just need to recognize 0.25 as the answer. Synergy fails because the primary KC (decimal subtraction) is not actually required to solve the problem, so the two knowledge components do not work together as intended.
A16: TD | B16: Question 15 | C16: 0 | D16: 10.436213 | E16: 1 | F16: 1 | G16: 1 | H16: 1 | I16: 1 | J16: 1 | K16: 1 | L16: 1 | M16: 1 | N16: 1 | O16: 1
A17: TD | B17: Question 16 | C17: 0 | D17: 12.342287 | E17: 1 | F17: 1 | G17: 1 | H17: 1 | I17: 1 | J17: 0 | K17: 1 | L17: 1 | M17: 1 | N17: 1 | O17: 1 | P17: Grade Alignment: The problem requires converting 2.45 to fraction form 245/100, then simplifying to 49/20, and final answer 147/20. Working with complex fractions like 49/20 and 147/20 exceeds typical Primary 4 mathematical abilities.
A18: TD | B18: Question 17 | C18: 0 | D18: 3.0017624 | E18: 1 | F18: 1 | G18: 1 | H18: 1 | I18: 1 | J18: 1 | K18: 1 | L18: 1 | M18: 1 | N18: 1 | O18: 1
A19: TD | B19: Question 18 | C19: 0 | D19: 7.3627777 | E19: 1 | F19: 1 | G19: 1 | H19: 1 | I19: 1 | J19: 1 | K19: 1 | L19: 1 | M19: 1 | N19: 1 | O19: 1
A20: TD | B20: Question 19 | C20: 0 | D20: 11.361562 | E20: 0 | F20: 'NA | G20: 'NA | H20: 'NA | I20: 'NA | J20: 'NA | K20: 'NA | L20: 'NA | M20: 'NA | N20: 'NA | O20: 'NA | P20: Answerability: The question what is the total distance Sarah swam per lap over the two days is ambiguous and unclear what specific calculation is required. Secondary KC alignment: Adding decimals is not clearly required since the question does not definitively ask for combining the per-lap distances. Synergy: The two knowledge components are not used in tandem as the addition step is not clearly necessary. Real-world feasibility: Swimming laps of 1.56-1.75 km each around a pool is unrealistic as typical pool laps are much shorter distances. Clarity: The final question is ambiguous about what calculation is actually wanted.
A21: TD | B21: Question 20 | C21: 0 | D21: 9.224318 | E21: 1 | F21: 1 | G21: 1 | H21: 1 | I21: 1 | J21: 1 | K21: 1 | L21: 1 | M21: 1 | N21: 1 | O21: 1
A22: TD | B22: Question 21 | C22: 0 | D22: 10.124666 | E22: 1 | F22: 1 | G22: 1 | H22: 1 | I22: 1 | J22: 1 | K22: 1 | L22: 1 | M22: 1 | N22: 1 | O22: 1
A23: TD | B23: Question 22 | C23: 0 | D23: 10.531391 | E23: 1 | F23: 1 | G23: 1 | H23: 1 | I23: 1 | J23: 1 | K23: 1 | L23: 1 | M23: 1 | N23: 1 | O23: 1
A24: TD | B24: Question 23 | C24: 0 | D24: 9.2260921 | E24: 1 | F24: 1 | G24: 1 | H24: 1 | I24: 1 | J24: 1 | K24: 1 | L24: 1 | M24: 1 | N24: 1 | O24: 1
A25: TD | B25: Question 24 | C25: 0 | D25: 2.8937142 | E25: 1 | F25: 1 | G25: 1 | H25: 1 | I25: 1 | J25: 1 | K25: 1 | L25: 1 | M25: 1 | N25: 1 | O25: 1
A26: TD | B26: Question 25 | C26: 0 | D26: 10.699326 | E26: 1 | F26: 1 | G26: 1 | H26: 1 | I26: 1 | J26: 1 | K26: 1 | L26: 1 | M26: 1 | N26: 1 | O26: 1
A27: TD | B27: Question 26 | C27: 0 | D27: 5.4365289 | E27: 1 | F27: 0 | G27: 1 | H27: 'NA | I27: 1 | J27: 'NA | K27: 1 | L27: 1 | M27: 1 | N27: 1 | O27: 1 | P27: Primary KC Alignment: The problem only requires adding fractions (7/4 + 5/3, 9/5 + 8/7, and summing the results). No multiplication of improper fractions is needed to solve any part of the problem. Synergy: The primary KC (multiplying improper fractions) is not used at all in the solution, so there is no synergy between the primary and secondary knowledge components.
A28: TD | B28: Question 27 | C28: 0 | D28: 14.998528 | E28: 1 | F28: 0 | G28: 1 | H28: 'NA | I28: 1 | J28: 'NA | K28: 1 | L28: 1 | M28: 1 | N28: 1 | O28: 1 | P28: Primary KC alignment: The problem does not focus on multiplying improper fractions as the main concept. The multiplication 23/12 * 3/2 occurs as part of division by reciprocal, not as the primary skill being tested. The main operations are fraction addition, subtraction, and division. Synergy: Since the primary KC is not properly aligned, the intended synergy between multiplying improper fractions and subtracting fractions is not achieved in the problem structure.
A29: TD | B29: Question 28 | C29: 0 | D29: 10.22271 | E29: 1 | F29: 1 | G29: 1 | H29: 1 | I29: 1 | J29: 1 | K29: 1 | L29: 1 | M29: 1 | N29: 1 | O29: 1
A30: TD | B30: Question 29 | C30: 0 | D30: 10.951265 | E30: 1 | F30: 1 | G30: 0 | H30: 'NA | I30: 1 | J30: 1 | K30: 1 | L30: 1 | M30: 1 | N30: 1 | O30: 1 | P30: Secondary KC alignment fails because the subtraction step involves whole numbers (22 - 19 = 3) rather than fractions as specified in the intended Secondary Knowledge Component of subtracting fractions.
A31: TD | B31: Question 30 | C31: 0 | D31: 6.4785011 | E31: 1 | F31: 0 | G31: 1 | H31: 'NA | I31: 1 | J31: 'NA | K31: 1 | L31: 1 | M31: 1 | N31: 1 | O31: 1 | P31: Primary KC alignment fails because the problem requires multiplying 0.875 x 300, which is multiplying a decimal by a whole number that is not 10, 100, 1000 or their multiples. The intended primary KC specifically targets multiplication by 10, 100, 1000 and their multiples only. Synergy fails because the primary KC (decimal multiplication by powers of 10) is not actually needed to solve this problem - students would directly multiply 0.875 x 300 without using the specific skill of multiplying by 10, 100, 1000, then convert the result to mixed number form using only the secondary KC.
A32: TD | B32: Question 31 | C32: 0 | D32: 6.3718319 | E32: 1 | F32: 0 | G32: 1 | H32: 'NA | I32: 1 | J32: 'NA | K32: 1 | L32: 1 | M32: 1 | N32: 1 | O32: 1 | P32: Primary KC alignment: The problem requires multiplying 0.125 x 400, which is multiplying a decimal by a whole number, not specifically multiplying decimals by 10, 100, 1000 or their multiples as intended. Synergy: The two parts of the problem are independent - the first part calculates distance (0.125 x 400 = 50), the second part subtracts (65.8 - 50 = 15.8). The primary KC (decimal multiplication by powers of 10) and secondary KC (decimal subtraction) are not used in tandem as the multiplication does not involve powers of 10.
A33: TD | B33: Question 32 | C33: 0 | D33: 9.3042269 | E33: 1 | F33: 0 | G33: 1 | H33: 'NA | I33: 1 | J33: 'NA | K33: 1 | L33: 1 | M33: 1 | N33: 1 | O33: 1 | P33: Primary KC requires dividing decimals by 10, 100, 1000 and their multiples, but the problem divides 127.850 by 7, which is general decimal division not the specific targeted skill.
A34: TD | B34: Question 33 | C34: 0 | D34: 11.838382 | E34: 1 | F34: 1 | G34: 1 | H34: 1 | I34: 1 | J34: 1 | K34: 0 | L34: 1 | M34: 1 | N34: 1 | O34: 1 | P34: Real-world feasibility fails because swimming 40000 meters in 4 laps of approximately 10 minutes total would require each lap to be 10000 meters and swimming speed of about 60 km/h which is impossible for humans.
A35: TD | B35: Question 34 | C35: 0 | D35: 10.259708 | E35: 1 | F35: 1 | G35: 1 | H35: 1 | I35: 1 | J35: 1 | K35: 1 | L35: 1 | M35: 1 | N35: 1 | O35: 1
A36: TD | B36: Question 35 | C36: 0 | D36: 8.6072161 | E36: 1 | F36: 1 | G36: 1 | H36: 1 | I36: 1 | J36: 1 | K36: 0 | L36: 1 | M36: 1 | N36: 1 | O36: 1 | P36: Real-world feasibility: In basketball tournaments, teams typically have 5 starting players + 7-12 substitutes = 12-17 total players per team. Having 30 players per team with 15 eliminated per team is unrealistic for standard basketball tournament structure.
A37: TD | B37: Question 36 | C37: 0 | D37: 7.4785573 | E37: 1 | F37: 1 | G37: 1 | H37: 1 | I37: 1 | J37: 1 | K37: 0 | L37: 1 | M37: 1 | N37: 1 | O37: 1 | P37: Real-world feasibility fails because 1.25 km/h is an unrealistically slow running pace - this is slower than normal walking speed (4-5 km/h). Marathon runners typically run at 10-20 km/h during training. This speed would be more appropriate for a very slow walk rather than running training.
A38: TD | B38: Question 37 | C38: 0 | D38: 9.6309726 | E38: 1 | F38: 1 | G38: 1 | H38: 1 | I38: 1 | J38: 1 | K38: 1 | L38: 1 | M38: 1 | N38: 1 | O38: 1
A39: TD | B39: Question 38 | C39: 0 | D39: 3.0311999 | E39: 1 | F39: 1 | G39: 1 | H39: 1 | I39: 1 | J39: 1 | K39: 1 | L39: 1 | M39: 1 | N39: 1 | O39: 1
A40: TD | B40: Question 39 | C40: 0 | D40: 11.142194 | E40: 1 | F40: 1 | G40: 1 | H40: 1 | I40: 1 | J40: 1 | K40: 0 | L40: 1 | M40: 1 | N40: 1 | O40: 1 | P40: Real-world plausibility: The concept of dividing practice time over 2/3 of a week is unrealistic. People do not typically plan activities for fractional portions of a week in real life scenarios.
...

Sheet recreation_claude_v2_3
A1: Evaluator | B1: Question | C1: status | D1: response_time | E1: answerability | F1: primary_kc_alignment | G1: secondary_kc_alignment | H1: synergy | I1: topic_alignment | J1: grade_alignment | K1: real_world_feasibility | L1: clarity | M1: conciseness_and_relevance | N1: language_quality | O1: content_appropriateness | P1: explanation
A2: TD | B2: Question 1 | C2: 0 | D2: 9.9057977 | E2: 1 | F2: 1 | G2: 1 | H2: 1 | I2: 1 | J2: 1 | K2: 1 | L2: 1 | M2: 1 | N2: 1 | O2: 1
A3: TD | B3: Question 2 | C3: 0 | D3: 2.9739623 | E3: 1 | F3: 1 | G3: 1 | H3: 1 | I3: 1 | J3: 1 | K3: 1 | L3: 1 | M3: 1 | N3: 1 | O3: 1
A4: TD | B4: Question 3 | C4: 0 | D4: 7.9791753 | E4: 1 | F4: 1 | G4: 1 | H4: 1 | I4: 1 | J4: 1 | K4: 1 | L4: 1 | M4: 1 | N4: 1 | O4: 1
A5: TD | B5: Question 4 | C5: 0 | D5: 6.3302639 | E5: 1 | F5: 0 | G5: 1 | H5: 'NA | I5: 1 | J5: 'NA | K5: 1 | L5: 1 | M5: 1 | N5: 1 | O5: 1 | P5: Primary KC alignment: The problem requires multiplying 3-digit numbers (126, 148, 235) by 1-digit numbers (4, 3, 2), but the intended primary KC is multiplying whole numbers UP TO 3 digits by 1 digit, which typically means the multiplicand should be at most 3 digits but the complexity suggests this exceeds Primary 3 level expectations. Grade alignment: Multiplying 3-digit by 1-digit numbers like 126×4=504, 148×3=444, 235×2=470 requires advanced multiplication skills typically taught in Primary 4 or higher, not Primary 3.
A6: TD | B6: Question 5 | C6: 0 | D6: 2.9503314 | E6: 1 | F6: 1 | G6: 1 | H6: 1 | I6: 1 | J6: 1 | K6: 1 | L6: 1 | M6: 1 | N6: 1 | O6: 1
A7: TD | B7: Question 6 | C7: 0 | D7: 3.0048316 | E7: 1 | F7: 1 | G7: 1 | H7: 1 | I7: 1 | J7: 1 | K7: 1 | L7: 1 | M7: 1 | N7: 1 | O7: 1
A8: TD | B8: Question 7 | C8: 0 | D8: 10.941786 | E8: 1 | F8: 1 | G8: 1 | H8: 1 | I8: 1 | J8: 1 | K8: 1 | L8: 1 | M8: 1 | N8: 1 | O8: 1
A9: TD | B9: Question 8 | C9: 0 | D9: 8.5720222 | E9: 1 | F9: 1 | G9: 1 | H9: 1 | I9: 1 | J9: 1 | K9: 1 | L9: 1 | M9: 1 | N9: 1 | O9: 1
A10: TD | B10: Question 9 | C10: 0 | D10: 7.4044814 | E10: 1 | F10: 1 | G10: 1 | H10: 1 | I10: 1 | J10: 1 | K10: 1 | L10: 1 | M10: 1 | N10: 1 | O10: 1
A11: TD | B11: Question 10 | C11: 0 | D11: 10.857038 | E11: 1 | F11: 1 | G11: 1 | H11: 1 | I11: 1 | J11: 1 | K11: 1 | L11: 1 | M11: 1 | N11: 1 | O11: 1
A12: TD | B12: Question 11 | C12: 0 | D12: 13.191507 | E12: 0 | F12: 'NA | G12: 'NA | H12: 'NA | I12: 'NA | J12: 'NA | K12: 'NA | L12: 'NA | M12: 'NA | N12: 'NA | O12: 'NA | P12: Answerability: Questions (a) and (b) ask for totals but only provide single fractions per person per activity - Sarah has 2/3 painting and 1/4 music, Emma has 1/2 painting and 3/8 music. No addition possible. Primary KC Alignment: Primary component requires adding unlike fractions but questions (a) and (b) involve single fractions only, no addition needed. Synergy: Addition and comparison components cannot work together since addition component is not properly utilized. Clarity: Asking for total fractions when only single values exist per category creates confusion.
A13: TD | B13: Question 12 | C13: 0 | D13: 2.8128757 | E13: 1 | F13: 1 | G13: 1 | H13: 1 | I13: 1 | J13: 1 | K13: 1 | L13: 1 | M13: 1 | N13: 1 | O13: 1
A14: TD | B14: Question 13 | C14: 0 | D14: 11.63449 | E14: 1 | F14: 0 | G14: 1 | H14: 'NA | I14: 1 | J14: 'NA | K14: 1 | L14: 1 | M14: 1 | N14: 1 | O14: 1 | P14: Primary KC alignment: The problem requires adding decimals including 1.142 which has 3 decimal places, exceeding the intended scope of up to 2 decimal places for addition.
A15: TD | B15: Question 14 | C15: 0 | D15: 3.0382113 | E15: 1 | F15: 1 | G15: 1 | H15: 1 | I15: 1 | J15: 1 | K15: 1 | L15: 1 | M15: 1 | N15: 1 | O15: 1
A16: TD | B16: Question 15 | C16: 0 | D16: 9.9127398 | E16: 1 | F16: 1 | G16: 1 | H16: 1 | I16: 1 | J16: 1 | K16: 1 | L16: 1 | M16: 1 | N16: 1 | O16: 1
A17: TD | B17: Question 16 | C17: 0 | D17: 11.510377 | E17: 1 | F17: 1 | G17: 1 | H17: 1 | I17: 1 | J17: 0 | K17: 1 | L17: 1 | M17: 1 | N17: 1 | O17: 1 | P17: Grade Alignment: Converting decimals to fractions and fraction simplification are typically taught in Primary 5-6, making this problem too advanced for Primary 4 students.
A18: TD | B18: Question 17 | C18: 0 | D18: 2.9226916 | E18: 1 | F18: 1 | G18: 1 | H18: 1 | I18: 1 | J18: 1 | K18: 1 | L18: 1 | M18: 1 | N18: 1 | O18: 1
A19: TD | B19: Question 18 | C19: 0 | D19: 2.9136155 | E19: 1 | F19: 1 | G19: 1 | H19: 1 | I19: 1 | J19: 1 | K19: 1 | L19: 1 | M19: 1 | N19: 1 | O19: 1
A20: TD | B20: Question 19 | C20: 0 | D20: 11.08664 | E20: 1 | F20: 1 | G20: 1 | H20: 1 | I20: 1 | J20: 1 | K20: 1 | L20: 1 | M20: 1 | N20: 1 | O20: 1
A21: TD | B21: Question 20 | C21: 0 | D21: 10.205905 | E21: 1 | F21: 1 | G21: 1 | H21: 1 | I21: 1 | J21: 1 | K21: 1 | L21: 1 | M21: 1 | N21: 1 | O21: 1
A22: TD | B22: Question 21 | C22: 0 | D22: 9.5037072 | E22: 1 | F22: 1 | G22: 1 | H22: 1 | I22: 1 | J22: 1 | K22: 1 | L22: 1 | M22: 1 | N22: 1 | O22: 1
A23: TD | B23: Question 22 | C23: 0 | D23: 11.98301 | E23: 1 | F23: 1 | G23: 0 | H23: 'NA | I23: 1 | J23: 1 | K23: 1 | L23: 1 | M23: 1 | N23: 1 | O23: 1 | P23: Secondary KC Alignment: The comparison is between decimals 13.5 and 12.8, not fractions, so fraction comparison skills are not needed. Synergy: Since fraction comparison is not required, the primary and secondary knowledge components do not work together as intended.
A24: TD | B24: Question 23 | C24: 0 | D24: 8.1547527 | E24: 1 | F24: 1 | G24: 1 | H24: 1 | I24: 1 | J24: 1 | K24: 1 | L24: 1 | M24: 1 | N24: 1 | O24: 1
A25: TD | B25: Question 24 | C25: 0 | D25: 10.094259 | E25: 1 | F25: 1 | G25: 1 | H25: 1 | I25: 1 | J25: 1 | K25: 1 | L25: 1 | M25: 1 | N25: 1 | O25: 1
A26: TD | B26: Question 25 | C26: 0 | D26: 9.6442754 | E26: 1 | F26: 1 | G26: 1 | H26: 1 | I26: 1 | J26: 1 | K26: 1 | L26: 1 | M26: 1 | N26: 1 | O26: 1
A27: TD | B27: Question 26 | C27: 0 | D27: 8.2266335 | E27: 1 | F27: 0 | G27: 1 | H27: 'NA | I27: 1 | J27: 'NA | K27: 1 | L27: 1 | M27: 1 | N27: 1 | O27: 1 | P27: Primary KC Alignment: The problem only requires adding fractions (7/4 + 5/3, 9/5 + 8/7, then summing results). No multiplication of improper fractions is needed despite this being the intended primary KC. Synergy: Since the primary KC (multiplying improper fractions) is not actually used in the solution, there is no synergy between primary and secondary KCs - only the secondary KC (adding fractions) is utilized.
A28: TD | B28: Question 27 | C28: 0 | D28: 11.883206 | E28: 1 | F28: 0 | G28: 1 | H28: 'NA | I28: 1 | J28: 'NA | K28: 1 | L28: 1 | M28: 1 | N28: 1 | O28: 1 | P28: Primary KC Alignment: The problem primarily requires division of fractions (23/12 divided by 2/3), not multiplication of two improper fractions as intended. Synergy: The intended primary KC (multiplying improper fractions) and secondary KC (subtracting fractions) are not used in tandem - division is the main operation needed, not multiplication.
A29: TD | B29: Question 28 | C29: 0 | D29: 10.120775 | E29: 1 | F29: 1 | G29: 1 | H29: 1 | I29: 1 | J29: 1 | K29: 1 | L29: 1 | M29: 1 | N29: 1 | O29: 1
A30: TD | B30: Question 29 | C30: 0 | D30: 4.7794852 | E30: 1 | F30: 1 | G30: 1 | H30: 1 | I30: 1 | J30: 1 | K30: 0 | L30: 1 | M30: 1 | N30: 1 | O30: 1 | P30: Real-world feasibility: Swimming 2 3/4 laps per minute (165 laps per hour) and 3 1/6 laps per minute (190 laps per hour) are unrealistically fast rates for human swimming training. Typical competitive swimmers complete 1-2 laps per minute at most.
A31: TD | B31: Question 30 | C31: 0 | D31: 10.879211 | E31: 1 | F31: 0 | G31: 0 | H31: 'NA | I31: 1 | J31: 'NA | K31: 1 | L31: 1 | M31: 1 | N31: 1 | O31: 1 | P31: Primary KC: Problem requires 0.875 x 300 but 300 is not a multiple of 10, 100, or 1000 as specified. Secondary KC: Problem requires converting decimal to mixed number, not expressing decimal as fraction.
A32: TD | B32: Question 31 | C32: 0 | D32: 10.549736 | E32: 1 | F32: 0 | G32: 1 | H32: 'NA | I32: 1 | J32: 'NA | K32: 1 | L32: 1 | M32: 1 | N32: 1 | O32: 1 | P32: Primary KC misalignment: Problem requires 0.125 * 400 which is general decimal multiplication, not specifically multiplication by 10, 100, 1000 or their multiples as intended.
A33: TD | B33: Question 32 | C33: 0 | D33: 11.158752 | E33: 1 | F33: 0 | G33: 1 | H33: 'NA | I33: 1 | J33: 'NA | K33: 1 | L33: 1 | M33: 1 | N33: 1 | O33: 1 | P33: Primary KC alignment fails because the problem requires dividing by 7, but the intended primary KC specifically targets dividing by 10, 100, 1000 and their multiples. 7 is not a multiple of 10, 100, or 1000.
A34: TD | B34: Question 33 | C34: 0 | D34: 7.7823808 | E34: 1 | F34: 1 | G34: 1 | H34: 1 | I34: 1 | J34: 1 | K34: 0 | L34: 1 | M34: 1 | N34: 1 | O34: 1 | P34: Real-world feasibility issue: Swimming 40000 meters in 4 laps means each lap is 10000 meters (10 km), which is unrealistic for typical swimming practice. Standard pool laps are 25m, 50m, or at most a few hundred meters.
A35: TD | B35: Question 34 | C35: 0 | D35: 10.239755 | E35: 1 | F35: 1 | G35: 1 | H35: 1 | I35: 1 | J35: 1 | K35: 1 | L35: 1 | M35: 1 | N35: 1 | O35: 1
A36: TD | B36: Question 35 | C36: 0 | D36: 8.17382 | E36: 1 | F36: 1 | G36: 1 | H36: 1 | I36: 1 | J36: 1 | K36: 0 | L36: 1 | M36: 1 | N36: 1 | O36: 1 | P36: Real-world feasibility: Basketball teams typically have 5 players on court with limited substitutes (usually 7-12 total players per team). Having 30 players per team and eliminating 15 players in one round does not reflect realistic basketball tournament structure.
A37: TD | B37: Question 36 | C37: 0 | D37: 11.613573 | E37: 1 | F37: 1 | G37: 1 | H37: 1 | I37: 1 | J37: 1 | K37: 0 | L37: 1 | M37: 1 | N37: 1 | O37: 1 | P37: Real-world feasibility: 1.25 km/h is unrealistically slow for marathon training - this is slower than normal walking speed of 4-5 km/h. Marathon runners typically train at speeds of 8-15 km/h.
A38: TD | B38: Question 37 | C38: 0 | D38: 11.331115 | E38: 1 | F38: 1 | G38: 1 | H38: 1 | I38: 1 | J38: 1 | K38: 1 | L38: 1 | M38: 1 | N38: 1 | O38: 1
A39: TD | B39: Question 38 | C39: 0 | D39: 3.0335958 | E39: 1 | F39: 1 | G39: 1 | H39: 1 | I39: 1 | J39: 1 | K39: 1 | L39: 1 | M39: 1 | N39: 1 | O39: 1
A40: TD | B40: Question 39 | C40: 0 | D40: 13.636707 | E40: 1 | F40: 1 | G40: 1 | H40: 1 | I40: 1 | J40: 1 | K40: 0 | L40: 1 | M40: 1 | N40: 1 | O40: 1 | P40: Real-world plausibility fails because 2/3 of a week equals 4 + 2/3 days, but practicing for 2/3 of a day is unrealistic in normal daily scheduling. The mathematical result of 3/4 hours per day does not align with how people would typically plan practice sessions.
...

Sheet recreation_claude_v2_4
A1: Evaluator | B1: Question | C1: status | D1: response_time | E1: answerability | F1: primary_kc_alignment | G1: secondary_kc_alignment | H1: synergy | I1: topic_alignment | J1: grade_alignment | K1: real_world_feasibility | L1: clarity | M1: conciseness_and_relevance | N1: language_quality | O1: content_appropriateness | P1: explanation
A2: TD | B2: Question 1 | C2: 0 | D2: 9.1908042 | E2: 1 | F2: 1 | G2: 1 | H2: 1 | I2: 1 | J2: 1 | K2: 1 | L2: 1 | M2: 1 | N2: 1 | O2: 1
A3: TD | B3: Question 2 | C3: 0 | D3: 9.6037319 | E3: 1 | F3: 1 | G3: 1 | H3: 1 | I3: 1 | J3: 1 | K3: 1 | L3: 1 | M3: 1 | N3: 1 | O3: 1
A4: TD | B4: Question 3 | C4: 0 | D4: 11.292465 | E4: 1 | F4: 1 | G4: 1 | H4: 1 | I4: 1 | J4: 1 | K4: 1 | L4: 1 | M4: 1 | N4: 1 | O4: 1
A5: TD | B5: Question 4 | C5: 0 | D5: 6.7262769 | E5: 1 | F5: 0 | G5: 1 | H5: 'NA | I5: 1 | J5: 'NA | K5: 1 | L5: 1 | M5: 1 | N5: 1 | O5: 1 | P5: Primary KC Alignment: The problem requires multiplying 3-digit numbers (126, 148, 235) by 1-digit numbers (4, 3, 2), but the intended primary KC is multiplying whole numbers UP TO 3 digits by 1 digit, which typically means the multiplicand should be at most 99 for Primary 3 level. The numbers 126, 148, and 235 exceed this expectation. Grade Alignment: The calculations required (4x126=504, 3x148=444, 2x235=470) involve 3-digit by 1-digit multiplication that produces results in the hundreds, which may be too advanced for Primary 3 students who typically work with smaller numbers in multiplication.
A6: TD | B6: Question 5 | C6: 0 | D6: 3.033381 | E6: 1 | F6: 1 | G6: 1 | H6: 1 | I6: 1 | J6: 1 | K6: 1 | L6: 1 | M6: 1 | N6: 1 | O6: 1
A7: TD | B7: Question 6 | C7: 0 | D7: 2.8941858 | E7: 1 | F7: 1 | G7: 1 | H7: 1 | I7: 1 | J7: 1 | K7: 1 | L7: 1 | M7: 1 | N7: 1 | O7: 1
A8: TD | B8: Question 7 | C8: 0 | D8: 9.8123996 | E8: 1 | F8: 1 | G8: 1 | H8: 1 | I8: 1 | J8: 1 | K8: 1 | L8: 1 | M8: 1 | N8: 1 | O8: 1
A9: TD | B9: Question 8 | C9: 0 | D9: 9.6471558 | E9: 1 | F9: 1 | G9: 1 | H9: 1 | I9: 1 | J9: 1 | K9: 1 | L9: 1 | M9: 1 | N9: 1 | O9: 1
A10: TD | B10: Question 9 | C10: 0 | D10: 2.9008126 | E10: 1 | F10: 1 | G10: 1 | H10: 1 | I10: 1 | J10: 1 | K10: 1 | L10: 1 | M10: 1 | N10: 1 | O10: 1
A11: TD | B11: Question 10 | C11: 0 | D11: 10.316988 | E11: 1 | F11: 1 | G11: 1 | H11: 1 | I11: 1 | J11: 1 | K11: 1 | L11: 1 | M11: 1 | N11: 1 | O11: 1
A12: TD | B12: Question 11 | C12: 0 | D12: 12.80777 | E12: 0 | F12: 'NA | G12: 'NA | H12: 'NA | I12: 'NA | J12: 'NA | K12: 'NA | L12: 'NA | M12: 'NA | N12: 'NA | O12: 'NA | P12: Answerability: Questions (a) and (b) ask for totals when only single values are given per person - Sarah completed 2/3 painting and 1/4 music, so asking for her total in each category is unclear. Primary KC Alignment: Questions (a) and (b) do not require adding unlike fractions since only one fraction per person per challenge is provided - no addition needed. Synergy: Questions (a) and (b) results are not needed to solve question (c) which requires independent fraction addition and comparison. Clarity: Questions (a) and (b) are ambiguous about what total means when only single fractions are provided for each person per challenge.
A13: TD | B13: Question 12 | C13: 0 | D13: 11.209576 | E13: 1 | F13: 1 | G13: 1 | H13: 1 | I13: 1 | J13: 1 | K13: 1 | L13: 1 | M13: 1 | N13: 1 | O13: 1
A14: TD | B14: Question 13 | C14: 0 | D14: 13.171897 | E14: 1 | F14: 0 | G14: 1 | H14: 'NA | I14: 1 | J14: 'NA | K14: 1 | L14: 1 | M14: 1 | N14: 1 | O14: 1 | P14: Primary KC alignment: Problem requires adding decimals up to 3 decimal places (1.142) but intended KC specifies up to 2 decimal places only. Synergy: The two knowledge components work independently rather than in tandem - addition and comparison are separate tasks not building on each other. Grade alignment: Primary 4 students typically work with decimals up to 2 decimal places but this problem includes 3 decimal places which may be too advanced.
A15: TD | B15: Question 14 | C15: 0 | D15: 8.6759117 | E15: 1 | F15: 1 | G15: 1 | H15: 1 | I15: 1 | J15: 1 | K15: 1 | L15: 1 | M15: 1 | N15: 1 | O15: 1
A16: TD | B16: Question 15 | C16: 0 | D16: 2.8752611 | E16: 1 | F16: 1 | G16: 1 | H16: 1 | I16: 1 | J16: 1 | K16: 1 | L16: 1 | M16: 1 | N16: 1 | O16: 1
A17: TD | B17: Question 16 | C17: 0 | D17: 10.242868 | E17: 1 | F17: 1 | G17: 1 | H17: 1 | I17: 1 | J17: 1 | K17: 1 | L17: 1 | M17: 1 | N17: 1 | O17: 1
A18: TD | B18: Question 17 | C18: 0 | D18: 2.9498243 | E18: 1 | F18: 1 | G18: 1 | H18: 1 | I18: 1 | J18: 1 | K18: 1 | L18: 1 | M18: 1 | N18: 1 | O18: 1
A19: TD | B19: Question 18 | C19: 0 | D19: 2.9697349 | E19: 1 | F19: 1 | G19: 1 | H19: 1 | I19: 1 | J19: 1 | K19: 1 | L19: 1 | M19: 1 | N19: 1 | O19: 1
A20: TD | B20: Question 19 | C20: 0 | D20: 9.019249 | E20: 0 | F20: 'NA | G20: 'NA | H20: 'NA | I20: 'NA | J20: 'NA | K20: 'NA | L20: 'NA | M20: 'NA | N20: 'NA | O20: 'NA | P20: Answerability: The question 'What is the total distance Sarah swam per lap over the two days?' is ambiguous - unclear if asking for sum of distances per lap or separate calculations. Grade_alignment: Tuesday calculation 5.24 / 3 = 1.748 km results in 3 decimal places, exceeding Primary 4 expectation of 2 decimal places. Real_world_feasibility: Pool laps of different lengths (1.56 km vs 1.748 km) on consecutive days is unrealistic - pools have fixed perimeters. Clarity: Ambiguous phrasing makes the intended calculation unclear.
A21: TD | B21: Question 20 | C21: 0 | D21: 9.5956309 | E21: 1 | F21: 1 | G21: 1 | H21: 1 | I21: 1 | J21: 1 | K21: 1 | L21: 1 | M21: 1 | N21: 1 | O21: 1
A22: TD | B22: Question 21 | C22: 0 | D22: 8.8142426 | E22: 1 | F22: 1 | G22: 1 | H22: 1 | I22: 1 | J22: 1 | K22: 1 | L22: 1 | M22: 1 | N22: 1 | O22: 1
A23: TD | B23: Question 22 | C23: 0 | D23: 10.144593 | E23: 1 | F23: 1 | G23: 1 | H23: 1 | I23: 1 | J23: 1 | K23: 1 | L23: 1 | M23: 1 | N23: 1 | O23: 1
A24: TD | B24: Question 23 | C24: 0 | D24: 9.1206853 | E24: 1 | F24: 1 | G24: 1 | H24: 1 | I24: 1 | J24: 1 | K24: 1 | L24: 1 | M24: 1 | N24: 1 | O24: 1
A25: TD | B25: Question 24 | C25: 0 | D25: 10.171844 | E25: 1 | F25: 1 | G25: 1 | H25: 1 | I25: 1 | J25: 1 | K25: 1 | L25: 1 | M25: 1 | N25: 1 | O25: 1
A26: TD | B26: Question 25 | C26: 0 | D26: 10.005701 | E26: 1 | F26: 1 | G26: 1 | H26: 1 | I26: 1 | J26: 1 | K26: 1 | L26: 1 | M26: 1 | N26: 1 | O26: 1
A27: TD | B27: Question 26 | C27: 0 | D27: 7.9541109 | E27: 1 | F27: 0 | G27: 1 | H27: 'NA | I27: 1 | J27: 'NA | K27: 1 | L27: 1 | M27: 1 | N27: 1 | O27: 1 | P27: Primary KC Alignment: The problem requires only fraction addition, not multiplication of improper fractions as intended. No multiplication operations are needed to solve any part. Synergy: Since the primary KC (fraction multiplication) is not actually required, there is no synergy between the intended primary and secondary knowledge components. The problem only uses fraction addition throughout.
A28: TD | B28: Question 27 | C28: 0 | D28: 10.737911 | E28: 1 | F28: 1 | G28: 1 | H28: 1 | I28: 1 | J28: 1 | K28: 1 | L28: 1 | M28: 1 | N28: 1 | O28: 1
A29: TD | B29: Question 28 | C29: 0 | D29: 9.4137452 | E29: 1 | F29: 1 | G29: 1 | H29: 1 | I29: 1 | J29: 1 | K29: 1 | L29: 1 | M29: 1 | N29: 1 | O29: 1
A30: TD | B30: Question 29 | C30: 0 | D30: 9.1940057 | E30: 1 | F30: 1 | G30: 1 | H30: 1 | I30: 1 | J30: 1 | K30: 1 | L30: 1 | M30: 1 | N30: 1 | O30: 1
A31: TD | B31: Question 30 | C31: 0 | D31: 12.147567 | E31: 1 | F31: 0 | G31: 1 | H31: 'NA | I31: 1 | J31: 'NA | K31: 1 | L31: 1 | M31: 1 | N31: 1 | O31: 1 | P31: Primary KC alignment: Problem requires general decimal multiplication (0.875 * 300), not specifically multiplying decimals by 10, 100, 1000 or their multiples. Synergy: Since primary KC is not actually used, there is no synergy between intended primary and secondary knowledge components.
A32: TD | B32: Question 31 | C32: 0 | D32: 6.0864937 | E32: 1 | F32: 0 | G32: 1 | H32: 'NA | I32: 1 | J32: 'NA | K32: 1 | L32: 1 | M32: 1 | N32: 1 | O32: 1 | P32: Primary KC alignment: The problem requires 0.125 * 400 which is standard decimal multiplication, not specifically multiplying by 10, 100, 1000 or their multiples as intended. Synergy: The two parts can be solved independently - the second question uses 65.8 and 50 (result from first part) but does not require the primary KC of multiplying by multiples of 10/100/1000, only basic decimal subtraction.
A33: TD | B33: Question 32 | C33: 0 | D33: 8.9372134 | E33: 1 | F33: 0 | G33: 1 | H33: 'NA | I33: 1 | J33: 'NA | K33: 1 | L33: 1 | M33: 1 | N33: 1 | O33: 1 | P33: Primary KC alignment: The problem requires dividing 127.850 by 7, but the intended primary KC is dividing by 10, 100, 1000 and their multiples. 7 is not a multiple of these numbers. Synergy: Since the primary KC does not align with the actual division needed (127.850 / 7), the primary and secondary KCs cannot work together as intended in this problem.
A34: TD | B34: Question 33 | C34: 0 | D34: 14.500815 | E34: 0 | F34: 'NA | G34: 'NA | H34: 'NA | I34: 'NA | J34: 'NA | K34: 'NA | L34: 'NA | M34: 'NA | N34: 'NA | O34: 'NA | P34: Answerability: The mathematical relationship between dividing total time by 400 to get average time per 100m is logically flawed. Real-world feasibility: The calculation method described does not produce a meaningful real-world result. Clarity: The explanation of why dividing by 400 gives time per 100m is mathematically incorrect and confusing. Conciseness: The 40000 meters information is irrelevant to solving the problem and creates unnecessary confusion.
A35: TD | B35: Question 34 | C35: 0 | D35: 10.549078 | E35: 1 | F35: 1 | G35: 1 | H35: 1 | I35: 1 | J35: 1 | K35: 1 | L35: 1 | M35: 1 | N35: 1 | O35: 1
A36: TD | B36: Question 35 | C36: 0 | D36: 6.339045 | E36: 1 | F36: 1 | G36: 1 | H36: 1 | I36: 1 | J36: 1 | K36: 0 | L36: 1 | M36: 1 | N36: 1 | O36: 1 | P36: Real-world feasibility: In basketball tournaments, players are typically not eliminated from teams during matches - teams as units advance or are eliminated. Individual players being removed from multiple teams simultaneously (15 from each of 8 teams) does not reflect realistic basketball tournament operations.
A37: TD | B37: Question 36 | C37: 0 | D37: 11.857007 | E37: 1 | F37: 1 | G37: 1 | H37: 1 | I37: 1 | J37: 1 | K37: 0 | L37: 1 | M37: 1 | N37: 1 | O37: 1 | P37: Real-world feasibility: 1.25 km/hour is unrealistically slow for marathon training - this is walking speed not running speed. Marathon runners typically train at 8-15 km/hour.
A38: TD | B38: Question 37 | C38: 0 | D38: 12.424082 | E38: 1 | F38: 1 | G38: 1 | H38: 1 | I38: 1 | J38: 1 | K38: 1 | L38: 1 | M38: 1 | N38: 1 | O38: 1
A39: TD | B39: Question 38 | C39: 0 | D39: 7.8060708 | E39: 1 | F39: 1 | G39: 1 | H39: 1 | I39: 1 | J39: 1 | K39: 1 | L39: 1 | M39: 1 | N39: 1 | O39: 1
A40: TD | B40: Question 39 | C40: 0 | D40: 12.143643 | E40: 1 | F40: 1 | G40: 1 | H40: 1 | I40: 1 | J40: 1 | K40: 0 | L40: 1 | M40: 1 | N40: 1 | O40: 1 | P40: Real-world feasibility: The phrase 2/3 of the week is unrealistic. People do not typically plan activities using fractional portions of weeks. A more realistic scenario would specify a concrete number of days like the next 3 days or next 5 days.
...

Sheet recreation_claude_v2_5
A1: Evaluator | B1: Question | C1: status | D1: response_time | E1: answerability | F1: primary_kc_alignment | G1: secondary_kc_alignment | H1: synergy | I1: topic_alignment | J1: grade_alignment | K1: real_world_feasibility | L1: clarity | M1: conciseness_and_relevance | N1: language_quality | O1: content_appropriateness | P1: explanation
A2: TD | B2: Question 1 | C2: 0 | D2: 11.617415 | E2: 1 | F2: 1 | G2: 1 | H2: 1 | I2: 1 | J2: 0 | K2: 1 | L2: 1 | M2: 1 | N2: 1 | O2: 1 | P2: Grade alignment: 4-digit addition (1245+876, 987+1298, 1156+945) may be too advanced for Primary 3 students who typically work with 3-digit whole number operations in Singapore math curriculum.
A3: TD | B3: Question 2 | C3: 0 | D3: 9.4811239 | E3: 1 | F3: 1 | G3: 1 | H3: 1 | I3: 1 | J3: 1 | K3: 1 | L3: 1 | M3: 1 | N3: 1 | O3: 1
A4: TD | B4: Question 3 | C4: 0 | D4: 10.818715 | E4: 1 | F4: 1 | G4: 1 | H4: 1 | I4: 1 | J4: 1 | K4: 1 | L4: 1 | M4: 1 | N4: 1 | O4: 1
A5: TD | B5: Question 4 | C5: 0 | D5: 7.6704519 | E5: 1 | F5: 0 | G5: 1 | H5: 'NA | I5: 1 | J5: 'NA | K5: 1 | L5: 1 | M5: 1 | N5: 1 | O5: 1 | P5: Primary KC alignment: The problem requires multiplying 3-digit numbers (126, 148, 235) by 1-digit numbers (4, 3, 2), but the intended primary KC is multiplying whole numbers UP TO 3 digits by 1 digit, which typically means the multiplicand should be at most 3 digits. However, 126x4=504, 148x3=444, and 235x2=470 are all reasonable calculations, but 235 is a 3-digit number being multiplied, which pushes the boundary. More critically, this level of multiplication may be too advanced for the stated Primary KC scope. Grade alignment: For Primary 3 students, multiplying 3-digit numbers like 126x4, 148x3, and 235x2 is typically too advanced. Primary 3 students usually work with simpler multiplication problems involving smaller numbers.
A6: TD | B6: Question 5 | C6: 0 | D6: 2.8635883 | E6: 1 | F6: 1 | G6: 1 | H6: 1 | I6: 1 | J6: 1 | K6: 1 | L6: 1 | M6: 1 | N6: 1 | O6: 1
A7: TD | B7: Question 6 | C7: 0 | D7: 3.2042382 | E7: 1 | F7: 1 | G7: 1 | H7: 1 | I7: 1 | J7: 1 | K7: 1 | L7: 1 | M7: 1 | N7: 1 | O7: 1
A8: TD | B8: Question 7 | C8: 0 | D8: 10.661453 | E8: 1 | F8: 1 | G8: 1 | H8: 1 | I8: 1 | J8: 1 | K8: 1 | L8: 1 | M8: 1 | N8: 1 | O8: 1
A9: TD | B9: Question 8 | C9: 0 | D9: 8.7032056 | E9: 1 | F9: 1 | G9: 1 | H9: 1 | I9: 1 | J9: 1 | K9: 1 | L9: 1 | M9: 1 | N9: 1 | O9: 1
A10: TD | B10: Question 9 | C10: 0 | D10: 2.9548335 | E10: 1 | F10: 1 | G10: 1 | H10: 1 | I10: 1 | J10: 1 | K10: 1 | L10: 1 | M10: 1 | N10: 1 | O10: 1
A11: TD | B11: Question 10 | C11: 0 | D11: 9.9386742 | E11: 1 | F11: 1 | G11: 1 | H11: 1 | I11: 1 | J11: 1 | K11: 1 | L11: 1 | M11: 1 | N11: 1 | O11: 1
A12: TD | B12: Question 11 | C12: 0 | D12: 11.667341 | E12: 0 | F12: 'NA | G12: 'NA | H12: 'NA | I12: 'NA | J12: 'NA | K12: 'NA | L12: 'NA | M12: 'NA | N12: 'NA | O12: 'NA | P12: Questions (a) and (b) ask for totals when only single fractions are given for each activity - Sarah completed 2/3 of painting and 1/4 of music, but questions ask for totals implying addition is needed when none exists. Primary KC requires adding unlike fractions but the problem structure does not necessitate fraction addition since each person has single values per activity type. The primary and secondary knowledge components cannot work in tandem as intended because the fraction addition component is not properly integrated into the problem structure.
A13: TD | B13: Question 12 | C13: 0 | D13: 10.78279 | E13: 1 | F13: 1 | G13: 1 | H13: 1 | I13: 1 | J13: 1 | K13: 1 | L13: 1 | M13: 1 | N13: 1 | O13: 1
A14: TD | B14: Question 13 | C14: 0 | D14: 11.96278 | E14: 1 | F14: 0 | G14: 1 | H14: 'NA | I14: 1 | J14: 'NA | K14: 1 | L14: 1 | M14: 1 | N14: 1 | O14: 1 | P14: Primary KC alignment: Problem involves adding decimals with 3 decimal places (1.142) which exceeds the intended scope of up to 2 decimal places. Synergy: The two tasks (addition and comparison) are somewhat independent rather than truly integrated. Grade alignment: Using 3 decimal places (1.142) may be beyond Primary 4 level which typically focuses on 1-2 decimal places.
A15: TD | B15: Question 14 | C15: 0 | D15: 9.8080211 | E15: 1 | F15: 1 | G15: 1 | H15: 1 | I15: 1 | J15: 1 | K15: 1 | L15: 1 | M15: 0 | N15: 1 | O15: 1 | P15: The Tuesday practice time of 1.50 hours is mentioned but not needed for solving the problem, violating the requirement that all given numbers must be necessary.
A16: TD | B16: Question 15 | C16: 0 | D16: 9.8104343 | E16: 1 | F16: 1 | G16: 1 | H16: 1 | I16: 1 | J16: 1 | K16: 1 | L16: 1 | M16: 1 | N16: 1 | O16: 1
A17: TD | B17: Question 16 | C17: 0 | D17: 10.247204 | E17: 1 | F17: 1 | G17: 1 | H17: 1 | I17: 1 | J17: 1 | K17: 1 | L17: 1 | M17: 1 | N17: 1 | O17: 1
A18: TD | B18: Question 17 | C18: 0 | D18: 8.6891675 | E18: 1 | F18: 1 | G18: 1 | H18: 1 | I18: 1 | J18: 1 | K18: 1 | L18: 1 | M18: 1 | N18: 1 | O18: 1
A19: TD | B19: Question 18 | C19: 0 | D19: 3.0835211 | E19: 1 | F19: 1 | G19: 1 | H19: 1 | I19: 1 | J19: 1 | K19: 1 | L19: 1 | M19: 1 | N19: 1 | O19: 1
A20: TD | B20: Question 19 | C20: 0 | D20: 6.4564734 | E20: 0 | F20: 'NA | G20: 'NA | H20: 'NA | I20: 'NA | J20: 'NA | K20: 'NA | L20: 'NA | M20: 'NA | N20: 'NA | O20: 'NA | P20: answerability: The problem asks for 'total distance Sarah swam per lap over the two days' which is ambiguous. It could mean (1) distance per lap on each day then sum them, or (2) total distance over both days divided by total number of laps. The wording creates confusion about whether the answer should be 1.56 + 1.75 = 3.31 km or (4.68 + 5.24) / 6 = 1.65 km. clarity: The question 'What is the total distance Sarah swam per lap over the two days?' is unclear and can be interpreted in multiple ways, making it difficult for students to understand what exactly is being asked.
A21: TD | B21: Question 20 | C21: 0 | D21: 9.80902 | E21: 1 | F21: 1 | G21: 1 | H21: 1 | I21: 1 | J21: 1 | K21: 1 | L21: 1 | M21: 1 | N21: 1 | O21: 1
A22: TD | B22: Question 21 | C22: 0 | D22: 9.5236602 | E22: 1 | F22: 1 | G22: 1 | H22: 1 | I22: 1 | J22: 1 | K22: 1 | L22: 1 | M22: 1 | N22: 1 | O22: 1
A23: TD | B23: Question 22 | C23: 0 | D23: 9.412307 | E23: 1 | F23: 1 | G23: 1 | H23: 1 | I23: 1 | J23: 1 | K23: 1 | L23: 1 | M23: 1 | N23: 1 | O23: 1
A24: TD | B24: Question 23 | C24: 0 | D24: 9.0084975 | E24: 1 | F24: 1 | G24: 1 | H24: 1 | I24: 1 | J24: 1 | K24: 1 | L24: 1 | M24: 1 | N24: 1 | O24: 1
A25: TD | B25: Question 24 | C25: 0 | D25: 3.0714173 | E25: 1 | F25: 1 | G25: 1 | H25: 1 | I25: 1 | J25: 1 | K25: 1 | L25: 1 | M25: 1 | N25: 1 | O25: 1
A26: TD | B26: Question 25 | C26: 0 | D26: 8.3874447 | E26: 1 | F26: 1 | G26: 1 | H26: 1 | I26: 1 | J26: 1 | K26: 1 | L26: 1 | M26: 1 | N26: 1 | O26: 1
A27: TD | B27: Question 26 | C27: 0 | D27: 7.6903317 | E27: 1 | F27: 0 | G27: 1 | H27: 'NA | I27: 1 | J27: 'NA | K27: 1 | L27: 1 | M27: 1 | N27: 1 | O27: 1 | P27: Primary KC alignment fails because the problem only requires adding fractions (7/4 + 5/3, 9/5 + 8/7, then adding results) but the intended Primary KC is multiplying two improper fractions, which is not needed at all. Synergy fails because without the Primary KC being used, there is no synergy between Primary and Secondary KCs - only the Secondary KC (fraction addition) is used throughout the problem.
A28: TD | B28: Question 27 | C28: 0 | D28: 14.286865 | E28: 1 | F28: 0 | G28: 1 | H28: 'NA | I28: 1 | J28: 'NA | K28: 1 | L28: 1 | M28: 1 | N28: 1 | O28: 1 | P28: Primary KC alignment: The problem's main difficulty involves fraction addition/subtraction rather than multiplication of improper fractions. While multiplication occurs in the solution (23/12 * 3/2), it is not the primary focus. Synergy: Since the primary KC is not properly aligned, the intended synergy between multiplication and subtraction of fractions is not achieved as designed.
A29: TD | B29: Question 28 | C29: 0 | D29: 9.6711001 | E29: 1 | F29: 1 | G29: 1 | H29: 1 | I29: 1 | J29: 1 | K29: 1 | L29: 1 | M29: 1 | N29: 1 | O29: 1
A30: TD | B30: Question 29 | C30: 0 | D30: 7.8149142 | E30: 1 | F30: 1 | G30: 0 | H30: 'NA | I30: 1 | J30: 1 | K30: 1 | L30: 1 | M30: 1 | N30: 1 | O30: 1 | P30: Secondary KC Alignment: The problem requires subtracting whole numbers (22 - 19 = 3), not subtracting fractions as specified in the intended Secondary Knowledge Component. Synergy: Since the secondary KC (subtracting fractions) is not actually needed, the primary and secondary KCs are not used in tandem as required.
A31: TD | B31: Question 30 | C31: 0 | D31: 11.536116 | E31: 1 | F31: 0 | G31: 1 | H31: 'NA | I31: 1 | J31: 'NA | K31: 1 | L31: 1 | M31: 1 | N31: 1 | O31: 1 | P31: Primary KC alignment fails because the problem requires general decimal multiplication (0.875 × 300) rather than the intended specific skill of multiplying decimals by 10, 100, 1000 and their multiples. Synergy fails because the two knowledge components are used sequentially rather than in integrated tandem - first multiply decimals, then convert to fraction, without the components enhancing each other's application.
A32: TD | B32: Question 31 | C32: 0 | D32: 11.136322 | E32: 1 | F32: 0 | G32: 1 | H32: 'NA | I32: 1 | J32: 'NA | K32: 1 | L32: 1 | M32: 1 | N32: 1 | O32: 1 | P32: Primary KC requires multiplying decimals by 10, 100, 1000 and their multiples, but the problem uses 0.125 * 400 which is general decimal multiplication, not specifically by powers of 10 or their multiples.
A33: TD | B33: Question 32 | C33: 0 | D33: 11.403902 | E33: 1 | F33: 0 | G33: 1 | H33: 'NA | I33: 1 | J33: 'NA | K33: 1 | L33: 1 | M33: 1 | N33: 1 | O33: 1 | P33: Primary KC alignment fails because the problem requires dividing by 7, which is not a multiple of 10, 100, or 1000 as specified in the intended primary knowledge component. Synergy fails because the primary KC is not properly aligned, preventing the intended tandem use of both knowledge components.
A34: TD | B34: Question 33 | C34: 0 | D34: 14.810105 | E34: 0 | F34: 'NA | G34: 'NA | H34: 'NA | I34: 'NA | J34: 'NA | K34: 'NA | L34: 'NA | M34: 'NA | N34: 'NA | O34: 'NA | P34: Answerability: Swimming 40000 meters in practice is unrealistic and creates conflicting scenario. Real-world feasibility: 40 kilometers swimming in single practice session is completely implausible. Clarity: Relationship between 4 laps and 40000 total meters with division by 400 is confusing.
A35: TD | B35: Question 34 | C35: 0 | D35: 10.964511 | E35: 1 | F35: 1 | G35: 1 | H35: 1 | I35: 1 | J35: 1 | K35: 1 | L35: 1 | M35: 1 | N35: 1 | O35: 1
A36: TD | B36: Question 35 | C36: 0 | D36: 2.8423097 | E36: 1 | F36: 1 | G36: 1 | H36: 1 | I36: 1 | J36: 1 | K36: 1 | L36: 1 | M36: 1 | N36: 1 | O36: 1
A37: TD | B37: Question 36 | C37: 0 | D37: 6.9412949 | E37: 1 | F37: 1 | G37: 1 | H37: 1 | I37: 1 | J37: 1 | K37: 0 | L37: 1 | M37: 1 | N37: 1 | O37: 1 | P37: Real-world feasibility: Sarah's running speed of 1.25 km/hr is unrealistic for marathon training. Average walking speed is 5 km/hr and marathon runners train at 10-15 km/hr. A speed of 1.25 km/hr would be extremely slow walking pace, not suitable for marathon preparation.
A38: TD | B38: Question 37 | C38: 0 | D38: 10.952121 | E38: 1 | F38: 1 | G38: 1 | H38: 1 | I38: 1 | J38: 1 | K38: 1 | L38: 1 | M38: 1 | N38: 1 | O38: 1
A39: TD | B39: Question 38 | C39: 0 | D39: 2.9735079 | E39: 1 | F39: 1 | G39: 1 | H39: 1 | I39: 1 | J39: 1 | K39: 1 | L39: 1 | M39: 1 | N39: 1 | O39: 1
A40: TD | B40: Question 39 | C40: 0 | D40: 11.256452 | E40: 1 | F40: 1 | G40: 1 | H40: 1 | I40: 1 | J40: 1 | K40: 0 | L40: 1 | M40: 1 | N40: 1 | O40: 1 | P40: Real-world feasibility fails because dividing practice time over 2/3 of a week (4.67 days) is unrealistic - people typically plan practice schedules over whole days, not fractional portions of days.
...

Sheet Compiled Votes
A1: Evaluator | B1: Question | C1: status | D1: response_time | E1: answerability | F1: primary_kc_alignment | G1: secondary_kc_alignment | H1: topic_alignment | I1: grade_alignment | J1: real_world_feasibility | K1: synergy | L1: clarity | M1: conciseness_and_relevance | N1: language_quality | O1: content_appropriateness
