Workbook

Sheet householdfinance_v2_10
A1: Evaluator | B1: Question | C1: status | D1: response_time | E1: answerability | F1: primary_kc_alignment | G1: secondary_kc_alignment | H1: synergy | I1: topic_alignment | J1: grade_alignment | K1: real_world_feasibility | L1: clarity | M1: conciseness_and_relevance | N1: language_quality | O1: content_appropriateness | P1: explanation
A2: TD | B2: Question 1 | C2: 0 | D2: 2.65838 | E2: 1 | F2: 1 | G2: 1 | H2: 1 | I2: 1 | J2: 1 | K2: 1 | L2: 1 | M2: 1 | N2: 1 | O2: 1
A3: TD | B3: Question 2 | C3: 0 | D3: 6.8846681 | E3: 1 | F3: 1 | G3: 0 | H3: 'NA | I3: 1 | J3: 1 | K3: 1 | L3: 1 | M3: 0 | N3: 1 | O3: 1 | P3: Secondary KC alignment: The problem only requires subtraction (450 - 215 = 235). Addition is not needed to solve the problem. Synergy: Since only subtraction is required, there is no synergy between primary subtraction KC and secondary addition KC. The addition KC is not utilized. Conciseness and relevance: The information about father giving 80 dollars is irrelevant to solving the question asked. This extra information is not necessary for the solution.
A4: TD | B4: Question 3 | C4: 0 | D4: 6.5158162 | E4: 1 | F4: 1 | G4: 1 | H4: 1 | I4: 0 | J4: 1 | K4: 1 | L4: 1 | M4: 1 | N4: 1 | O4: 1 | P4: Topic Alignment: The problem involves sharing candies among children, which is a family/household activity but does not involve household finance concepts like income, utility bills, money, interest, savings, instalment, mortgage, or financial planning. The context is about candy distribution rather than financial matters.
A5: TD | B5: Question 4 | C5: 0 | D5: 2.8390956 | E5: 1 | F5: 1 | G5: 1 | H5: 1 | I5: 1 | J5: 1 | K5: 1 | L5: 1 | M5: 1 | N5: 1 | O5: 1
A6: TD | B6: Question 5 | C6: 0 | D6: 9.7706349 | E6: 1 | F6: 1 | G6: 1 | H6: 1 | I6: 1 | J6: 1 | K6: 1 | L6: 1 | M6: 1 | N6: 1 | O6: 1
A7: TD | B7: Question 6 | C7: 0 | D7: 4.9612947 | E7: 1 | F7: 1 | G7: 1 | H7: 0 | I7: 1 | J7: 1 | K7: 1 | L7: 1 | M7: 1 | N7: 1 | O7: 1 | P7: synergy: The two parts (a) and (b) are independent questions that can be solved separately. Part (a) requires fraction subtraction (5/12 - 1/4) while part (b) requires ordering the same fractions (1/4 and 5/12). The result from part (a) is not used as input for part (b), so the questions are not connected in tandem as required.
A8: TD | B8: Question 7 | C8: 0 | D8: 2.7199128 | E8: 1 | F8: 1 | G8: 1 | H8: 1 | I8: 1 | J8: 1 | K8: 1 | L8: 1 | M8: 1 | N8: 1 | O8: 1
A9: TD | B9: Question 8 | C9: 0 | D9: 8.4750845 | E9: 1 | F9: 1 | G9: 1 | H9: 1 | I9: 1 | J9: 1 | K9: 1 | L9: 1 | M9: 1 | N9: 1 | O9: 1
A10: TD | B10: Question 9 | C10: 0 | D10: 9.852365 | E10: 1 | F10: 1 | G10: 1 | H10: 1 | I10: 1 | J10: 1 | K10: 1 | L10: 1 | M10: 1 | N10: 1 | O10: 1
A11: TD | B11: Question 10 | C11: 0 | D11: 2.6821985 | E11: 1 | F11: 1 | G11: 1 | H11: 1 | I11: 1 | J11: 1 | K11: 1 | L11: 1 | M11: 1 | N11: 1 | O11: 1
A12: TD | B12: Question 11 | C12: 0 | D12: 9.0388017 | E12: 1 | F12: 1 | G12: 1 | H12: 1 | I12: 1 | J12: 1 | K12: 1 | L12: 1 | M12: 1 | N12: 1 | O12: 1
A13: TD | B13: Question 12 | C13: 0 | D13: 9.6715105 | E13: 1 | F13: 1 | G13: 1 | H13: 1 | I13: 1 | J13: 1 | K13: 1 | L13: 1 | M13: 1 | N13: 1 | O13: 1
A14: TD | B14: Question 13 | C14: 0 | D14: 9.8740914 | E14: 1 | F14: 1 | G14: 1 | H14: 0 | I14: 1 | J14: 1 | K14: 1 | L14: 1 | M14: 1 | N14: 1 | O14: 1 | P14: Synergy: Part (b) does not use the result from part (a). The two questions are independent and not connected, failing to meet the requirement that results from early questions should be used in later questions.
A15: TD | B15: Question 14 | C15: 0 | D15: 2.6689901 | E15: 1 | F15: 1 | G15: 1 | H15: 1 | I15: 1 | J15: 1 | K15: 1 | L15: 1 | M15: 1 | N15: 1 | O15: 1
A16: TD | B16: Question 15 | C16: 0 | D16: 2.6690743 | E16: 1 | F16: 1 | G16: 1 | H16: 1 | I16: 1 | J16: 1 | K16: 1 | L16: 1 | M16: 1 | N16: 1 | O16: 1
A17: TD | B17: Question 16 | C17: 0 | D17: 4.5211296 | E17: 1 | F17: 1 | G17: 1 | H17: 0 | I17: 1 | J17: 1 | K17: 1 | L17: 1 | M17: 1 | N17: 1 | O17: 1 | P17: synergy: The two parts (a) and (b) are independent questions that do not require using results from one part to solve the other part. Part (a) asks for multiplication of 2.75 * 5, while part (b) asks to convert 2.75 to a fraction. Neither question uses the answer from the other question.
A18: TD | B18: Question 17 | C18: 0 | D18: 10.172833 | E18: 1 | F18: 1 | G18: 1 | H18: 1 | I18: 1 | J18: 1 | K18: 1 | L18: 1 | M18: 1 | N18: 1 | O18: 1
A19: TD | B19: Question 18 | C19: 0 | D19: 3.0347002 | E19: 1 | F19: 1 | G19: 1 | H19: 1 | I19: 1 | J19: 1 | K19: 1 | L19: 1 | M19: 1 | N19: 1 | O19: 1
A20: TD | B20: Question 19 | C20: 0 | D20: 2.7250321 | E20: 1 | F20: 1 | G20: 1 | H20: 1 | I20: 1 | J20: 1 | K20: 1 | L20: 1 | M20: 1 | N20: 1 | O20: 1
A21: TD | B21: Question 20 | C21: 0 | D21: 10.517523 | E21: 0 | F21: 'NA | G21: 'NA | H21: 'NA | I21: 'NA | J21: 'NA | K21: 'NA | L21: 'NA | M21: 'NA | N21: 'NA | O21: 'NA | P21: Answerability: Mrs Tan cannot spend 1 1/4 + 2 2/3 = 3 11/12 of her budget which is nearly 4 times her total budget - this is mathematically impossible. Real-World Plausibility: Spending nearly 400% of ones budget on just groceries and utilities is unrealistic in household finance.
A22: TD | B22: Question 21 | C22: 0 | D22: 3.8668137 | E22: 1 | F22: 1 | G22: 1 | H22: 1 | I22: 1 | J22: 1 | K22: 0 | L22: 1 | M22: 1 | N22: 1 | O22: 1 | P22: Real-world feasibility: The amounts are unrealistic - $6 3/4 total savings and $4 5/8 electricity bill are too small for realistic household finance scenarios. Electricity bills and savings amounts are typically much larger in real-world contexts.
A23: TD | B23: Question 22 | C23: 0 | D23: 8.1191189 | E23: 0 | F23: 'NA | G23: 'NA | H23: 'NA | I23: 'NA | J23: 'NA | K23: 'NA | L23: 'NA | M23: 'NA | N23: 'NA | O23: 'NA | P23: ANSWERABILITY: The problem asks which amount is greater between Mrs Lims savings (3/4 * 120 = 90) and 90, but 90 = 90 so neither is greater - the question cannot be answered as posed. SECONDARY_KC_ALIGNMENT: No meaningful comparison is needed since 3/4 * 120 = 90, so comparing 90 to 90 does not require fraction comparison skills. SYNERGY: The two knowledge components do not work together meaningfully since the comparison becomes trivial (90 vs 90). CONCISENESS_AND_RELEVANCE: The comparison value of 90 creates a trivial comparison since it equals the calculated savings amount.
A24: TD | B24: Question 23 | C24: 0 | D24: 2.6406589 | E24: 1 | F24: 1 | G24: 1 | H24: 1 | I24: 1 | J24: 1 | K24: 1 | L24: 1 | M24: 1 | N24: 1 | O24: 1
A25: TD | B25: Question 24 | C25: 0 | D25: 7.2839677 | E25: 1 | F25: 1 | G25: 0 | H25: 'NA | I25: 1 | J25: 1 | K25: 1 | L25: 1 | M25: 1 | N25: 1 | O25: 1 | P25: Secondary KC Alignment: The problem only requires fraction multiplication (2/3 × 600, 3/4 × 200, 1/6 × 50) and whole number subtraction (600 - 400, 200 - 150). No fraction addition is needed to solve the problem. Synergy: Since the Secondary Knowledge Component (fraction addition) is not required, there is no synergy between Primary and Secondary Knowledge Components. The problem can be solved using only fraction multiplication and basic arithmetic.
A26: TD | B26: Question 25 | C26: 0 | D26: 2.7380834 | E26: 1 | F26: 1 | G26: 1 | H26: 1 | I26: 1 | J26: 1 | K26: 1 | L26: 1 | M26: 1 | N26: 1 | O26: 1
A27: TD | B27: Question 26 | C27: 0 | D27: 3.8156612 | E27: 1 | F27: 1 | G27: 1 | H27: 1 | I27: 0 | J27: 1 | K27: 1 | L27: 1 | M27: 1 | N27: 1 | O27: 1 | P27: Topic Alignment: The problem context is about buying fruit juice for a family gathering, which belongs to food/beverage consumption rather than household finance topics like income, utility bills, money, interest, savings, instalment, mortgage, or financial planning.
A28: TD | B28: Question 27 | C28: 0 | D28: 9.8709166 | E28: 0 | F28: 'NA | G28: 'NA | H28: 'NA | I28: 'NA | J28: 'NA | K28: 'NA | L28: 'NA | M28: 'NA | N28: 'NA | O28: 'NA | P28: Answerability: The problem has illogical relationship - spending 7/4 + 5/3 = 41/12 of savings means spending more than the total amount saved (41/12 > 1), which is impossible. Primary KC Alignment: Problem requires multiplying improper fraction by whole number, not multiplying two improper fractions together. Secondary KC Alignment: The subtraction is between whole dollar amounts (420 - 400), not subtracting fractions. Synergy: Since neither intended knowledge component is properly used, they cannot work in tandem. Real-World Feasibility: Impossible to spend $820 from $240 savings - violates basic financial logic.
A29: TD | B29: Question 28 | C29: 0 | D29: 15.163302 | E29: 0 | F29: 'NA | G29: 'NA | H29: 'NA | I29: 'NA | J29: 'NA | K29: 'NA | L29: 'NA | M29: 'NA | N29: 'NA | O29: 'NA | P29: Answerability: 6/5 of money spent cannot be used as 6/5 > 1 creates logical impossibility. Primary KC: Problem requires (4/11) * 150 and fraction operations but not multiplying two improper fractions together. Synergy: Logical impossibility prevents knowledge components from working together properly. Real-world feasibility: Cannot use more money than you spent. Clarity: Phrase about using 6/5 of spent money is confusing and mathematically problematic.
A30: TD | B30: Question 29 | C30: 0 | D30: 10.793735 | E30: 1 | F30: 1 | G30: 1 | H30: 1 | I30: 0 | J30: 1 | K30: 1 | L30: 1 | M30: 1 | N30: 1 | O30: 1 | P30: Topic alignment: The problem focuses on baking business operations rather than core household finance concepts like income management, utility bills, savings, financial planning, or budgeting that are central to the intended topic.
A31: TD | B31: Question 30 | C31: 0 | D31: 12.256469 | E31: 1 | F31: 0 | G31: 1 | H31: 'NA | I31: 1 | J31: 'NA | K31: 1 | L31: 1 | M31: 1 | N31: 1 | O31: 1 | P31: Primary KC alignment: Part (a) requires general decimal multiplication (3.75 * 0.174 * 100) rather than focusing on multiplying decimals by multiples of 10/100/1000 as the main skill. Synergy: The two parts are independent - part (b) does not use results from part (a), and they target different knowledge components without working together.
A32: TD | B32: Question 31 | C32: 0 | D32: 12.46513 | E32: 1 | F32: 0 | G32: 0 | H32: 'NA | I32: 1 | J32: 'NA | K32: 0 | L32: 0 | M32: 1 | N32: 1 | O32: 1 | P32: Primary KC requires multiplying by 10/100/1000 or multiples, but problem uses 73.245 x 0.15 which is general decimal multiplication. Secondary KC requires subtraction but problem needs addition of service fee. Clarity issue: states service fee should be subtracted when calculating total bill, which is contradictory. Real-world issue: service fees are added to bills, not subtracted from cost calculations.
A33: TD | B33: Question 32 | C33: 0 | D33: 2.7459159 | E33: 1 | F33: 1 | G33: 1 | H33: 1 | I33: 1 | J33: 1 | K33: 1 | L33: 1 | M33: 1 | N33: 1 | O33: 1
A34: TD | B34: Question 33 | C34: 0 | D34: 13.149689 | E34: 0 | F34: 'NA | G34: 'NA | H34: 'NA | I34: 'NA | J34: 'NA | K34: 'NA | L34: 'NA | M34: 'NA | N34: 'NA | O34: 'NA | P34: Answerability: The problem is ambiguous about whether Mrs Lim kept a share for herself when splitting money among 10 grandchildren. Synergy: The ambiguity prevents clear connection between division and addition steps. Real-world feasibility: Unrealistic scenario where someone splits money among grandchildren while keeping an unspecified share. Clarity: The phrase her own share from the original savings jar is confusing when the problem states money was split among grandchildren.
A35: TD | B35: Question 34 | C35: 0 | D35: 11.111356 | E35: 1 | F35: 1 | G35: 0 | H35: 'NA | I35: 1 | J35: 1 | K35: 1 | L35: 1 | M35: 1 | N35: 1 | O35: 1 | P35: Secondary KC alignment fails because the problem requires decimal multiplication (800 x 0.15) rather than whole number multiplication as specified in the intended Secondary Knowledge Component.
A36: TD | B36: Question 35 | C36: 0 | D36: 2.7748928 | E36: 1 | F36: 1 | G36: 1 | H36: 1 | I36: 1 | J36: 1 | K36: 1 | L36: 1 | M36: 1 | N36: 1 | O36: 1
A37: TD | B37: Question 36 | C37: 0 | D37: 9.8246069 | E37: 1 | F37: 1 | G37: 1 | H37: 1 | I37: 1 | J37: 1 | K37: 1 | L37: 1 | M37: 1 | N37: 1 | O37: 1
A38: TD | B38: Question 37 | C38: 0 | D38: 2.6745052 | E38: 1 | F38: 1 | G38: 1 | H38: 1 | I38: 1 | J38: 1 | K38: 1 | L38: 1 | M38: 1 | N38: 1 | O38: 1
A39: TD | B39: Question 38 | C39: 0 | D39: 3.8939869 | E39: 1 | F39: 1 | G39: 1 | H39: 1 | I39: 0 | J39: 1 | K39: 1 | L39: 1 | M39: 1 | N39: 1 | O39: 1 | P39: Topic Alignment: The problem context involves baking cookies for a school fundraiser, which belongs to school/baking activities rather than household finance topics like income, utility bills, money, interest, savings, instalment, mortgage, or financial planning.
A40: TD | B40: Question 39 | C40: 0 | D40: 11.716369 | E40: 1 | F40: 1 | G40: 0 | H40: 'NA | I40: 1 | J40: 1 | K40: 0 | L40: 1 | M40: 1 | N40: 1 | O40: 1 | P40: Secondary KC alignment fails because 120 - 180 = -60, which is not fraction subtraction but results in negative money. Synergy fails because the two questions are independent - the answer to question 1 (1 month with 30 dollars left) does not connect to question 2. Real-world feasibility fails because Mrs Tan cannot realistically pay 180 dollars in bills when she only has 120 dollars saved.
...

Sheet householdfinance_v2_6
A1: Evaluator | B1: Question | C1: status | D1: response_time | E1: answerability | F1: primary_kc_alignment | G1: secondary_kc_alignment | H1: synergy | I1: topic_alignment | J1: grade_alignment | K1: real_world_feasibility | L1: clarity | M1: conciseness_and_relevance | N1: language_quality | O1: content_appropriateness | P1: explanation
A2: TD | B2: Question 1 | C2: 0 | D2: 2.8642614 | E2: 1 | F2: 1 | G2: 1 | H2: 1 | I2: 1 | J2: 1 | K2: 1 | L2: 1 | M2: 1 | N2: 1 | O2: 1
A3: TD | B3: Question 2 | C3: 0 | D3: 5.5466685 | E3: 1 | F3: 1 | G3: 0 | H3: 'NA | I3: 1 | J3: 1 | K3: 1 | L3: 1 | M3: 0 | N3: 1 | O3: 1 | P3: Secondary KC Alignment: The problem only requires subtraction (450 - 215 = 235) to find how much Sarah spent. Addition is not needed since the extra $80 from father is irrelevant to the question asked. Synergy: Since only subtraction is needed and addition is not required, the two knowledge components do not work in tandem. Conciseness and Relevance: The information about father giving $80 extra money is irrelevant to solving the problem and makes the problem less concise.
A4: TD | B4: Question 3 | C4: 0 | D4: 10.793092 | E4: 1 | F4: 1 | G4: 1 | H4: 1 | I4: 0 | J4: 1 | K4: 1 | L4: 1 | M4: 1 | N4: 1 | O4: 1 | P4: Topic Alignment: The problem context is about sharing candies among children, which does not belong to household finance. Household finance involves income, utility bills, money, interest, savings, installment, mortgage, financial planning etc. This is a general sharing/distribution context, not financial management.
A5: TD | B5: Question 4 | C5: 0 | D5: 2.9079974 | E5: 1 | F5: 1 | G5: 1 | H5: 1 | I5: 1 | J5: 1 | K5: 1 | L5: 1 | M5: 1 | N5: 1 | O5: 1
A6: TD | B6: Question 5 | C6: 0 | D6: 9.1129642 | E6: 1 | F6: 1 | G6: 1 | H6: 1 | I6: 1 | J6: 1 | K6: 1 | L6: 1 | M6: 1 | N6: 1 | O6: 1
A7: TD | B7: Question 6 | C7: 0 | D7: 5.6548495 | E7: 1 | F7: 1 | G7: 1 | H7: 0 | I7: 1 | J7: 0 | K7: 1 | L7: 1 | M7: 1 | N7: 1 | O7: 1 | P7: Synergy: The two questions (a) and (b) are independent of each other. Question (b) does not use the result from question (a) as known information, so the primary and secondary knowledge components are not used in tandem. Grade Alignment: The problem involves fractions with denominators 12 and 4, requiring finding common denominators and complex fraction operations that are typically beyond Primary 3 level. Primary 3 students usually work with simpler fractions like halves, quarters, and thirds.
A8: TD | B8: Question 7 | C8: 0 | D8: 2.8231153 | E8: 1 | F8: 1 | G8: 1 | H8: 1 | I8: 1 | J8: 1 | K8: 1 | L8: 1 | M8: 1 | N8: 1 | O8: 1
A9: TD | B9: Question 8 | C9: 0 | D9: 6.6261528 | E9: 1 | F9: 1 | G9: 0 | H9: 'NA | I9: 1 | J9: 1 | K9: 1 | L9: 1 | M9: 1 | N9: 1 | O9: 1 | P9: Secondary KC alignment fails: The intended Secondary Knowledge Component specifies rounding to nearest 10, 100, or 1000, but the problem asks to round 684 to nearest hundred. Since 684 rounded to nearest hundred is 700 (difference of 16), this falls within the easier rounding to nearest 10 category rather than requiring the full complexity of the intended Secondary KC which should involve numbers where rounding to nearest 100 creates more significant changes.
A10: TD | B10: Question 9 | C10: 0 | D10: 10.385254 | E10: 1 | F10: 1 | G10: 1 | H10: 1 | I10: 1 | J10: 1 | K10: 1 | L10: 1 | M10: 1 | N10: 1 | O10: 1
A11: TD | B11: Question 10 | C11: 0 | D11: 4.3310516 | E11: 1 | F11: 1 | G11: 1 | H11: 1 | I11: 1 | J11: 1 | K11: 0 | L11: 1 | M11: 1 | N11: 1 | O11: 1 | P11: Real-world feasibility: An electricity bill of $3287 for 4 months ($821.75 per month) is unrealistically high for a typical family household. Most residential electricity bills range from $50-300 per month, making this amount implausible for the intended context.
A12: TD | B12: Question 11 | C12: 0 | D12: 13.033499 | E12: 0 | F12: 'NA | G12: 'NA | H12: 'NA | I12: 'NA | J12: 'NA | K12: 'NA | L12: 'NA | M12: 'NA | N12: 'NA | O12: 'NA | P12: Answerability: The problem has conflicting information - Grace cannot save 3/8 + 2/3 = 25/24 > 1 of her allowance, which is mathematically impossible if referring to fractions of the same total allowance. Real-world feasibility: The scenario is illogical as one cannot save more than 100% of a fixed amount.
A13: TD | B13: Question 12 | C13: 0 | D13: 13.044367 | E13: 1 | F13: 1 | G13: 1 | H13: 1 | I13: 1 | J13: 1 | K13: 0 | L13: 1 | M13: 1 | N13: 1 | O13: 1 | P13: The problem states Amy saved $7 5/12 and then spent $1 1/3 on a book, asking how much money she had left. This creates a logical inconsistency - if she saved the money and then spent part of it, she would be spending from her savings, not having money left from the original saved amount. The scenario does not mirror realistic financial behavior.
A14: TD | B14: Question 13 | C14: 0 | D14: 11.205176 | E14: 1 | F14: 1 | G14: 1 | H14: 0 | I14: 1 | J14: 1 | K14: 0 | L14: 1 | M14: 1 | N14: 1 | O14: 1 | P14: Synergy: The two parts are independent - part b does not use the result from part a, lacking required connection between questions. Real-world feasibility: Electricity bills typically do not have 3 decimal places like 45.605 dollars in actual billing systems.
A15: TD | B15: Question 14 | C15: 0 | D15: 9.2436345 | E15: 1 | F15: 1 | G15: 1 | H15: 1 | I15: 1 | J15: 1 | K15: 1 | L15: 1 | M15: 1 | N15: 1 | O15: 1
A16: TD | B16: Question 15 | C16: 0 | D16: 5.2362072 | E16: 1 | F16: 1 | G16: 0 | H16: 'NA | I16: 1 | J16: 1 | K16: 1 | L16: 1 | M16: 1 | N16: 1 | O16: 1 | P16: Secondary KC alignment: Part (b) asks to round to nearest dollar AND to 1 decimal place, but 123.45 - 97.88 = 25.57. Rounding 25.57 to nearest dollar gives 26, and to 1 decimal place gives 25.6. The intended Secondary KC is rounding decimals up to 3 decimal places, but the result 25.57 only has 2 decimal places, not utilizing the full scope of the intended rounding knowledge component.
A17: TD | B17: Question 16 | C17: 0 | D17: 5.2376604 | E17: 1 | F17: 1 | G17: 1 | H17: 0 | I17: 1 | J17: 1 | K17: 1 | L17: 1 | M17: 1 | N17: 1 | O17: 1 | P17: Synergy: The two parts (a) and (b) are independent questions that both use the same given information ($2.75 per day) but do not build upon each other. Part (a) requires multiplying 2.75 x 5, and part (b) requires converting 2.75 to a fraction. The result from part (a) is not used as input for part (b), so the primary and secondary knowledge components are not used in tandem.
A18: TD | B18: Question 17 | C18: 0 | D18: 9.2734091 | E18: 1 | F18: 1 | G18: 1 | H18: 1 | I18: 1 | J18: 1 | K18: 1 | L18: 1 | M18: 1 | N18: 1 | O18: 1
A19: TD | B19: Question 18 | C19: 0 | D19: 2.980253 | E19: 1 | F19: 1 | G19: 1 | H19: 1 | I19: 1 | J19: 1 | K19: 1 | L19: 1 | M19: 1 | N19: 1 | O19: 1
A20: TD | B20: Question 19 | C20: 0 | D20: 2.86992 | E20: 1 | F20: 1 | G20: 1 | H20: 1 | I20: 1 | J20: 1 | K20: 1 | L20: 1 | M20: 1 | N20: 1 | O20: 1
A21: TD | B21: Question 20 | C21: 0 | D21: 11.382793 | E21: 0 | F21: 'NA | G21: 'NA | H21: 'NA | I21: 'NA | J21: 'NA | K21: 'NA | L21: 'NA | M21: 'NA | N21: 'NA | O21: 'NA | P21: Answerability: The fractions 1 1/4 + 2 2/3 = approximately 3.92, meaning Mrs Tan spent nearly 400% of her budget on just two items, which is mathematically impossible. Real-world feasibility: No one can spend almost 4 times their budget on groceries and utilities alone in a realistic household finance scenario.
A22: TD | B22: Question 21 | C22: 0 | D22: 9.8640211 | E22: 1 | F22: 1 | G22: 1 | H22: 1 | I22: 1 | J22: 1 | K22: 1 | L22: 1 | M22: 1 | N22: 1 | O22: 1
A23: TD | B23: Question 22 | C23: 0 | D23: 8.121099 | E23: 0 | F23: 'NA | G23: 'NA | H23: 'NA | I23: 'NA | J23: 'NA | K23: 'NA | L23: 'NA | M23: 'NA | N23: 'NA | O23: 'NA | P23: ANSWERABILITY: The calculation gives 3/4 * 120 = 90, making both amounts equal to $90. Comparing $90 to $90 has no definitive answer since they are equal, not one being greater. SECONDARY_KC_ALIGNMENT: No meaningful comparison occurs since 3/4 * 120 = 90, so comparing $90 to $90 does not require fraction comparison skills. SYNERGY: The two knowledge components do not work in tandem since the comparison component is not meaningfully utilized when comparing equal amounts. CONCISENESS_AND_RELEVANCE: The problem setup leads to a trivial comparison of equal amounts, making the comparison question essentially irrelevant.
A24: TD | B24: Question 23 | C24: 0 | D24: 2.8723402 | E24: 1 | F24: 1 | G24: 1 | H24: 1 | I24: 1 | J24: 1 | K24: 1 | L24: 1 | M24: 1 | N24: 1 | O24: 1
A25: TD | B25: Question 24 | C25: 0 | D25: 6.5781851 | E25: 1 | F25: 1 | G25: 0 | H25: 'NA | I25: 1 | J25: 1 | K25: 1 | L25: 1 | M25: 1 | N25: 1 | O25: 1 | P25: Secondary KC Alignment: The problem only requires subtraction operations (600-400=200, 200-150=50), not addition of fractions as specified in the secondary knowledge component. Synergy: Since the secondary knowledge component (adding fractions) is not actually needed to solve the problem, the primary and secondary components do not work in tandem as required.
A26: TD | B26: Question 25 | C26: 0 | D26: 7.5990891 | E26: 1 | F26: 1 | G26: 0 | H26: 'NA | I26: 1 | J26: 1 | K26: 1 | L26: 1 | M26: 1 | N26: 1 | O26: 1 | P26: Secondary KC alignment fails because the final answer 150 is already a whole number in simplest form, so no fraction simplification is needed. Synergy fails because the Secondary Knowledge Component (fraction simplification) is not actually required to solve the problem, making the two knowledge components not work in tandem as intended.
A27: TD | B27: Question 26 | C27: 0 | D27: 10.381288 | E27: 1 | F27: 1 | G27: 1 | H27: 1 | I27: 0 | J27: 1 | K27: 1 | L27: 1 | M27: 1 | N27: 1 | O27: 1 | P27: Topic alignment: The problem context is about buying fruit juice for a family gathering, which does not belong to household finance topics like income, utility bills, money, interest, savings, instalment, mortgage, or financial planning. The problem focuses on quantities and fractions rather than financial concepts.
A28: TD | B28: Question 27 | C28: 0 | D28: 12.235963 | E28: 0 | F28: 'NA | G28: 'NA | H28: 'NA | I28: 'NA | J28: 'NA | K28: 'NA | L28: 'NA | M28: 'NA | N28: 'NA | O28: 'NA | P28: Answerability: Mrs Tan cannot spend 7/4 + 5/3 = 21/12 + 20/12 = 41/12 = 342% of her savings when she only has 100% available. Real-World Plausibility: Spending 342% of monthly savings is unrealistic and impossible in normal circumstances.
A29: TD | B29: Question 28 | C29: 0 | D29: 13.910086 | E29: 0 | F29: 'NA | G29: 'NA | H29: 'NA | I29: 'NA | J29: 'NA | K29: 'NA | L29: 'NA | M29: 'NA | N29: 'NA | O29: 'NA | P29: Answerability: Using 6/5 of money spent means using 120% which is illogical - cannot use more money than spent. Primary KC Alignment: Problem does not require multiplying two improper fractions as main solution method. Real World Feasibility: Cannot use 120% of money already spent on brushes. Clarity: Phrase about money spent on brushes being actually used is ambiguous and confusing.
A30: TD | B30: Question 29 | C30: 0 | D30: 11.16716 | E30: 1 | F30: 1 | G30: 1 | H30: 1 | I30: 0 | J30: 1 | K30: 1 | L30: 1 | M30: 1 | N30: 1 | O30: 1 | P30: Topic_alignment: The problem focuses on ingredient usage in baking rather than household finance topics like income, bills, savings, interest, or financial planning as specified in the intended topic.
A31: TD | B31: Question 30 | C31: 0 | D31: 10.600064 | E31: 1 | F31: 1 | G31: 1 | H31: 0 | I31: 1 | J31: 1 | K31: 1 | L31: 1 | M31: 1 | N31: 1 | O31: 1 | P31: The two parts of the problem are independent of each other. Part (b) does not use the result from part (a), so the primary and secondary knowledge components are not used in tandem as required for synergy.
A32: TD | B32: Question 31 | C32: 0 | D32: 12.764509 | E32: 0 | F32: 'NA | G32: 'NA | H32: 'NA | I32: 'NA | J32: 'NA | K32: 'NA | L32: 'NA | M32: 'NA | N32: 'NA | O32: 'NA | P32: Primary KC requires multiplying by multiples of 10/100/1000, but problem uses 0.15. Secondary KC involves subtraction but service fees are typically added to bills, not subtracted, creating logical inconsistency. This makes the problem unclear and unrealistic as service fees increase rather than decrease bills.
A33: TD | B33: Question 32 | C33: 0 | D33: 2.9394612 | E33: 1 | F33: 1 | G33: 1 | H33: 1 | I33: 1 | J33: 1 | K33: 1 | L33: 1 | M33: 1 | N33: 1 | O33: 1
A34: TD | B34: Question 33 | C34: 0 | D34: 14.28937 | E34: 0 | F34: 'NA | G34: 'NA | H34: 'NA | I34: 'NA | J34: 'NA | K34: 'NA | L34: 'NA | M34: 'NA | N34: 'NA | O34: 'NA | P34: Answerability: Mrs Lim splits 27.650 dollars equally among 10 grandchildren, giving away all money, but problem refers to her own share which does not exist. Synergy: The division and addition cannot work together due to logical inconsistency - no remaining amount to add 4.25 dollars to. Real-world feasibility: Unrealistic for someone to give entire savings to grandchildren while expecting personal share. Clarity: Her own share from original savings jar is ambiguous when entire amount was distributed.
A35: TD | B35: Question 34 | C35: 0 | D35: 9.6630378 | E35: 1 | F35: 1 | G35: 1 | H35: 1 | I35: 1 | J35: 1 | K35: 1 | L35: 1 | M35: 1 | N35: 1 | O35: 1
A36: TD | B36: Question 35 | C36: 0 | D36: 2.9780767 | E36: 1 | F36: 1 | G36: 1 | H36: 1 | I36: 1 | J36: 1 | K36: 1 | L36: 1 | M36: 1 | N36: 1 | O36: 1
A37: TD | B37: Question 36 | C37: 0 | D37: 11.513881 | E37: 1 | F37: 1 | G37: 1 | H37: 1 | I37: 1 | J37: 1 | K37: 1 | L37: 1 | M37: 1 | N37: 1 | O37: 1
A38: TD | B38: Question 37 | C38: 0 | D38: 2.8828423 | E38: 1 | F38: 1 | G38: 1 | H38: 1 | I38: 1 | J38: 1 | K38: 1 | L38: 1 | M38: 1 | N38: 1 | O38: 1
A39: TD | B39: Question 38 | C39: 0 | D39: 10.336394 | E39: 1 | F39: 1 | G39: 1 | H39: 1 | I39: 0 | J39: 1 | K39: 1 | L39: 1 | M39: 1 | N39: 1 | O39: 1 | P39: Topic Alignment: The word problem context is about baking cookies for a school fundraiser, which does not belong to household finance topics like income, utility bills, money, interest, savings, instalment, mortgage, or financial planning.
A40: TD | B40: Question 39 | C40: 0 | D40: 15.15023 | E40: 0 | F40: 'NA | G40: 'NA | H40: 'NA | I40: 'NA | J40: 'NA | K40: 'NA | L40: 'NA | M40: 'NA | N40: 'NA | O40: 'NA | P40: Answerability: Problem asks to pay 2 months bills costing 2 * 90 = 180 dollars but only 120 dollars available, creating impossible scenario. Secondary KC Alignment: Problem requires subtracting whole numbers 120 - 180, not subtracting fractions as intended. Synergy: Questions not properly connected due to mathematical impossibility of second question. Real World Feasibility: Unrealistic to pay bills exceeding available funds. Clarity: Logical inconsistency makes problem confusing.
...

Sheet householdfinance_v2_7
A1: Evaluator | B1: Question | C1: status | D1: response_time | E1: answerability | F1: primary_kc_alignment | G1: secondary_kc_alignment | H1: synergy | I1: topic_alignment | J1: grade_alignment | K1: real_world_feasibility | L1: clarity | M1: conciseness_and_relevance | N1: language_quality | O1: content_appropriateness | P1: explanation
A2: TD | B2: Question 1 | C2: 0 | D2: 2.9586365 | E2: 1 | F2: 1 | G2: 1 | H2: 1 | I2: 1 | J2: 1 | K2: 1 | L2: 1 | M2: 1 | N2: 1 | O2: 1
A3: TD | B3: Question 2 | C3: 0 | D3: 11.211002 | E3: 1 | F3: 1 | G3: 0 | H3: 'NA | I3: 1 | J3: 1 | K3: 1 | L3: 1 | M3: 0 | N3: 1 | O3: 1 | P3: Secondary KC alignment: Problem only requires subtraction (450 - 215 = 235), no addition needed. Synergy: No synergy between addition and subtraction since addition is not required. Conciseness: The $80 from father is irrelevant information not needed to solve the problem.
A4: TD | B4: Question 3 | C4: 0 | D4: 9.9578664 | E4: 1 | F4: 1 | G4: 1 | H4: 1 | I4: 0 | J4: 1 | K4: 1 | L4: 1 | M4: 1 | N4: 1 | O4: 1 | P4: Topic alignment: The problem context involves candy sharing which does not belong to household finance topics such as income, utility bills, money, interest, savings, instalment, mortgage, or financial planning.
A5: TD | B5: Question 4 | C5: 0 | D5: 10.283072 | E5: 1 | F5: 1 | G5: 1 | H5: 1 | I5: 1 | J5: 1 | K5: 1 | L5: 1 | M5: 1 | N5: 1 | O5: 1
A6: TD | B6: Question 5 | C6: 0 | D6: 10.372951 | E6: 1 | F6: 1 | G6: 1 | H6: 1 | I6: 1 | J6: 1 | K6: 1 | L6: 1 | M6: 1 | N6: 1 | O6: 1
A7: TD | B7: Question 6 | C7: 0 | D7: 6.2830966 | E7: 1 | F7: 1 | G7: 1 | H7: 0 | I7: 1 | J7: 0 | K7: 1 | L7: 1 | M7: 1 | N7: 1 | O7: 1 | P7: Synergy: The two parts (a) and (b) are independent questions that can be solved separately. Part (b) does not use the result from part (a), so they are not connected in tandem as required. Grade Alignment: Primary 3 students typically work with simpler fractions like halves, quarters, and thirds. The fraction 5/12 and operations requiring common denominators of 12 are too advanced for Primary 3 level, as students at this grade have not yet mastered complex fraction operations with denominators exceeding basic unit fractions.
A8: TD | B8: Question 7 | C8: 0 | D8: 2.8644083 | E8: 1 | F8: 1 | G8: 1 | H8: 1 | I8: 1 | J8: 1 | K8: 1 | L8: 1 | M8: 1 | N8: 1 | O8: 1
A9: TD | B9: Question 8 | C9: 0 | D9: 5.7703128 | E9: 1 | F9: 1 | G9: 0 | H9: 'NA | I9: 1 | J9: 1 | K9: 1 | L9: 1 | M9: 1 | N9: 1 | O9: 1 | P9: secondary_kc_alignment: Part (b) asks to round 684 to the nearest hundred dollars, but the intended Secondary Knowledge Component specifies rounding to nearest 10, 100 or 1000 for numbers up to 100000. Since 684 is less than 100000 and rounding to nearest 100 is within the specified range, this should align. However, the problem asks to round to nearest hundred dollars specifically, which may not perfectly match the pure mathematical rounding component intended.
A10: TD | B10: Question 9 | C10: 0 | D10: 10.264436 | E10: 1 | F10: 1 | G10: 1 | H10: 1 | I10: 1 | J10: 1 | K10: 1 | L10: 1 | M10: 1 | N10: 1 | O10: 1
A11: TD | B11: Question 10 | C11: 0 | D11: 9.3520939 | E11: 1 | F11: 1 | G11: 1 | H11: 1 | I11: 1 | J11: 1 | K11: 1 | L11: 1 | M11: 1 | N11: 1 | O11: 1
A12: TD | B12: Question 11 | C12: 0 | D12: 10.719038 | E12: 0 | F12: 'NA | G12: 'NA | H12: 'NA | I12: 'NA | J12: 'NA | K12: 'NA | L12: 'NA | M12: 'NA | N12: 'NA | O12: 'NA | P12: Answerability: The problem leads to Grace saving 3/8 + 2/3 = 25/24 > 1 whole allowance, which is logically impossible since she cannot save more than 100% of her weekly allowance over two separate weeks without additional income sources. Real-world feasibility: The scenario is unrealistic as it implies saving 104% of total allowances, which contradicts how allowances and savings work in reality.
A13: TD | B13: Question 12 | C13: 0 | D13: 11.570011 | E13: 1 | F13: 1 | G13: 1 | H13: 1 | I13: 1 | J13: 1 | K13: 1 | L13: 1 | M13: 1 | N13: 1 | O13: 1
A14: TD | B14: Question 13 | C14: 0 | D14: 9.6837184 | E14: 1 | F14: 1 | G14: 1 | H14: 0 | I14: 1 | J14: 1 | K14: 1 | L14: 1 | M14: 1 | N14: 1 | O14: 1 | P14: The two parts of the problem are independent of each other. Part b does not use the result from part a as input, so the questions are not connected as required for synergy.
A15: TD | B15: Question 14 | C15: 0 | D15: 2.9758184 | E15: 1 | F15: 1 | G15: 1 | H15: 1 | I15: 1 | J15: 1 | K15: 1 | L15: 1 | M15: 1 | N15: 1 | O15: 1
A16: TD | B16: Question 15 | C16: 0 | D16: 2.9777377 | E16: 1 | F16: 1 | G16: 1 | H16: 1 | I16: 1 | J16: 1 | K16: 1 | L16: 1 | M16: 1 | N16: 1 | O16: 1
A17: TD | B17: Question 16 | C17: 0 | D17: 5.1390803 | E17: 1 | F17: 1 | G17: 1 | H17: 0 | I17: 1 | J17: 1 | K17: 1 | L17: 1 | M17: 1 | N17: 1 | O17: 1 | P17: Synergy criterion failed: The two parts (a) and (b) are independent questions that both use the same given value $2.75. Part (a) requires multiplying $2.75 x 5 using decimal multiplication, while part (b) requires converting $2.75 to fraction form. However, the result from part (a) is not used as input for part (b), so the primary and secondary knowledge components are not used in tandem as required.
A18: TD | B18: Question 17 | C18: 0 | D18: 10.212519 | E18: 1 | F18: 1 | G18: 1 | H18: 1 | I18: 1 | J18: 1 | K18: 1 | L18: 1 | M18: 1 | N18: 1 | O18: 1
A19: TD | B19: Question 18 | C19: 0 | D19: 9.4264596 | E19: 1 | F19: 1 | G19: 1 | H19: 1 | I19: 1 | J19: 1 | K19: 1 | L19: 1 | M19: 1 | N19: 1 | O19: 1
A20: TD | B20: Question 19 | C20: 0 | D20: 11.775519 | E20: 1 | F20: 1 | G20: 1 | H20: 1 | I20: 1 | J20: 1 | K20: 1 | L20: 1 | M20: 1 | N20: 1 | O20: 1
A21: TD | B21: Question 20 | C21: 0 | D21: 11.756493 | E21: 0 | F21: 'NA | G21: 'NA | H21: 'NA | I21: 'NA | J21: 'NA | K21: 'NA | L21: 'NA | M21: 'NA | N21: 'NA | O21: 'NA | P21: The problem contains illogical information: 1 1/4 + 2 2/3 = 3 11/12 of budget, meaning Mrs Tan spent nearly 4 times her entire budget, which is impossible in reality. The fractions should sum to less than 1 whole budget to be mathematically and practically coherent.
A22: TD | B22: Question 21 | C22: 0 | D22: 9.9716451 | E22: 1 | F22: 1 | G22: 1 | H22: 1 | I22: 1 | J22: 1 | K22: 1 | L22: 1 | M22: 1 | N22: 1 | O22: 1
A23: TD | B23: Question 22 | C23: 0 | D23: 12.131802 | E23: 1 | F23: 1 | G23: 1 | H23: 1 | I23: 1 | J23: 1 | K23: 0 | L23: 1 | M23: 1 | N23: 1 | O23: 1 | P23: Real-world feasibility: Adults typically receive salaries or income, not monthly allowances. The term allowance is inconsistent with Mrs Lim being an adult.
A24: TD | B24: Question 23 | C24: 0 | D24: 2.9763913 | E24: 1 | F24: 1 | G24: 1 | H24: 1 | I24: 1 | J24: 1 | K24: 1 | L24: 1 | M24: 1 | N24: 1 | O24: 1
A25: TD | B25: Question 24 | C25: 0 | D25: 12.449578 | E25: 1 | F25: 1 | G25: 0 | H25: 'NA | I25: 1 | J25: 1 | K25: 1 | L25: 1 | M25: 1 | N25: 1 | O25: 1 | P25: Secondary KC Alignment: Problem only requires fraction multiplication (2/3 * 600, 3/4 * 200, 1/6 * 50) and whole number subtraction (600-400, 200-150). No addition of fractions is needed. Synergy: Since secondary KC adding fractions is not used, there is no synergy between primary and secondary knowledge components.
A26: TD | B26: Question 25 | C26: 0 | D26: 6.7170522 | E26: 1 | F26: 1 | G26: 0 | H26: 'NA | I26: 1 | J26: 1 | K26: 1 | L26: 1 | M26: 1 | N26: 1 | O26: 1 | P26: Secondary KC alignment: The final answer 3/4 × 2/5 × 500 = 150/1 = 150 is already in simplest form as a whole number, so no fraction simplification is needed. Synergy: Since no actual fraction simplification occurs in solving this problem, the primary and secondary knowledge components are not used in tandem - only the primary KC (fraction multiplication) is utilized.
A27: TD | B27: Question 26 | C27: 0 | D27: 10.027637 | E27: 1 | F27: 1 | G27: 1 | H27: 1 | I27: 0 | J27: 1 | K27: 1 | L27: 1 | M27: 1 | N27: 1 | O27: 1 | P27: Topic alignment fails because the problem involves buying fruit juice for a family gathering, which is a simple consumer purchase scenario, not household finance topics like income, utility bills, money management, interest, savings, installments, mortgages, or financial planning.
A28: TD | B28: Question 27 | C28: 0 | D28: 12.968567 | E28: 0 | F28: 'NA | G28: 'NA | H28: 'NA | I28: 'NA | J28: 'NA | K28: 'NA | L28: 'NA | M28: 'NA | N28: 'NA | O28: 'NA | P28: Answerability: 7/4 + 5/3 = 41/12 > 1, meaning spending exceeds 100% of savings which is illogical. Primary KC: Problem requires fraction × whole number, not fraction × fraction multiplication. Secondary KC: Problem uses whole number subtraction (400 - 320 = 80), not fraction subtraction. Synergy: Knowledge components not used in tandem as intended. Real-world: Spending 341.7% of monthly savings is unrealistic.
A29: TD | B29: Question 28 | C29: 0 | D29: 14.374652 | E29: 0 | F29: 'NA | G29: 'NA | H29: 'NA | I29: 'NA | J29: 'NA | K29: 'NA | L29: 'NA | M29: 'NA | N29: 'NA | O29: 'NA | P29: Answerability: The phrase 6/5 of money spent on brushes was actually used is illogical - cannot use 120% of money already spent. Real-world feasibility: Same issue - using 6/5 = 1.2 times the money spent violates real-world constraints as you cannot use more than 100% of money that was already spent.
A30: TD | B30: Question 29 | C30: 0 | D30: 11.021643 | E30: 1 | F30: 1 | G30: 1 | H30: 1 | I30: 0 | J30: 1 | K30: 1 | L30: 1 | M30: 1 | N30: 1 | O30: 1 | P30: Topic Alignment: The problem focuses on ingredient quantities and baking operations rather than household finance aspects like income, expenses, financial planning, savings, or money management that the intended topic requires.
A31: TD | B31: Question 30 | C31: 0 | D31: 11.393996 | E31: 1 | F31: 0 | G31: 1 | H31: 'NA | I31: 1 | J31: 'NA | K31: 1 | L31: 1 | M31: 1 | N31: 1 | O31: 1 | P31: Primary KC alignment: The main calculation in part (a) is 3.75 x 0.174 x 100, which primarily involves general decimal multiplication (3.75 x 0.174) rather than specifically multiplying decimals by multiples of 10/100/1000. Synergy: Parts (a) and (b) are independent questions that do not work in tandem - the result from part (a) is not used in part (b), and both parts use the same given information (3.75 kWh) separately.
A32: TD | B32: Question 31 | C32: 0 | D32: 11.574322 | E32: 1 | F32: 0 | G32: 0 | H32: 'NA | I32: 1 | J32: 'NA | K32: 1 | L32: 0 | M32: 1 | N32: 1 | O32: 1 | P32: Primary KC requires multiplication by 10/100/1000 or multiples, but problem uses 73.245 * 0.15 which is general decimal multiplication. Secondary KC requires subtraction but problem needs addition of service fee despite contradictory wording. No synergy exists between intended components. Clarity fails due to contradiction between stating to subtract service fee but asking for amount including the fee.
A33: TD | B33: Question 32 | C33: 0 | D33: 3.0298712 | E33: 1 | F33: 1 | G33: 1 | H33: 1 | I33: 1 | J33: 1 | K33: 1 | L33: 1 | M33: 1 | N33: 1 | O33: 1
A34: TD | B34: Question 33 | C34: 0 | D34: 13.660419 | E34: 0 | F34: 'NA | G34: 'NA | H34: 'NA | I34: 'NA | J34: 'NA | K34: 'NA | L34: 'NA | M34: 'NA | N34: 'NA | O34: 'NA | P34: Answerability: Problem has illogical information - Mrs Lim splits all $27.65 among 10 grandchildren leaving her with $0, but then asks about adding $4.25 to her own share which would be $0. Real-world feasibility: The scenario is illogical - if someone gives away all their money, they cannot have a share to add money to. Clarity: The concept of Mrs Lim having her own share after giving everything away creates confusion and ambiguity.
A35: TD | B35: Question 34 | C35: 0 | D35: 9.6729572 | E35: 1 | F35: 1 | G35: 0 | H35: 'NA | I35: 1 | J35: 1 | K35: 1 | L35: 1 | M35: 1 | N35: 1 | O35: 1 | P35: Secondary KC alignment fails because the problem requires decimal multiplication (800 * 0.15) rather than whole number multiplication as specified in the intended Secondary Knowledge Component.
A36: TD | B36: Question 35 | C36: 0 | D36: 2.9746802 | E36: 1 | F36: 1 | G36: 1 | H36: 1 | I36: 1 | J36: 1 | K36: 1 | L36: 1 | M36: 1 | N36: 1 | O36: 1
A37: TD | B37: Question 36 | C37: 0 | D37: 9.8585706 | E37: 1 | F37: 1 | G37: 1 | H37: 1 | I37: 1 | J37: 1 | K37: 1 | L37: 1 | M37: 1 | N37: 1 | O37: 1
A38: TD | B38: Question 37 | C38: 0 | D38: 10.379353 | E38: 1 | F38: 0 | G38: 1 | H38: 'NA | I38: 1 | J38: 'NA | K38: 1 | L38: 1 | M38: 1 | N38: 1 | O38: 1 | P38: Primary KC Alignment: The problem requires dividing a dollar amount (9/4) rather than dividing a proper fraction by a whole number. The intended primary knowledge component of fraction division is not actually needed to solve this problem.
A39: TD | B39: Question 38 | C39: 0 | D39: 4.207639 | E39: 1 | F39: 1 | G39: 1 | H39: 1 | I39: 0 | J39: 1 | K39: 1 | L39: 1 | M39: 1 | N39: 1 | O39: 1 | P39: Topic Alignment: The word problem context involves baking cookies for a school fundraiser, which does not belong to household finance topics such as income, utility bills, money, interest, savings, instalment, mortgage, or financial planning. The context is more related to school activities or food preparation rather than household finance.
A40: TD | B40: Question 39 | C40: 0 | D40: 8.8314698 | E40: 0 | F40: 'NA | G40: 'NA | H40: 'NA | I40: 'NA | J40: 'NA | K40: 'NA | L40: 'NA | M40: 'NA | N40: 'NA | O40: 'NA | P40: Answerability: The problem contains illogical information - Mrs Tan cannot pay 2 months of bills ($90 each = $180 total) with only $120 saved, resulting in negative money left (-$60). Synergy: The two questions are independent - question 1 asks maximum months possible (4/3 months), while question 2 assumes paying exactly 2 months. The result from question 1 is not used in question 2. Real-world feasibility: It is unrealistic for someone to decide to pay 2 months of utility bills when they only have enough money for 1.33 months, and having negative money left contradicts normal financial behavior.
...

Sheet householdfinance_v2_8
A1: Evaluator | B1: Question | C1: status | D1: response_time | E1: answerability | F1: primary_kc_alignment | G1: secondary_kc_alignment | H1: synergy | I1: topic_alignment | J1: grade_alignment | K1: real_world_feasibility | L1: clarity | M1: conciseness_and_relevance | N1: language_quality | O1: content_appropriateness | P1: explanation
A2: TD | B2: Question 1 | C2: 0 | D2: 2.7456977 | E2: 1 | F2: 1 | G2: 1 | H2: 1 | I2: 1 | J2: 1 | K2: 1 | L2: 1 | M2: 1 | N2: 1 | O2: 1
A3: TD | B3: Question 2 | C3: 0 | D3: 6.3697183 | E3: 1 | F3: 1 | G3: 0 | H3: 'NA | I3: 1 | J3: 1 | K3: 1 | L3: 1 | M3: 0 | N3: 1 | O3: 1 | P3: Secondary KC Alignment: The problem only requires subtraction (450 - 215 = 235) to find how much Sarah spent. Addition is not needed since the father's 80 dollars is given after the spending occurred and is irrelevant to the question asked. Synergy: Since only subtraction is needed to solve the problem, there is no synergy between addition and subtraction knowledge components. The addition component is not utilized. Conciseness and Relevance: The information about father giving 80 dollars is irrelevant to solving the question about how much Sarah spent before receiving the extra money. This makes the problem less concise.
A4: TD | B4: Question 3 | C4: 0 | D4: 10.071184 | E4: 1 | F4: 1 | G4: 1 | H4: 1 | I4: 0 | J4: 1 | K4: 1 | L4: 1 | M4: 1 | N4: 1 | O4: 1 | P4: Topic alignment: The problem context involves sharing candies among children, which does not align with household finance topics like income, utility bills, money, interest, savings, installment, mortgage, or financial planning.
A5: TD | B5: Question 4 | C5: 0 | D5: 2.7321181 | E5: 1 | F5: 1 | G5: 1 | H5: 1 | I5: 1 | J5: 1 | K5: 1 | L5: 1 | M5: 1 | N5: 1 | O5: 1
A6: TD | B6: Question 5 | C6: 0 | D6: 10.951045 | E6: 1 | F6: 1 | G6: 1 | H6: 1 | I6: 1 | J6: 1 | K6: 0 | L6: 1 | M6: 1 | N6: 1 | O6: 1 | P6: Real-world feasibility: A parent giving away 100% of savings (276/3 = 92 per child, 92*3 = 276 total) leaving $0 remaining is unrealistic behavior as parents typically retain emergency funds.
A7: TD | B7: Question 6 | C7: 0 | D7: 6.2781928 | E7: 1 | F7: 1 | G7: 1 | H7: 0 | I7: 1 | J7: 0 | K7: 1 | L7: 1 | M7: 1 | N7: 1 | O7: 1 | P7: Synergy: The two parts (a) and (b) are independent questions that do not require using the result from part (a) to solve part (b). Part (b) can be solved directly using the given fractions 5/12 and 1/4 without needing the answer from part (a). Grade Alignment: Primary 3 students typically work with simpler fractions with smaller denominators like halves, thirds, and quarters. The fraction 5/12 and operations requiring finding common denominators with 12 are too advanced for Primary 3 level, as students at this grade have not yet mastered complex fraction operations with denominators exceeding basic unit fractions.
A8: TD | B8: Question 7 | C8: 0 | D8: 2.9518454 | E8: 1 | F8: 1 | G8: 1 | H8: 1 | I8: 1 | J8: 1 | K8: 1 | L8: 1 | M8: 1 | N8: 1 | O8: 1
A9: TD | B9: Question 8 | C9: 0 | D9: 5.549159 | E9: 1 | F9: 1 | G9: 0 | H9: 'NA | I9: 1 | J9: 1 | K9: 1 | L9: 1 | M9: 1 | N9: 1 | O9: 1 | P9: secondary_kc_alignment: Part (b) asks to round to the nearest hundred dollars, but the intended Secondary Knowledge Component specifies rounding to the nearest 10, 100 or 1000. While rounding to nearest hundred is within this range, the answer from part (a) is 57 * 12 = 684, which when rounded to nearest hundred gives 700. This rounding task is too simple for Primary 4 level as 684 clearly rounds to 700 without much complexity, not fully demonstrating the intended rounding knowledge component.
A10: TD | B10: Question 9 | C10: 0 | D10: 10.584555 | E10: 1 | F10: 1 | G10: 1 | H10: 1 | I10: 1 | J10: 1 | K10: 1 | L10: 1 | M10: 1 | N10: 1 | O10: 1
A11: TD | B11: Question 10 | C11: 0 | D11: 2.7719247 | E11: 1 | F11: 1 | G11: 1 | H11: 1 | I11: 1 | J11: 1 | K11: 1 | L11: 1 | M11: 1 | N11: 1 | O11: 1
A12: TD | B12: Question 11 | C12: 0 | D12: 8.6305315 | E12: 1 | F12: 1 | G12: 1 | H12: 1 | I12: 1 | J12: 1 | K12: 1 | L12: 1 | M12: 1 | N12: 1 | O12: 1
A13: TD | B13: Question 12 | C13: 0 | D13: 9.8959744 | E13: 1 | F13: 1 | G13: 0 | H13: 'NA | I13: 1 | J13: 1 | K13: 1 | L13: 1 | M13: 1 | N13: 1 | O13: 1 | P13: Secondary KC alignment: The answer 7 5/12 - 1 4/12 = 6 1/12 is already in simplest form, so no simplification is actually needed. Synergy: Since no simplification occurs, the primary and secondary knowledge components do not work together as intended.
A14: TD | B14: Question 13 | C14: 0 | D14: 9.9349146 | E14: 1 | F14: 1 | G14: 1 | H14: 0 | I14: 1 | J14: 1 | K14: 1 | L14: 1 | M14: 1 | N14: 1 | O14: 1 | P14: synergy: The two parts (a) and (b) are independent questions. Part (b) does not use the total amount calculated in part (a) as input. The questions lack the required connection where early question results should be used in later questions.
A15: TD | B15: Question 14 | C15: 0 | D15: 9.4533296 | E15: 1 | F15: 1 | G15: 1 | H15: 1 | I15: 1 | J15: 1 | K15: 1 | L15: 1 | M15: 1 | N15: 1 | O15: 1
A16: TD | B16: Question 15 | C16: 0 | D16: 2.756 | E16: 1 | F16: 1 | G16: 1 | H16: 1 | I16: 1 | J16: 1 | K16: 1 | L16: 1 | M16: 1 | N16: 1 | O16: 1
A17: TD | B17: Question 16 | C17: 0 | D17: 5.1542161 | E17: 1 | F17: 1 | G17: 1 | H17: 0 | I17: 1 | J17: 1 | K17: 1 | L17: 1 | M17: 1 | N17: 1 | O17: 1 | P17: The two parts (a) and (b) are independent questions that both use the same given information ($2.75 per day) but do not require each other's results. Part (a) asks for multiplication of $2.75 * 5 days, while part (b) asks to convert $2.75 to a fraction. The result from part (a) is not needed to solve part (b), so the questions are not connected in tandem as required for synergy.
A18: TD | B18: Question 17 | C18: 0 | D18: 9.7039649 | E18: 1 | F18: 1 | G18: 1 | H18: 1 | I18: 1 | J18: 1 | K18: 1 | L18: 1 | M18: 1 | N18: 1 | O18: 1
A19: TD | B19: Question 18 | C19: 0 | D19: 9.3133733 | E19: 1 | F19: 1 | G19: 1 | H19: 1 | I19: 1 | J19: 1 | K19: 1 | L19: 1 | M19: 1 | N19: 1 | O19: 1
A20: TD | B20: Question 19 | C20: 0 | D20: 6.8033786 | E20: 1 | F20: 1 | G20: 1 | H20: 1 | I20: 1 | J20: 1 | K20: 1 | L20: 1 | M20: 1 | N20: 1 | O20: 1
A21: TD | B21: Question 20 | C21: 0 | D21: 10.038023 | E21: 0 | F21: 'NA | G21: 'NA | H21: 'NA | I21: 'NA | J21: 'NA | K21: 'NA | L21: 'NA | M21: 'NA | N21: 'NA | O21: 'NA | P21: Answerability: The problem states Mrs Tan spent 1 1/4 + 2 2/3 = 3 11/12 of her budget, which is nearly 4 times her budget - this is mathematically impossible. Real-World Plausibility: It is unrealistic for someone to spend nearly 4 times their budget on just two expense categories.
A22: TD | B22: Question 21 | C22: 0 | D22: 9.5109997 | E22: 1 | F22: 1 | G22: 1 | H22: 1 | I22: 1 | J22: 1 | K22: 1 | L22: 1 | M22: 1 | N22: 1 | O22: 1
A23: TD | B23: Question 22 | C23: 0 | D23: 6.6462603 | E23: 1 | F23: 1 | G23: 1 | H23: 1 | I23: 1 | J23: 1 | K23: 0 | L23: 1 | M23: 0 | N23: 1 | O23: 1 | P23: Real-world feasibility: Adults typically receive salaries or wages, not allowances like children. Conciseness and relevance: The problem setup where 3/4 of 120 equals exactly 90 creates a trivial comparison (90 vs 90) that lacks educational value, suggesting the numbers were not optimally chosen for meaningful learning.
A24: TD | B24: Question 23 | C24: 0 | D24: 2.8456194 | E24: 1 | F24: 1 | G24: 1 | H24: 1 | I24: 1 | J24: 1 | K24: 1 | L24: 1 | M24: 1 | N24: 1 | O24: 1
A25: TD | B25: Question 24 | C25: 0 | D25: 12.330169 | E25: 1 | F25: 1 | G25: 0 | H25: 'NA | I25: 1 | J25: 1 | K25: 1 | L25: 1 | M25: 1 | N25: 1 | O25: 1 | P25: Secondary KC alignment fails because the problem requires only subtraction operations (600-400, 200-150), not addition of fractions as intended. Synergy fails because the secondary KC (adding fractions) is not actually needed to solve the problem, so primary and secondary KCs are not used in tandem.
A26: TD | B26: Question 25 | C26: 0 | D26: 6.7070074 | E26: 1 | F26: 1 | G26: 0 | H26: 'NA | I26: 1 | J26: 1 | K26: 1 | L26: 1 | M26: 1 | N26: 1 | O26: 1 | P26: Secondary KC Alignment: The problem asks for answer in simplest form but the final answer 150 is already a whole number, so no actual simplification of fractions is required. Synergy: Since no fraction simplification is actually needed, the primary and secondary knowledge components are not used in tandem - only fraction multiplication is required to solve the problem.
A27: TD | B27: Question 26 | C27: 0 | D27: 3.8690052 | E27: 1 | F27: 1 | G27: 1 | H27: 1 | I27: 0 | J27: 1 | K27: 1 | L27: 1 | M27: 1 | N27: 1 | O27: 1 | P27: Topic Alignment: The problem is about buying and consuming fruit juice at a family gathering, which belongs to food/consumption context rather than household finance topics like income, utility bills, money, interest, savings, instalment, mortgage, or financial planning.
A28: TD | B28: Question 27 | C28: 0 | D28: 11.717184 | E28: 0 | F28: 'NA | G28: 'NA | H28: 'NA | I28: 'NA | J28: 'NA | K28: 'NA | L28: 'NA | M28: 'NA | N28: 'NA | O28: 'NA | P28: Answerability: The problem contains conflicting information - Mrs Tan cannot spend 7/4 + 5/3 = 21/12 + 20/12 = 41/12 = 342% of her savings when she only has 100% available. Real-world feasibility: It is unrealistic for someone to spend 342% of their monthly savings while the problem describes dividing savings into two parts.
A29: TD | B29: Question 28 | C29: 0 | D29: 13.229451 | E29: 1 | F29: 1 | G29: 1 | H29: 1 | I29: 1 | J29: 1 | K29: 0 | L29: 1 | M29: 1 | N29: 1 | O29: 1 | P29: Real-world plausibility issue: 6/5 of brush money being used means 120% was actually spent, which exceeds the original brush allocation and contradicts the budget constraint setup.
A30: TD | B30: Question 29 | C30: 0 | D30: 10.358027 | E30: 1 | F30: 1 | G30: 1 | H30: 1 | I30: 0 | J30: 1 | K30: 1 | L30: 1 | M30: 1 | N30: 1 | O30: 1 | P30: Topic alignment: The problem focuses on ingredient calculation for baking rather than household finance topics like income, utility bills, savings, interest, mortgage, or financial planning.
A31: TD | B31: Question 30 | C31: 0 | D31: 11.880476 | E31: 1 | F31: 1 | G31: 1 | H31: 0 | I31: 1 | J31: 1 | K31: 1 | L31: 1 | M31: 1 | N31: 1 | O31: 1 | P31: The two parts operate independently - part (a) uses decimal multiplication while part (b) uses decimal-to-fraction conversion, but neither result is needed to solve the other part. The questions are not connected in a way that requires using the result of one part as input for the other part.
A32: TD | B32: Question 31 | C32: 0 | D32: 7.6546407 | E32: 0 | F32: 'NA | G32: 'NA | H32: 'NA | I32: 'NA | J32: 'NA | K32: 'NA | L32: 'NA | M32: 'NA | N32: 'NA | O32: 'NA | P32: Answerability: The problem contains contradictory information - it states Mr Lim needs to subtract the service fee from his cost calculation, but then asks for the amount including the service fee, making it unclear what the actual question is asking. Primary KC Alignment: The problem requires multiplying 73.245 by 0.15, which involves multiplying decimals by decimals, not by 10, 100, 1000 or their multiples as specified in the intended primary knowledge component. Secondary KC Alignment: The problem involves adding a service fee rather than subtracting decimals as specified in the intended secondary knowledge component. Synergy: Since neither the primary nor secondary knowledge components are properly aligned, they cannot work in tandem as required. Real-world feasibility: The scenario is unrealistic - service fees are typically added to electricity bills, not subtracted from cost calculations as described. Clarity: The problem statement is confusing about whether to subtract or add the service fee, creating ambiguity in what is being asked.
A33: TD | B33: Question 32 | C33: 0 | D33: 2.697648 | E33: 1 | F33: 1 | G33: 1 | H33: 1 | I33: 1 | J33: 1 | K33: 1 | L33: 1 | M33: 1 | N33: 1 | O33: 1
A34: TD | B34: Question 33 | C34: 0 | D34: 12.739278 | E34: 0 | F34: 'NA | G34: 'NA | H34: 'NA | I34: 'NA | J34: 'NA | K34: 'NA | L34: 'NA | M34: 'NA | N34: 'NA | O34: 'NA | P34: Answerability: Problem states Mrs Lim splits 27.650 equally among 10 grandchildren but then refers to her own share from original jar - if she gave everything to grandchildren she has no share, creating logical contradiction. Primary KC Alignment: Due to ambiguity, unclear whether division should be 27.650/10 or 27.650/11, making primary knowledge component application uncertain. Synergy: Ambiguity prevents proper connection between division and addition steps. Clarity: Critical ambiguity about whether Mrs Lim is included in the equal split makes problem unclear.
A35: TD | B35: Question 34 | C35: 0 | D35: 11.122808 | E35: 1 | F35: 1 | G35: 0 | H35: 'NA | I35: 1 | J35: 1 | K35: 1 | L35: 1 | M35: 1 | N35: 1 | O35: 1 | P35: Secondary KC alignment fails because the problem requires decimal multiplication (800 x 0.15) rather than whole number multiplication as specified in the intended Secondary Knowledge Component.
A36: TD | B36: Question 35 | C36: 0 | D36: 2.748059 | E36: 1 | F36: 1 | G36: 1 | H36: 1 | I36: 1 | J36: 1 | K36: 1 | L36: 1 | M36: 1 | N36: 1 | O36: 1
A37: TD | B37: Question 36 | C37: 0 | D37: 9.1709218 | E37: 1 | F37: 1 | G37: 1 | H37: 1 | I37: 1 | J37: 1 | K37: 1 | L37: 1 | M37: 1 | N37: 1 | O37: 1
A38: TD | B38: Question 37 | C38: 0 | D38: 11.283223 | E38: 1 | F38: 0 | G38: 1 | H38: 'NA | I38: 1 | J38: 'NA | K38: 1 | L38: 1 | M38: 1 | N38: 1 | O38: 1 | P38: Primary KC alignment: Problem requires dividing $9 by 4 weeks, not dividing a proper fraction by a whole number. Synergy: The two knowledge components are used in separate parts rather than working together in tandem.
A39: TD | B39: Question 38 | C39: 0 | D39: 3.5471656 | E39: 1 | F39: 1 | G39: 1 | H39: 1 | I39: 0 | J39: 1 | K39: 1 | L39: 1 | M39: 1 | N39: 1 | O39: 1 | P39: Topic Alignment: The problem context involves baking cookies for a school fundraiser, which belongs to education/school activities rather than household finance topics like income, utility bills, money, interest, savings, installment, mortgage, or financial planning.
A40: TD | B40: Question 39 | C40: 0 | D40: 15.164603 | E40: 0 | F40: 'NA | G40: 'NA | H40: 'NA | I40: 'NA | J40: 'NA | K40: 'NA | L40: 'NA | M40: 'NA | N40: 'NA | O40: 'NA | P40: Answerability: Problem has logical conflict - cannot pay 2 months of $90 bills with only $120. Secondary KC: Problem requires subtracting whole numbers, not fractions as intended. Synergy: Questions are independent, first answer not used in second question. Real-world feasibility: Unrealistic to plan paying 2 months when only having enough for 1.33 months. Clarity: Contradictory questions create confusion about problem intent.
...

Sheet householdfinance_v2_9
A1: Evaluator | B1: Question | C1: status | D1: response_time | E1: answerability | F1: primary_kc_alignment | G1: secondary_kc_alignment | H1: synergy | I1: topic_alignment | J1: grade_alignment | K1: real_world_feasibility | L1: clarity | M1: conciseness_and_relevance | N1: language_quality | O1: content_appropriateness | P1: explanation
A2: TD | B2: Question 1 | C2: 0 | D2: 2.7407186 | E2: 1 | F2: 1 | G2: 1 | H2: 1 | I2: 1 | J2: 1 | K2: 1 | L2: 1 | M2: 1 | N2: 1 | O2: 1
A3: TD | B3: Question 2 | C3: 0 | D3: 7.7022882 | E3: 1 | F3: 1 | G3: 0 | H3: 'NA | I3: 1 | J3: 1 | K3: 1 | L3: 1 | M3: 0 | N3: 1 | O3: 1 | P3: Secondary KC Alignment: Problem only requires subtraction (450 - 215 = 235). The intended secondary knowledge component of addition is not needed to solve the problem. Synergy: Since addition is not required, there is no synergy between primary subtraction KC and secondary addition KC. The problem can be solved using only subtraction. Conciseness and Relevance: The $80 given by father is irrelevant information that is not needed to solve the problem, violating the requirement that all given numbers must be necessary.
A4: TD | B4: Question 3 | C4: 0 | D4: 11.642371 | E4: 1 | F4: 1 | G4: 1 | H4: 1 | I4: 0 | J4: 1 | K4: 1 | L4: 1 | M4: 1 | N4: 1 | O4: 1 | P4: Topic alignment fails: The problem context is about sharing candies in a family setting, which relates to food/family activities rather than household finance topics like income, utility bills, money management, savings, installment, mortgage, or financial planning.
A5: TD | B5: Question 4 | C5: 0 | D5: 9.5465512 | E5: 1 | F5: 1 | G5: 1 | H5: 1 | I5: 1 | J5: 1 | K5: 1 | L5: 1 | M5: 1 | N5: 1 | O5: 1
A6: TD | B6: Question 5 | C6: 0 | D6: 2.7545986 | E6: 1 | F6: 1 | G6: 1 | H6: 1 | I6: 1 | J6: 1 | K6: 1 | L6: 1 | M6: 1 | N6: 1 | O6: 1
A7: TD | B7: Question 6 | C7: 0 | D7: 6.7824647 | E7: 1 | F7: 1 | G7: 1 | H7: 0 | I7: 1 | J7: 0 | K7: 1 | L7: 1 | M7: 1 | N7: 1 | O7: 1 | P7: Synergy: The two parts (a) and (b) are independent questions that do not require using results from one part to solve the other part. Part (a) involves fraction subtraction and part (b) involves fraction comparison, but they operate on the same given fractions without connection between the solutions. Grade Alignment: The problem involves fractions with denominators 12 and 4, requiring finding common denominators and performing operations like 5/12 - 1/4 = 5/12 - 3/12 = 2/12 = 1/6. This level of fraction manipulation with multiple denominators and simplification typically exceeds Primary 3 level, where students usually work with simpler fractions and basic concepts.
A8: TD | B8: Question 7 | C8: 0 | D8: 2.704792 | E8: 1 | F8: 1 | G8: 1 | H8: 1 | I8: 1 | J8: 1 | K8: 1 | L8: 1 | M8: 1 | N8: 1 | O8: 1
