Workbook

Sheet services_v8_v1_split_1
A1: Evaluator | B1: Question | C1: status | D1: answerability | E1: primary_kc_alignment | F1: secondary_kc_alignment | G1: topic_alignment | H1: grade_alignment | I1: real_world_feasibility | J1: synergy | K1: clarity | L1: conciseness_and_relevance | M1: language_quality | N1: content_appropriateness | O1: explanation | P1: response_time | Q1: language_quality1
A2: TD | B2: Question 1 | C2: 0 | D2: 1 | E2: 1 | F2: 1 | G2: 1 | H2: 1 | I2: 1 | J2: 1 | K2: 1 | L2: 1 | M2: 1 | N2: 1 | P2: 1.7294452
A3: TD | B3: Question 2 | C3: 0 | D3: 1 | E3: 1 | F3: 1 | G3: 1 | H3: 1 | I3: 1 | J3: 1 | K3: 1 | L3: 1 | M3: 1 | N3: 1 | P3: 1.1833944
A4: TD | B4: Question 3 | C4: 0 | D4: 1 | E4: 1 | F4: 1 | G4: 1 | H4: 1 | I4: 1 | J4: 1 | K4: 1 | L4: 1 | M4: 1 | N4: 1 | P4: 1.6417899
A5: TD | B5: Question 4 | C5: 0 | D5: 1 | E5: 1 | F5: 1 | G5: 1 | H5: 1 | I5: 1 | J5: 1 | K5: 1 | L5: 1 | M5: 1 | N5: 1 | P5: 1.3574936
A6: TD | B6: Question 5 | C6: 0 | D6: 1 | E6: 1 | F6: 1 | G6: 1 | H6: 1 | I6: 1 | J6: 1 | K6: 1 | L6: 1 | M6: 1 | N6: 1 | P6: 1.5421603
A7: TD | B7: Question 6 | C7: 0 | D7: 1 | E7: 1 | F7: 1 | G7: 1 | H7: 1 | I7: 1 | J7: 1 | K7: 1 | L7: 1 | M7: 1 | N7: 1 | P7: 1.0707474
A8: TD | B8: Question 7 | C8: 0 | D8: 1 | E8: 1 | F8: 1 | G8: 1 | H8: 1 | I8: 1 | J8: 1 | K8: 1 | L8: 1 | M8: 1 | N8: 1 | P8: 1.1521637
A9: TD | B9: Question 8 | C9: 0 | D9: 1 | E9: 1 | F9: 1 | G9: 1 | H9: 1 | I9: 1 | J9: 1 | K9: 1 | L9: 1 | M9: 1 | N9: 1 | P9: 1.2082791
A10: TD | B10: Question 9 | C10: 0 | D10: 1 | E10: 1 | F10: 1 | G10: 1 | H10: 1 | I10: 1 | J10: 1 | K10: 1 | L10: 1 | M10: 1 | N10: 1 | P10: 1.5106106
A11: TD | B11: Question 10 | C11: 0 | D11: 1 | E11: 1 | F11: 1 | G11: 1 | H11: 1 | I11: 1 | J11: 1 | K11: 1 | L11: 1 | M11: 1 | N11: 1 | P11: 1.0836513
A12: TD | B12: Question 11 | C12: 0 | D12: 1 | E12: 1 | F12: 1 | G12: 1 | H12: 1 | I12: 1 | J12: 1 | K12: 1 | L12: 1 | M12: 1 | N12: 1 | P12: 1.161694
A13: TD | B13: Question 12 | C13: 0 | D13: 1 | E13: 0 | F13: 1 | G13: 1 | H13: 'NA | I13: 1 | J13: 'NA | K13: 1 | L13: 1 | M13: 1 | N13: 1 | O13: primary_kc_alignment: The problem asks for a comparison (ratio/fraction) between two amounts, not for subtracting unlike fractions as required by the primary KC. synergy: Solving the problem does not require both subtracting unlike fractions and simplifying a fraction; only simplification is necessary. | P13: 15.936013
A14: TD | B14: Question 13 | C14: 0 | D14: 1 | E14: 1 | F14: 1 | G14: 1 | H14: 1 | I14: 1 | J14: 1 | K14: 1 | L14: 1 | M14: 1 | N14: 1 | P14: 1.2003603
A15: TD | B15: Question 14 | C15: 0 | D15: 1 | E15: 1 | F15: 1 | G15: 1 | H15: 1 | I15: 1 | J15: 1 | K15: 1 | L15: 1 | M15: 1 | N15: 1 | P15: 1.106673
A16: TD | B16: Question 15 | C16: 0 | D16: 1 | E16: 1 | F16: 1 | G16: 1 | H16: 1 | I16: 1 | J16: 1 | K16: 1 | L16: 1 | M16: 1 | N16: 1 | P16: 1.5923073
A17: TD | B17: Question 16 | C17: 0 | D17: 1 | E17: 1 | F17: 1 | G17: 1 | H17: 1 | I17: 1 | J17: 1 | K17: 1 | L17: 1 | M17: 1 | N17: 1 | P17: 1.1827509
A18: TD | B18: Question 17 | C18: 0 | D18: 1 | E18: 1 | F18: 1 | G18: 1 | H18: 1 | I18: 1 | J18: 1 | K18: 1 | L18: 1 | M18: 1 | N18: 1 | P18: 1.7943628
A19: TD | B19: Question 18 | C19: 0 | D19: 1 | E19: 0 | F19: 1 | G19: 1 | H19: 'NA | I19: 1 | J19: 'NA | K19: 1 | L19: 1 | M19: 1 | N19: 1 | O19: Primary KC: The question requires dividing $38.75 by 5 for (a), but the quotient is $7.75, which involves dividing a decimal with two decimal places by a 1-digit number. However, part (b) compares a 3-decimal place number ($9.725) with a 2-decimal place number ($7.75), and while comparison/alignment works, using $9.725 as a price per room is unrealistic for Singapore currency and exceeds the P4 syllabus, which only expects students to work with decimals up to 2 decimal places. Grade Alignment: The use of $9.725 is outside the Primary 4 MOE curriculum, which restricts decimal work to 2 d.p. for both calculation and comparison, making it unsuitable for P4 students. | P19: 4.4835992
A20: TD | B20: Question 19 | C20: 0 | D20: 1 | E20: 1 | F20: 1 | G20: 1 | H20: 1 | I20: 1 | J20: 1 | K20: 1 | L20: 1 | M20: 1 | N20: 1 | P20: 1.556649
A21: TD | B21: Question 20 | C21: 0 | D21: 1 | E21: 1 | F21: 1 | G21: 1 | H21: 1 | I21: 1 | J21: 1 | K21: 1 | L21: 1 | M21: 1 | N21: 1 | P21: 1.3002613
A22: TD | B22: Question 21 | C22: 0 | D22: 1 | E22: 1 | F22: 1 | G22: 1 | H22: 1 | I22: 1 | J22: 0 | K22: 1 | L22: 1 | M22: 1 | N22: 1 | O22: 7. The two parts of the word problem ((a) subtraction, (b) comparison/ordering) are independent and do not require results to be used across parts. Each part can be solved separately, so there is no synergy between the knowledge components. | P22: 3.5205433
A23: TD | B23: Question 22 | C23: 0 | D23: 1 | E23: 1 | F23: 0 | G23: 1 | H23: 1 | I23: 1 | J23: 'NA | K23: 1 | L23: 1 | M23: 1 | N23: 1 | O23: 3. The secondary KC specified is 'FRACTIONS | Comparison and ordering | comparing and ordering fractions', but the comparison in part (b) is between a whole number and a fraction of that whole number, not between two fractions or ordering of multiple fractions. 7. The two parts of the question do not require the combined use of both Primary and Secondary KCs to solve. Part (a) is just multiplying a fraction by a whole, and part (b) simply repeats the calculation and subtracts absolute numbers, not using comparison/ordering of fractions. | P23: 2.4759388
A24: TD | B24: Question 23 | C24: 0 | D24: 1 | E24: 1 | F24: 1 | G24: 1 | H24: 1 | I24: 1 | J24: 1 | K24: 1 | L24: 1 | M24: 1 | N24: 1 | P24: 1.366713
A25: TD | B25: Question 24 | C25: 0 | D25: 1 | E25: 1 | F25: 1 | G25: 1 | H25: 1 | I25: 1 | J25: 1 | K25: 1 | L25: 1 | M25: 1 | N25: 1 | P25: 1.2464883
A26: TD | B26: Question 25 | C26: 0 | D26: 1 | E26: 1 | F26: 1 | G26: 1 | H26: 1 | I26: 1 | J26: 1 | K26: 1 | L26: 1 | M26: 1 | N26: 1 | P26: 1.8140666
A27: TD | B27: Question 26 | C27: 0 | D27: 1 | E27: 0 | F27: 1 | G27: 1 | H27: 'NA | I27: 1 | J27: 'NA | K27: 1 | L27: 1 | M27: 1 | N27: 1 | O27: Primary KC Alignment (0): The word problem requires multiplying an improper fraction ($[FORMULA]$) by a whole number (3), which does not involve multiplying two improper fractions as specified by the intended primary knowledge component. It only requires the multiplication of a fraction by a whole number, which is a different—and simpler—skill. | P27: 3.2918026
A28: TD | B28: Question 27 | C28: 0 | D28: 1 | E28: 1 | F28: 1 | G28: 1 | H28: 1 | I28: 1 | J28: 1 | K28: 1 | L28: 1 | M28: 1 | N28: 1 | P28: 1.4767232
A29: TD | B29: Question 28 | C29: 0 | D29: 1 | E29: 1 | F29: 1 | G29: 1 | H29: 1 | I29: 1 | J29: 1 | K29: 1 | L29: 1 | M29: 1 | N29: 1 | P29: 1.3438215
A30: TD | B30: Question 29 | C30: 0 | D30: 1 | E30: 1 | F30: 1 | G30: 1 | H30: 1 | I30: 1 | J30: 1 | K30: 1 | L30: 1 | M30: 1 | N30: 1 | P30: 1.795882
A31: TD | B31: Question 30 | C31: 0 | D31: 1 | E31: 0 | F31: 1 | G31: 1 | H31: 'NA | I31: 1 | J31: 'NA | K31: 1 | L31: 1 | M31: 1 | N31: 1 | O31: Primary KC Alignment: The calculation required is $3.75 [FORMULA] 12$ (multiplying a decimal by a whole number), not multiplying a decimal by 10, 100, 1000 or their multiples as specified in the intended Primary Knowledge Component. Therefore, the main calculation does not require this specific KC, so it does not fully satisfy Primary KC Alignment. | P31: 2.5092857
A32: TD | B32: Question 31 | C32: 0 | D32: 1 | E32: 0 | F32: 1 | G32: 1 | H32: 'NA | I32: 1 | J32: 'NA | K32: 1 | L32: 1 | M32: 1 | N32: 1 | O32: B2: The intended primary KC specifies 'multiplying decimals (up to 3 decimal places) by 10, 100, 1000 and their multiples'. However, the multiplication needed is 3.850 [FORMULA] 140 and 3.850 [FORMULA] 1.4, which is not using 10, 100, 1000 or their multiples directly but multiplying by arbitrary numbers (140 and 1.4). This does not strictly target the intended KC. | P32: 2.2778325
A33: TD | B33: Question 32 | C33: 0 | D33: 1 | E33: 1 | F33: 1 | G33: 1 | H33: 1 | I33: 1 | J33: 1 | K33: 1 | L33: 1 | M33: 1 | N33: 1 | P33: 1.8629761
A34: TD | B34: Question 33 | C34: 0 | D34: 1 | E34: 0 | F34: 1 | G34: 1 | H34: 'NA | I34: 1 | J34: 'NA | K34: 1 | L34: 1 | M34: 1 | N34: 1 | O34: primary_kc_alignment: The division in the problem involves $12.500 [FORMULA] 1000$ (where $12.500$ appears to be a formatting error for $12,500$, but for decimals, $12.500$ should mean $12.50$ or $12.500$, which is typically Primary 6 material; Primary 5 typically does not use values beyond 2 decimal places. Additionally, dividing by 1000, while valid, is not the central focus here as the cost per square metre is not presented in a way that emphasizes the learning objective (dividing decimals up to 3 decimal places by 10, 100, or 1000). grade_alignment: The inclusion of a three-decimal place value ($12.500$) is uncommon for Primary 5, and cost division across such a value is not grade-appropriate as expected in Singapore's syllabus at this level. | P34: 4.6130879
A35: TD | B35: Question 34 | C35: 0 | D35: 1 | E35: 1 | F35: 1 | G35: 1 | H35: 1 | I35: 1 | J35: 1 | K35: 1 | L35: 1 | M35: 1 | N35: 1 | P35: 1.3212917
A36: TD | B36: Question 35 | C36: 0 | D36: 1 | E36: 1 | F36: 1 | G36: 1 | H36: 1 | I36: 1 | J36: 1 | K36: 1 | L36: 1 | M36: 1 | N36: 1 | P36: 1.4192681
A37: TD | B37: Question 36 | C37: 0 | D37: 1 | E37: 1 | F37: 1 | G37: 1 | H37: 1 | I37: 1 | J37: 1 | K37: 1 | L37: 1 | M37: 1 | N37: 1 | P37: 1.2292421
A38: TD | B38: Question 37 | C38: 0 | D38: 1 | E38: 0 | F38: 0 | G38: 1 | H38: 'NA | I38: 1 | J38: 'NA | K38: 1 | L38: 1 | M38: 1 | N38: 1 | O38: Primary KC Alignment: The main calculation in (a) requires dividing a fraction by a fraction (3/4 ÷ 1/8), not dividing a fraction by a whole number as required by the Primary KC. Secondary KC Alignment: The solution to (b) asks for summing the number of loads (i.e., whole numbers), not adding fractions. Thus, the intended secondary KC of adding fractions is not aligned. | P38: 2.6250014
A39: TD | B39: Question 38 | C39: 0 | D39: 1 | E39: 1 | F39: 1 | G39: 1 | H39: 1 | I39: 1 | J39: 1 | K39: 1 | L39: 1 | M39: 1 | N39: 1 | P39: 1.8294985
A40: TD | B40: Question 39 | C40: 0 | D40: 1 | E40: 1 | F40: 1 | G40: 1 | H40: 1 | I40: 1 | J40: 1 | K40: 1 | L40: 1 | M40: 1 | N40: 1 | P40: 1.2209606
...

Sheet services_v8_v1_split_2
A1: Evaluator | B1: Question | C1: status | D1: answerability | E1: primary_kc_alignment | F1: secondary_kc_alignment | G1: topic_alignment | H1: grade_alignment | I1: real_world_feasibility | J1: synergy | K1: clarity | L1: conciseness_and_relevance | M1: language_quality | N1: content_appropriateness | O1: explanation | P1: response_time | Q1: language_quality1
A2: TD | B2: Question 1 | C2: 0 | D2: 1 | E2: 1 | F2: 1 | G2: 1 | H2: 1 | I2: 1 | J2: 1 | K2: 1 | L2: 1 | M2: 1 | N2: 1 | P2: 1.6861002
A3: TD | B3: Question 2 | C3: 0 | D3: 1 | E3: 1 | F3: 1 | G3: 1 | H3: 1 | I3: 1 | J3: 1 | K3: 1 | L3: 1 | M3: 1 | N3: 1 | P3: 1.2542369
A4: TD | B4: Question 3 | C4: 0 | D4: 1 | E4: 1 | F4: 1 | G4: 1 | H4: 1 | I4: 1 | J4: 1 | K4: 1 | L4: 1 | M4: 1 | N4: 1 | P4: 1.2422731
A5: TD | B5: Question 4 | C5: 0 | D5: 1 | E5: 1 | F5: 1 | G5: 1 | H5: 1 | I5: 1 | J5: 1 | K5: 1 | L5: 1 | M5: 1 | N5: 1 | P5: 1.3139629
A6: TD | B6: Question 5 | C6: 0 | D6: 1 | E6: 1 | F6: 1 | G6: 1 | H6: 1 | I6: 1 | J6: 1 | K6: 1 | L6: 1 | M6: 1 | N6: 1 | P6: 1.2585614
A7: TD | B7: Question 6 | C7: 0 | D7: 1 | E7: 1 | F7: 1 | G7: 1 | H7: 1 | I7: 1 | J7: 1 | K7: 1 | L7: 1 | M7: 1 | N7: 1 | P7: 2.8658195
A8: TD | B8: Question 7 | C8: 0 | D8: 1 | E8: 1 | F8: 1 | G8: 1 | H8: 1 | I8: 1 | J8: 1 | K8: 1 | L8: 1 | M8: 1 | N8: 1 | P8: 1.501395
A9: TD | B9: Question 8 | C9: 0 | D9: 1 | E9: 1 | F9: 1 | G9: 1 | H9: 1 | I9: 1 | J9: 1 | K9: 1 | L9: 1 | M9: 1 | N9: 1 | P9: 1.7782958
A10: TD | B10: Question 9 | C10: 0 | D10: 1 | E10: 1 | F10: 1 | G10: 1 | H10: 1 | I10: 1 | J10: 1 | K10: 1 | L10: 1 | M10: 1 | N10: 1 | P10: 2.6582363
A11: TD | B11: Question 10 | C11: 0 | D11: 1 | E11: 1 | F11: 1 | G11: 1 | H11: 1 | I11: 1 | J11: 1 | K11: 1 | L11: 1 | M11: 1 | N11: 1 | P11: 1.8057995
A12: TD | B12: Question 11 | C12: 0 | D12: 1 | E12: 1 | F12: 1 | G12: 1 | H12: 1 | I12: 1 | J12: 1 | K12: 1 | L12: 1 | M12: 1 | N12: 1 | P12: 1.3955023
A13: TD | B13: Question 12 | C13: 0 | D13: 1 | E13: 0 | F13: 1 | G13: 1 | H13: 'NA | I13: 1 | J13: 'NA | K13: 1 | L13: 1 | M13: 1 | N13: 1 | O13: Primary KC Alignment: The problem asks for a comparison (as a fraction) of streaming service to cleaning supplies, which mathematically means forming the ratio (division) of the two fractions, not subtraction. Thus, it does not require subtracting unlike fractions, so intended Primary KC is not met. Synergy: The components needed to solve the question are division and then simplification, but since subtraction is not necessary, the intended synergy between subtraction and simplification is missing. | P13: 3.240299
A14: TD | B14: Question 13 | C14: 0 | D14: 1 | E14: 1 | F14: 1 | G14: 1 | H14: 1 | I14: 1 | J14: 1 | K14: 1 | L14: 1 | M14: 1 | N14: 1 | P14: 2.4666107
A15: TD | B15: Question 14 | C15: 0 | D15: 1 | E15: 1 | F15: 1 | G15: 1 | H15: 1 | I15: 1 | J15: 1 | K15: 1 | L15: 1 | M15: 1 | N15: 1 | P15: 1.2102401
A16: TD | B16: Question 15 | C16: 0 | D16: 1 | E16: 1 | F16: 1 | G16: 1 | H16: 1 | I16: 1 | J16: 1 | K16: 1 | L16: 1 | M16: 1 | N16: 1 | P16: 1.3226342
A17: TD | B17: Question 16 | C17: 0 | D17: 1 | E17: 1 | F17: 1 | G17: 1 | H17: 1 | I17: 1 | J17: 1 | K17: 1 | L17: 1 | M17: 1 | N17: 1 | P17: 1.5769408
A18: TD | B18: Question 17 | C18: 0 | D18: 1 | E18: 1 | F18: 1 | G18: 1 | H18: 1 | I18: 1 | J18: 1 | K18: 1 | L18: 1 | M18: 1 | N18: 1 | P18: 1.7207723
A19: TD | B19: Question 18 | C19: 0 | D19: 1 | E19: 0 | F19: 1 | G19: 1 | H19: 'NA | I19: 1 | J19: 'NA | K19: 1 | L19: 1 | M19: 1 | N19: 1 | O19: Primary KC Alignment: The intended division should be 'dividing decimals (up to 2 decimal places) by a 1-digit whole number', but $38.75 [FORMULA] 5$ involves a decimal with 2 decimal places by a 1-digit whole number, which fits; however, in part (b), comparison involves 3 decimal places ($9.725$), not 2, which means Primary KC is not the sole focus. Grade Alignment: Primary 4 students in Singapore typically are not expected to work with or compare decimals up to 3 decimal places ($9.725$) at this level. This is likely expected at a higher grade. | P19: 2.7095566
A20: TD | B20: Question 19 | C20: 0 | D20: 1 | E20: 1 | F20: 1 | G20: 1 | H20: 1 | I20: 1 | J20: 1 | K20: 1 | L20: 1 | M20: 1 | N20: 1 | P20: 1.5042558
A21: TD | B21: Question 20 | C21: 0 | D21: 1 | E21: 1 | F21: 1 | G21: 1 | H21: 1 | I21: 1 | J21: 1 | K21: 1 | L21: 1 | M21: 1 | N21: 1 | P21: 1.1493943
A22: TD | B22: Question 21 | C22: 0 | D22: 1 | E22: 1 | F22: 1 | G22: 1 | H22: 1 | I22: 1 | J22: 1 | K22: 1 | L22: 1 | M22: 1 | N22: 1 | P22: 1.7887921
A23: TD | B23: Question 22 | C23: 0 | D23: 1 | E23: 1 | F23: 1 | G23: 1 | H23: 1 | I23: 1 | J23: 1 | K23: 1 | L23: 1 | M23: 1 | N23: 1 | P23: 1.812434
A24: TD | B24: Question 23 | C24: 0 | D24: 1 | E24: 1 | F24: 1 | G24: 1 | H24: 1 | I24: 1 | J24: 1 | K24: 1 | L24: 1 | M24: 1 | N24: 1 | P24: 2.46455
A25: TD | B25: Question 24 | C25: 0 | D25: 1 | E25: 1 | F25: 1 | G25: 1 | H25: 1 | I25: 1 | J25: 1 | K25: 1 | L25: 1 | M25: 1 | N25: 1 | P25: 1.4776635
A26: TD | B26: Question 25 | C26: 0 | D26: 1 | E26: 1 | F26: 1 | G26: 1 | H26: 1 | I26: 1 | J26: 1 | K26: 1 | L26: 1 | M26: 1 | N26: 1 | P26: 1.2422709
A27: TD | B27: Question 26 | C27: 0 | D27: 1 | E27: 0 | F27: 1 | G27: 1 | H27: 'NA | I27: 1 | J27: 'NA | K27: 1 | L27: 1 | M27: 1 | N27: 1 | O27: Primary KC Alignment: The intended primary KC is 'multiplying two improper fractions', but the word problem only requires multiplying an improper fraction by a whole number (3), not another improper fraction. The scenario never asks the student to multiply two improper fractions as required by the primary KC. | P27: 2.8525422
A28: TD | B28: Question 27 | C28: 0 | D28: 1 | E28: 1 | F28: 0 | G28: 1 | H28: 1 | I28: 1 | J28: 'NA | K28: 1 | L28: 1 | M28: 1 | N28: 1 | O28: Secondary KC Alignment: The question asks 'How many loads are not sent for ironing?' This requires subtracting the number of loads sent for ironing from the total. However, since $[FORMULA]$ of the total are sent for ironing, the remaining not sent is simply $1-[FORMULA]=[FORMULA]$ of the total. This is multiplicative rather than a distinct subtraction of fractions step. Thus, the secondary KC (subtracting fractions) is not strictly necessary as the subtraction is trivial and embedded in the context. Synergy: The steps do not require the results of one component to be used directly in the second in a way that demonstrates true synergy; instead, the procedure is a sequence of two independent calculations. | P28: 3.8100648
A29: TD | B29: Question 28 | C29: 0 | D29: 1 | E29: 1 | F29: 1 | G29: 1 | H29: 1 | I29: 1 | J29: 1 | K29: 1 | L29: 1 | M29: 1 | N29: 1 | P29: 2.1237674
A30: TD | B30: Question 29 | C30: 0 | D30: 1 | E30: 1 | F30: 1 | G30: 1 | H30: 1 | I30: 1 | J30: 1 | K30: 1 | L30: 1 | M30: 1 | N30: 1 | P30: 1.2770839
A31: TD | B31: Question 30 | C31: 0 | D31: 1 | E31: 0 | F31: 1 | G31: 1 | H31: 'NA | I31: 1 | J31: 'NA | K31: 1 | L31: 1 | M31: 1 | N31: 1 | O31: Primary KC Alignment: The multiplication required in part (a) is $3.75 [FORMULA] 12$, which is multiplying a decimal by a whole number. However, the Intended Primary Knowledge Component specifies multiplying decimals by 10, 100, 1000 and their multiples, not by a general whole number. Thus, this problem does not strictly require the targeted multiplication type. | P31: 2.2203612
A32: TD | B32: Question 31 | C32: 0 | D32: 1 | E32: 0 | F32: 1 | G32: 1 | H32: 'NA | I32: 1 | J32: 'NA | K32: 1 | L32: 1 | M32: 1 | N32: 1 | O32: Primary KC Alignment: The question requires multiplication of decimals up to 3 decimal places (3.850 × area), but the context does NOT require multiplying by 10, 100, 1000 or their multiples as explicitly stated in the intended KC. The multiplication here is by 140 and 138.6 (whole numbers/decimals), not multiples of 10/100/1000. | P32: 2.864079
A33: TD | B33: Question 32 | C33: 0 | D33: 1 | E33: 1 | F33: 1 | G33: 1 | H33: 1 | I33: 1 | J33: 1 | K33: 1 | L33: 1 | M33: 1 | N33: 1 | P33: 1.7734344
A34: TD | B34: Question 33 | C34: 0 | D34: 1 | E34: 0 | F34: 1 | G34: 1 | H34: 'NA | I34: 1 | J34: 'NA | K34: 1 | L34: 1 | M34: 0 | N34: 1 | O34: Primary KC Alignment: The division required here is $12.500 ÷ 1000$, which does not require handling decimals up to 3 decimal places, as the dividend is a whole number with three decimal places and the divisor is 1000. This is more about understanding place value with dividing by 10/100/1000 rather than practical division with non-trivial decimals in both numbers. Thus, the problem does not strongly require dividing decimals as intended.Language Quality: The amount [FORMULA]12.500 uses a decimal format uncommon in Singapore context—should be $12.50$ for $12 and 50 cents, not $12.500$ (which suggests three decimal places for currency, which is not standard). Also, 'service charges are divided equally among all square metres cleaned' sounds redundant after the first rate is established, and the final part (c) is repetitive with (b). | P34: 3.7795115
A35: TD | B35: Question 34 | C35: 0 | D35: 1 | E35: 1 | F35: 1 | G35: 1 | H35: 1 | I35: 1 | J35: 1 | K35: 1 | L35: 1 | M35: 1 | N35: 1 | P35: 1.1932802
A36: TD | B36: Question 35 | C36: 0 | D36: 1 | E36: 1 | F36: 1 | G36: 1 | H36: 1 | I36: 1 | J36: 1 | K36: 1 | L36: 1 | M36: 1 | N36: 1 | P36: 1.0953043
A37: TD | B37: Question 36 | C37: 0 | D37: 1 | E37: 1 | F37: 1 | G37: 1 | H37: 1 | I37: 1 | J37: 1 | K37: 1 | L37: 1 | M37: 1 | N37: 1 | P37: 1.2998397
A38: TD | B38: Question 37 | C38: 0 | D38: 1 | E38: 0 | F38: 0 | G38: 1 | H38: 'NA | I38: 1 | J38: 'NA | K38: 1 | L38: 1 | M38: 1 | N38: 1 | O38: Primary KC Alignment=0: The problem requires dividing a fraction by a fraction, not by a whole number as specified by the intended primary knowledge component (dividing a proper fraction by a whole number). / Secondary KC Alignment=0: The addition involved is of whole numbers (number of loads for two items), not the addition of fractions itself as in the intended secondary knowledge component. / Synergy=0: The two sub-questions are independent and do not require the use of the answer from (a) as input for (b); the loads for curtains and cushion covers are calculated separately and then simply tallied up. | P38: 6.6966822
A39: TD | B39: Question 38 | C39: 0 | D39: 1 | E39: 1 | F39: 1 | G39: 1 | H39: 1 | I39: 1 | J39: 1 | K39: 1 | L39: 1 | M39: 1 | N39: 1 | P39: 1.1935899
A40: TD | B40: Question 39 | C40: 0 | D40: 1 | E40: 1 | F40: 1 | G40: 1 | H40: 1 | I40: 1 | J40: 1 | K40: 1 | L40: 1 | M40: 1 | N40: 1 | P40: 2.2261558
...

Sheet services_v8_v1_split_3
A1: Evaluator | B1: Question | C1: status | D1: answerability | E1: primary_kc_alignment | F1: secondary_kc_alignment | G1: topic_alignment | H1: grade_alignment | I1: real_world_feasibility | J1: synergy | K1: clarity | L1: conciseness_and_relevance | M1: language_quality | N1: content_appropriateness | O1: explanation | P1: response_time | Q1: language_quality1
A2: TD | B2: Question 1 | C2: 0 | D2: 1 | E2: 1 | F2: 1 | G2: 1 | H2: 1 | I2: 1 | J2: 1 | K2: 1 | L2: 1 | M2: 1 | N2: 1 | P2: 1.4358344
A3: TD | B3: Question 2 | C3: 0 | D3: 1 | E3: 1 | F3: 1 | G3: 1 | H3: 1 | I3: 1 | J3: 1 | K3: 1 | L3: 1 | M3: 1 | N3: 1 | P3: 1.2256327
A4: TD | B4: Question 3 | C4: 0 | D4: 1 | E4: 1 | F4: 1 | G4: 1 | H4: 1 | I4: 1 | J4: 1 | K4: 1 | L4: 1 | M4: 1 | N4: 1 | P4: 3.7735586
A5: TD | B5: Question 4 | C5: 0 | D5: 1 | E5: 1 | F5: 1 | G5: 1 | H5: 1 | I5: 1 | J5: 1 | K5: 1 | L5: 1 | M5: 1 | N5: 1 | P5: 1.3616157
A6: TD | B6: Question 5 | C6: 0 | D6: 1 | E6: 1 | F6: 1 | G6: 1 | H6: 1 | I6: 1 | J6: 1 | K6: 1 | L6: 1 | M6: 1 | N6: 1 | P6: 1.5372276
A7: TD | B7: Question 6 | C7: 0 | D7: 1 | E7: 1 | F7: 1 | G7: 1 | H7: 1 | I7: 1 | J7: 1 | K7: 1 | L7: 1 | M7: 1 | N7: 1 | P7: 1.2145395
A8: TD | B8: Question 7 | C8: 0 | D8: 1 | E8: 1 | F8: 1 | G8: 1 | H8: 1 | I8: 1 | J8: 1 | K8: 1 | L8: 1 | M8: 1 | N8: 1 | P8: 1.2895463
A9: TD | B9: Question 8 | C9: 0 | D9: 1 | E9: 1 | F9: 1 | G9: 1 | H9: 1 | I9: 1 | J9: 1 | K9: 1 | L9: 1 | M9: 1 | N9: 1 | P9: 1.1941273
A10: TD | B10: Question 9 | C10: 0 | D10: 1 | E10: 1 | F10: 1 | G10: 1 | H10: 1 | I10: 1 | J10: 1 | K10: 1 | L10: 1 | M10: 1 | N10: 1 | P10: 1.2945511
A11: TD | B11: Question 10 | C11: 0 | D11: 1 | E11: 1 | F11: 1 | G11: 1 | H11: 1 | I11: 1 | J11: 1 | K11: 1 | L11: 1 | M11: 1 | N11: 1 | P11: 2.9018707
A12: TD | B12: Question 11 | C12: 0 | D12: 1 | E12: 1 | F12: 1 | G12: 1 | H12: 1 | I12: 1 | J12: 0 | K12: 1 | L12: 1 | M12: 1 | N12: 1 | O12: 7: The two parts (addition and ordering of fractions) are independent in this word problem. The answer to (1) is not necessary for (2), nor vice versa. The problems do not build on each other, so synergy is lacking. | P12: 1.813031
A13: TD | B13: Question 12 | C13: 0 | D13: 1 | E13: 0 | F13: 1 | G13: 1 | H13: 'NA | I13: 1 | J13: 'NA | K13: 1 | L13: 1 | M13: 1 | N13: 1 | O13: B1- The question asks for the fraction of the allowance spent on streaming compared to cleaning supplies, which requires division (finding the ratio), not subtraction of fractions as stipulated in the intended Primary Knowledge Component. B7- The word problem does not require synergy between subtraction and simplification: only comparing via division is needed and then simplifying, not using subtraction and simplification together. | P13: 2.4905815
A14: TD | B14: Question 13 | C14: 0 | D14: 1 | E14: 1 | F14: 1 | G14: 1 | H14: 0 | I14: 0 | J14: 1 | K14: 1 | L14: 1 | M14: 1 | N14: 1 | O14: 5: The word problem requires students to compare and order decimal values with three decimal places (e.g., $36.450$), but Primary 4 students in Singapore are only expected to work with decimals up to two decimal places. This exceeds the grade level expectation. 6: Receipt totals including three decimal places (even though the service sums only need two) are not realistic in Singapore, as services almost always round to two decimal places due to the currency system—that is, cents. Receipts to the thousandth of a dollar aren't used. | P14: 8.0114985
A15: TD | B15: Question 14 | C15: 0 | D15: 1 | E15: 1 | F15: 1 | G15: 1 | H15: 1 | I15: 1 | J15: 1 | K15: 1 | L15: 1 | M15: 1 | N15: 1 | P15: 2.0466049
A16: TD | B16: Question 15 | C16: 0 | D16: 1 | E16: 1 | F16: 1 | G16: 1 | H16: 1 | I16: 1 | J16: 1 | K16: 1 | L16: 1 | M16: 1 | N16: 1 | P16: 1.3831022
A17: TD | B17: Question 16 | C17: 0 | D17: 1 | E17: 1 | F17: 1 | G17: 1 | H17: 1 | I17: 1 | J17: 0 | K17: 1 | L17: 1 | M17: 1 | N17: 1 | O17: 7- The two parts (a) and (b) are independent of each other and do not demonstrate synergy; solving one does not require the result of the other. | P17: 2.1098597
A18: TD | B18: Question 17 | C18: 0 | D18: 1 | E18: 1 | F18: 1 | G18: 1 | H18: 1 | I18: 1 | J18: 1 | K18: 1 | L18: 1 | M18: 1 | N18: 1 | P18: 1.6059194
A19: TD | B19: Question 18 | C19: 0 | D19: 1 | E19: 0 | F19: 1 | G19: 1 | H19: 'NA | I19: 1 | J19: 'NA | K19: 1 | L19: 1 | M19: 1 | N19: 1 | O19: Primary KC Alignment: - The division required in (a) is $38.75 [FORMULA] 5 = 7.75$, which only involves dividing a number with at most 2 decimal places by a single-digit whole number, satisfying the intended KC. However, in part (b), the comparison involves a number ($9.725$) with 3 decimal places in the context of Singapore Primary 4, students typically only work with up to 2 decimal places in routine division situations. Grade Alignment: - Part (b) requires students to compare $7.75$ and $9.725$, where $9.725$ is written with 3 decimal places, which is beyond the typical Primary 4 decimal comparison syllabus in Singapore, as this level usually restricts questions to decimals with up to 2 decimal places. | P19: 3.2708125
A20: TD | B20: Question 19 | C20: 0 | D20: 1 | E20: 1 | F20: 1 | G20: 1 | H20: 1 | I20: 1 | J20: 1 | K20: 1 | L20: 1 | M20: 1 | N20: 1 | P20: 1.1546955
A21: TD | B21: Question 20 | C21: 0 | D21: 1 | E21: 1 | F21: 1 | G21: 1 | H21: 1 | I21: 1 | J21: 1 | K21: 1 | L21: 1 | M21: 1 | N21: 1 | P21: 1.1216848
A22: TD | B22: Question 21 | C22: 0 | D22: 1 | E22: 1 | F22: 1 | G22: 1 | H22: 1 | I22: 1 | J22: 1 | K22: 1 | L22: 1 | M22: 1 | N22: 1 | P22: 1.2392769
A23: TD | B23: Question 22 | C23: 0 | D23: 1 | E23: 1 | F23: 0 | G23: 1 | H23: 1 | I23: 1 | J23: 'NA | K23: 1 | L23: 1 | M23: 1 | N23: 1 | O23: secondary_kc_alignment: The secondary knowledge component (comparison and ordering of fractions) is not directly required—the comparison in (b) can be done by comparing two whole numbers, not fractions, as both Mrs Lim's and her friend's values will be turned into whole numbers for comparison. synergy: The result from (a) is used in (b), but the intended secondary KC is not needed, so strong synergy between the two intended KCs is absent. | P23: 2.7512496
A24: TD | B24: Question 23 | C24: 0 | D24: 1 | E24: 1 | F24: 1 | G24: 1 | H24: 1 | I24: 1 | J24: 1 | K24: 1 | L24: 1 | M24: 1 | N24: 1 | P24: 1.8896658
A25: TD | B25: Question 24 | C25: 0 | D25: 1 | E25: 1 | F25: 1 | G25: 1 | H25: 1 | I25: 1 | J25: 1 | K25: 1 | L25: 1 | M25: 1 | N25: 1 | P25: 1.1975698
A26: TD | B26: Question 25 | C26: 0 | D26: 1 | E26: 1 | F26: 1 | G26: 1 | H26: 1 | I26: 1 | J26: 1 | K26: 1 | L26: 1 | M26: 1 | N26: 1 | P26: 1.5837059
A27: TD | B27: Question 26 | C27: 0 | D27: 1 | E27: 0 | F27: 1 | G27: 1 | H27: 'NA | I27: 1 | J27: 'NA | K27: 1 | L27: 1 | M27: 1 | N27: 1 | O27: primary_kc_alignment: The problem requires multiplying the improper fraction \([FORMULA]\) by the integer 3, not multiplying two improper fractions as specified in the intended primary KC. Multiplication is with a whole number, not an improper fraction. | P27: 1.837652
A28: TD | B28: Question 27 | C28: 0 | D28: 1 | E28: 1 | F28: 1 | G28: 1 | H28: 1 | I28: 1 | J28: 1 | K28: 1 | L28: 1 | M28: 1 | N28: 1 | P28: 1.1256123
A29: TD | B29: Question 28 | C29: 0 | D29: 1 | E29: 1 | F29: 1 | G29: 1 | H29: 1 | I29: 0 | J29: 1 | K29: 1 | L29: 1 | M29: 1 | N29: 1 | O29: Real World Feasibility: - In real situations, it is highly unlikely to clean a non-whole-number of rooms (8/5 = 1.6 rooms) in a session, especially for a cleaning company that counts by discrete rooms, not fractions of a room. This makes the scenario unrealistic for the intended grade and context. | P29: 3.0800958
A30: TD | B30: Question 29 | C30: 0 | D30: 1 | E30: 1 | F30: 1 | G30: 1 | H30: 1 | I30: 1 | J30: 1 | K30: 1 | L30: 1 | M30: 1 | N30: 1 | P30: 1.4802535
A31: TD | B31: Question 30 | C31: 0 | D31: 1 | E31: 0 | F31: 1 | G31: 1 | H31: 'NA | I31: 1 | J31: 'NA | K31: 1 | L31: 1 | M31: 1 | N31: 1 | O31: Primary KC Alignment: The word problem does require multiplication involving decimals (3.75 x 12), but it does not require multiplying by 10, 100, 1000 or their multiples, as specified in the intended Primary Knowledge Component. Instead, it is simply multiplying two numbers with decimals, which is a different skill focus. | P31: 1.9709678
A32: TD | B32: Question 31 | C32: 0 | D32: 1 | E32: 1 | F32: 1 | G32: 1 | H32: 1 | I32: 1 | J32: 1 | K32: 1 | L32: 1 | M32: 1 | N32: 1 | P32: 1.2840397
A33: TD | B33: Question 32 | C33: 0 | D33: 1 | E33: 1 | F33: 1 | G33: 1 | H33: 1 | I33: 1 | J33: 1 | K33: 1 | L33: 1 | M33: 1 | N33: 1 | P33: 1.1874092
A34: TD | B34: Question 33 | C34: 0 | D34: 1 | E34: 0 | F34: 1 | G34: 1 | H34: 'NA | I34: 1 | J34: 'NA | K34: 1 | L34: 1 | M34: 0 | N34: 1 | O34: primary_kc_alignment: The main knowledge component requires dividing decimals by 10, 100, 1000 or their multiples. The value 12.500 looks like a formatting or decimal point error (should be $12,500 or $12.50). If it's $12.50, dividing by 1000 gives the unit cost, but the presence of three decimal places is not evident in the calculation. The KC doesn't emphasize dividing by 10, 100, 1000 specifically.language_quality: There's a formatting error in the currency value: '[FORMULA]12.500' is not standard for dollars and cents. This may cause confusion for students and should be corrected. | P34: 2.8934646
A35: TD | B35: Question 34 | C35: 0 | D35: 1 | E35: 1 | F35: 1 | G35: 1 | H35: 1 | I35: 1 | J35: 1 | K35: 1 | L35: 1 | M35: 1 | N35: 1 | P35: 2.5798905
A36: TD | B36: Question 35 | C36: 0 | D36: 1 | E36: 1 | F36: 1 | G36: 1 | H36: 1 | I36: 1 | J36: 1 | K36: 1 | L36: 1 | M36: 1 | N36: 1 | P36: 1.6847355
A37: TD | B37: Question 36 | C37: 0 | D37: 1 | E37: 1 | F37: 1 | G37: 1 | H37: 1 | I37: 1 | J37: 1 | K37: 1 | L37: 1 | M37: 1 | N37: 1 | P37: 1.4750748
A38: TD | B38: Question 37 | C38: 0 | D38: 1 | E38: 0 | F38: 0 | G38: 1 | H38: 'NA | I38: 1 | J38: 'NA | K38: 1 | L38: 1 | M38: 1 | N38: 1 | O38: Primary KC Alignment: The problem asks students to compute how many loads by dividing a fraction by a fraction (3/4 ÷ 1/8), not by a whole number as specified in the intended KC. Secondary KC Alignment: Students are not required to add fractions; rather, the total is found by summing two whole numbers of loads, which doesn't require the operation of adding fractions. Synergy: The two sub-questions (a) and (b) can be answered independently; they are connected by context but not by their mathematical operations or results (the answer for (a) is not needed to answer (b)). | P38: 3.4917967
A39: TD | B39: Question 38 | C39: 0 | D39: 1 | E39: 1 | F39: 1 | G39: 1 | H39: 1 | I39: 1 | J39: 1 | K39: 1 | L39: 1 | M39: 1 | N39: 1 | P39: 1.3485582
A40: TD | B40: Question 39 | C40: 0 | D40: 1 | E40: 1 | F40: 1 | G40: 1 | H40: 1 | I40: 1 | J40: 1 | K40: 1 | L40: 1 | M40: 1 | N40: 1 | P40: 1.1097412
...

Sheet services_v8_v1_split_4
A1: Evaluator | B1: Question | C1: status | D1: answerability | E1: primary_kc_alignment | F1: secondary_kc_alignment | G1: topic_alignment | H1: grade_alignment | I1: real_world_feasibility | J1: synergy | K1: clarity | L1: conciseness_and_relevance | M1: language_quality | N1: content_appropriateness | O1: explanation | P1: response_time | Q1: language_quality1
A2: TD | B2: Question 1 | C2: 0 | D2: 1 | E2: 1 | F2: 1 | G2: 1 | H2: 1 | I2: 1 | J2: 1 | K2: 1 | L2: 1 | M2: 1 | N2: 1 | P2: 2.3237884
A3: TD | B3: Question 2 | C3: 0 | D3: 1 | E3: 1 | F3: 1 | G3: 1 | H3: 1 | I3: 1 | J3: 1 | K3: 1 | L3: 1 | M3: 1 | N3: 1 | P3: 1.6036172
A4: TD | B4: Question 3 | C4: 0 | D4: 1 | E4: 1 | F4: 1 | G4: 1 | H4: 1 | I4: 1 | J4: 1 | K4: 1 | L4: 1 | M4: 1 | N4: 1 | P4: 1.1431363
A5: TD | B5: Question 4 | C5: 0 | D5: 1 | E5: 0 | F5: 1 | G5: 1 | H5: 'NA | I5: 1 | J5: 'NA | K5: 1 | L5: 1 | M5: 1 | N5: 1 | O5: Primary KC Alignment: The problem requires 7 × 128 and 5 × 153 multiplications (3 digits × 1 digit and 3 digits × 1 digit), but Primary 3 Singapore syllabus only covers multiplication of up to 3 digits by 1 digit for WHOLE NUMBERS. Multiplying by 128 and 153 both require a 3-digit × 1-digit, but this could be challenging at Primary 3 because students are not expected to directly multiply 3-digit by 1-digit through mental methods, but rather with possible scaffolding steps. However, the question may be slightly advanced as it expects handling of multiples beyond the lower 100s, so partial credit could be argued—but strictly, it would be more appropriate if numbers were capped at lower 3-digit values for Primary 3. | P5: 3.2959087
A6: TD | B6: Question 5 | C6: 0 | D6: 1 | E6: 1 | F6: 1 | G6: 1 | H6: 1 | I6: 1 | J6: 1 | K6: 1 | L6: 1 | M6: 1 | N6: 1 | P6: 1.1317205
A7: TD | B7: Question 6 | C7: 0 | D7: 1 | E7: 1 | F7: 1 | G7: 1 | H7: 1 | I7: 1 | J7: 1 | K7: 1 | L7: 1 | M7: 1 | N7: 1 | P7: 2.1605623
A8: TD | B8: Question 7 | C8: 0 | D8: 1 | E8: 1 | F8: 1 | G8: 1 | H8: 1 | I8: 1 | J8: 1 | K8: 1 | L8: 1 | M8: 1 | N8: 1 | P8: 1.2190931
A9: TD | B9: Question 8 | C9: 0 | D9: 1 | E9: 1 | F9: 1 | G9: 1 | H9: 1 | I9: 1 | J9: 1 | K9: 1 | L9: 1 | M9: 1 | N9: 1 | P9: 1.6791534
A10: TD | B10: Question 9 | C10: 0 | D10: 1 | E10: 1 | F10: 1 | G10: 1 | H10: 1 | I10: 1 | J10: 1 | K10: 1 | L10: 1 | M10: 1 | N10: 1 | P10: 2.318548
A11: TD | B11: Question 10 | C11: 0 | D11: 1 | E11: 1 | F11: 1 | G11: 1 | H11: 1 | I11: 1 | J11: 1 | K11: 1 | L11: 1 | M11: 1 | N11: 1 | P11: 2.1317003
A12: TD | B12: Question 11 | C12: 0 | D12: 1 | E12: 1 | F12: 1 | G12: 1 | H12: 1 | I12: 1 | J12: 1 | K12: 1 | L12: 1 | M12: 1 | N12: 1 | P12: 13.478088
A13: TD | B13: Question 12 | C13: 0 | D13: 1 | E13: 0 | F13: 1 | G13: 1 | H13: 'NA | I13: 1 | J13: 'NA | K13: 1 | L13: 1 | M13: 1 | N13: 1 | O13: Primary KC Alignment and Synergy: The question asks for a COMPARISON between the spending on streaming and cleaning supplies, which leads to forming a ratio or a fraction ([FORMULA] compared to [FORMULA]) rather than the subtraction of the two fractions. Therefore, subtracting unlike fractions is not necessary or used in the solution, so the primary KC is not aligned and there is no synergy present between the primary and secondary KCs. | P13: 2.190896
A14: TD | B14: Question 13 | C14: 0 | D14: 1 | E14: 1 | F14: 1 | G14: 1 | H14: 1 | I14: 1 | J14: 1 | K14: 1 | L14: 1 | M14: 1 | N14: 1 | P14: 1.2049429
A15: TD | B15: Question 14 | C15: 0 | D15: 1 | E15: 1 | F15: 1 | G15: 1 | H15: 1 | I15: 1 | J15: 1 | K15: 1 | L15: 1 | M15: 1 | N15: 1 | P15: 2.1968625
A16: TD | B16: Question 15 | C16: 0 | D16: 1 | E16: 1 | F16: 1 | G16: 1 | H16: 1 | I16: 1 | J16: 1 | K16: 1 | L16: 1 | M16: 1 | N16: 1 | P16: 1.8490651
A17: TD | B17: Question 16 | C17: 0 | D17: 1 | E17: 1 | F17: 1 | G17: 1 | H17: 1 | I17: 1 | J17: 1 | K17: 1 | L17: 1 | M17: 1 | N17: 1 | P17: 1.2850058
A18: TD | B18: Question 17 | C18: 0 | D18: 1 | E18: 1 | F18: 1 | G18: 1 | H18: 1 | I18: 1 | J18: 1 | K18: 1 | L18: 1 | M18: 1 | N18: 1 | P18: 1.5740914
A19: TD | B19: Question 18 | C19: 0 | D19: 1 | E19: 0 | F19: 1 | G19: 1 | H19: 'NA | I19: 1 | J19: 'NA | K19: 1 | L19: 1 | M19: 1 | N19: 1 | O19: Primary KC Alignment: The division required to solve part (a) involves dividing $38.75 by 5, which can result in a value with up to 3 decimal places (7.75), but the context reasonably limits it to 2 decimal places; however, part (b) asks to compare $9.725 per room (3 decimal places), which is not in line with Primary 4 knowledge, as official Singapore syllabus up to Primary 4 only expects working with decimals to 2 decimal places for division. Grade Alignment: Based on the official Singapore Math syllabus, comparing and ordering decimals up to 3 decimal places is not expected at Primary 4, which is appropriate for comparing and ordering decimals up to only 2 decimal places. | P19: 8.2338071
A20: TD | B20: Question 19 | C20: 0 | D20: 1 | E20: 1 | F20: 1 | G20: 1 | H20: 1 | I20: 1 | J20: 1 | K20: 1 | L20: 1 | M20: 1 | N20: 1 | P20: 1.2660003
A21: TD | B21: Question 20 | C21: 0 | D21: 1 | E21: 1 | F21: 1 | G21: 1 | H21: 1 | I21: 1 | J21: 1 | K21: 1 | L21: 1 | M21: 1 | N21: 1 | P21: 1.3131759
A22: TD | B22: Question 21 | C22: 0 | D22: 1 | E22: 1 | F22: 1 | G22: 1 | H22: 1 | I22: 1 | J22: 1 | K22: 1 | L22: 1 | M22: 1 | N22: 1 | P22: 1.3503015
A23: TD | B23: Question 22 | C23: 0 | D23: 1 | E23: 1 | F23: 0 | G23: 1 | H23: 1 | I23: 1 | J23: 'NA | K23: 1 | L23: 1 | M23: 1 | N23: 1 | O23: Secondary KC Alignment (0): The problem only requires multiplying fractions and a whole number, and finding a simple difference. It does not actually require comparing and ordering two fractions directly for its solution. Synergy (0): The first part's result is simply used as a value in a difference calculation, but no comparison of fractions (secondary KC) is used, so there is no meaningful synergy between primary and secondary. | P23: 2.0593617
A24: TD | B24: Question 23 | C24: 0 | D24: 1 | E24: 1 | F24: 1 | G24: 1 | H24: 1 | I24: 1 | J24: 1 | K24: 1 | L24: 1 | M24: 1 | N24: 1 | P24: 1.2655065
A25: TD | B25: Question 24 | C25: 0 | D25: 1 | E25: 1 | F25: 1 | G25: 1 | H25: 1 | I25: 1 | J25: 1 | K25: 1 | L25: 1 | M25: 1 | N25: 1 | P25: 1.1676579
A26: TD | B26: Question 25 | C26: 0 | D26: 1 | E26: 1 | F26: 1 | G26: 1 | H26: 1 | I26: 1 | J26: 1 | K26: 1 | L26: 1 | M26: 1 | N26: 1 | P26: 1.2662535
A27: TD | B27: Question 26 | C27: 0 | D27: 1 | E27: 0 | F27: 1 | G27: 1 | H27: 'NA | I27: 1 | J27: 'NA | K27: 1 | L27: 1 | M27: 1 | N27: 1 | O27: Primary KC Alignment: The multiplication in part (a) requires multiplying an improper fraction by a whole number (not by another improper fraction as intended by the metadata: 'multiplying two improper fractions'). | P27: 2.3791063
A28: TD | B28: Question 27 | C28: 0 | D28: 1 | E28: 1 | F28: 1 | G28: 1 | H28: 1 | I28: 1 | J28: 1 | K28: 1 | L28: 1 | M28: 1 | N28: 1 | P28: 1.5917971
A29: TD | B29: Question 28 | C29: 0 | D29: 1 | E29: 1 | F29: 1 | G29: 1 | H29: 1 | I29: 1 | J29: 1 | K29: 1 | L29: 1 | M29: 1 | N29: 1 | P29: 1.1366558
A30: TD | B30: Question 29 | C30: 0 | D30: 1 | E30: 1 | F30: 1 | G30: 1 | H30: 1 | I30: 1 | J30: 1 | K30: 1 | L30: 1 | M30: 1 | N30: 1 | P30: 1.282769
A31: TD | B31: Question 30 | C31: 0 | D31: 1 | E31: 0 | F31: 1 | G31: 1 | H31: 'NA | I31: 1 | J31: 'NA | K31: 1 | L31: 1 | M31: 1 | N31: 1 | O31: Primary KC Alignment: The main calculation in (a) is $3.75 [FORMULA] 12$, which does not involve multiplying by 10, 100, 1000 or their multiples, so the specific intended skill is not required. Synergy: The two parts (a) and (b) are not interdependent; the answer from (a) is not needed for (b), thus there is no synergy between the KC's. | P31: 4.1398644
A32: TD | B32: Question 31 | C32: 0 | D32: 1 | E32: 0 | F32: 1 | G32: 1 | H32: 'NA | I32: 1 | J32: 'NA | K32: 1 | L32: 1 | M32: 1 | N32: 1 | O32: Primary KC Alignment: The focus is on multiplication of decimals by whole numbers (3.850 x 140), but the intent was 'multiplying decimals (up to 3 decimal places) by 10, 100, 1000 and their multiples.' In this problem, students do not multiply specifically by 10/100/1000 or their multiples; instead, they multiply by 140 and by 1.4. The multiplication by 140 is not strictly aligning with the target KC of applying scalar multiples of 10/100/1000. The question, therefore, does not require the intended KC as necessitated. | P32: 3.2442324
A33: TD | B33: Question 32 | C33: 0 | D33: 1 | E33: 1 | F33: 1 | G33: 1 | H33: 1 | I33: 1 | J33: 1 | K33: 1 | L33: 1 | M33: 1 | N33: 1 | P33: 1.7444165
A34: TD | B34: Question 33 | C34: 0 | D34: 1 | E34: 0 | F34: 1 | G34: 1 | H34: 'NA | I34: 1 | J34: 'NA | K34: 1 | L34: 1 | M34: 1 | N34: 1 | O34: Primary KC Alignment: The division $12.500 [FORMULA] 1000$ for (a) does not align with the intended KC, as Primary 5 curriculum focuses on numbers with up to 2 decimal places and does not use notation like $[FORMULA]12.500$. This result also requires handling currency values beyond expected decimals for this level. Grade Alignment: Same issue as above. Handling $12.500$ is not typical or expected for Primary 5, as the decimal notation is non-standard in Singapore primary curriculum. A more suitable figure would be $12.50$. | P34: 3.0748825
A35: TD | B35: Question 34 | C35: 0 | D35: 1 | E35: 1 | F35: 1 | G35: 1 | H35: 1 | I35: 1 | J35: 1 | K35: 1 | L35: 1 | M35: 1 | N35: 1 | P35: 1.6374686
A36: TD | B36: Question 35 | C36: 0 | D36: 1 | E36: 1 | F36: 1 | G36: 1 | H36: 1 | I36: 1 | J36: 1 | K36: 1 | L36: 1 | M36: 1 | N36: 1 | P36: 1.1745088
A37: TD | B37: Question 36 | C37: 0 | D37: 1 | E37: 1 | F37: 1 | G37: 1 | H37: 1 | I37: 1 | J37: 1 | K37: 1 | L37: 1 | M37: 1 | N37: 1 | P37: 1.1860778
A38: TD | B38: Question 37 | C38: 0 | D38: 1 | E38: 0 | F38: 0 | G38: 1 | H38: 'NA | I38: 1 | J38: 'NA | K38: 1 | L38: 1 | M38: 1 | N38: 1 | O38: Primary KC Alignment: The problem involves dividing a fraction by a fraction ($[FORMULA] [FORMULA] [FORMULA]$), not dividing a proper fraction by a whole number as intended. Secondary KC Alignment: The problem requires addition of whole numbers (loads), not addition of fractions. | P38: 1.7388387
A39: TD | B39: Question 38 | C39: 0 | D39: 1 | E39: 1 | F39: 1 | G39: 1 | H39: 1 | I39: 1 | J39: 1 | K39: 1 | L39: 1 | M39: 1 | N39: 1 | P39: 1.654583
A40: TD | B40: Question 39 | C40: 0 | D40: 1 | E40: 1 | F40: 1 | G40: 1 | H40: 1 | I40: 1 | J40: 1 | K40: 1 | L40: 1 | M40: 1 | N40: 1 | P40: 1.7214978
...

Sheet services_v8_v1_split_5
A1: Evaluator | B1: Question | C1: status | D1: answerability | E1: primary_kc_alignment | F1: secondary_kc_alignment | G1: topic_alignment | H1: grade_alignment | I1: real_world_feasibility | J1: synergy | K1: clarity | L1: conciseness_and_relevance | M1: language_quality | N1: content_appropriateness | O1: explanation | P1: response_time | Q1: language_quality1
A2: TD | B2: Question 1 | C2: 0 | D2: 1 | E2: 1 | F2: 1 | G2: 1 | H2: 1 | I2: 1 | J2: 1 | K2: 1 | L2: 1 | M2: 1 | N2: 1 | P2: 2.892709
A3: TD | B3: Question 2 | C3: 0 | D3: 1 | E3: 1 | F3: 1 | G3: 1 | H3: 1 | I3: 1 | J3: 1 | K3: 1 | L3: 1 | M3: 1 | N3: 1 | P3: 1.5651164
A4: TD | B4: Question 3 | C4: 0 | D4: 1 | E4: 1 | F4: 1 | G4: 1 | H4: 1 | I4: 1 | J4: 1 | K4: 1 | L4: 1 | M4: 1 | N4: 1 | P4: 1.1845906
A5: TD | B5: Question 4 | C5: 0 | D5: 1 | E5: 1 | F5: 1 | G5: 1 | H5: 1 | I5: 1 | J5: 1 | K5: 1 | L5: 1 | M5: 1 | N5: 1 | P5: 1.3986135
A6: TD | B6: Question 5 | C6: 0 | D6: 1 | E6: 1 | F6: 1 | G6: 1 | H6: 1 | I6: 1 | J6: 1 | K6: 1 | L6: 1 | M6: 1 | N6: 1 | P6: 2.2525892
A7: TD | B7: Question 6 | C7: 0 | D7: 1 | E7: 1 | F7: 1 | G7: 1 | H7: 1 | I7: 1 | J7: 1 | K7: 1 | L7: 1 | M7: 1 | N7: 1 | P7: 1.3041592
A8: TD | B8: Question 7 | C8: 0 | D8: 1 | E8: 1 | F8: 1 | G8: 1 | H8: 1 | I8: 1 | J8: 1 | K8: 1 | L8: 1 | M8: 1 | N8: 1 | P8: 2.1331723
A9: TD | B9: Question 8 | C9: 0 | D9: 1 | E9: 1 | F9: 1 | G9: 1 | H9: 1 | I9: 1 | J9: 1 | K9: 1 | L9: 1 | M9: 1 | N9: 1 | P9: 1.1178393
A10: TD | B10: Question 9 | C10: 0 | D10: 1 | E10: 1 | F10: 1 | G10: 1 | H10: 1 | I10: 1 | J10: 1 | K10: 1 | L10: 1 | M10: 1 | N10: 1 | P10: 1.2017143
A11: TD | B11: Question 10 | C11: 0 | D11: 1 | E11: 1 | F11: 1 | G11: 1 | H11: 1 | I11: 1 | J11: 1 | K11: 1 | L11: 1 | M11: 1 | N11: 1 | P11: 1.3063612
A12: TD | B12: Question 11 | C12: 0 | D12: 1 | E12: 1 | F12: 1 | G12: 1 | H12: 1 | I12: 1 | J12: 0 | K12: 1 | L12: 1 | M12: 1 | N12: 1 | O12: 7: The two sub-questions are independent; solving Q1 (addition) is not required to answer Q2 (comparison and ordering), and vice versa, so Primary KC and Secondary KC are not used in tandem. | P12: 2.1675339
A13: TD | B13: Question 12 | C13: 0 | D13: 1 | E13: 0 | F13: 1 | G13: 1 | H13: 'NA | I13: 1 | J13: 'NA | K13: 1 | L13: 1 | M13: 1 | N13: 1 | O13: Primary KC Alignment: The problem asks for 'What fraction of her allowance did Aisha spend on the streaming service compared to the cleaning supplies?' This leads students to find the ratio (i.e., division) of the two fractions, not the difference (subtraction), which is the intended primary knowledge component.Synergy: The intended synergy was that students would need to subtract the fractions and then simplify, but since the problem only asks for the ratio and then to simplify, only the secondary KC is necessary. | P13: 4.1346498
A14: TD | B14: Question 13 | C14: 0 | D14: 1 | E14: 1 | F14: 1 | G14: 1 | H14: 0 | I14: 0 | J14: 1 | K14: 1 | L14: 1 | M14: 1 | N14: 1 | O14: E: The receipts display totals with 3 decimal places (e.g., $36.450$), but the sums of actual service charges (money) should always be shown up to only 2 decimal places. Singapore Primary 4 students are only expected to work with money in 2 decimal places. This makes the question too advanced for this grade. F: In real life, payment receipts for money are never written as $36.450$; monetary values are recorded with 2 decimal places (i.e., $36.45$). Having 3 decimal places for dollars and cents is not a typical real-world scenario for receipts. | P14: 4.0231805
A15: TD | B15: Question 14 | C15: 0 | D15: 1 | E15: 1 | F15: 1 | G15: 1 | H15: 1 | I15: 1 | J15: 1 | K15: 1 | L15: 1 | M15: 1 | N15: 1 | P15: 1.2098517
A16: TD | B16: Question 15 | C16: 0 | D16: 1 | E16: 1 | F16: 1 | G16: 1 | H16: 1 | I16: 1 | J16: 1 | K16: 1 | L16: 1 | M16: 1 | N16: 1 | P16: 2.3098817
A17: TD | B17: Question 16 | C17: 0 | D17: 1 | E17: 1 | F17: 1 | G17: 1 | H17: 1 | I17: 1 | J17: 1 | K17: 1 | L17: 1 | M17: 1 | N17: 1 | P17: 1.9737151
A18: TD | B18: Question 17 | C18: 0 | D18: 1 | E18: 1 | F18: 1 | G18: 1 | H18: 1 | I18: 1 | J18: 1 | K18: 1 | L18: 1 | M18: 1 | N18: 1 | P18: 1.2898533
A19: TD | B19: Question 18 | C19: 0 | D19: 1 | E19: 0 | F19: 1 | G19: 1 | H19: 'NA | I19: 1 | J19: 'NA | K19: 1 | L19: 1 | M19: 1 | N19: 1 | O19: Primary KC Alignment: The expected division involves dividing $38.75 by 5. However, the quotient is $7.75, not a decimal with up to 2 decimal places divided by a 1-digit whole number, so it fits at first glance. BUT, part (b) introduces comparison of 3 decimal places ($9.725), which exceeds Primary 4 expectations for dividing decimals up to 2 decimal places. Grade Alignment: The presence of $9.725 (requiring understanding of decimals to 3 decimal places), and comparison/ordering at that precision, is beyond typical Primary 4 standards in Singapore. Students are only expected to work with decimals up to 2 decimal places in both calculations and comparisons at this level. | P19: 2.6584413
A20: TD | B20: Question 19 | C20: 0 | D20: 1 | E20: 1 | F20: 1 | G20: 1 | H20: 1 | I20: 1 | J20: 1 | K20: 1 | L20: 1 | M20: 1 | N20: 1 | P20: 1.1681368
A21: TD | B21: Question 20 | C21: 0 | D21: 1 | E21: 1 | F21: 1 | G21: 1 | H21: 1 | I21: 1 | J21: 1 | K21: 1 | L21: 1 | M21: 1 | N21: 1 | P21: 1.8566313
A22: TD | B22: Question 21 | C22: 0 | D22: 1 | E22: 1 | F22: 1 | G22: 1 | H22: 1 | I22: 1 | J22: 0 | K22: 1 | L22: 1 | M22: 1 | N22: 1 | O22: Synergy = 0: The questions (a) subtraction and (b) ordering are independent and do not require results from each other; solving (a) is not needed for (b), and vice versa. | P22: 3.3182828
A23: TD | B23: Question 22 | C23: 0 | D23: 1 | E23: 1 | F23: 0 | G23: 1 | H23: 1 | I23: 1 | J23: 'NA | K23: 1 | L23: 1 | M23: 1 | N23: 1 | O23: C3: The Secondary KC requires explicit need for comparing and ordering fractions. In this word problem, part (b) involves finding out how many uniforms Mrs Lim's friend laundered (which is less), but students only subtract the smaller (friend) from the larger (Mrs Lim) to answer 'who laundered more and by how many'. This does not require any actual comparison or ordering of fractions, as it is clear from context that Mrs Lim's friend laundered less (since [FORMULA] < 1). There is no question or situation requiring explicit comparison of two fractions. | P23: 3.0460413
A24: TD | B24: Question 23 | C24: 0 | D24: 1 | E24: 1 | F24: 1 | G24: 1 | H24: 1 | I24: 1 | J24: 1 | K24: 1 | L24: 1 | M24: 1 | N24: 1 | P24: 2.0433326
A25: TD | B25: Question 24 | C25: 0 | D25: 1 | E25: 1 | F25: 1 | G25: 1 | H25: 1 | I25: 1 | J25: 1 | K25: 1 | L25: 1 | M25: 1 | N25: 1 | P25: 1.8533928
A26: TD | B26: Question 25 | C26: 0 | D26: 1 | E26: 1 | F26: 1 | G26: 1 | H26: 1 | I26: 1 | J26: 1 | K26: 1 | L26: 1 | M26: 1 | N26: 1 | P26: 1.1325202
A27: TD | B27: Question 26 | C27: 0 | D27: 1 | E27: 0 | F27: 1 | G27: 1 | H27: 'NA | I27: 1 | J27: 'NA | K27: 1 | L27: 1 | M27: 1 | N27: 1 | O27: Primary KC Alignment: The problem requires multiplying a fraction by a whole number ([FORMULA] [FORMULA] 3), not multiplying two improper fractions as intended. Therefore, the main intent of practicing multiplication of two improper fractions is not met. | P27: 2.5853088
A28: TD | B28: Question 27 | C28: 0 | D28: 1 | E28: 1 | F28: 1 | G28: 1 | H28: 1 | I28: 1 | J28: 1 | K28: 1 | L28: 1 | M28: 1 | N28: 1 | P28: 1.1307583
A29: TD | B29: Question 28 | C29: 0 | D29: 1 | E29: 1 | F29: 1 | G29: 1 | H29: 1 | I29: 1 | J29: 1 | K29: 1 | L29: 1 | M29: 1 | N29: 1 | P29: 1.8251584
A30: TD | B30: Question 29 | C30: 0 | D30: 1 | E30: 1 | F30: 1 | G30: 1 | H30: 1 | I30: 1 | J30: 1 | K30: 1 | L30: 1 | M30: 1 | N30: 1 | P30: 1.8888743
A31: TD | B31: Question 30 | C31: 0 | D31: 1 | E31: 0 | F31: 1 | G31: 1 | H31: 'NA | I31: 1 | J31: 'NA | K31: 1 | L31: 1 | M31: 1 | N31: 1 | O31: Primary KC Alignment: The multiplication required is 3.75 × 12. While multiplying decimals by a whole number is involved, it does not require multiplying by 10, 100, 1000, or their multiples as intended by the Primary KC. Synergy: The two parts (a) and (b) are independent; the conversion from decimal to fraction does not depend on the cost calculation in (a), nor does (a) require the fraction form from (b). | P31: 3.200918
A32: TD | B32: Question 31 | C32: 0 | D32: 1 | E32: 0 | F32: 1 | G32: 1 | H32: 'NA | I32: 1 | J32: 'NA | K32: 1 | L32: 1 | M32: 1 | N32: 1 | O32: Primary KC Alignment=0: The word problem asks for multiplication of a decimal (3.850) by a whole number (140), which is not specifically targeting multiplying decimals by 10, 100, 1000 or their multiples as intended in the primary KC. Instead, the multiplication is by 140, which is not a straightforward application of multiplying by 10, 100, 1000 and their multiples. | P32: 3.9469965
A33: TD | B33: Question 32 | C33: 0 | D33: 1 | E33: 1 | F33: 1 | G33: 1 | H33: 1 | I33: 1 | J33: 1 | K33: 1 | L33: 1 | M33: 1 | N33: 1 | P33: 1.5335612
A34: TD | B34: Question 33 | C34: 0 | D34: 1 | E34: 0 | F34: 1 | G34: 1 | H34: 'NA | I34: 1 | J34: 'NA | K34: 1 | L34: 1 | M34: 1 | N34: 1 | O34: Primary KC Alignment: The intended primary KC is dividing decimals (up to 3 decimal places) by 10, 100, 1000 and their multiples. In the problem, students are required to divide 12.500 by 1000 and then later by 1250 (1000 + 250) to find per square metre costs, but neither divisor (1250) is 10, 100, 1000 or their multiples. The problem does not require the specific use of dividing decimals by the given types of divisors; therefore, it does not fully satisfy the intended primary knowledge component. | P34: 6.160677
A35: TD | B35: Question 34 | C35: 0 | D35: 1 | E35: 1 | F35: 1 | G35: 1 | H35: 1 | I35: 1 | J35: 1 | K35: 1 | L35: 1 | M35: 1 | N35: 1 | P35: 1.7336931
A36: TD | B36: Question 35 | C36: 0 | D36: 1 | E36: 1 | F36: 1 | G36: 1 | H36: 1 | I36: 1 | J36: 1 | K36: 1 | L36: 1 | M36: 1 | N36: 1 | P36: 1.3040788
A37: TD | B37: Question 36 | C37: 0 | D37: 1 | E37: 1 | F37: 1 | G37: 1 | H37: 1 | I37: 1 | J37: 1 | K37: 1 | L37: 1 | M37: 1 | N37: 1 | P37: 1.5145795
A38: TD | B38: Question 37 | C38: 0 | D38: 1 | E38: 0 | F38: 0 | G38: 1 | H38: 'NA | I38: 1 | J38: 'NA | K38: 1 | L38: 1 | M38: 1 | N38: 1 | O38: Primary KC Alignment (0): The intended primary KC is dividing a proper fraction by a whole number, but the problem requires dividing a proper fraction (e.g., 3/4) by another proper fraction (1/8), not a whole number. Secondary KC Alignment (0): The intended secondary KC is adding fractions, but the problem requires adding numbers of loads (whole numbers) from each part, not fractions themselves. | P38: 1.9133818
A39: TD | B39: Question 38 | C39: 0 | D39: 1 | E39: 1 | F39: 1 | G39: 1 | H39: 1 | I39: 1 | J39: 1 | K39: 1 | L39: 1 | M39: 1 | N39: 1 | P39: 1.1394653
A40: TD | B40: Question 39 | C40: 0 | D40: 1 | E40: 1 | F40: 1 | G40: 1 | H40: 1 | I40: 1 | J40: 1 | K40: 1 | L40: 1 | M40: 1 | N40: 1 | P40: 1.2322116
...

Sheet Compiled Votes
A1: Evaluator | B1: Question | C1: status | D1: answerability | E1: primary_kc_alignment | F1: secondary_kc_alignment | G1: topic_alignment | H1: grade_alignment | I1: real_world_feasibility | J1: synergy | K1: clarity | L1: conciseness_and_relevance | M1: language_quality | N1: content_appropriateness | O1: response_time | P1: language_quality1
A2: TD | B2: Question 1 | C2: 0 | D2: =ROUND(SUM(services_v8_v1_split_5!D2,services_v8_v1_split_4!D2,services_v8_v1_split_3!D2,services_v8_v1_split_2!D2,services_v8_v1_split_1!D2)/COUNT(services_v8_v1_split_5!D2,services_v8_v1_split_4!D2,services_v8_v1_split_3!D2,services_v8_v1_split_2!D2,services_v8_v1_split_1!D2),0) -> 1 | E2: =IF($D2 = 1,ROUND(SUM(services_v8_v1_split_5!E2,services_v8_v1_split_4!E2,services_v8_v1_split_3!E2,services_v8_v1_split_2!E2,services_v8_v1_split_1!E2)/COUNT(services_v8_v1_split_5!E2,services_v8_v1_split_4!E2,services_v8_v1_split_3!E2,services_v8_v1_split_2!E2,services_v8_v1_split_1!E2),0),"NA") -> 1 | F2: =IF($D2 = 1,ROUND(SUM(services_v8_v1_split_5!F2,services_v8_v1_split_4!F2,services_v8_v1_split_3!F2,services_v8_v1_split_2!F2,services_v8_v1_split_1!F2)/COUNT(services_v8_v1_split_5!F2,services_v8_v1_split_4!F2,services_v8_v1_split_3!F2,services_v8_v1_split_2!F2,services_v8_v1_split_1!F2),0),"NA") -> 1 | G2: =IF($D2 = 1,ROUND(SUM(services_v8_v1_split_5!G2,services_v8_v1_split_4!G2,services_v8_v1_split_3!G2,services_v8_v1_split_2!G2,services_v8_v1_split_1!G2)/COUNT(services_v8_v1_split_5!G2,services_v8_v1_split_4!G2,services_v8_v1_split_3!G2,services_v8_v1_split_2!G2,services_v8_v1_split_1!G2),0),"NA") -> 1 | H2: =IF($E2 = 1,ROUND(SUM(services_v8_v1_split_5!H2,services_v8_v1_split_4!H2,services_v8_v1_split_3!H2,services_v8_v1_split_2!H2,services_v8_v1_split_1!H2)/COUNT(services_v8_v1_split_5!H2,services_v8_v1_split_4!H2,services_v8_v1_split_3!H2,services_v8_v1_split_2!H2,services_v8_v1_split_1!H2),0),"NA") -> 1 | I2: =IF($D2 = 1,ROUND(SUM(services_v8_v1_split_5!I2,services_v8_v1_split_4!I2,services_v8_v1_split_3!I2,services_v8_v1_split_2!I2,services_v8_v1_split_1!I2)/COUNT(services_v8_v1_split_5!I2,services_v8_v1_split_4!I2,services_v8_v1_split_3!I2,services_v8_v1_split_2!I2,services_v8_v1_split_1!I2),0),"NA") -> 1 | J2: =IF(AND(E2 = 1,F2=1),ROUND(SUM(services_v8_v1_split_5!J2,services_v8_v1_split_4!J2,services_v8_v1_split_3!J2,services_v8_v1_split_2!J2,services_v8_v1_split_1!J2)/COUNT(services_v8_v1_split_5!J2,services_v8_v1_split_4!J2,services_v8_v1_split_3!J2,services_v8_v1_split_2!J2,services_v8_v1_split_1!J2),0),"NA") -> 1 | K2: =IF($D2 = 1,ROUND(SUM(services_v8_v1_split_5!K2,services_v8_v1_split_4!K2,services_v8_v1_split_3!K2,services_v8_v1_split_2!K2,services_v8_v1_split_1!K2)/COUNT(services_v8_v1_split_5!K2,services_v8_v1_split_4!K2,services_v8_v1_split_3!K2,services_v8_v1_split_2!K2,services_v8_v1_split_1!K2),0),"NA") -> 1 | L2: =IF($D2 = 1,ROUND(SUM(services_v8_v1_split_5!L2,services_v8_v1_split_4!L2,services_v8_v1_split_3!L2,services_v8_v1_split_2!L2,services_v8_v1_split_1!L2)/COUNT(services_v8_v1_split_5!L2,services_v8_v1_split_4!L2,services_v8_v1_split_3!L2,services_v8_v1_split_2!L2,services_v8_v1_split_1!L2),0),"NA") -> 1 | M2: =IF($D2 = 1,ROUND(SUM(services_v8_v1_split_5!M2,services_v8_v1_split_4!M2,services_v8_v1_split_3!M2,services_v8_v1_split_2!M2,services_v8_v1_split_1!M2)/COUNT(services_v8_v1_split_5!M2,services_v8_v1_split_4!M2,services_v8_v1_split_3!M2,services_v8_v1_split_2!M2,services_v8_v1_split_1!M2),0),"NA") -> 1 | N2: =IF($D2 = 1,ROUND(SUM(services_v8_v1_split_5!N2,services_v8_v1_split_4!N2,services_v8_v1_split_3!N2,services_v8_v1_split_2!N2,services_v8_v1_split_1!N2)/COUNT(services_v8_v1_split_5!N2,services_v8_v1_split_4!N2,services_v8_v1_split_3!N2,services_v8_v1_split_2!N2,services_v8_v1_split_1!N2),0),"NA") -> 1 | O2: 2.892709
