Workbook

Sheet recreation_v2_common_1
A1: Evaluator | B1: Question | C1: status | D1: answerability | E1: primary_kc_alignment | F1: secondary_kc_alignment | G1: topic_alignment | H1: grade_alignment | I1: real_world_feasibility | J1: synergy | K1: clarity | L1: conciseness_and_relevance | M1: language_quality | N1: content_appropriateness | O1: explanation | P1: response_time
A2: All | B2: Question 1 | C2: 0 | D2: 1 | E2: 1 | F2: 1 | G2: 1 | H2: 1 | I2: 1 | J2: 1 | K2: 1 | L2: 1 | M2: 1 | N2: 1 | P2: 2.1706738
A3: All | B3: Question 2 | C3: 0 | D3: 1 | E3: 1 | F3: 1 | G3: 1 | H3: 1 | I3: 0 | J3: 1 | K3: 1 | L3: 1 | M3: 1 | N3: 1 | O3: real_world_feasibility: The scenario presents a situation where Alvin intends to 'divide his time equally among as many songs as possible' but then instead spends 2/3 of his entire practice time on the first song, which contradicts the equal division stated earlier. In practical terms, if he is dividing time equally, he cannot then spend a disproportionate amount (2/3) on the first song; this creates an unrealistic or confusing expectation about what is really happening during the practice session. | P3: 2.621151
A4: All | B4: Question 3 | C4: 0 | D4: 1 | E4: 1 | F4: 1 | G4: 1 | H4: 1 | I4: 1 | J4: 1 | K4: 1 | L4: 1 | M4: 1 | N4: 1 | P4: 1.3482804
A5: All | B5: Question 4 | C5: 0 | D5: 1 | E5: 1 | F5: 1 | G5: 1 | H5: 1 | I5: 1 | J5: 1 | K5: 1 | L5: 1 | M5: 1 | N5: 1 | P5: 1.9925642
A6: All | B6: Question 5 | C6: 0 | D6: 1 | E6: 1 | F6: 1 | G6: 1 | H6: 1 | I6: 1 | J6: 1 | K6: 1 | L6: 1 | M6: 1 | N6: 1 | P6: 1.4973304
A7: All | B7: Question 6 | C7: 0 | D7: 1 | E7: 1 | F7: 1 | G7: 1 | H7: 1 | I7: 1 | J7: 1 | K7: 1 | L7: 1 | M7: 1 | N7: 1 | P7: 1.5839996
A8: All | B8: Question 7 | C8: 0 | D8: 1 | E8: 1 | F8: 1 | G8: 1 | H8: 1 | I8: 1 | J8: 1 | K8: 1 | L8: 1 | M8: 1 | N8: 1 | P8: 1.9166331
A9: All | B9: Question 8 | C9: 0 | D9: 1 | E9: 1 | F9: 1 | G9: 1 | H9: 1 | I9: 1 | J9: 1 | K9: 1 | L9: 1 | M9: 1 | N9: 1 | P9: 1.5742252
A10: All | B10: Question 9 | C10: 0 | D10: 1 | E10: 1 | F10: 1 | G10: 1 | H10: 1 | I10: 1 | J10: 1 | K10: 1 | L10: 1 | M10: 1 | N10: 1 | P10: 1.3755021
A11: All | B11: Question 10 | C11: 0 | D11: 1 | E11: 1 | F11: 1 | G11: 1 | H11: 1 | I11: 1 | J11: 1 | K11: 1 | L11: 1 | M11: 1 | N11: 1 | P11: 2.3105531
A12: All | B12: Question 11 | C12: 0 | D12: 1 | E12: 0 | F12: 1 | G12: 1 | H12: 1 | I12: 1 | J12: 1 | K12: 1 | L12: 1 | M12: 1 | N12: 1 | O12: Primary Knowledge Component Alignment: While the problem does require subtraction of mixed numbers in part (b), finding out how much further Sarah needs to cycle, the first question (adding the two mixed numbers) is the more central and necessary step. The primary operation the student must perform is addition of mixed numbers (question a), while the subtraction is a dependent and simpler follow-up using the combined distance. Therefore, addition is far more central, and making subtraction the primary KC is not justified by the structure of the questions. | P12: 3.7945702
A13: All | B13: Question 12 | C13: 0 | D13: 1 | E13: 1 | F13: 1 | G13: 1 | H13: 1 | I13: 1 | J13: 1 | K13: 1 | L13: 1 | M13: 1 | N13: 1 | P13: 2.1255364
A14: All | B14: Question 13 | C14: 0 | D14: 1 | E14: 1 | F14: 1 | G14: 1 | H14: 1 | I14: 1 | J14: 1 | K14: 1 | L14: 1 | M14: 1 | N14: 1 | P14: 1.4113662
A15: All | B15: Question 14 | C15: 0 | D15: 1 | E15: 1 | F15: 0 | G15: 1 | H15: 1 | I15: 1 | J15: 0 | K15: 1 | L15: 1 | M15: 1 | N15: 1 | O15: Secondary KC Alignment (0): The problem requires division (70 divided by 250) then multiplying by 100, which is more about division and percentage rather than multiplication of whole numbers as a standalone operation. Synergy (0): The multiplication knowledge (as a secondary KC) is not needed in tandem with the concept of expressing part of a whole as a percentage in a way that deepens or connects the two concepts; the main operation is division for finding the fraction, then multiplication by 100 is standard in percentage calculation but doesn't elevate multiplication to a significant secondary component role. | P15: 2.7380521
A16: All | B16: Question 15 | C16: 0 | D16: 1 | E16: 0 | F16: 1 | G16: 1 | H16: 1 | I16: 1 | J16: 1 | K16: 1 | L16: 1 | M16: 1 | N16: 1 | O16: Primary KC Alignment: The intended primary knowledge component is 'multiplying decimals (up to 3 decimal places) by 10, 100, 1000 and their multiples.' However, in this problem, the multiplication required is 3.275 × 20, where 20 is not a multiple of 10, 100 or 1000. Instead, the multiplication is a whole number with a decimal by a number that is not a power of ten or their multiples, so this does not fully align with the specified KC. | P16: 2.9748859
A17: All | B17: Question 16 | C17: 0 | D17: 1 | E17: 1 | F17: 1 | G17: 1 | H17: 1 | I17: 1 | J17: 1 | K17: 1 | L17: 1 | M17: 1 | N17: 1 | P17: 1.3289552
A18: All | B18: Question 17 | C18: 0 | D18: 1 | E18: 1 | F18: 1 | G18: 1 | H18: 1 | I18: 1 | J18: 1 | K18: 1 | L18: 1 | M18: 1 | N18: 1 | P18: 1.5157855
A19: All | B19: Question 18 | C19: 0 | D19: 1 | E19: 1 | F19: 0 | G19: 0 | H19: 1 | I19: 1 | J19: 1 | K19: 1 | L19: 1 | M19: 1 | N19: 1 | O19: Secondary Knowledge Component: The secondary KC is subtracting fractions, but the actual process involves finding a fraction of a whole number (fraction of bookmarks) and then a whole number subtraction, not a pure fraction-fraction subtraction. Topic Alignment: 'Making bookmarks' is a craft or practical activity, but it is not strictly a recreation from the listed examples (sports, games, music, etc.). Thus, the intended topic alignment is not fully satisfied. | P19: 2.6697042
A20: All | B20: Question 19 | C20: 0 | D20: 1 | E20: 1 | F20: 1 | G20: 1 | H20: 1 | I20: 1 | J20: 1 | K20: 1 | L20: 1 | M20: 1 | N20: 1 | P20: 3.529762
A21: All | B21: Question 20 | C21: 0 | D21: 1 | E21: 1 | F21: 1 | G21: 1 | H21: 1 | I21: 1 | J21: 1 | K21: 1 | L21: 1 | M21: 1 | N21: 1 | P21: 1.9920475
A22: All | B22: Question 21 | C22: 0 | D22: 1 | E22: 1 | F22: 1 | G22: 1 | H22: 1 | I22: 1 | J22: 1 | K22: 1 | L22: 1 | M22: 1 | N22: 1 | P22: 1.4483109
A23: All | B23: Question 22 | C23: 0 | D23: 1 | E23: 1 | F23: 1 | G23: 1 | H23: 1 | I23: 1 | J23: 1 | K23: 1 | L23: 1 | M23: 1 | N23: 1 | P23: 1.9525518
A24: All | B24: Question 23 | C24: 0 | D24: 1 | E24: 0 | F24: 1 | G24: 1 | H24: 0 | I24: 1 | J24: 1 | K24: 1 | L24: 1 | M24: 1 | N24: 1 | O24: Primary KC alignment: The first question (a) requires subtracting 6.43 from 7.85, which fits 'subtracting decimals up to 2 decimal places.' However, the third round score is 7.802 (3 d.p.), but the subtraction isn't needed with that, so the problem doesn't require harder KC for subtraction in Q(a), thus borderline. However, the inclusion of a 3 d.p. decimal in the scores may confuse students not expected to handle subtraction with more than 2 d.p. even if not strictly required for Q(a).Grade alignment: Comparing and ordering decimals up to 3 decimal places is slightly above the expected Primary 4 knowledge based on the Singapore syllabus, which covers mostly up to 2 decimal places at this level. The presence of a 3 decimal-place value for arranging (Q(b)) would be more suitable for Primary 5. Hence, grade alignment is not fully met. | P24: 5.9807456
A25: All | B25: Question 24 | C25: 0 | D25: 1 | E25: 1 | F25: 1 | G25: 1 | H25: 1 | I25: 1 | J25: 1 | K25: 1 | L25: 1 | M25: 1 | N25: 1 | P25: 2.7597234
A26: All | B26: Question 25 | C26: 0 | D26: 1 | E26: 1 | F26: 1 | G26: 1 | H26: 1 | I26: 1 | J26: 1 | K26: 1 | L26: 1 | M26: 1 | N26: 1 | P26: 1.6122153
A27: All | B27: Question 26 | C27: 0 | D27: 1 | E27: 1 | F27: 1 | G27: 1 | H27: 1 | I27: 1 | J27: 1 | K27: 1 | L27: 1 | M27: 1 | N27: 1 | P27: 1.7007899
A28: All | B28: Question 27 | C28: 0 | D28: 1 | E28: 1 | F28: 1 | G28: 1 | H28: 1 | I28: 1 | J28: 1 | K28: 1 | L28: 1 | M28: 1 | N28: 1 | P28: 1.9631679
A29: All | B29: Question 28 | C29: 0 | D29: 1 | E29: 1 | F29: 1 | G29: 1 | H29: 1 | I29: 1 | J29: 1 | K29: 1 | L29: 1 | M29: 1 | N29: 1 | P29: 1.3275898
A30: All | B30: Question 29 | C30: 0 | D30: 0 | E30: 1 | F30: 1 | G30: 1 | H30: 1 | I30: 1 | J30: 0 | K30: 1 | L30: 0 | M30: 1 | N30: 1 | O30: answerability: The stem states Elaine spent a total of 1 hour, but the sum of the given fractions (5/6 + 1/4 = 11/12) is less than 1 hour, which is a contradiction. synergy: The answer to part (a) is not strictly needed to answer part (b); they can be solved independently. conciseness_and_relevance: The statement 'She spent a total of 1 hour doing these activities.' is not necessary and introduces conflicting information. | P30: 2.5442524
A31: All | B31: Question 30 | C31: 0 | D31: 1 | E31: 1 | F31: 1 | G31: 1 | H31: 1 | I31: 1 | J31: 1 | K31: 1 | L31: 1 | M31: 1 | N31: 1 | P31: 1.3472352
A32: All | B32: Question 31 | C32: 0 | D32: 1 | E32: 1 | F32: 1 | G32: 1 | H32: 1 | I32: 1 | J32: 1 | K32: 1 | L32: 1 | M32: 1 | N32: 1 | P32: 1.4456277
A33: All | B33: Question 32 | C33: 0 | D33: 1 | E33: 1 | F33: 1 | G33: 1 | H33: 1 | I33: 1 | J33: 1 | K33: 1 | L33: 1 | M33: 1 | N33: 1 | P33: 1.6236658
A34: All | B34: Question 33 | C34: 0 | D34: 1 | E34: 1 | F34: 1 | G34: 1 | H34: 1 | I34: 1 | J34: 1 | K34: 1 | L34: 1 | M34: 1 | N34: 1 | P34: 1.4303083
A35: All | B35: Question 34 | C35: 0 | D35: 1 | E35: 1 | F35: 1 | G35: 1 | H35: 1 | I35: 1 | J35: 1 | K35: 1 | L35: 1 | M35: 1 | N35: 1 | P35: 1.2865915
A36: All | B36: Question 35 | C36: 0 | D36: 1 | E36: 1 | F36: 1 | G36: 1 | H36: 1 | I36: 1 | J36: 1 | K36: 1 | L36: 1 | M36: 1 | N36: 1 | P36: 2.1296873
A37: All | B37: Question 36 | C37: 0 | D37: 1 | E37: 1 | F37: 1 | G37: 1 | H37: 1 | I37: 1 | J37: 1 | K37: 1 | L37: 1 | M37: 1 | N37: 1 | P37: 1.237299
A38: All | B38: Question 37 | C38: 0 | D38: 1 | E38: 1 | F38: 1 | G38: 1 | H38: 1 | I38: 1 | J38: 1 | K38: 1 | L38: 1 | M38: 1 | N38: 1 | P38: 3.0167956
A39: All | B39: Question 38 | C39: 0 | D39: 1 | E39: 1 | F39: 1 | G39: 1 | H39: 1 | I39: 1 | J39: 1 | K39: 1 | L39: 1 | M39: 1 | N39: 1 | P39: 1.4570186
A40: All | B40: Question 39 | C40: 0 | D40: 1 | E40: 1 | F40: 1 | G40: 1 | H40: 1 | I40: 1 | J40: 1 | K40: 1 | L40: 1 | M40: 1 | N40: 1 | P40: 1.3227735
...

Sheet recreation_v2_common_2
A1: Evaluator | B1: Question | C1: status | D1: answerability | E1: primary_kc_alignment | F1: secondary_kc_alignment | G1: topic_alignment | H1: grade_alignment | I1: real_world_feasibility | J1: synergy | K1: clarity | L1: conciseness_and_relevance | M1: language_quality | N1: content_appropriateness | O1: explanation | P1: response_time
A2: All | B2: Question 1 | C2: 0 | D2: 1 | E2: 1 | F2: 1 | G2: 1 | H2: 1 | I2: 1 | J2: 1 | K2: 1 | L2: 1 | M2: 1 | N2: 1 | P2: 1.5273788
A3: All | B3: Question 2 | C3: 0 | D3: 1 | E3: 1 | F3: 1 | G3: 1 | H3: 1 | I3: 1 | J3: 1 | K3: 1 | L3: 1 | M3: 1 | N3: 1 | P3: 1.4075608
A4: All | B4: Question 3 | C4: 0 | D4: 1 | E4: 1 | F4: 1 | G4: 1 | H4: 1 | I4: 1 | J4: 1 | K4: 1 | L4: 1 | M4: 1 | N4: 1 | P4: 1.3210969
A5: All | B5: Question 4 | C5: 0 | D5: 1 | E5: 1 | F5: 1 | G5: 1 | H5: 1 | I5: 1 | J5: 1 | K5: 1 | L5: 1 | M5: 1 | N5: 1 | P5: 1.5837023
A6: All | B6: Question 5 | C6: 0 | D6: 1 | E6: 1 | F6: 1 | G6: 1 | H6: 1 | I6: 1 | J6: 1 | K6: 1 | L6: 1 | M6: 1 | N6: 1 | P6: 4.0828681
A7: All | B7: Question 6 | C7: 0 | D7: 1 | E7: 1 | F7: 1 | G7: 1 | H7: 1 | I7: 1 | J7: 1 | K7: 1 | L7: 1 | M7: 1 | N7: 1 | P7: 1.8642516
A8: All | B8: Question 7 | C8: 0 | D8: 1 | E8: 1 | F8: 1 | G8: 1 | H8: 1 | I8: 1 | J8: 1 | K8: 1 | L8: 1 | M8: 1 | N8: 1 | P8: 2.1124008
A9: All | B9: Question 8 | C9: 0 | D9: 1 | E9: 1 | F9: 1 | G9: 1 | H9: 1 | I9: 1 | J9: 1 | K9: 1 | L9: 1 | M9: 1 | N9: 1 | P9: 1.5286555
A10: All | B10: Question 9 | C10: 0 | D10: 1 | E10: 1 | F10: 1 | G10: 1 | H10: 1 | I10: 1 | J10: 1 | K10: 1 | L10: 1 | M10: 1 | N10: 1 | P10: 1.3453364
A11: All | B11: Question 10 | C11: 0 | D11: 1 | E11: 1 | F11: 1 | G11: 1 | H11: 1 | I11: 1 | J11: 1 | K11: 1 | L11: 1 | M11: 1 | N11: 1 | P11: 1.4256697
A12: All | B12: Question 11 | C12: 0 | D12: 1 | E12: 0 | F12: 1 | G12: 1 | H12: 1 | I12: 1 | J12: 1 | K12: 1 | L12: 1 | M12: 1 | N12: 1 | O12: Primary KC (subtracting mixed numbers) is not central to solving part (a), which is addition of mixed numbers. Although part (b) requires subtraction, it is secondary and uses the result from part (a), making addition (secondary KC) the primary skill in the problem. | P12: 2.6095788
A13: All | B13: Question 12 | C13: 0 | D13: 1 | E13: 1 | F13: 1 | G13: 1 | H13: 1 | I13: 1 | J13: 1 | K13: 1 | L13: 1 | M13: 1 | N13: 1 | P13: 1.6737418
A14: All | B14: Question 13 | C14: 0 | D14: 1 | E14: 0 | F14: 1 | G14: 1 | H14: 1 | I14: 1 | J14: 0 | K14: 1 | L14: 1 | M14: 1 | N14: 1 | O14: primary_kc_alignment: The primary knowledge component is expressing a part of a whole as a percentage. In this problem, only part (b) requires calculating percentage, and it is a straightforward application rather than emphasizing percentage representation as the main focus of the problem. The main calculation required is addition in part (a), making addition appear as the main knowledge component. synergy: The two questions are sequential, but calculating the percentage in (b) uses the answer from (a) as a whole, not integrating both components in a truly synergistic way. The percentage part does not add complexity depending on the addition process, so there is no strong synergy. | P14: 4.3861275
A15: All | B15: Question 14 | C15: 0 | D15: 1 | E15: 1 | F15: 0 | G15: 1 | H15: 1 | I15: 1 | J15: 0 | K15: 1 | L15: 1 | M15: 1 | N15: 1 | O15: Secondary KC: The question only requires division (70 divided by 250) and then expressing as a percentage (by multiplying by 100), which is technically part of the percentage KC. It does not involve explicit multiplication of whole numbers as a second step for problem-solving outside the percentage context, so the secondary KC targeted (whole number multiplication) is not fully required as an independent step.[FORMULA]: The two KCs do not interact as distinct steps. Multiplication by 100 is universally part of converting fractions to percentages, rather than a conceptual multiplication step with whole numbers needed for another reason. | P15: 4.2382126
A16: All | B16: Question 15 | C16: 0 | D16: 1 | E16: 0 | F16: 1 | G16: 1 | H16: 1 | I16: 1 | J16: 1 | K16: 1 | L16: 1 | M16: 1 | N16: 1 | O16: Primary KC Alignment: The problem only requires multiplying a decimal (3.275) by a whole number (20). It does not specifically require multiplying decimals by 10, 100, 1000, or their multiples, as stated in the intended Primary Knowledge Component. The multiplication here does not align with the intended KC focus. | P16: 1.9724753
A17: All | B17: Question 16 | C17: 0 | D17: 1 | E17: 1 | F17: 1 | G17: 1 | H17: 1 | I17: 1 | J17: 1 | K17: 1 | L17: 1 | M17: 1 | N17: 1 | P17: 1.2554104
A18: All | B18: Question 17 | C18: 0 | D18: 1 | E18: 1 | F18: 1 | G18: 1 | H18: 1 | I18: 1 | J18: 1 | K18: 1 | L18: 1 | M18: 1 | N18: 1 | P18: 3.1135337
A19: All | B19: Question 18 | C19: 0 | D19: 1 | E19: 1 | F19: 1 | G19: 0 | H19: 1 | I19: 1 | J19: 1 | K19: 1 | L19: 1 | M19: 1 | N19: 1 | O19: topic_alignment: The problem context is about making bookmarks with ribbon, which is more aligned with crafts or everyday activities, and does not directly fit under 'Recreation' as defined by sports, games, music, movie, dancing, painting, fishing, and other such recreational activities. | P19: 2.2198379
A20: All | B20: Question 19 | C20: 0 | D20: 1 | E20: 1 | F20: 1 | G20: 1 | H20: 1 | I20: 1 | J20: 1 | K20: 1 | L20: 1 | M20: 1 | N20: 1 | P20: 3.0761116
A21: All | B21: Question 20 | C21: 0 | D21: 1 | E21: 1 | F21: 1 | G21: 1 | H21: 1 | I21: 1 | J21: 1 | K21: 1 | L21: 1 | M21: 1 | N21: 1 | P21: 1.4663224
A22: All | B22: Question 21 | C22: 0 | D22: 1 | E22: 1 | F22: 1 | G22: 1 | H22: 1 | I22: 1 | J22: 1 | K22: 1 | L22: 1 | M22: 1 | N22: 1 | P22: 2.0367453
A23: All | B23: Question 22 | C23: 0 | D23: 1 | E23: 1 | F23: 1 | G23: 1 | H23: 1 | I23: 1 | J23: 1 | K23: 1 | L23: 1 | M23: 1 | N23: 1 | P23: 1.4118071
A24: All | B24: Question 23 | C24: 0 | D24: 1 | E24: 0 | F24: 1 | G24: 1 | H24: 0 | I24: 1 | J24: 1 | K24: 1 | L24: 1 | M24: 1 | N24: 1 | O24: Primary KC Alignment: Part (a) asks for subtraction of decimals, but the third round score (7.802) has three decimal places, while the intended KC is subtraction up to 2 decimal places. The word problem thus requires knowledge of subtracting decimals beyond 2 decimal places if the students attempt to compare or incorporate the third round. Grade Alignment: Primary 4 syllabus typically restricts students to operations with decimals up to 2 decimal places. The inclusion of 7.802 in part (b) is slightly above the intended grade level. | P24: 2.8601685
A25: All | B25: Question 24 | C25: 0 | D25: 1 | E25: 1 | F25: 1 | G25: 1 | H25: 1 | I25: 1 | J25: 1 | K25: 1 | L25: 1 | M25: 1 | N25: 1 | P25: 1.563287
A26: All | B26: Question 25 | C26: 0 | D26: 1 | E26: 1 | F26: 1 | G26: 1 | H26: 1 | I26: 1 | J26: 1 | K26: 1 | L26: 1 | M26: 1 | N26: 1 | P26: 1.4376094
A27: All | B27: Question 26 | C27: 0 | D27: 1 | E27: 1 | F27: 1 | G27: 1 | H27: 1 | I27: 1 | J27: 1 | K27: 1 | L27: 1 | M27: 1 | N27: 1 | P27: 1.2657053
A28: All | B28: Question 27 | C28: 0 | D28: 1 | E28: 1 | F28: 1 | G28: 1 | H28: 1 | I28: 1 | J28: 1 | K28: 1 | L28: 1 | M28: 1 | N28: 1 | P28: 1.7621019
A29: All | B29: Question 28 | C29: 0 | D29: 1 | E29: 1 | F29: 1 | G29: 1 | H29: 1 | I29: 1 | J29: 1 | K29: 1 | L29: 1 | M29: 1 | N29: 1 | P29: 1.4680336
A30: All | B30: Question 29 | C30: 0 | D30: 0 | E30: 0 | F30: 1 | G30: 1 | H30: 1 | I30: 1 | J30: 0 | K30: 1 | L30: 0 | M30: 1 | N30: 1 | O30: answerability: The problem gives the total time Elaine spent as 1 hour, but separately states painting and piano as 5/6 and 1/4 hours, whose sum (5/6 + 1/4 = 10/12 + 3/12 = 13/12 = 1 1/12 hrs) exceeds 1 hour contradicting the 'total of 1 hour' statement. The information is conflicting and not answerable.primary_kc_alignment: The intended primary KC is subtracting unlike fractions, but only part (b) needs subtraction (5/6 - 1/4), and since the given numbers for time sum to more than 1, the subtraction does not match a plausible context. The faulty data means this KC is not aligned as intended.synergy: There is no required use of the answer from (a) in (b); each can be done independently. Also, the contradiction in time data hinders meaningful synergy between the problems.conciseness_and_relevance: The statement 'She spent a total of 1 hour doing these activities.' is unnecessary and conflicts with the sum of the provided times, creating confusion and irrelevance in the data. | P30: 4.6284673
A31: All | B31: Question 30 | C31: 0 | D31: 1 | E31: 1 | F31: 1 | G31: 1 | H31: 1 | I31: 1 | J31: 1 | K31: 1 | L31: 1 | M31: 1 | N31: 1 | P31: 1.5381019
A32: All | B32: Question 31 | C32: 0 | D32: 1 | E32: 1 | F32: 1 | G32: 1 | H32: 1 | I32: 1 | J32: 1 | K32: 1 | L32: 1 | M32: 1 | N32: 1 | P32: 1.5017464
A33: All | B33: Question 32 | C33: 0 | D33: 1 | E33: 1 | F33: 1 | G33: 1 | H33: 1 | I33: 0 | J33: 1 | K33: 1 | L33: 1 | M33: 1 | N33: 1 | O33: G: Although the scenario models a standard math situation of inverse proportion, in reality the time taken by a group to learn choreography rarely decreases perfectly inversely with group size. Coordination, teaching limits, and diminishing returns often mean that doubling the group does not halve the learning time. However, for math problem contexts, this is commonly accepted, but it is not truly realistic. | P33: 3.066205
A34: All | B34: Question 33 | C34: 0 | D34: 1 | E34: 1 | F34: 1 | G34: 1 | H34: 1 | I34: 1 | J34: 1 | K34: 1 | L34: 1 | M34: 1 | N34: 1 | P34: 2.1734476
A35: All | B35: Question 34 | C35: 0 | D35: 1 | E35: 1 | F35: 1 | G35: 1 | H35: 1 | I35: 1 | J35: 1 | K35: 1 | L35: 1 | M35: 1 | N35: 1 | P35: 1.3853226
A36: All | B36: Question 35 | C36: 0 | D36: 1 | E36: 1 | F36: 1 | G36: 1 | H36: 1 | I36: 1 | J36: 1 | K36: 1 | L36: 1 | M36: 1 | N36: 1 | P36: 1.4514508
A37: All | B37: Question 36 | C37: 0 | D37: 1 | E37: 1 | F37: 1 | G37: 1 | H37: 1 | I37: 1 | J37: 1 | K37: 1 | L37: 1 | M37: 1 | N37: 1 | P37: 1.4627981
A38: All | B38: Question 37 | C38: 0 | D38: 1 | E38: 1 | F38: 1 | G38: 1 | H38: 1 | I38: 1 | J38: 1 | K38: 1 | L38: 1 | M38: 1 | N38: 1 | P38: 3.6317351
A39: All | B39: Question 38 | C39: 0 | D39: 1 | E39: 1 | F39: 1 | G39: 1 | H39: 1 | I39: 1 | J39: 1 | K39: 1 | L39: 1 | M39: 1 | N39: 1 | P39: 1.3179255
A40: All | B40: Question 39 | C40: 0 | D40: 1 | E40: 1 | F40: 1 | G40: 1 | H40: 1 | I40: 1 | J40: 1 | K40: 1 | L40: 1 | M40: 1 | N40: 1 | P40: 1.4182882
...

Sheet recreation_v2_common_3
A1: Evaluator | B1: Question | C1: status | D1: answerability | E1: primary_kc_alignment | F1: secondary_kc_alignment | G1: topic_alignment | H1: grade_alignment | I1: real_world_feasibility | J1: synergy | K1: clarity | L1: conciseness_and_relevance | M1: language_quality | N1: content_appropriateness | O1: explanation | P1: response_time
A2: All | B2: Question 1 | C2: 0 | D2: 1 | E2: 1 | F2: 1 | G2: 1 | H2: 1 | I2: 1 | J2: 1 | K2: 1 | L2: 1 | M2: 1 | N2: 1 | P2: 1.3903565
A3: All | B3: Question 2 | C3: 0 | D3: 1 | E3: 1 | F3: 1 | G3: 1 | H3: 1 | I3: 1 | J3: 1 | K3: 1 | L3: 1 | M3: 1 | N3: 1 | P3: 1.6623056
A4: All | B4: Question 3 | C4: 0 | D4: 1 | E4: 1 | F4: 1 | G4: 1 | H4: 1 | I4: 1 | J4: 1 | K4: 1 | L4: 1 | M4: 1 | N4: 1 | P4: 1.9156013
A5: All | B5: Question 4 | C5: 0 | D5: 1 | E5: 1 | F5: 1 | G5: 1 | H5: 1 | I5: 1 | J5: 1 | K5: 1 | L5: 1 | M5: 1 | N5: 1 | P5: 1.9153974
A6: All | B6: Question 5 | C6: 0 | D6: 1 | E6: 1 | F6: 1 | G6: 1 | H6: 1 | I6: 1 | J6: 1 | K6: 1 | L6: 1 | M6: 1 | N6: 1 | P6: 2.6678784
A7: All | B7: Question 6 | C7: 0 | D7: 1 | E7: 1 | F7: 1 | G7: 1 | H7: 1 | I7: 1 | J7: 1 | K7: 1 | L7: 1 | M7: 1 | N7: 1 | P7: 1.25776
A8: All | B8: Question 7 | C8: 0 | D8: 1 | E8: 1 | F8: 1 | G8: 1 | H8: 1 | I8: 1 | J8: 1 | K8: 1 | L8: 1 | M8: 1 | N8: 1 | P8: 1.4543834
A9: All | B9: Question 8 | C9: 0 | D9: 1 | E9: 1 | F9: 1 | G9: 1 | H9: 1 | I9: 1 | J9: 1 | K9: 1 | L9: 1 | M9: 1 | N9: 1 | P9: 2.1317558
A10: All | B10: Question 9 | C10: 0 | D10: 1 | E10: 1 | F10: 1 | G10: 1 | H10: 1 | I10: 1 | J10: 1 | K10: 1 | L10: 1 | M10: 1 | N10: 1 | P10: 1.52564
A11: All | B11: Question 10 | C11: 0 | D11: 1 | E11: 1 | F11: 1 | G11: 1 | H11: 1 | I11: 1 | J11: 1 | K11: 1 | L11: 1 | M11: 1 | N11: 1 | P11: 1.7444935
A12: All | B12: Question 11 | C12: 0 | D12: 1 | E12: 0 | F12: 1 | G12: 1 | H12: 1 | I12: 1 | J12: 1 | K12: 1 | L12: 1 | M12: 1 | N12: 1 | O12: Primary KC Alignment (0): The main operation required first is addition of mixed numbers to find the total distance cycled before and after the break. To answer part (b), subtraction of mixed numbers is used, but it is secondary since the student must first add in (a). The question more centrally assesses addition of mixed numbers (secondary KC) rather than subtraction (primary KC), so it does not fully satisfy the intended hierarchy. | P12: 2.6786718
A13: All | B13: Question 12 | C13: 0 | D13: 1 | E13: 1 | F13: 1 | G13: 1 | H13: 1 | I13: 1 | J13: 1 | K13: 1 | L13: 1 | M13: 1 | N13: 1 | P13: 1.5335813
A14: All | B14: Question 13 | C14: 0 | D14: 1 | E14: 0 | F14: 1 | G14: 1 | H14: 1 | I14: 1 | J14: 1 | K14: 1 | L14: 1 | M14: 1 | N14: 1 | O14: The primary knowledge component is percentage, with the focus on 'expressing a part of a whole as a percentage.' In this problem, students are asked to find the percentage of swimming participants out of the total, which appears to match. However, the application does not fully align with the Singapore syllabus's expectation for Primary 5, which typically requires a deeper or less scaffolded engagement with percentages—such as finding percentage given a part and a whole, solving for unknowns or interpreting practical situations. Here, the first part gives away the total, and the second part is a direct calculation. Furthermore, the knowledge component used for answering (b) is somewhat basic and doesn't require significant understanding of percentages beyond plugging numbers into a formula, which can be addressed as a calculation routine. Therefore, partial alignment, but not full as intended. | P14: 3.4027882
A15: All | B15: Question 14 | C15: 0 | D15: 1 | E15: 1 | F15: 0 | G15: 1 | H15: 1 | I15: 1 | J15: 0 | K15: 1 | L15: 1 | M15: 1 | N15: 1 | O15: Secondary KC: The calculation to find percentage is (70/250)*100, which involves division and multiplication with 100, but 'multiplying whole numbers' as a secondary KC is not specifically required or highlighted in this problem, as P5 students already commonly multiply by 100 as part of percentage concept. Synergy: The multiplication skill (secondary KC) does not add a layer of complexity independently or in tandem—the entire calculation is integral to finding the percentage. If there were a step where students must multiply numbers first before plugging the result into a percentage calculation, synergy would be stronger. | P15: 2.7624059
A16: All | B16: Question 15 | C16: 0 | D16: 1 | E16: 0 | F16: 1 | G16: 1 | H16: 1 | I16: 1 | J16: 1 | K16: 1 | L16: 1 | M16: 1 | N16: 1 | O16: Primary KC Alignment: The intended primary knowledge component is multiplying decimals (up to 3 decimal places) by 10, 100, 1000, and their multiples. The problem instead requires multiplying 3.275 by 20, which is NOT a multiplication by 10, 100, 1000, or multiples thereof, but rather a general multiplication of a decimal by a whole number. This does not precisely match the letter of the intended knowledge component. | P16: 2.4263031
A17: All | B17: Question 16 | C17: 0 | D17: 1 | E17: 1 | F17: 1 | G17: 1 | H17: 1 | I17: 1 | J17: 1 | K17: 1 | L17: 1 | M17: 1 | N17: 1 | P17: 1.3294127
A18: All | B18: Question 17 | C18: 0 | D18: 1 | E18: 1 | F18: 1 | G18: 1 | H18: 1 | I18: 1 | J18: 1 | K18: 1 | L18: 1 | M18: 1 | N18: 1 | P18: 1.5226545
A19: All | B19: Question 18 | C19: 0 | D19: 1 | E19: 1 | F19: 0 | G19: 0 | H19: 1 | I19: 1 | J19: 1 | K19: 1 | L19: 1 | M19: 1 | N19: 1 | O19: Secondary Knowledge Component: In (b), the solution requires finding how many bookmarks Lina gave away by multiplying a fraction by a whole number (fraction of a quantity), and then subtracting that from the total. The explicit act of subtracting fractions (e.g., 6 - 4/5) does not appear; instead, the fractional value is subtracted as a whole number quantity. Therefore, the secondary KC is not directly needed. Topic Alignment: The intended topic is 'Recreation such as sports, games, exercises, music, movie, dancing, painting, fishing and other recreation activities.' Making bookmarks with ribbon, while a craft, does not explicitly match these specified recreational activities. | P19: 5.1856549
A20: All | B20: Question 19 | C20: 0 | D20: 1 | E20: 1 | F20: 1 | G20: 1 | H20: 1 | I20: 1 | J20: 1 | K20: 1 | L20: 1 | M20: 1 | N20: 1 | P20: 1.3287339
A21: All | B21: Question 20 | C21: 0 | D21: 1 | E21: 1 | F21: 1 | G21: 1 | H21: 1 | I21: 1 | J21: 1 | K21: 1 | L21: 1 | M21: 1 | N21: 1 | P21: 1.2949991
A22: All | B22: Question 21 | C22: 0 | D22: 1 | E22: 1 | F22: 1 | G22: 1 | H22: 1 | I22: 1 | J22: 1 | K22: 1 | L22: 1 | M22: 1 | N22: 1 | P22: 1.406503
A23: All | B23: Question 22 | C23: 0 | D23: 1 | E23: 1 | F23: 1 | G23: 1 | H23: 1 | I23: 1 | J23: 1 | K23: 1 | L23: 1 | M23: 1 | N23: 1 | P23: 1.9687953
A24: All | B24: Question 23 | C24: 0 | D24: 1 | E24: 0 | F24: 1 | G24: 1 | H24: 0 | I24: 1 | J24: 0 | K24: 1 | L24: 1 | M24: 1 | N24: 1 | O24: Primary KC alignment: The subtraction in part (a) involves 7.85 - 6.43, which both have up to 2 decimal places and is good, but in part (b), students also need to compare 7.802, which has 3 decimal places, which exceeds the intended primary K.C. of comparing up to 2 decimal places only. Grade alignment: Comparing and ordering decimals to 3 decimal places is not typically required at Primary 4 according to the Singapore syllabus. Synergy: The two parts (a) and (b) are independent; the answer from (a) is not needed to solve (b), so there is no synergy between questions. | P24: 4.6911037
A25: All | B25: Question 24 | C25: 0 | D25: 1 | E25: 1 | F25: 1 | G25: 1 | H25: 1 | I25: 1 | J25: 1 | K25: 1 | L25: 1 | M25: 1 | N25: 1 | P25: 1.2620041
A26: All | B26: Question 25 | C26: 0 | D26: 1 | E26: 1 | F26: 1 | G26: 1 | H26: 1 | I26: 1 | J26: 1 | K26: 1 | L26: 1 | M26: 1 | N26: 1 | P26: 1.3513937
A27: All | B27: Question 26 | C27: 0 | D27: 1 | E27: 1 | F27: 1 | G27: 1 | H27: 1 | I27: 1 | J27: 1 | K27: 1 | L27: 1 | M27: 1 | N27: 1 | P27: 2.3128715
A28: All | B28: Question 27 | C28: 0 | D28: 1 | E28: 1 | F28: 1 | G28: 1 | H28: 1 | I28: 1 | J28: 1 | K28: 1 | L28: 1 | M28: 1 | N28: 1 | P28: 2.0715375
A29: All | B29: Question 28 | C29: 0 | D29: 1 | E29: 1 | F29: 1 | G29: 1 | H29: 1 | I29: 1 | J29: 1 | K29: 1 | L29: 1 | M29: 1 | N29: 1 | P29: 1.4633749
A30: All | B30: Question 29 | C30: 0 | D30: 0 | E30: 0 | F30: 1 | G30: 1 | H30: 1 | I30: 1 | J30: 0 | K30: 1 | L30: 0 | M30: 1 | N30: 1 | O30: answerability: The sum of the times is 5/6 + 1/4, which is more than 1 hour (5/6 + 1/4 = 10/12 + 3/12 = 13/12 > 1), but the problem states Elaine spent a total of 1 hour, creating a conflict and making it unanswerable. primary_kc_alignment: Although subtraction of unlike fractions is intended for (b), the problem's focus is clouded because the sum (a) involves addition, and (b) requires subtraction, but the conflicting information about the total time makes it invalid. synergy: Parts (a) and (b) are not connected as the result of (a) is not used in (b), and no meaningful tandem use of both KCs is required. conciseness_and_relevance: The statement 'She spent a total of 1 hour doing these activities' is false based on the numbers given and introduces confusion, making the information not relevant or consistent. | P30: 4.3817699
A31: All | B31: Question 30 | C31: 0 | D31: 1 | E31: 1 | F31: 1 | G31: 1 | H31: 1 | I31: 1 | J31: 1 | K31: 1 | L31: 1 | M31: 1 | N31: 1 | P31: 1.719101
A32: All | B32: Question 31 | C32: 0 | D32: 1 | E32: 1 | F32: 1 | G32: 1 | H32: 1 | I32: 1 | J32: 1 | K32: 1 | L32: 1 | M32: 1 | N32: 1 | P32: 1.5144196
A33: All | B33: Question 32 | C33: 0 | D33: 1 | E33: 1 | F33: 1 | G33: 1 | H33: 1 | I33: 1 | J33: 1 | K33: 1 | L33: 1 | M33: 1 | N33: 1 | P33: 1.5091593
A34: All | B34: Question 33 | C34: 0 | D34: 1 | E34: 1 | F34: 1 | G34: 1 | H34: 1 | I34: 1 | J34: 1 | K34: 1 | L34: 1 | M34: 1 | N34: 1 | P34: 2.0616333
A35: All | B35: Question 34 | C35: 0 | D35: 1 | E35: 1 | F35: 1 | G35: 1 | H35: 1 | I35: 1 | J35: 1 | K35: 1 | L35: 1 | M35: 1 | N35: 1 | P35: 2.1403296
A36: All | B36: Question 35 | C36: 0 | D36: 1 | E36: 1 | F36: 1 | G36: 1 | H36: 1 | I36: 1 | J36: 1 | K36: 1 | L36: 1 | M36: 1 | N36: 1 | P36: 1.2684345
A37: All | B37: Question 36 | C37: 0 | D37: 1 | E37: 1 | F37: 1 | G37: 1 | H37: 1 | I37: 1 | J37: 1 | K37: 1 | L37: 1 | M37: 1 | N37: 1 | P37: 1.3569059
A38: All | B38: Question 37 | C38: 0 | D38: 1 | E38: 1 | F38: 1 | G38: 1 | H38: 1 | I38: 1 | J38: 1 | K38: 1 | L38: 1 | M38: 1 | N38: 1 | P38: 1.337923
A39: All | B39: Question 38 | C39: 0 | D39: 1 | E39: 1 | F39: 1 | G39: 1 | H39: 1 | I39: 1 | J39: 1 | K39: 1 | L39: 1 | M39: 1 | N39: 1 | P39: 1.5715656
A40: All | B40: Question 39 | C40: 0 | D40: 1 | E40: 1 | F40: 1 | G40: 1 | H40: 1 | I40: 1 | J40: 1 | K40: 1 | L40: 1 | M40: 1 | N40: 1 | P40: 1.5883608
...

Sheet recreation_v2_common_4
A1: Evaluator | B1: Question | C1: status | D1: answerability | E1: primary_kc_alignment | F1: secondary_kc_alignment | G1: topic_alignment | H1: grade_alignment | I1: real_world_feasibility | J1: synergy | K1: clarity | L1: conciseness_and_relevance | M1: language_quality | N1: content_appropriateness | O1: explanation | P1: response_time
A2: All | B2: Question 1 | C2: 0 | D2: 1 | E2: 1 | F2: 1 | G2: 1 | H2: 1 | I2: 1 | J2: 1 | K2: 1 | L2: 1 | M2: 1 | N2: 1 | P2: 2.6142495
A3: All | B3: Question 2 | C3: 0 | D3: 1 | E3: 1 | F3: 1 | G3: 1 | H3: 1 | I3: 1 | J3: 1 | K3: 1 | L3: 1 | M3: 1 | N3: 1 | P3: 2.0073767
A4: All | B4: Question 3 | C4: 0 | D4: 1 | E4: 1 | F4: 1 | G4: 1 | H4: 1 | I4: 1 | J4: 1 | K4: 1 | L4: 1 | M4: 1 | N4: 1 | P4: 1.8472683
A5: All | B5: Question 4 | C5: 0 | D5: 1 | E5: 1 | F5: 1 | G5: 1 | H5: 1 | I5: 1 | J5: 1 | K5: 1 | L5: 1 | M5: 1 | N5: 1 | P5: 1.4543777
A6: All | B6: Question 5 | C6: 0 | D6: 1 | E6: 1 | F6: 1 | G6: 1 | H6: 1 | I6: 1 | J6: 1 | K6: 1 | L6: 1 | M6: 1 | N6: 1 | P6: 2.3461075
A7: All | B7: Question 6 | C7: 0 | D7: 1 | E7: 1 | F7: 1 | G7: 1 | H7: 1 | I7: 1 | J7: 1 | K7: 1 | L7: 1 | M7: 1 | N7: 1 | P7: 1.6648738
A8: All | B8: Question 7 | C8: 0 | D8: 1 | E8: 1 | F8: 1 | G8: 1 | H8: 1 | I8: 1 | J8: 1 | K8: 1 | L8: 1 | M8: 1 | N8: 1 | P8: 1.6408262
A9: All | B9: Question 8 | C9: 0 | D9: 1 | E9: 1 | F9: 1 | G9: 1 | H9: 1 | I9: 1 | J9: 1 | K9: 1 | L9: 1 | M9: 1 | N9: 1 | P9: 1.4178624
A10: All | B10: Question 9 | C10: 0 | D10: 1 | E10: 1 | F10: 1 | G10: 1 | H10: 1 | I10: 1 | J10: 1 | K10: 1 | L10: 1 | M10: 1 | N10: 1 | P10: 2.1736014
A11: All | B11: Question 10 | C11: 0 | D11: 1 | E11: 1 | F11: 1 | G11: 1 | H11: 1 | I11: 1 | J11: 1 | K11: 1 | L11: 1 | M11: 1 | N11: 1 | P11: 2.1429029
A12: All | B12: Question 11 | C12: 0 | D12: 1 | E12: 0 | F12: 1 | G12: 1 | H12: 1 | I12: 1 | J12: 1 | K12: 1 | L12: 1 | M12: 1 | N12: 1 | O12: Primary KC alignment is rated 0 because the main calculation in (a) is adding mixed numbers (adding fractions), and in (b) the student needs to subtract a mixed number from another mixed number (8 1/2 - the total found in (a)). While subtraction of mixed numbers is used in (b), the main and first operation in the problem is addition of mixed numbers, which would be considered the primary KC, not subtraction. | P12: 2.9791348
A13: All | B13: Question 12 | C13: 0 | D13: 1 | E13: 1 | F13: 1 | G13: 1 | H13: 1 | I13: 1 | J13: 1 | K13: 1 | L13: 1 | M13: 1 | N13: 1 | P13: 1.762229
A14: All | B14: Question 13 | C14: 0 | D14: 1 | E14: 1 | F14: 1 | G14: 1 | H14: 1 | I14: 1 | J14: 1 | K14: 1 | L14: 1 | M14: 1 | N14: 1 | P14: 1.5345891
A15: All | B15: Question 14 | C15: 0 | D15: 1 | E15: 1 | F15: 0 | G15: 1 | H15: 1 | I15: 1 | J15: 0 | K15: 1 | L15: 1 | M15: 1 | N15: 1 | O15: Secondary Knowledge Component (Multiplying whole numbers) is not explicitly needed because finding the percentage involves dividing 70 by 250 and multiplying by 100, but the multiplication involved (by 100) is not the focus and does not add meaningful complexity as secondary KC here.[FORMULA]: The secondary KC does not work in tandem with the primary; only expressing as percentage is needed, and multiplication step is routine within percentage calculation, not as a genuine separate skill required. | P15: 2.7643158
A16: All | B16: Question 15 | C16: 0 | D16: 1 | E16: 0 | F16: 1 | G16: 1 | H16: 1 | I16: 1 | J16: 0 | K16: 1 | L16: 1 | M16: 1 | N16: 1 | O16: Primary KC: The problem requires multiplying a decimal (3.275) by a whole number (20), which is standard multiplication, but the Primary KC specifies 'multiplying decimals (up to 3 decimal places) by 10, 100, 1000 and their multiples.' Here, 20 is not a power of ten or its straightforward multiple used in such contexts.[FORMULA]: The primary and secondary KCs do not work strictly in tandem; while rounding (secondary) is only used after a regular decimal x whole number multiplication (not the intended Primary KC), so both are not needed together to generate the answer for any single part. | P16: 2.9045937
A17: All | B17: Question 16 | C17: 0 | D17: 1 | E17: 1 | F17: 1 | G17: 1 | H17: 1 | I17: 1 | J17: 1 | K17: 1 | L17: 1 | M17: 1 | N17: 1 | P17: 1.5538397
A18: All | B18: Question 17 | C18: 0 | D18: 1 | E18: 1 | F18: 1 | G18: 1 | H18: 1 | I18: 1 | J18: 1 | K18: 1 | L18: 1 | M18: 1 | N18: 1 | P18: 1.8102825
A19: All | B19: Question 18 | C19: 0 | D19: 1 | E19: 1 | F19: 0 | G19: 0 | H19: 1 | I19: 1 | J19: 1 | K19: 1 | L19: 1 | M19: 1 | N19: 1 | O19: Secondary KC alignment: The intended secondary knowledge component is 'subtracting fractions', but part (b) requires subtracting a whole number from a whole number, not fractions.Topic alignment: Making bookmarks is not directly aligned with 'recreation' as defined by activities like sports, games, music, dancing, painting, fishing, and other similar activities. | P19: 3.3812983
A20: All | B20: Question 19 | C20: 0 | D20: 1 | E20: 1 | F20: 1 | G20: 1 | H20: 1 | I20: 1 | J20: 1 | K20: 1 | L20: 1 | M20: 1 | N20: 1 | P20: 2.1634693
A21: All | B21: Question 20 | C21: 0 | D21: 1 | E21: 1 | F21: 1 | G21: 1 | H21: 1 | I21: 1 | J21: 1 | K21: 1 | L21: 1 | M21: 1 | N21: 1 | P21: 1.9569945
A22: All | B22: Question 21 | C22: 0 | D22: 1 | E22: 1 | F22: 1 | G22: 1 | H22: 1 | I22: 1 | J22: 1 | K22: 1 | L22: 1 | M22: 1 | N22: 1 | P22: 1.9358702
A23: All | B23: Question 22 | C23: 0 | D23: 1 | E23: 1 | F23: 1 | G23: 1 | H23: 1 | I23: 1 | J23: 1 | K23: 1 | L23: 1 | M23: 1 | N23: 1 | P23: 2.7851334
A24: All | B24: Question 23 | C24: 0 | D24: 1 | E24: 0 | F24: 1 | G24: 1 | H24: 0 | I24: 1 | J24: 1 | K24: 1 | L24: 1 | M24: 1 | N24: 1 | O24: primary_kc_alignment: The subtraction between $7.85$ (2 d.p.) and $6.43$ (2 d.p.) matches the primary KC, but the inclusion of $7.802$ (3 d.p.) in the data causes the problem to contain numbers outside of the intended difficulty, as Primary 4 focuses on up to 2 decimal places only. grade_alignment: The third round score ($7.802$) requires handling decimals to 3 decimal places, which is beyond the intended Primary 4 level for both subtraction and comparison. | P24: 3.425174
A25: All | B25: Question 24 | C25: 0 | D25: 1 | E25: 1 | F25: 1 | G25: 1 | H25: 1 | I25: 1 | J25: 1 | K25: 1 | L25: 1 | M25: 1 | N25: 1 | P25: 1.620048
A26: All | B26: Question 25 | C26: 0 | D26: 1 | E26: 1 | F26: 1 | G26: 1 | H26: 1 | I26: 1 | J26: 1 | K26: 1 | L26: 1 | M26: 1 | N26: 1 | P26: 1.4135756
A27: All | B27: Question 26 | C27: 0 | D27: 1 | E27: 1 | F27: 1 | G27: 1 | H27: 1 | I27: 1 | J27: 1 | K27: 1 | L27: 1 | M27: 1 | N27: 1 | P27: 1.8719897
A28: All | B28: Question 27 | C28: 0 | D28: 1 | E28: 1 | F28: 1 | G28: 1 | H28: 1 | I28: 0 | J28: 1 | K28: 1 | L28: 1 | M28: 1 | N28: 1 | O28: G: It is highly unrealistic for a game of badminton to last [FORMULA] (2[FORMULA]) hours and for a group to complete exactly [FORMULA] (2[FORMULA]) games. In typical real-world recreation, games have standard durations (commonly under 1 hour). People do not count games in halves quite this way, nor does a single game last so long. This makes the scenario implausible as described. | P28: 2.9788249
A29: All | B29: Question 28 | C29: 0 | D29: 1 | E29: 1 | F29: 1 | G29: 1 | H29: 1 | I29: 1 | J29: 1 | K29: 1 | L29: 1 | M29: 1 | N29: 1 | P29: 1.8336248
A30: All | B30: Question 29 | C30: 0 | D30: 0 | E30: 0 | F30: 1 | G30: 1 | H30: 1 | I30: 0 | J30: 0 | K30: 1 | L30: 1 | M30: 1 | N30: 1 | O30: answerability: (a) asks for the sum of the times, but the next sentence already contradicts this by declaring the total as '1 hour,' which is not the sum of 5/6 + 1/4 (which equals 13/12). The facts in the problem are inconsistent. primary_kc_alignment: The subtraction of 5/6 - 1/4 is never explicitly required for the answer to (a), and for (b), the main KC is subtraction, but because the premise is inconsistent, its application is meaningless. synergy: Since the explicit total given (1 hour) contradicts the operation needed for (a), the questions do not build coherently on one another; (a) cannot logically feed into (b) due to contradiction. real_world_feasibility: The premise includes spending 5/6 hour on one activity and 1/4 hour on another in one afternoon, but claims the sum is 1 hour, which is not true or realistic; it makes the scenario impossible. | P30: 5.5380611
A31: All | B31: Question 30 | C31: 0 | D31: 1 | E31: 1 | F31: 1 | G31: 1 | H31: 1 | I31: 1 | J31: 1 | K31: 1 | L31: 1 | M31: 1 | N31: 1 | P31: 1.3675561
A32: All | B32: Question 31 | C32: 0 | D32: 1 | E32: 1 | F32: 1 | G32: 1 | H32: 1 | I32: 1 | J32: 1 | K32: 1 | L32: 1 | M32: 1 | N32: 1 | P32: 1.3986461
A33: All | B33: Question 32 | C33: 0 | D33: 1 | E33: 1 | F33: 1 | G33: 1 | H33: 1 | I33: 1 | J33: 1 | K33: 1 | L33: 1 | M33: 1 | N33: 1 | P33: 1.4445076
A34: All | B34: Question 33 | C34: 0 | D34: 1 | E34: 1 | F34: 1 | G34: 1 | H34: 1 | I34: 1 | J34: 1 | K34: 1 | L34: 1 | M34: 1 | N34: 1 | P34: 1.9434144
A35: All | B35: Question 34 | C35: 0 | D35: 1 | E35: 1 | F35: 1 | G35: 1 | H35: 1 | I35: 1 | J35: 1 | K35: 1 | L35: 1 | M35: 1 | N35: 1 | P35: 1.4375687
A36: All | B36: Question 35 | C36: 0 | D36: 1 | E36: 1 | F36: 1 | G36: 1 | H36: 1 | I36: 1 | J36: 1 | K36: 1 | L36: 1 | M36: 1 | N36: 1 | P36: 1.5380859
A37: All | B37: Question 36 | C37: 0 | D37: 1 | E37: 1 | F37: 1 | G37: 1 | H37: 1 | I37: 1 | J37: 1 | K37: 1 | L37: 1 | M37: 1 | N37: 1 | P37: 1.651494
A38: All | B38: Question 37 | C38: 0 | D38: 1 | E38: 1 | F38: 1 | G38: 1 | H38: 1 | I38: 1 | J38: 1 | K38: 1 | L38: 1 | M38: 1 | N38: 1 | P38: 1.8525784
A39: All | B39: Question 38 | C39: 0 | D39: 1 | E39: 1 | F39: 1 | G39: 1 | H39: 1 | I39: 1 | J39: 0 | K39: 1 | L39: 1 | M39: 1 | N39: 1 | O39: The two parts (a) and (b) are not directly interconnected: part (b) does not require the answer from part (a) but is solved independently using the information about the last day only. For full synergy, ideally, information or results from (a) would be needed in (b). | P39: 2.7792919
A40: All | B40: Question 39 | C40: 0 | D40: 1 | E40: 1 | F40: 1 | G40: 1 | H40: 1 | I40: 1 | J40: 1 | K40: 1 | L40: 1 | M40: 1 | N40: 1 | P40: 1.4226875
...

Sheet recreation_v2_common_5
A1: Evaluator | B1: Question | C1: status | D1: answerability | E1: primary_kc_alignment | F1: secondary_kc_alignment | G1: topic_alignment | H1: grade_alignment | I1: real_world_feasibility | J1: synergy | K1: clarity | L1: conciseness_and_relevance | M1: language_quality | N1: content_appropriateness | O1: explanation | P1: response_time
A2: All | B2: Question 1 | C2: 0 | D2: 1 | E2: 1 | F2: 1 | G2: 1 | H2: 1 | I2: 1 | J2: 1 | K2: 1 | L2: 1 | M2: 1 | N2: 1 | P2: 1.535495
A3: All | B3: Question 2 | C3: 0 | D3: 1 | E3: 1 | F3: 1 | G3: 1 | H3: 1 | I3: 1 | J3: 1 | K3: 1 | L3: 1 | M3: 1 | N3: 1 | P3: 1.4433422
A4: All | B4: Question 3 | C4: 0 | D4: 1 | E4: 1 | F4: 1 | G4: 1 | H4: 1 | I4: 1 | J4: 1 | K4: 1 | L4: 1 | M4: 1 | N4: 1 | P4: 1.6430717
A5: All | B5: Question 4 | C5: 0 | D5: 1 | E5: 1 | F5: 1 | G5: 1 | H5: 1 | I5: 1 | J5: 1 | K5: 1 | L5: 1 | M5: 1 | N5: 1 | P5: 1.6684437
A6: All | B6: Question 5 | C6: 0 | D6: 1 | E6: 1 | F6: 1 | G6: 1 | H6: 1 | I6: 1 | J6: 1 | K6: 1 | L6: 1 | M6: 1 | N6: 1 | P6: 2.0273478
A7: All | B7: Question 6 | C7: 0 | D7: 1 | E7: 1 | F7: 1 | G7: 1 | H7: 1 | I7: 1 | J7: 1 | K7: 1 | L7: 1 | M7: 1 | N7: 1 | P7: 1.4518943
A8: All | B8: Question 7 | C8: 0 | D8: 1 | E8: 1 | F8: 1 | G8: 1 | H8: 1 | I8: 1 | J8: 1 | K8: 1 | L8: 1 | M8: 1 | N8: 1 | P8: 2.3503082
A9: All | B9: Question 8 | C9: 0 | D9: 1 | E9: 1 | F9: 1 | G9: 1 | H9: 1 | I9: 1 | J9: 1 | K9: 1 | L9: 1 | M9: 1 | N9: 1 | P9: 1.3405204
A10: All | B10: Question 9 | C10: 0 | D10: 1 | E10: 1 | F10: 1 | G10: 1 | H10: 1 | I10: 1 | J10: 1 | K10: 1 | L10: 1 | M10: 1 | N10: 1 | P10: 2.1477404
A11: All | B11: Question 10 | C11: 0 | D11: 1 | E11: 1 | F11: 1 | G11: 1 | H11: 1 | I11: 1 | J11: 1 | K11: 1 | L11: 1 | M11: 1 | N11: 1 | P11: 3.0851109
A12: All | B12: Question 11 | C12: 0 | D12: 1 | E12: 0 | F12: 1 | G12: 1 | H12: 1 | I12: 1 | J12: 1 | K12: 1 | L12: 1 | M12: 1 | N12: 1 | O12: Primary Knowledge Component Alignment: The main calculation in the first part requires addition of mixed numbers (secondary KC: addition of fractions/mixed numbers), while the second part requires subtraction of mixed numbers (primary KC). The problem order makes addition the initial and primary required knowledge, thus misaligning with the intended primary knowledge component of subtraction of mixed numbers. | P12: 2.3609169
A13: All | B13: Question 12 | C13: 0 | D13: 1 | E13: 1 | F13: 1 | G13: 1 | H13: 1 | I13: 1 | J13: 1 | K13: 1 | L13: 1 | M13: 1 | N13: 1 | P13: 1.3451829
A14: All | B14: Question 13 | C14: 0 | D14: 1 | E14: 1 | F14: 1 | G14: 1 | H14: 1 | I14: 1 | J14: 1 | K14: 1 | L14: 1 | M14: 1 | N14: 1 | P14: 2.0411274
A15: All | B15: Question 14 | C15: 0 | D15: 1 | E15: 1 | F15: 0 | G15: 1 | H15: 1 | I15: 1 | J15: 0 | K15: 1 | L15: 1 | M15: 1 | N15: 1 | O15: Secondary Knowledge Component: The problem requires division and multiplication by 100 when finding the percentage (e.g., 70 / 250 * 100), but the explicit requirement for using multiplication as a standalone knowledge component (beyond scaling by 100 in conversion) is minimal. Division is the main operation apart from representing as a percentage, so it does not fully satisfy the intent of a multiplication knowledge component for its own sake. Synergy: The requirement to multiply whole numbers is not distinctly needed for the solution, as multiplication is only applied as part of converting a fraction to a percentage; it is not interactively paired with the primary knowledge component in a way that both are jointly necessary. | P15: 2.9808941
A16: All | B16: Question 15 | C16: 0 | D16: 1 | E16: 0 | F16: 1 | G16: 1 | H16: 1 | I16: 1 | J16: 1 | K16: 1 | L16: 1 | M16: 1 | N16: 1 | O16: Primary KC alignment: The multiplication required in the question is '3.275 × 20'. The intended Primary Knowledge Component is multiplying decimals (up to 3 decimal places) by 10, 100, 1000 and their multiples. However, multiplying by 20 is not within the specified KC, which restricts to 10, 100, 1000 and their multiples (i.e., 10×, 100×, 1000× etc.), while 20 is not a direct multiple of 10, 100, or 1000 according to Singapore syllabus; usually such items require multiplying by numbers like 10, 20, 40, 100 etc. For Primary 5 in Singapore math, the KC intended here focuses on clean multiples of 10, 100, or 1000. If strict adherence is required, multiplying by 20 may be considered marginal and not strictly matching the intent of multiplying by 10, 100, 1000 and their multiples (interpreted as numbers like 30, 40, 50, 100, 200 etc. but the curriculum usually assesses multiplying by 10/100/1000 and shifting decimal places, not just general two-digit numbers). If we take 'multiples' to include 20, then it could be 1; but strict curriculum interpretation would mark it as 0. | P16: 6.3048511
A17: All | B17: Question 16 | C17: 0 | D17: 1 | E17: 1 | F17: 1 | G17: 1 | H17: 1 | I17: 1 | J17: 1 | K17: 1 | L17: 1 | M17: 1 | N17: 1 | P17: 1.822746
A18: All | B18: Question 17 | C18: 0 | D18: 1 | E18: 1 | F18: 1 | G18: 1 | H18: 1 | I18: 1 | J18: 1 | K18: 1 | L18: 1 | M18: 1 | N18: 1 | P18: 2.5585396
A19: All | B19: Question 18 | C19: 0 | D19: 1 | E19: 1 | F19: 1 | G19: 0 | H19: 1 | I19: 1 | J19: 1 | K19: 1 | L19: 1 | M19: 1 | N19: 1 | O19: E.5: The context 'making bookmarks out of ribbon' does not fit under the intended topic of 'Recreation such as sports, games, exercises, music, movie, dancing, painting, fishing and other recreation activities.' It is more related to a crafts or practical context rather than recreation or sports. | P19: 2.0686698
A20: All | B20: Question 19 | C20: 0 | D20: 1 | E20: 1 | F20: 1 | G20: 1 | H20: 1 | I20: 1 | J20: 1 | K20: 1 | L20: 1 | M20: 1 | N20: 1 | P20: 2.5558918
A21: All | B21: Question 20 | C21: 0 | D21: 1 | E21: 1 | F21: 1 | G21: 1 | H21: 1 | I21: 1 | J21: 1 | K21: 1 | L21: 1 | M21: 1 | N21: 1 | P21: 1.5312564
A22: All | B22: Question 21 | C22: 0 | D22: 1 | E22: 1 | F22: 1 | G22: 1 | H22: 1 | I22: 1 | J22: 1 | K22: 1 | L22: 1 | M22: 1 | N22: 1 | P22: 1.6431608
A23: All | B23: Question 22 | C23: 0 | D23: 1 | E23: 1 | F23: 1 | G23: 1 | H23: 1 | I23: 1 | J23: 1 | K23: 1 | L23: 1 | M23: 1 | N23: 1 | P23: 1.4406567
A24: All | B24: Question 23 | C24: 0 | D24: 1 | E24: 0 | F24: 1 | G24: 1 | H24: 0 | I24: 1 | J24: 1 | K24: 1 | L24: 1 | M24: 1 | N24: 1 | O24: Primary KC (subtracting decimals, up to 2 decimal places): The first and second numbers have 2 decimal places, so part (a) aligns. However, the third score (7.802) has 3 decimal places, which is not required for subtraction in part (a). Part (a) meets Primary KC, but including 7.802 in the data could mislead students to unnecessarily consider more decimal places for subtraction at this grade.Grade Alignment: The word problem includes a score of 7.802 (3 decimal places), but Primary 4 generally expects comparison of decimals up to 2 decimal places, not 3. This could make (b) slightly above the intended difficulty for Primary 4. | P24: 3.5868127
A25: All | B25: Question 24 | C25: 0 | D25: 1 | E25: 1 | F25: 1 | G25: 1 | H25: 1 | I25: 1 | J25: 1 | K25: 1 | L25: 1 | M25: 1 | N25: 1 | P25: 1.4421842
A26: All | B26: Question 25 | C26: 0 | D26: 1 | E26: 1 | F26: 1 | G26: 1 | H26: 1 | I26: 1 | J26: 1 | K26: 1 | L26: 1 | M26: 1 | N26: 1 | P26: 1.5506692
A27: All | B27: Question 26 | C27: 0 | D27: 1 | E27: 1 | F27: 1 | G27: 1 | H27: 1 | I27: 1 | J27: 1 | K27: 1 | L27: 1 | M27: 1 | N27: 1 | P27: 1.6423352
A28: All | B28: Question 27 | C28: 0 | D28: 1 | E28: 1 | F28: 1 | G28: 1 | H28: 1 | I28: 1 | J28: 1 | K28: 1 | L28: 1 | M28: 1 | N28: 1 | P28: 1.4204416
A29: All | B29: Question 28 | C29: 0 | D29: 1 | E29: 1 | F29: 1 | G29: 1 | H29: 1 | I29: 1 | J29: 1 | K29: 1 | L29: 1 | M29: 1 | N29: 1 | P29: 1.4557657
A30: All | B30: Question 29 | C30: 0 | D30: 0 | E30: 1 | F30: 1 | G30: 1 | H30: 1 | I30: 1 | J30: 1 | K30: 1 | L30: 0 | M30: 1 | N30: 1 | O30: A. Answerability: The sum $[FORMULA] + [FORMULA] = [FORMULA] + [FORMULA] = [FORMULA]$ hours $> 1$ hour. Thus, the totals do not match the problem statement 'She spent a total of 1 hour doing these activities.' This is conflicting information, making the problem technically not answerable as stated. C. Conciseness_and_relevance: The statement that 'she spent a total of 1 hour' is not needed to answer either question and contradicts the numbers given, introducing irrelevant and confusing information. | P30: 3.3723707
A31: All | B31: Question 30 | C31: 0 | D31: 1 | E31: 1 | F31: 1 | G31: 1 | H31: 1 | I31: 1 | J31: 1 | K31: 1 | L31: 1 | M31: 1 | N31: 1 | P31: 2.5703208
A32: All | B32: Question 31 | C32: 0 | D32: 1 | E32: 1 | F32: 1 | G32: 1 | H32: 1 | I32: 1 | J32: 1 | K32: 1 | L32: 1 | M32: 1 | N32: 1 | P32: 1.3373532
A33: All | B33: Question 32 | C33: 0 | D33: 1 | E33: 1 | F33: 1 | G33: 1 | H33: 1 | I33: 0 | J33: 1 | K33: 1 | L33: 1 | M33: 1 | N33: 1 | O33: G: While the concept of work inversely proportional to the number of dancers is mathematically valid, in real-world group choreography, increasing the number of dancers rarely decreases total practice time in precise inverse proportion, due to the complexity of coordination and group dynamics. Thus, the scenario is not fully plausible as stated. | P33: 3.3824639
A34: All | B34: Question 33 | C34: 0 | D34: 1 | E34: 1 | F34: 1 | G34: 1 | H34: 1 | I34: 1 | J34: 1 | K34: 1 | L34: 1 | M34: 1 | N34: 1 | P34: 1.6382735
A35: All | B35: Question 34 | C35: 0 | D35: 1 | E35: 1 | F35: 1 | G35: 1 | H35: 1 | I35: 1 | J35: 1 | K35: 1 | L35: 1 | M35: 1 | N35: 1 | P35: 1.456605
A36: All | B36: Question 35 | C36: 0 | D36: 1 | E36: 1 | F36: 1 | G36: 1 | H36: 1 | I36: 1 | J36: 1 | K36: 1 | L36: 1 | M36: 1 | N36: 1 | P36: 1.9334273
A37: All | B37: Question 36 | C37: 0 | D37: 1 | E37: 1 | F37: 1 | G37: 1 | H37: 1 | I37: 1 | J37: 1 | K37: 1 | L37: 1 | M37: 1 | N37: 1 | P37: 1.9600754
A38: All | B38: Question 37 | C38: 0 | D38: 1 | E38: 1 | F38: 1 | G38: 1 | H38: 1 | I38: 1 | J38: 1 | K38: 1 | L38: 1 | M38: 1 | N38: 1 | P38: 3.5266094
A39: All | B39: Question 38 | C39: 0 | D39: 1 | E39: 1 | F39: 1 | G39: 1 | H39: 1 | I39: 1 | J39: 0 | K39: 1 | L39: 1 | M39: 1 | N39: 1 | O39: Synergy=0: The two parts (a) and (b) are only loosely related; the answer from (a) is not required to solve (b), nor is there a necessary transfer of information from the first to the second. Part (b) only needs the daily painting hours, not the total from (a). | P39: 4.7793703
A40: All | B40: Question 39 | C40: 0 | D40: 1 | E40: 1 | F40: 1 | G40: 1 | H40: 1 | I40: 1 | J40: 1 | K40: 1 | L40: 1 | M40: 1 | N40: 1 | P40: 2.4680417
...

Sheet Compiled Votes
A1: Evaluator | B1: Question | C1: status | D1: answerability | E1: primary_kc_alignment | F1: secondary_kc_alignment | G1: topic_alignment | H1: grade_alignment | I1: real_world_feasibility | J1: synergy | K1: clarity | L1: conciseness_and_relevance | M1: language_quality | N1: content_appropriateness | O1: response_time
A2: All | B2: Question 1 | C2: 0 | D2: =ROUND(SUM(recreation_v2_common_5!D2,recreation_v2_common_4!D2,recreation_v2_common_3!D2,recreation_v2_common_2!D2,recreation_v2_common_1!D2)/COUNT(recreation_v2_common_5!D2,recreation_v2_common_4!D2,recreation_v2_common_3!D2,recreation_v2_common_2!D2,recreation_v2_common_1!D2),0) -> 1 | E2: =IF($D2=0,"NA",ROUND(SUM(recreation_v2_common_5!E2,recreation_v2_common_4!E2,recreation_v2_common_3!E2,recreation_v2_common_2!E2,recreation_v2_common_1!E2)/COUNT(recreation_v2_common_5!E2,recreation_v2_common_4!E2,recreation_v2_common_3!E2,recreation_v2_common_2!E2,recreation_v2_common_1!E2),0)) -> 1 | F2: =IF($D2=0,"NA",ROUND(SUM(recreation_v2_common_5!F2,recreation_v2_common_4!F2,recreation_v2_common_3!F2,recreation_v2_common_2!F2,recreation_v2_common_1!F2)/COUNT(recreation_v2_common_5!F2,recreation_v2_common_4!F2,recreation_v2_common_3!F2,recreation_v2_common_2!F2,recreation_v2_common_1!F2),0)) -> 1 | G2: =IF($D2=0,"NA",ROUND(SUM(recreation_v2_common_5!G2,recreation_v2_common_4!G2,recreation_v2_common_3!G2,recreation_v2_common_2!G2,recreation_v2_common_1!G2)/COUNT(recreation_v2_common_5!G2,recreation_v2_common_4!G2,recreation_v2_common_3!G2,recreation_v2_common_2!G2,recreation_v2_common_1!G2),0)) -> 1 | H2: =IF(E2=1, ROUND(SUM(recreation_v2_common_5!H2,recreation_v2_common_4!H2,recreation_v2_common_3!H2,recreation_v2_common_2!H2,recreation_v2_common_1!H2)/COUNT(recreation_v2_common_5!H2,recreation_v2_common_4!H2,recreation_v2_common_3!H2,recreation_v2_common_2!H2,recreation_v2_common_1!H2),0),"NA") -> 1 | I2: =IF($D2=0,"NA",ROUND(SUM(recreation_v2_common_5!I2,recreation_v2_common_4!I2,recreation_v2_common_3!I2,recreation_v2_common_2!I2,recreation_v2_common_1!I2)/COUNT(recreation_v2_common_5!I2,recreation_v2_common_4!I2,recreation_v2_common_3!I2,recreation_v2_common_2!I2,recreation_v2_common_1!I2),0)) -> 1 | J2: =IF(AND(E2 = 1, F2 = 1),ROUND(SUM(recreation_v2_common_5!J2,recreation_v2_common_4!J2,recreation_v2_common_3!J2,recreation_v2_common_2!J2,recreation_v2_common_1!J2)/COUNT(recreation_v2_common_5!J2,recreation_v2_common_4!J2,recreation_v2_common_3!J2,recreation_v2_common_2!J2,recreation_v2_common_1!J2),0),"NA") -> 1 | K2: =IF($D2=0,"NA",ROUND(SUM(recreation_v2_common_5!K2,recreation_v2_common_4!K2,recreation_v2_common_3!K2,recreation_v2_common_2!K2,recreation_v2_common_1!K2)/COUNT(recreation_v2_common_5!K2,recreation_v2_common_4!K2,recreation_v2_common_3!K2,recreation_v2_common_2!K2,recreation_v2_common_1!K2),0)) -> 1 | L2: =IF($D2=0,"NA",ROUND(SUM(recreation_v2_common_5!L2,recreation_v2_common_4!L2,recreation_v2_common_3!L2,recreation_v2_common_2!L2,recreation_v2_common_1!L2)/COUNT(recreation_v2_common_5!L2,recreation_v2_common_4!L2,recreation_v2_common_3!L2,recreation_v2_common_2!L2,recreation_v2_common_1!L2),0)) -> 1 | M2: =IF($D2=0,"NA",ROUND(SUM(recreation_v2_common_5!M2,recreation_v2_common_4!M2,recreation_v2_common_3!M2,recreation_v2_common_2!M2,recreation_v2_common_1!M2)/COUNT(recreation_v2_common_5!M2,recreation_v2_common_4!M2,recreation_v2_common_3!M2,recreation_v2_common_2!M2,recreation_v2_common_1!M2),0)) -> 1 | N2: =IF($D2=0,"NA",ROUND(SUM(recreation_v2_common_5!N2,recreation_v2_common_4!N2,recreation_v2_common_3!N2,recreation_v2_common_2!N2,recreation_v2_common_1!N2)/COUNT(recreation_v2_common_5!N2,recreation_v2_common_4!N2,recreation_v2_common_3!N2,recreation_v2_common_2!N2,recreation_v2_common_1!N2),0)) -> 1 | O2: 1.535495
A3: All | B3: Question 2 | C3: 0 | D3: =ROUND(SUM(recreation_v2_common_5!D3,recreation_v2_common_4!D3,recreation_v2_common_3!D3,recreation_v2_common_2!D3,recreation_v2_common_1!D3)/COUNT(recreation_v2_common_5!D3,recreation_v2_common_4!D3,recreation_v2_common_3!D3,recreation_v2_common_2!D3,recreation_v2_common_1!D3),0) -> 1 | E3: =IF($D3=0,"NA",ROUND(SUM(recreation_v2_common_5!E3,recreation_v2_common_4!E3,recreation_v2_common_3!E3,recreation_v2_common_2!E3,recreation_v2_common_1!E3)/COUNT(recreation_v2_common_5!E3,recreation_v2_common_4!E3,recreation_v2_common_3!E3,recreation_v2_common_2!E3,recreation_v2_common_1!E3),0)) -> 1 | F3: =IF($D3=0,"NA",ROUND(SUM(recreation_v2_common_5!F3,recreation_v2_common_4!F3,recreation_v2_common_3!F3,recreation_v2_common_2!F3,recreation_v2_common_1!F3)/COUNT(recreation_v2_common_5!F3,recreation_v2_common_4!F3,recreation_v2_common_3!F3,recreation_v2_common_2!F3,recreation_v2_common_1!F3),0)) -> 1 | G3: =IF($D3=0,"NA",ROUND(SUM(recreation_v2_common_5!G3,recreation_v2_common_4!G3,recreation_v2_common_3!G3,recreation_v2_common_2!G3,recreation_v2_common_1!G3)/COUNT(recreation_v2_common_5!G3,recreation_v2_common_4!G3,recreation_v2_common_3!G3,recreation_v2_common_2!G3,recreation_v2_common_1!G3),0)) -> 1 | H3: =IF(E3=1, ROUND(SUM(recreation_v2_common_5!H3,recreation_v2_common_4!H3,recreation_v2_common_3!H3,recreation_v2_common_2!H3,recreation_v2_common_1!H3)/COUNT(recreation_v2_common_5!H3,recreation_v2_common_4!H3,recreation_v2_common_3!H3,recreation_v2_common_2!H3,recreation_v2_common_1!H3),0),"NA") -> 1 | I3: =IF($D3=0,"NA",ROUND(SUM(recreation_v2_common_5!I3,recreation_v2_common_4!I3,recreation_v2_common_3!I3,recreation_v2_common_2!I3,recreation_v2_common_1!I3)/COUNT(recreation_v2_common_5!I3,recreation_v2_common_4!I3,recreation_v2_common_3!I3,recreation_v2_common_2!I3,recreation_v2_common_1!I3),0)) -> 1 | J3: =IF(AND(E3 = 1, F3 = 1),ROUND(SUM(recreation_v2_common_5!J3,recreation_v2_common_4!J3,recreation_v2_common_3!J3,recreation_v2_common_2!J3,recreation_v2_common_1!J3)/COUNT(recreation_v2_common_5!J3,recreation_v2_common_4!J3,recreation_v2_common_3!J3,recreation_v2_common_2!J3,recreation_v2_common_1!J3),0),"NA") -> 1 | K3: =IF($D3=0,"NA",ROUND(SUM(recreation_v2_common_5!K3,recreation_v2_common_4!K3,recreation_v2_common_3!K3,recreation_v2_common_2!K3,recreation_v2_common_1!K3)/COUNT(recreation_v2_common_5!K3,recreation_v2_common_4!K3,recreation_v2_common_3!K3,recreation_v2_common_2!K3,recreation_v2_common_1!K3),0)) -> 1 | L3: =IF($D3=0,"NA",ROUND(SUM(recreation_v2_common_5!L3,recreation_v2_common_4!L3,recreation_v2_common_3!L3,recreation_v2_common_2!L3,recreation_v2_common_1!L3)/COUNT(recreation_v2_common_5!L3,recreation_v2_common_4!L3,recreation_v2_common_3!L3,recreation_v2_common_2!L3,recreation_v2_common_1!L3),0)) -> 1 | M3: =IF($D3=0,"NA",ROUND(SUM(recreation_v2_common_5!M3,recreation_v2_common_4!M3,recreation_v2_common_3!M3,recreation_v2_common_2!M3,recreation_v2_common_1!M3)/COUNT(recreation_v2_common_5!M3,recreation_v2_common_4!M3,recreation_v2_common_3!M3,recreation_v2_common_2!M3,recreation_v2_common_1!M3),0)) -> 1 | N3: =IF($D3=0,"NA",ROUND(SUM(recreation_v2_common_5!N3,recreation_v2_common_4!N3,recreation_v2_common_3!N3,recreation_v2_common_2!N3,recreation_v2_common_1!N3)/COUNT(recreation_v2_common_5!N3,recreation_v2_common_4!N3,recreation_v2_common_3!N3,recreation_v2_common_2!N3,recreation_v2_common_1!N3),0)) -> 1 | O3: 1.4433422
