Workbook

Sheet householdfinance_v4_1
A1: Evaluator | B1: Question | C1: status | D1: answerability | E1: primary_kc_alignment | F1: secondary_kc_alignment | G1: topic_alignment | H1: grade_alignment | I1: real_world_feasibility | J1: synergy | K1: clarity | L1: conciseness_and_relevance | M1: language_quality | N1: content_appropriateness | O1: explanation | P1: response_time | Q1: language_quality1
A2: TD | B2: Question 1 | C2: 0 | D2: 1 | E2: 1 | F2: 1 | G2: 1 | H2: 1 | I2: 1 | J2: 1 | K2: 1 | L2: 1 | M2: 1 | N2: 1 | P2: 2.7986028
A3: TD | B3: Question 2 | C3: 0 | D3: 1 | E3: 1 | F3: 0 | G3: 1 | H3: 1 | I3: 1 | J3: 'NA | K3: 1 | L3: 1 | M3: 1 | N3: 1 | O3: secondary_kc_alignment: The problem only requires subtraction (450 - 215) to find out how much Sarah spent before her father gave extra money. The extra $80 from her father is not needed to solve the problem, so addition is not necessary. synergy: Addition and subtraction are not used together to solve for the answer; only subtraction is needed. | P3: 2.7419116
A4: TD | B4: Question 3 | C4: 0 | D4: 1 | E4: 1 | F4: 1 | G4: 0 | H4: 1 | I4: 1 | J4: 1 | K4: 1 | L4: 1 | M4: 1 | N4: 1 | O4: D4*: The context describes sharing candies among children, which does not explicitly connect to the intended topic of 'Household finance such as income, utility bills, money, interest, savings, instalment, mortgage, financial planning etc.' The math situation is more about fair sharing/division with remainders, not a financial scenario. | P4: 2.2084112
A5: TD | B5: Question 4 | C5: 0 | D5: 1 | E5: 1 | F5: 1 | G5: 1 | H5: 1 | I5: 1 | J5: 1 | K5: 1 | L5: 1 | M5: 1 | N5: 1 | P5: 1.2284405
A6: TD | B6: Question 5 | C6: 0 | D6: 1 | E6: 1 | F6: 1 | G6: 1 | H6: 1 | I6: 1 | J6: 1 | K6: 1 | L6: 1 | M6: 1 | N6: 1 | P6: 1.4809985
A7: TD | B7: Question 6 | C7: 0 | D7: 1 | E7: 1 | F7: 1 | G7: 1 | H7: 1 | I7: 1 | J7: 1 | K7: 1 | L7: 1 | M7: 1 | N7: 1 | P7: 1.590306
A8: TD | B8: Question 7 | C8: 0 | D8: 1 | E8: 1 | F8: 1 | G8: 0 | H8: 1 | I8: 1 | J8: 1 | K8: 1 | L8: 1 | M8: 1 | N8: 1 | O8: D4: The scenario is about purchasing light bulbs for a house, which is only loosely related to household finance. The context does not directly address financial elements such as cost, budgeting, expenses, or savings, which are core to the intended topic of household finance. | P8: 1.7504017
A9: TD | B9: Question 8 | C9: 0 | D9: 1 | E9: 1 | F9: 1 | G9: 1 | H9: 1 | I9: 1 | J9: 1 | K9: 1 | L9: 1 | M9: 1 | N9: 1 | P9: 1.2563605
A10: TD | B10: Question 9 | C10: 0 | D10: 1 | E10: 1 | F10: 0 | G10: 1 | H10: 1 | I10: 1 | J10: 'NA | K10: 1 | L10: 1 | M10: 1 | N10: 1 | O10: Secondary KC Alignment: The problem does not require subtraction — only division is needed to answer the question. Synergy: Only division is required to solve for the amount each child receives; no combination of division and subtraction is needed. | P10: 1.7207451
A11: TD | B11: Question 10 | C11: 0 | D11: 1 | E11: 1 | F11: 1 | G11: 1 | H11: 1 | I11: 1 | J11: 1 | K11: 1 | L11: 1 | M11: 1 | N11: 1 | P11: 1.4076006
A12: TD | B12: Question 11 | C12: 0 | D12: 1 | E12: 1 | F12: 1 | G12: 1 | H12: 1 | I12: 1 | J12: 1 | K12: 1 | L12: 1 | M12: 1 | N12: 1 | P12: 1.5367053
A13: TD | B13: Question 12 | C13: 0 | D13: 1 | E13: 1 | F13: 1 | G13: 1 | H13: 1 | I13: 1 | J13: 1 | K13: 1 | L13: 1 | M13: 1 | N13: 1 | P13: 1.5695918
A14: TD | B14: Question 13 | C14: 0 | D14: 1 | E14: 0 | F14: 1 | G14: 1 | H14: 'NA | I14: 0 | J14: 'NA | K14: 1 | L14: 1 | M14: 1 | N14: 1 | O14: Primary KC alignment: 0 - Q(b) does not require students to add decimals to 2 decimal places; Q(a) is suitable but only requires standard addition, not more complex beyond 2DP. Grade alignment: 0 - The electricity bill in part (b) uses 3 decimal places ($45.605), which is beyond Primary 4 (which typically handles up to 2 decimal places). Real-world feasibility: 0 - Utility bills in Singapore (and nearly all real-world money contexts) do not use 3 decimal places, so a bill of $45.605 is not realistic. | P14: 6.1486974
A15: TD | B15: Question 14 | C15: 0 | D15: 1 | E15: 1 | F15: 1 | G15: 1 | H15: 1 | I15: 1 | J15: 1 | K15: 1 | L15: 1 | M15: 1 | N15: 1 | P15: 1.2660744
A16: TD | B16: Question 15 | C16: 0 | D16: 1 | E16: 1 | F16: 1 | G16: 1 | H16: 1 | I16: 1 | J16: 1 | K16: 1 | L16: 1 | M16: 1 | N16: 1 | P16: 1.7776628
A17: TD | B17: Question 16 | C17: 0 | D17: 1 | E17: 1 | F17: 1 | G17: 1 | H17: 1 | I17: 1 | J17: 1 | K17: 1 | L17: 1 | M17: 1 | N17: 1 | P17: 3.2931232
A18: TD | B18: Question 17 | C18: 0 | D18: 1 | E18: 1 | F18: 1 | G18: 1 | H18: 1 | I18: 1 | J18: 1 | K18: 1 | L18: 1 | M18: 1 | N18: 1 | P18: 1.2436643
A19: TD | B19: Question 18 | C19: 0 | D19: 1 | E19: 1 | F19: 1 | G19: 1 | H19: 1 | I19: 1 | J19: 1 | K19: 1 | L19: 1 | M19: 1 | N19: 1 | P19: 3.2166991
A20: TD | B20: Question 19 | C20: 0 | D20: 1 | E20: 1 | F20: 1 | G20: 1 | H20: 1 | I20: 1 | J20: 1 | K20: 1 | L20: 1 | M20: 1 | N20: 1 | P20: 1.2960212
A21: TD | B21: Question 20 | C21: 0 | D21: 1 | E21: 1 | F21: 1 | G21: 1 | H21: 1 | I21: 1 | J21: 1 | K21: 1 | L21: 1 | M21: 1 | N21: 1 | P21: 1.4096179
A22: TD | B22: Question 21 | C22: 0 | D22: 1 | E22: 1 | F22: 1 | G22: 1 | H22: 1 | I22: 1 | J22: 1 | K22: 1 | L22: 1 | M22: 1 | N22: 1 | P22: 1.304297
A23: TD | B23: Question 22 | C23: 0 | D23: 1 | E23: 1 | F23: 0 | G23: 1 | H23: 1 | I23: 1 | J23: 'NA | K23: 1 | L23: 1 | M23: 1 | N23: 1 | O23: Secondary KC Alignment: 0 - The intended secondary KC is comparing and ordering fractions, but the problem only compares a whole number ($90) with the computed fractional amount (which is a whole number after calculation). The question does not require comparing two fractions. Synergy: 0 - The solution requires the use of the primary KC (fraction multiplication), but does not require the secondary KC (comparing fractions), so the components are not used in tandem. | P23: 3.6889248
A24: TD | B24: Question 23 | C24: 0 | D24: 1 | E24: 1 | F24: 1 | G24: 1 | H24: 1 | I24: 1 | J24: 1 | K24: 1 | L24: 1 | M24: 1 | N24: 1 | P24: 3.231071
A25: TD | B25: Question 24 | C25: 0 | D25: 1 | E25: 1 | F25: 0 | G25: 1 | H25: 1 | I25: 1 | J25: 'NA | K25: 1 | L25: 1 | M25: 1 | N25: 1 | O25: Secondary KC Alignment: The problem only requires the use of multiplication of fractions sequentially. There is no requirement to add any fractions together in order to solve the problem, so Addition of Fractions is not targeted. Synergy: Only the Primary KC (Multiplication of Fractions) is needed for every operation in the sequence, so the word problem does not require both the Primary and Secondary KCs to work together. | P25: 2.0974202
A26: TD | B26: Question 25 | C26: 0 | D26: 1 | E26: 1 | F26: 1 | G26: 1 | H26: 1 | I26: 1 | J26: 1 | K26: 1 | L26: 1 | M26: 1 | N26: 1 | P26: 1.7663052
A27: TD | B27: Question 26 | C27: 0 | D27: 1 | E27: 1 | F27: 0 | G27: 0 | H27: 1 | I27: 1 | J27: 'NA | K27: 1 | L27: 1 | M27: 1 | N27: 1 | O27: 3-The secondary knowledge component is addition of fractions, but all calculations needed are multiplication and subtraction of fractions; at no point is adding of fractions required. 4-The context is about buying fruit juice for a gathering, which falls under food and daily life, not under household finance topic such as income, utility bills, or savings. | P27: 3.0723376
A28: TD | B28: Question 27 | C28: 0 | D28: 0 | E28: 'NA | F28: 'NA | G28: 'NA | H28: 'NA | I28: 'NA | J28: 'NA | K28: 'NA | L28: 'NA | M28: 1 | N28: 'NA | O28: answerability: The fractions '7/4' and '5/3' of the savings exceed 1 (whole), which is illogical since you cannot use more than 100% of the savings for each expense, thus the problem is not answerable.primary_kc_alignment: Multiplying the total by improper fractions greater than 1 is not a standard operation for allocation problems at Primary 5 and doesn't teach the intended KC properly, also the intended KC is multiplying two improper fractions, but the word problem only requires multiplying a whole by a fraction.secondary_kc_alignment: The subtraction is just simple whole number subtraction, not fraction subtraction between two fractional amounts.grade_alignment: The arithmetic involving improper fractions of a whole for allocations is beyond the typical level for Primary 5 and may confuse students.real_world_feasibility: No real-world scenario would have expenses that are more than the whole of one's savings for each category.synergy: The two KCs do not work in tandem, the student only applies fraction multiplication (using improper fractions unrealistically) and then does a subtraction with whole numbers, not with fractions. | P28: 3.8039804 | Q28: 'NA
A29: TD | B29: Question 28 | C29: 0 | D29: 1 | E29: 1 | F29: 1 | G29: 1 | H29: 1 | I29: 1 | J29: 1 | K29: 1 | L29: 1 | M29: 1 | N29: 1 | P29: 1.2004128
A30: TD | B30: Question 29 | C30: 0 | D30: 1 | E30: 1 | F30: 1 | G30: 0 | H30: 1 | I30: 1 | J30: 1 | K30: 1 | L30: 1 | M30: 1 | N30: 1 | O30: D-4: While the problem involves baking and the use of ingredients, it does NOT actually involve any of the specified household finance topics such as income, utility bills, money, interest, savings, instalment, mortgage, or financial planning. It stays in food preparation/consumption domain, not finance. | P30: 1.9118454
A31: TD | B31: Question 30 | C31: 0 | D31: 1 | E31: 0 | F31: 1 | G31: 1 | H31: 'NA | I31: 1 | J31: 'NA | K31: 1 | L31: 1 | M31: 1 | N31: 1 | O31: primary_kc_alignment: The main multiplication required is $3.75 [FORMULA] 100$ to get daily usage over 100 days (which equals 375), and then multiply by 0.174 (cost per kWh), so $375 [FORMULA] 0.174$. However, this does not require specifically multiplying decimals by 10, 100, 1000 and their multiples safely; it's normal decimal multiplication, but the focus is not explicitly on multiplying decimals by 10, 100, or 1000, as intended.[FORMULA]: The two parts (a) and (b) are independent; the answer from (a) is not required for (b), nor do they build on each other. | P31: 3.2674489
A32: TD | B32: Question 31 | C32: 0 | D32: 1 | E32: 0 | F32: 1 | G32: 1 | H32: 'NA | I32: 1 | J32: 'NA | K32: 1 | L32: 1 | M32: 1 | N32: 1 | O32: Primary KC Alignment: The problem describes decimal multiplication (73.245 × 0.15), but this involves multiplying decimals not specifically by 10, 100, 1000, or their multiples, which is what the intended KC targets. The product requires multiplying decimals generally, not scaling by powers of 10. Synergy: Subtraction should be applied after multiplication, but the scenario describes subtracting the service fee from the electricity cost, which is not actually correct since the fee should be added, not subtracted—this makes the synergy between multiplication and subtraction not logically coherent as per the premise. | P32: 2.662971
A33: TD | B33: Question 32 | C33: 0 | D33: 1 | E33: 1 | F33: 1 | G33: 1 | H33: 1 | I33: 1 | J33: 1 | K33: 1 | L33: 1 | M33: 1 | N33: 1 | P33: 2.6296833
A34: TD | B34: Question 33 | C34: 0 | D34: 1 | E34: 1 | F34: 1 | G34: 1 | H34: 1 | I34: 1 | J34: 1 | K34: 1 | L34: 1 | M34: 0 | N34: 1 | O34: language_quality: The use of '[FORMULA]' and decimal formatting ('$27.650') is not standard for financial notation—the correct format should be '$27.65'. This can confuse students and is considered a language/notation issue. | P34: 1.8400176
A35: TD | B35: Question 34 | C35: 0 | D35: 1 | E35: 1 | F35: 1 | G35: 1 | H35: 1 | I35: 1 | J35: 1 | K35: 1 | L35: 1 | M35: 1 | N35: 1 | P35: 1.5757596
A36: TD | B36: Question 35 | C36: 0 | D36: 1 | E36: 1 | F36: 1 | G36: 1 | H36: 1 | I36: 1 | J36: 1 | K36: 1 | L36: 1 | M36: 1 | N36: 1 | P36: 1.2426701
A37: TD | B37: Question 36 | C37: 0 | D37: 1 | E37: 1 | F37: 1 | G37: 1 | H37: 1 | I37: 1 | J37: 1 | K37: 1 | L37: 1 | M37: 1 | N37: 1 | P37: 1.2363698
A38: TD | B38: Question 37 | C38: 0 | D38: 1 | E38: 1 | F38: 1 | G38: 1 | H38: 1 | I38: 1 | J38: 1 | K38: 1 | L38: 1 | M38: 1 | N38: 1 | P38: 1.2000263
A39: TD | B39: Question 38 | C39: 0 | D39: 1 | E39: 0 | F39: 1 | G39: 0 | H39: 'NA | I39: 1 | J39: 'NA | K39: 1 | L39: 1 | M39: 1 | N39: 1 | O39: Primary KC Alignment: The intended primary KC is dividing a proper fraction by a whole number, but 2[FORMULA] (an improper/mixed fraction) divided by 5 is tested here, which is different in complexity from dividing a proper fraction. Topic Alignment: The scenario is about a school fundraiser and splitting cookies, which does not fit the intended topic of household finance (income, utility bills, money, etc.). | P39: 2.0618622
A40: TD | B40: Question 39 | C40: 0 | D40: 1 | E40: 0 | F40: 0 | G40: 1 | H40: 'NA | I40: 1 | J40: 'NA | K40: 1 | L40: 1 | M40: 1 | N40: 1 | O40: PRIMARY KC: The main operation needed is dividing $120$ by $3/4 [FORMULA] 120$ to find how many months the bills can be paid, but this results in dividing by a whole number (not a fraction by a fraction). The calculation required is $120 [FORMULA] 90$. SEC KC: No explicit need to subtract fractions; the subtraction is '120 - (2 [FORMULA] (3/4 [FORMULA] 120))', which is not subtraction of a fraction from a fraction or whole, so does not directly target the intended secondary KC. SYNERGY: The primary and secondary KCs are not necessary in tandem; the operations stand largely on their own and do not build off each other. | P40: 3.5045531
...

Sheet householdfinance_v4_2
A1: Evaluator | B1: Question | C1: status | D1: answerability | E1: primary_kc_alignment | F1: secondary_kc_alignment | G1: topic_alignment | H1: grade_alignment | I1: real_world_feasibility | J1: synergy | K1: clarity | L1: conciseness_and_relevance | M1: language_quality | N1: content_appropriateness | O1: explanation | P1: response_time | Q1: language_quality1
A2: TD | B2: Question 1 | C2: 0 | D2: 1 | E2: 1 | F2: 1 | G2: 1 | H2: 1 | I2: 1 | J2: 1 | K2: 1 | L2: 1 | M2: 1 | N2: 1 | P2: 1.7458415
A3: TD | B3: Question 2 | C3: 0 | D3: 1 | E3: 1 | F3: 0 | G3: 1 | H3: 1 | I3: 1 | J3: 'NA | K3: 1 | L3: 1 | M3: 1 | N3: 1 | O3: Secondary KC Alignment=0: The problem requires only subtraction to find out how much Sarah spent before her father gave her extra money; addition is not necessary to solve the problem. Synergy=0: There is no need to use both addition and subtraction together for this problem to be solved—the extra money from the father is not used in the calculation. | P3: 1.8329563
A4: TD | B4: Question 3 | C4: 0 | D4: 1 | E4: 1 | F4: 1 | G4: 0 | H4: 1 | I4: 1 | J4: 1 | K4: 1 | L4: 1 | M4: 1 | N4: 1 | O4: 4. Topic Alignment = 0: The problem is about sharing candies and not related to household finance topics like income, bills, money management, or financial planning as specified. | P4: 1.506896
A5: TD | B5: Question 4 | C5: 0 | D5: 1 | E5: 1 | F5: 1 | G5: 1 | H5: 1 | I5: 1 | J5: 1 | K5: 1 | L5: 1 | M5: 1 | N5: 1 | P5: 1.5906646
A6: TD | B6: Question 5 | C6: 0 | D6: 1 | E6: 1 | F6: 1 | G6: 1 | H6: 1 | I6: 1 | J6: 1 | K6: 1 | L6: 1 | M6: 1 | N6: 1 | P6: 1.2036586
A7: TD | B7: Question 6 | C7: 0 | D7: 1 | E7: 1 | F7: 1 | G7: 1 | H7: 1 | I7: 1 | J7: 1 | K7: 1 | L7: 1 | M7: 1 | N7: 1 | P7: 1.2201073
A8: TD | B8: Question 7 | C8: 0 | D8: 1 | E8: 1 | F8: 1 | G8: 0 | H8: 1 | I8: 1 | J8: 1 | K8: 1 | L8: 1 | M8: 1 | N8: 1 | O8: 4- Topic is household finance, but the question is about counting light bulbs, not related to finance topics like savings, bills, money, or planning. | P8: 3.1718147
A9: TD | B9: Question 8 | C9: 0 | D9: 1 | E9: 1 | F9: 1 | G9: 1 | H9: 1 | I9: 1 | J9: 1 | K9: 1 | L9: 1 | M9: 1 | N9: 1 | P9: 1.1983654
A10: TD | B10: Question 9 | C10: 0 | D10: 1 | E10: 1 | F10: 0 | G10: 1 | H10: 1 | I10: 1 | J10: 'NA | K10: 1 | L10: 1 | M10: 1 | N10: 1 | O10: 3,7: The secondary KC of subtraction is not necessary to solve for the amount each child receives—the problem can be solved solely with division. Synergy fails because knowledge of subtraction is not required, and no connected multi-step question involving subtraction is present. | P10: 3.1221344
A11: TD | B11: Question 10 | C11: 0 | D11: 1 | E11: 1 | F11: 1 | G11: 1 | H11: 1 | I11: 1 | J11: 1 | K11: 1 | L11: 1 | M11: 1 | N11: 1 | P11: 1.3676319
A12: TD | B12: Question 11 | C12: 0 | D12: 1 | E12: 1 | F12: 1 | G12: 1 | H12: 1 | I12: 1 | J12: 1 | K12: 1 | L12: 1 | M12: 1 | N12: 1 | P12: 1.4330013
A13: TD | B13: Question 12 | C13: 0 | D13: 1 | E13: 1 | F13: 1 | G13: 1 | H13: 1 | I13: 1 | J13: 1 | K13: 1 | L13: 1 | M13: 1 | N13: 1 | P13: 1.2430379
A14: TD | B14: Question 13 | C14: 0 | D14: 1 | E14: 0 | F14: 0 | G14: 1 | H14: 'NA | I14: 0 | J14: 'NA | K14: 1 | L14: 1 | M14: 1 | N14: 1 | O14: Primary KC: The electricity bill for July uses a value with 3 decimal places ($45.605$), but the intended difficulty is for adding decimals up to 2 decimal places only, which is violated. Secondary KC: The comparison requires comparison of $45.60$ and $45.605$ (2 vs 3 decimal places), but at the P4 level, students may not have been taught to compare decimals beyond 2 decimal places, especially when extra digits do not realistically occur in Singaporean utility billing.Grade alignment: Use of $45.605$ is not appropriate for P4 standard practice, which expects decimals up to 2 decimal places for money calculations.Real-world feasibility: In real-world utility bills, especially in Singapore, currency is not denominated to 3 decimal places; bills are always rounded to 2 decimal places. Thus, $45.605$ is not plausible. | P14: 2.9998636
A15: TD | B15: Question 14 | C15: 0 | D15: 1 | E15: 1 | F15: 1 | G15: 1 | H15: 1 | I15: 1 | J15: 1 | K15: 1 | L15: 1 | M15: 1 | N15: 1 | P15: 2.328481
A16: TD | B16: Question 15 | C16: 0 | D16: 1 | E16: 1 | F16: 1 | G16: 1 | H16: 1 | I16: 1 | J16: 1 | K16: 1 | L16: 1 | M16: 1 | N16: 1 | P16: 2.457175
A17: TD | B17: Question 16 | C17: 0 | D17: 1 | E17: 1 | F17: 1 | G17: 1 | H17: 1 | I17: 1 | J17: 0 | K17: 1 | L17: 1 | M17: 1 | N17: 1 | O17: G: The two parts (a) and (b) are independent; the answer to (a) does not need (b) and vice versa. The fraction in part (b) is not required for solving part (a), so synergy between primary/secondary KCs is not achieved. | P17: 1.6984537
A18: TD | B18: Question 17 | C18: 0 | D18: 1 | E18: 1 | F18: 1 | G18: 1 | H18: 1 | I18: 1 | J18: 1 | K18: 1 | L18: 1 | M18: 1 | N18: 1 | P18: 1.6143937
A19: TD | B19: Question 18 | C19: 0 | D19: 1 | E19: 1 | F19: 1 | G19: 1 | H19: 1 | I19: 1 | J19: 1 | K19: 1 | L19: 1 | M19: 1 | N19: 1 | P19: 1.8342416
A20: TD | B20: Question 19 | C20: 0 | D20: 1 | E20: 1 | F20: 1 | G20: 1 | H20: 1 | I20: 1 | J20: 1 | K20: 1 | L20: 1 | M20: 1 | N20: 1 | P20: 2.4994836
A21: TD | B21: Question 20 | C21: 0 | D21: 0 | E21: 'NA | F21: 'NA | G21: 'NA | H21: 'NA | I21: 'NA | J21: 'NA | K21: 'NA | L21: 'NA | M21: 1 | N21: 'NA | O21: answerability: Value '$1[FORMULA]$ of her budget' and '$2[FORMULA]$ of her budget' result in sums greater than 1 whole budget, which is illogical for expenses unless explained (exceeds 100% of the budget); unit phrasing is ambiguous (should be fractions of her budget or actual values). primary_kc_alignment: Since the fractions are of the same quantity and both are over 1 (more than the entire budget), the addition lacks real relevance and context, and the phrasing makes it unclear—also, you are not actually adding mixed numbers that make sense in this context. secondary_kc_alignment: Since the fractions are not directly compared as fractions but as labels for amounts (with the same denominator 'of her budget'), the comparison is less meaningful or even misleading, especially since both are greater than 1. synergy: The answer to (a) does not help answer (b); the two sub-questions work independently. real_world_feasibility: No one spends more than their total budget on individual items and certainly not 1 and 2 times the entire budget in a single month; the scenario is unrealistic. | P21: 4.0242484 | Q21: 'NA
A22: TD | B22: Question 21 | C22: 0 | D22: 1 | E22: 1 | F22: 1 | G22: 1 | H22: 1 | I22: 1 | J22: 1 | K22: 1 | L22: 1 | M22: 1 | N22: 1 | P22: 1.2892666
A23: TD | B23: Question 22 | C23: 0 | D23: 1 | E23: 1 | F23: 0 | G23: 1 | H23: 1 | I23: 1 | J23: 'NA | K23: 1 | L23: 1 | M23: 1 | N23: 1 | O23: C3: The comparison required is between a whole number (90) and the amount saved, which would be a whole number after multiplying the fraction by $120. This does not require use of comparing and ordering fractions, so the intended secondary KC is not targeted. C7: The use of comparison is not dependent on the understanding or outcome of the multiplication step; once the product is known, the comparison is trivial and does not require knowledge of fractions comparison/order. | P23: 2.7969849
A24: TD | B24: Question 23 | C24: 0 | D24: 1 | E24: 1 | F24: 1 | G24: 1 | H24: 1 | I24: 1 | J24: 1 | K24: 1 | L24: 1 | M24: 1 | N24: 1 | P24: 2.0710509
A25: TD | B25: Question 24 | C25: 0 | D25: 1 | E25: 1 | F25: 0 | G25: 1 | H25: 1 | I25: 1 | J25: 'NA | K25: 1 | L25: 1 | M25: 1 | N25: 1 | O25: Secondary KC Alignment: No addition of fractions is required to solve the problem—only sequential multiplication and subtraction. Synergy: Since the Secondary KC (Addition of Fractions) is not involved, the two components do not work together in the word problem. | P25: 1.9946694
A26: TD | B26: Question 25 | C26: 0 | D26: 1 | E26: 1 | F26: 1 | G26: 1 | H26: 1 | I26: 1 | J26: 1 | K26: 1 | L26: 1 | M26: 1 | N26: 1 | P26: 1.6299584
A27: TD | B27: Question 26 | C27: 0 | D27: 1 | E27: 0 | F27: 0 | G27: 0 | H27: 'NA | I27: 1 | J27: 'NA | K27: 1 | L27: 1 | M27: 1 | N27: 1 | O27: Primary KC Alignment(0): To multiply two improper fractions, you need two fractional numbers as factors. Here, the multiplication required is a whole number (3) times an improper fraction ($[FORMULA]$), NOT two improper fractions.[FORMULA] KC Alignment(0): Addition of fractions is not required to solve any step in this word problem; only multiplication and subtraction of fractions are needed.[FORMULA] Alignment(0): The context is about buying fruit juice for a gathering, which fits a real-world context but is NOT connected to household finance topics such as income, bills, savings, etc. | P27: 5.4544685
A28: TD | B28: Question 27 | C28: 0 | D28: 0 | E28: 'NA | F28: 'NA | G28: 'NA | H28: 'NA | I28: 'NA | J28: 'NA | K28: 'NA | L28: 'NA | M28: 1 | N28: 'NA | O28: A.1: The word problem is not answerable because the fractions 7/4 and 5/3 both exceed 1, and sum to more than her total savings, which is impossible (she cannot spend more than she has). A.2: The main calculation involves multiplying by improper fractions greater than 1, which is not suitable for the context and is mathematically incoherent for the scenario. A.3: Instead of requiring subtraction of fractions, the solution would only require subtraction of resulting dollar values, not a meaningful use of fraction subtraction. A.5: This type of mistake with improper fractions and financial context is not suitable for Primary 5. A.6: The situation is unrealistic as someone cannot spend more than their total savings. A.7: There is no authentic synergy as the fraction subtraction does not meaningfully contribute to solving the problem. A.8: The description is confusing due to the misuse of fractions (improper, sum over 1, not logical in context). | P28: 5.3324885 | Q28: 'NA
A29: TD | B29: Question 28 | C29: 0 | D29: 1 | E29: 1 | F29: 1 | G29: 1 | H29: 1 | I29: 1 | J29: 1 | K29: 1 | L29: 1 | M29: 1 | N29: 1 | P29: 1.8802369
A30: TD | B30: Question 29 | C30: 0 | D30: 1 | E30: 1 | F30: 1 | G30: 0 | H30: 1 | I30: 1 | J30: 1 | K30: 1 | L30: 1 | M30: 1 | N30: 1 | O30: 4- The context is about baking and using chocolate, which does not explicitly relate to household finance (topic intended: income, utility bills, money, interest, savings, instalment, mortgage, financial planning etc). It is more about baking and ingredient usage, not financial matters. | P30: 3.0508986
A31: TD | B31: Question 30 | C31: 0 | D31: 1 | E31: 0 | F31: 1 | G31: 1 | H31: 'NA | I31: 1 | J31: 'NA | K31: 1 | L31: 1 | M31: 1 | N31: 1 | O31: Primary KC alignment = 0 because the question does not explicitly require multiplying a decimal by 10, 100, 1000 or their multiples. Part (a) asks to multiply two decimals ($3.75 [FORMULA] 100 [FORMULA] 0.174$), but the direct multiplication by 10, 100, or 1000 is not the necessary step, merely multiplying decimals and whole numbers. If the intention was to focus practice on multiplying decimals by 10, 100, or 1000, the question should highlight such operation. | P31: 2.4173615
A32: TD | B32: Question 31 | C32: 0 | D32: 1 | E32: 0 | F32: 1 | G32: 1 | H32: 'NA | I32: 1 | J32: 'NA | K32: 1 | L32: 1 | M32: 1 | N32: 1 | O32: Primary KC Alignment: The question requires multiplying 73.245 by 0.15, but this is not multiplication by 10, 100, 1000, or their multiples, as specified in the intended primary KC. It is just multiplying decimals, not with base-10 numbers. Synergy: There is no actual need to subtract the service fee from the initial calculated cost since the description says the fee should be included but Mr Lim subtracts it in his calculation, which is illogical. The problems do not require using both multiplication by multiples of 10 and subtraction in tandem for the solution. | P32: 2.7731516
A33: TD | B33: Question 32 | C33: 0 | D33: 1 | E33: 1 | F33: 1 | G33: 1 | H33: 1 | I33: 1 | J33: 1 | K33: 1 | L33: 1 | M33: 1 | N33: 1 | P33: 1.1990125
A34: TD | B34: Question 33 | C34: 0 | D34: 1 | E34: 1 | F34: 1 | G34: 1 | H34: 1 | I34: 1 | J34: 1 | K34: 1 | L34: 1 | M34: 1 | N34: 1 | P34: 1.2195737
A35: TD | B35: Question 34 | C35: 0 | D35: 1 | E35: 1 | F35: 1 | G35: 1 | H35: 1 | I35: 1 | J35: 1 | K35: 1 | L35: 1 | M35: 1 | N35: 1 | P35: 1.6749773
A36: TD | B36: Question 35 | C36: 0 | D36: 1 | E36: 1 | F36: 1 | G36: 1 | H36: 1 | I36: 1 | J36: 1 | K36: 1 | L36: 1 | M36: 1 | N36: 1 | P36: 1.542454
A37: TD | B37: Question 36 | C37: 0 | D37: 1 | E37: 1 | F37: 1 | G37: 1 | H37: 1 | I37: 1 | J37: 1 | K37: 1 | L37: 1 | M37: 1 | N37: 1 | P37: 1.6807382
A38: TD | B38: Question 37 | C38: 0 | D38: 1 | E38: 1 | F38: 1 | G38: 1 | H38: 1 | I38: 1 | J38: 1 | K38: 1 | L38: 1 | M38: 1 | N38: 1 | P38: 1.9444273
A39: TD | B39: Question 38 | C39: 0 | D39: 1 | E39: 0 | F39: 1 | G39: 0 | H39: 'NA | I39: 1 | J39: 'NA | K39: 1 | L39: 1 | M39: 1 | N39: 1 | O39: Primary KC Alignment: The problem deals with dividing a mixed number (improper fraction) by a whole number, not a proper fraction as specified by the intended KC. Topic Alignment: The context is school fundraising, baking, and donation, which is not related to household finance as intended (i.e., not about money, bills, income, etc.). | P39: 2.6583643
A40: TD | B40: Question 39 | C40: 0 | D40: 1 | E40: 0 | F40: 0 | G40: 1 | H40: 'NA | I40: 1 | J40: 'NA | K40: 1 | L40: 1 | M40: 1 | N40: 1 | O40: Primary KC Alignment (0): The question requires dividing $120 by [FORMULA] [FORMULA] 120$, which is a whole number divided by a whole number, not a proper fraction. Division of a whole number by a proper fraction (intended KC) does not occur. | Secondary KC Alignment (0): The subtraction required is whole number minus whole number, not involving fraction subtraction (i.e. not subtracting fractions). | Synergy (0): The two questions are sequential but do not require using both KC (division and fraction subtraction) together – only basic arithmetic with some fractions. | P40: 3.4104009
...

Sheet householdfinance_v4_3
A1: Evaluator | B1: Question | C1: status | D1: answerability | E1: primary_kc_alignment | F1: secondary_kc_alignment | G1: topic_alignment | H1: grade_alignment | I1: real_world_feasibility | J1: synergy | K1: clarity | L1: conciseness_and_relevance | M1: language_quality | N1: content_appropriateness | O1: explanation | P1: response_time | Q1: language_quality1
A2: TD | B2: Question 1 | C2: 0 | D2: 1 | E2: 1 | F2: 1 | G2: 1 | H2: 1 | I2: 1 | J2: 1 | K2: 1 | L2: 1 | M2: 1 | N2: 1 | P2: 1.1645322
A3: TD | B3: Question 2 | C3: 0 | D3: 1 | E3: 1 | F3: 0 | G3: 1 | H3: 1 | I3: 1 | J3: 'NA | K3: 1 | L3: 1 | M3: 1 | N3: 1 | O3: Secondary KC Alignment: The problem only requires initial subtraction (2450-21535), so addition of whole numbers is not needed. Synergy: Only the primary KC is required, so both KCs are not used in tandem. | P3: 2.7829387
A4: TD | B4: Question 3 | C4: 0 | D4: 1 | E4: 1 | F4: 1 | G4: 0 | H4: 1 | I4: 1 | J4: 1 | K4: 1 | L4: 1 | M4: 1 | N4: 1 | O4: D4: The topic is household finance, involving money or financial planning, but the problem is about candies being distributed among children with no connection to financial concepts. | P4: 1.6966138
A5: TD | B5: Question 4 | C5: 0 | D5: 1 | E5: 1 | F5: 1 | G5: 1 | H5: 1 | I5: 1 | J5: 1 | K5: 1 | L5: 1 | M5: 1 | N5: 1 | P5: 1.0988777
A6: TD | B6: Question 5 | C6: 0 | D6: 1 | E6: 1 | F6: 1 | G6: 1 | H6: 1 | I6: 1 | J6: 1 | K6: 1 | L6: 1 | M6: 1 | N6: 1 | P6: 1.2089908
A7: TD | B7: Question 6 | C7: 0 | D7: 1 | E7: 1 | F7: 1 | G7: 1 | H7: 1 | I7: 1 | J7: 1 | K7: 1 | L7: 1 | M7: 1 | N7: 1 | P7: 1.2596488
A8: TD | B8: Question 7 | C8: 0 | D8: 1 | E8: 1 | F8: 1 | G8: 0 | H8: 1 | I8: 1 | J8: 1 | K8: 1 | L8: 1 | M8: 1 | N8: 1 | O8: 4: The context is buying light bulbs for a house, which is general shopping, not specifically household finance such as income, bills, interest, savings, instalment, mortgage, or financial planning. Therefore, it does not align with the intended topic. | P8: 3.3258212
A9: TD | B9: Question 8 | C9: 0 | D9: 1 | E9: 1 | F9: 1 | G9: 1 | H9: 1 | I9: 1 | J9: 1 | K9: 1 | L9: 1 | M9: 1 | N9: 1 | P9: 3.0744078
A10: TD | B10: Question 9 | C10: 0 | D10: 1 | E10: 1 | F10: 0 | G10: 1 | H10: 1 | I10: 1 | J10: 'NA | K10: 1 | L10: 1 | M10: 1 | N10: 1 | O10: secondary_kc_alignment- The use of subtraction (to subtract household expenses from monthly salary) is not required to find out how much each child receives; only division is necessary. synergy- Only the primary knowledge component (division) is required to answer the problem; there is no dependency between division and subtraction, nor is subtraction needed to solve for what each child received. | P10: 3.2832241
A11: TD | B11: Question 10 | C11: 0 | D11: 1 | E11: 1 | F11: 1 | G11: 1 | H11: 1 | I11: 1 | J11: 1 | K11: 1 | L11: 1 | M11: 1 | N11: 1 | P11: 1.2175198
A12: TD | B12: Question 11 | C12: 0 | D12: 1 | E12: 1 | F12: 1 | G12: 1 | H12: 1 | I12: 1 | J12: 1 | K12: 1 | L12: 1 | M12: 1 | N12: 1 | P12: 1.1791115
A13: TD | B13: Question 12 | C13: 0 | D13: 1 | E13: 1 | F13: 1 | G13: 1 | H13: 1 | I13: 1 | J13: 1 | K13: 1 | L13: 1 | M13: 1 | N13: 1 | P13: 2.0069952
A14: TD | B14: Question 13 | C14: 0 | D14: 1 | E14: 0 | F14: 0 | G14: 1 | H14: 'NA | I14: 0 | J14: 'NA | K14: 1 | L14: 1 | M14: 1 | N14: 1 | O14: Primary KC Alignment: Question (a) is aligned but question (b) presents a bill with three decimal places ($45.605) when all Singapore currency transactions are expressed up to 2 decimal places, making it misaligned with 'adding decimals (up to 2 decimal places)'.Secondary KC Alignment: Comparison involves 3 decimal places, but it is not relevant to actual currency context and exceeds the secondary KC expected difficulty and context for P4.Grade Alignment: The use of $45.605 is not appropriate for Primary 4 as Singapore currency and school curriculum always uses 2 decimal places for money; comparison beyond 2 dp is outside grade and context.Real-World Feasibility: Utility bills are never stated or paid to 3 decimal places for Singapore dollars ($45.605 impossible/illogical in real-life). | P14: 5.9032586
A15: TD | B15: Question 14 | C15: 0 | D15: 1 | E15: 1 | F15: 1 | G15: 1 | H15: 1 | I15: 1 | J15: 1 | K15: 1 | L15: 1 | M15: 1 | N15: 1 | P15: 1.295989
A16: TD | B16: Question 15 | C16: 0 | D16: 1 | E16: 1 | F16: 1 | G16: 1 | H16: 1 | I16: 1 | J16: 1 | K16: 1 | L16: 1 | M16: 1 | N16: 1 | P16: 1.4113255
A17: TD | B17: Question 16 | C17: 0 | D17: 1 | E17: 1 | F17: 1 | G17: 1 | H17: 1 | I17: 1 | J17: 1 | K17: 1 | L17: 1 | M17: 1 | N17: 1 | P17: 1.7385006
A18: TD | B18: Question 17 | C18: 0 | D18: 1 | E18: 1 | F18: 1 | G18: 1 | H18: 1 | I18: 1 | J18: 1 | K18: 1 | L18: 1 | M18: 1 | N18: 1 | P18: 1.3546555
A19: TD | B19: Question 18 | C19: 0 | D19: 1 | E19: 1 | F19: 1 | G19: 1 | H19: 1 | I19: 1 | J19: 1 | K19: 1 | L19: 1 | M19: 1 | N19: 1 | P19: 1.5273533
A20: TD | B20: Question 19 | C20: 0 | D20: 1 | E20: 1 | F20: 1 | G20: 1 | H20: 1 | I20: 1 | J20: 1 | K20: 1 | L20: 1 | M20: 1 | N20: 1 | P20: 1.1372061
A21: TD | B21: Question 20 | C21: 0 | D21: 1 | E21: 1 | F21: 1 | G21: 1 | H21: 1 | I21: 1 | J21: 1 | K21: 1 | L21: 1 | M21: 1 | N21: 1 | P21: 3.3776476
A22: TD | B22: Question 21 | C22: 0 | D22: 1 | E22: 1 | F22: 1 | G22: 1 | H22: 1 | I22: 1 | J22: 1 | K22: 1 | L22: 1 | M22: 1 | N22: 1 | P22: 1.6866493
A23: TD | B23: Question 22 | C23: 0 | D23: 1 | E23: 1 | F23: 0 | G23: 1 | H23: 1 | I23: 1 | J23: 'NA | K23: 1 | L23: 1 | M23: 1 | N23: 1 | O23: Secondary KC Alignment(0): The problem involves comparing two whole numbers (40 from savings, and 090), not comparing or ordering fractions. Synergy(0): The comparison step does not require explicit use of the secondary KC (comparing/ordering fractions), only the result of fraction multiplication is used. | P23: 2.1250935
A24: TD | B24: Question 23 | C24: 0 | D24: 1 | E24: 1 | F24: 1 | G24: 1 | H24: 1 | I24: 1 | J24: 1 | K24: 1 | L24: 1 | M24: 1 | N24: 1 | P24: 1.1742108
A25: TD | B25: Question 24 | C25: 0 | D25: 1 | E25: 1 | F25: 0 | G25: 1 | H25: 1 | I25: 1 | J25: 'NA | K25: 1 | L25: 1 | M25: 1 | N25: 1 | O25: Secondary KC Alignment (0): The problem only requires repeated multiplication of fractions and does not require addition of fractions at any point.///Synergy (0): Since only multiplication of fractions is used at each stage, there is no need to combine multiplication and addition of fractions to solve for the final answer. | P25: 1.8734167
A26: TD | B26: Question 25 | C26: 0 | D26: 1 | E26: 1 | F26: 1 | G26: 1 | H26: 1 | I26: 1 | J26: 1 | K26: 1 | L26: 1 | M26: 1 | N26: 1 | P26: 2.8625042
A27: TD | B27: Question 26 | C27: 0 | D27: 1 | E27: 0 | F27: 0 | G27: 0 | H27: 'NA | I27: 1 | J27: 'NA | K27: 1 | L27: 1 | M27: 1 | N27: 1 | O27: 2: The problem only requires multiplication of a fraction by a whole number, not multiplying two fractions together as intended in the primary KC. 3: No addition of fractions is necessary; the problem solely involves multiplication and subtraction. 4: The scenario is about fruit juice purchase/consumption, not about household finance matters such as bills or money. 7: The questions are sequential but do not require both intended KCs synergistically, as there is no required addition of fractions or multiplication of two fractions. | P27: 2.5133607
A28: TD | B28: Question 27 | C28: 0 | D28: 0 | E28: 'NA | F28: 'NA | G28: 'NA | H28: 'NA | I28: 'NA | J28: 'NA | K28: 'NA | L28: 'NA | M28: 1 | N28: 'NA | O28: A: The fractions \([FORMULA]\) and \([FORMULA]\) imply she spends more than her total savings (1 whole) on utilities or groceries, which is impossible and creates a logical conflict. B: To solve, direct multiplication with \([FORMULA]\) and \([FORMULA]\) is not appropriate, as they exceed 1, and thus do not align with the intended Knowledge Component of multiplying two improper fractions in a meaningful or logical way for P5 math. C: Subtraction of the 'utilities' and 'groceries' amounts does not require subtraction of fractions, since both are calculated as amounts in dollars. S: Even if calculations were possible, the fractions provided do not produce physically meaningful values, and the required operations (multiplying and subtracting fractions) are not appropriately integrated. G: Primary 5 students are not expected to work with improper fractions greater than 1 when representing parts of a whole, and the scenario is unrealistic for their level. R: No household would allocate more than 100% of savings to either utilities or groceries, so these numbers are not feasible. C: Ambiguity arises as the fractions exceed 1, causing confusion about how the money could be allocated. | P28: 4.1972029 | Q28: 'NA
A29: TD | B29: Question 28 | C29: 0 | D29: 1 | E29: 1 | F29: 1 | G29: 1 | H29: 1 | I29: 1 | J29: 1 | K29: 1 | L29: 1 | M29: 1 | N29: 1 | P29: 1.7419102
A30: TD | B30: Question 29 | C30: 0 | D30: 1 | E30: 1 | F30: 1 | G30: 0 | H30: 1 | I30: 1 | J30: 1 | K30: 1 | L30: 1 | M30: 1 | N30: 1 | O30: 4: The context is about baking and measuring chocolate, not on household finance (income, bills, savings etc), so it does not align with the intended topic. | P30: 1.6975362
A31: TD | B31: Question 30 | C31: 0 | D31: 1 | E31: 0 | F31: 1 | G31: 1 | H31: 'NA | I31: 1 | J31: 'NA | K31: 1 | L31: 1 | M31: 1 | N31: 1 | O31: Primary KC Alignment: The multiplication required is $3.75 [FORMULA] 0.174 [FORMULA] 100$, which involves multiplying decimals, but not specifically by 10, 100, 1000 and their multiples as per the intended Primary KC. The most challenging multiplication is not the focus skill intended. Synergy: The two parts (a) and (b) are independent and not linked; the answer from one is not required for the other. | P31: 2.8946471
A32: TD | B32: Question 31 | C32: 0 | D32: 1 | E32: 0 | F32: 1 | G32: 1 | H32: 'NA | I32: 1 | J32: 'NA | K32: 1 | L32: 1 | M32: 1 | N32: 1 | O32: Primary KC Alignment: The core multiplication done here is $73.245 [FORMULA] 0.15$, which does not qualify as 'multiplying decimals by 10, 100, 1000 or their multiples'; it is general decimal multiplication, not multiplication by powers of ten. Synergy: The subtraction of $1.80$ is not mathematically synergistic with the multiplication; the result of the multiplication is not needed to correctly perform the subtraction operation (the subtraction is said to be from his cost calculation, but the logic requires him to ADD the service fee, not subtract it, so the required relationship between KC's is not clearly aligned). | P32: 2.5113463
A33: TD | B33: Question 32 | C33: 0 | D33: 1 | E33: 1 | F33: 1 | G33: 1 | H33: 1 | I33: 1 | J33: 1 | K33: 1 | L33: 1 | M33: 1 | N33: 1 | P33: 2.1388664
A34: TD | B34: Question 33 | C34: 0 | D34: 1 | E34: 1 | F34: 1 | G34: 1 | H34: 1 | I34: 1 | J34: 1 | K34: 1 | L34: 1 | M34: 1 | N34: 1 | P34: 1.823765
A35: TD | B35: Question 34 | C35: 0 | D35: 1 | E35: 1 | F35: 1 | G35: 1 | H35: 1 | I35: 1 | J35: 1 | K35: 1 | L35: 1 | M35: 1 | N35: 1 | P35: 1.4226642
A36: TD | B36: Question 35 | C36: 0 | D36: 1 | E36: 1 | F36: 1 | G36: 1 | H36: 1 | I36: 1 | J36: 1 | K36: 1 | L36: 1 | M36: 1 | N36: 1 | P36: 1.078141
A37: TD | B37: Question 36 | C37: 0 | D37: 1 | E37: 1 | F37: 1 | G37: 1 | H37: 1 | I37: 1 | J37: 1 | K37: 1 | L37: 1 | M37: 1 | N37: 1 | P37: 2.9683318
A38: TD | B38: Question 37 | C38: 0 | D38: 1 | E38: 1 | F38: 1 | G38: 1 | H38: 1 | I38: 1 | J38: 1 | K38: 1 | L38: 1 | M38: 1 | N38: 1 | P38: 1.8440206
A39: TD | B39: Question 38 | C39: 0 | D39: 1 | E39: 1 | F39: 1 | G39: 0 | H39: 1 | I39: 1 | J39: 1 | K39: 1 | L39: 1 | M39: 1 | N39: 1 | O39: 4: The context is about baking for a school fundraiser and distributing cookies, not related to household finance or any of the listed financial topics (such as income, bills, or savings). | P39: 1.74123
A40: TD | B40: Question 39 | C40: 0 | D40: 1 | E40: 0 | F40: 0 | G40: 1 | H40: 'NA | I40: 1 | J40: 'NA | K40: 1 | L40: 1 | M40: 1 | N40: 1 | O40: Primary KC Alignment: The calculation required to find how many months $120 can pay for is $120 [FORMULA] (3/4 [FORMULA] 120)$, which simplifies to $120 [FORMULA] 90 = 1.33...$, and NOT a whole number divided by a proper fraction as specified. The phrasing and construction do not enforce the need to divide by a fraction. Secondary KC Alignment: The problem only requires simple subtraction of whole numbers ($120 - 2 [FORMULA] 90 = $ amount left) and NOT the explicit subtraction of fractions as a requisite. Synergy: The knowledge components (dividing a whole number by a fraction and subtracting fractions) are not used in tandem to produce an answer; instead, each operates in isolation if at all. | P40: 4.4487026
...

Sheet householdfinance_v4_4
A1: Evaluator | B1: Question | C1: status | D1: answerability | E1: primary_kc_alignment | F1: secondary_kc_alignment | G1: topic_alignment | H1: grade_alignment | I1: real_world_feasibility | J1: synergy | K1: clarity | L1: conciseness_and_relevance | M1: language_quality | N1: content_appropriateness | O1: explanation | P1: response_time | Q1: language_quality1
A2: TD | B2: Question 1 | C2: 0 | D2: 1 | E2: 1 | F2: 1 | G2: 1 | H2: 1 | I2: 1 | J2: 1 | K2: 1 | L2: 1 | M2: 1 | N2: 1 | P2: 1.2219443
A3: TD | B3: Question 2 | C3: 0 | D3: 1 | E3: 1 | F3: 0 | G3: 1 | H3: 1 | I3: 1 | J3: 'NA | K3: 1 | L3: 1 | M3: 1 | N3: 1 | O3: Secondary KC Alignment: The problem only requires subtraction to find how much Sarah spent before her father gave her more money. The additional $80 is mentioned but not needed for any calculation related to the question, so addition is not required nor tested for solving. Synergy: Only the subtraction operation is essential to solve the problem; addition is not required at all, so the KCs are not synergistic. | P3: 2.8440704
A4: TD | B4: Question 3 | C4: 0 | D4: 1 | E4: 1 | F4: 1 | G4: 0 | H4: 1 | I4: 1 | J4: 1 | K4: 1 | L4: 1 | M4: 1 | N4: 1 | O4: 4: The scenario is about sharing candies among children, which does not align with the intended topic of household finance (e.g., money, bills, savings, etc.). | P4: 1.688848
A5: TD | B5: Question 4 | C5: 0 | D5: 1 | E5: 1 | F5: 1 | G5: 1 | H5: 1 | I5: 1 | J5: 1 | K5: 1 | L5: 1 | M5: 1 | N5: 1 | P5: 1.4934435
A6: TD | B6: Question 5 | C6: 0 | D6: 1 | E6: 1 | F6: 1 | G6: 1 | H6: 1 | I6: 1 | J6: 1 | K6: 1 | L6: 1 | M6: 1 | N6: 1 | P6: 2.2394876
A7: TD | B7: Question 6 | C7: 0 | D7: 1 | E7: 1 | F7: 1 | G7: 1 | H7: 1 | I7: 1 | J7: 1 | K7: 1 | L7: 1 | M7: 1 | N7: 1 | P7: 1.2877691
A8: TD | B8: Question 7 | C8: 0 | D8: 1 | E8: 1 | F8: 1 | G8: 0 | H8: 1 | I8: 1 | J8: 1 | K8: 1 | L8: 1 | M8: 1 | N8: 1 | O8: 4- The context is bulk purchase of light bulbs for a new house, which is more closely related to household supplies rather than specific household finance topics such as income, utility bills, money, interest, savings, instalments, mortgage, or financial planning as listed in the intended topic metadata. | P8: 2.3983157
A9: TD | B9: Question 8 | C9: 0 | D9: 1 | E9: 1 | F9: 1 | G9: 1 | H9: 1 | I9: 1 | J9: 1 | K9: 1 | L9: 1 | M9: 1 | N9: 1 | P9: 1.2872007
A10: TD | B10: Question 9 | C10: 0 | D10: 1 | E10: 1 | F10: 0 | G10: 1 | H10: 1 | I10: 1 | J10: 'NA | K10: 1 | L10: 1 | M10: 1 | N10: 1 | O10: 3: Subtraction is not actually required to solve the problem as posed; students only need to subtract if they are determining how much is distributed to the children, but the direct question only asks for how much each child receives—which is solved directly by division. 7: The division and subtraction do not need to be used together in this problem—the subtraction (3872-320) is not needed for the main question. | P10: 2.3286996
A11: TD | B11: Question 10 | C11: 0 | D11: 1 | E11: 1 | F11: 1 | G11: 1 | H11: 1 | I11: 1 | J11: 1 | K11: 1 | L11: 1 | M11: 1 | N11: 1 | P11: 2.1397135
A12: TD | B12: Question 11 | C12: 0 | D12: 1 | E12: 1 | F12: 1 | G12: 1 | H12: 1 | I12: 1 | J12: 1 | K12: 1 | L12: 1 | M12: 1 | N12: 1 | P12: 1.1427646
A13: TD | B13: Question 12 | C13: 0 | D13: 1 | E13: 1 | F13: 1 | G13: 1 | H13: 1 | I13: 1 | J13: 1 | K13: 1 | L13: 1 | M13: 1 | N13: 1 | P13: 1.1573029
A14: TD | B14: Question 13 | C14: 0 | D14: 1 | E14: 0 | F14: 1 | G14: 1 | H14: 'NA | I14: 0 | J14: 'NA | K14: 1 | L14: 1 | M14: 1 | N14: 1 | O14: Primary KC Alignment: The electricity bill in part (b) uses 3 decimal places ($45.605$), which exceeds the intended KC of adding decimals up to 2 decimal places. Furthermore, addition in (a), although correct KC, is paired with (b) that requires understanding numbers with 3 decimal places, which is not expected at Primary 4 level. Grade Alignment: At Primary 4 in Singapore, students typically only work with decimals up to 2 places; using 3 decimal places (and especially for a monetary value) is not suitable for this level. Real-World Feasibility: Monetary amounts are never listed as $45.605$; actual bills would only be given in cents. Synergy: Part (b) is unrelated to the computation in (a) except for using the word 'electricity bill'; no result from (a) is used to answer (b). | P14: 3.3945925
A15: TD | B15: Question 14 | C15: 0 | D15: 1 | E15: 1 | F15: 1 | G15: 1 | H15: 1 | I15: 1 | J15: 1 | K15: 1 | L15: 1 | M15: 1 | N15: 1 | P15: 1.8518035
A16: TD | B16: Question 15 | C16: 0 | D16: 1 | E16: 1 | F16: 1 | G16: 1 | H16: 1 | I16: 1 | J16: 1 | K16: 1 | L16: 1 | M16: 1 | N16: 1 | P16: 1.1612937
A17: TD | B17: Question 16 | C17: 0 | D17: 1 | E17: 1 | F17: 1 | G17: 1 | H17: 1 | I17: 1 | J17: 0 | K17: 1 | L17: 1 | M17: 1 | N17: 1 | O17: Synergy = 0: The two questions (a and b) are not connected; the answer from part (a) is not needed for part (b) and vice versa. Each part can be completed independently; thus, no synergy between the primary and secondary KC. | P17: 3.2059748
A18: TD | B18: Question 17 | C18: 0 | D18: 1 | E18: 1 | F18: 1 | G18: 1 | H18: 1 | I18: 1 | J18: 1 | K18: 1 | L18: 1 | M18: 1 | N18: 1 | P18: 1.7473373
A19: TD | B19: Question 18 | C19: 0 | D19: 1 | E19: 1 | F19: 1 | G19: 1 | H19: 1 | I19: 1 | J19: 1 | K19: 1 | L19: 1 | M19: 1 | N19: 1 | P19: 4.708442
A20: TD | B20: Question 19 | C20: 0 | D20: 1 | E20: 1 | F20: 1 | G20: 1 | H20: 1 | I20: 1 | J20: 1 | K20: 1 | L20: 1 | M20: 1 | N20: 1 | P20: 1.8247626
A21: TD | B21: Question 20 | C21: 0 | D21: 1 | E21: 1 | F21: 1 | G21: 1 | H21: 1 | I21: 0 | J21: 1 | K21: 1 | L21: 1 | M21: 1 | N21: 1 | O21: 6: The fractions $1[FORMULA]$ and $2[FORMULA]$ both describe spending 'more than the whole budget' individually, which is unrealistic. In real household finance, fractions of a budget spent should each be less than or equal to 1 (100%), or at least the total should not exceed the budget by such a large amount. This situation is not feasible for a real-world household scenario. | P21: 3.1137216
A22: TD | B22: Question 21 | C22: 0 | D22: 1 | E22: 1 | F22: 1 | G22: 1 | H22: 1 | I22: 1 | J22: 1 | K22: 1 | L22: 1 | M22: 1 | N22: 1 | P22: 1.3676219
A23: TD | B23: Question 22 | C23: 0 | D23: 1 | E23: 1 | F23: 0 | G23: 1 | H23: 1 | I23: 1 | J23: 'NA | K23: 1 | L23: 1 | M23: 1 | N23: 1 | O23: Secondary KC Alignment (3): The problem only requires a direct comparison between two whole numbers (amount saved and $90). There is no need to compare or order two fractions as intended; the comparison is a simple greater/less than between whole numbers. Synergy (7): The solution does not integrate both the multiplication of fractions and the comparison and ordering of fractions, as intended by the Secondary Knowledge Component. Thus, the components are not used in tandem. | P23: 2.1229117
A24: TD | B24: Question 23 | C24: 0 | D24: 1 | E24: 1 | F24: 1 | G24: 1 | H24: 1 | I24: 1 | J24: 1 | K24: 1 | L24: 1 | M24: 1 | N24: 1 | P24: 1.6866653
A25: TD | B25: Question 24 | C25: 0 | D25: 1 | E25: 1 | F25: 0 | G25: 1 | H25: 1 | I25: 1 | J25: 'NA | K25: 1 | L25: 1 | M25: 1 | N25: 1 | O25: Secondary KC Alignment (Addition): The solution only requires multiplying by fractions at each step. At no point does the student need to add any fractions to determine the final answer, so the adding fractions knowledge component is not necessary. Synergy: Because addition of fractions is not required in this problem, the two KCs are not used in tandem. | P25: 2.9219103
A26: TD | B26: Question 25 | C26: 0 | D26: 1 | E26: 1 | F26: 1 | G26: 1 | H26: 1 | I26: 1 | J26: 1 | K26: 1 | L26: 1 | M26: 1 | N26: 1 | P26: 1.1313078
A27: TD | B27: Question 26 | C27: 0 | D27: 1 | E27: 0 | F27: 0 | G27: 0 | H27: 'NA | I27: 1 | J27: 'NA | K27: 1 | L27: 1 | M27: 1 | N27: 1 | O27: 2: Primary KC is multiplying improper fractions, but all multiplications are with a whole number (3) and an improper fraction, not two improper fractions. 3: Secondary KC is 'adding fractions', but the only calculations required are subtraction and multiplication, not addition of fractions. 4: Topic is household finance, but the problem is about food volume, specifically juice, not finances, expenses, or money. | P27: 4.7269297
A28: TD | B28: Question 27 | C28: 0 | D28: 0 | E28: 'NA | F28: 'NA | G28: 'NA | H28: 'NA | I28: 'NA | J28: 'NA | K28: 'NA | L28: 'NA | M28: 1 | N28: 'NA | O28: answerability: a) Fractions used (7/4 and 5/3) are greater than 1, which means more was spent than saved, leading to an illogical scenario for dividing up a whole into parts. b) The fractions do not represent parts of the whole, violating basic sense of partition.primary_kc_alignment: a) The solution requires multiplying a fraction by a whole number, not multiplying two fractions as required by the intended KC.secondary_kc_alignment: a) No actual fractional subtraction is required; subtraction is with whole numbers resulting from previous step, not between fractions, so intended KC is not well-aligned.grade_alignment: a) Problems expecting students to use improper fractions greater than 1 to represent partitions or allocations are not suitable for Primary 5 curriculum; b) Fractions >1 in real-life contexts like this are not typically introduced until secondary level.real_world_feasibility: a) It is not possible for someone to spend more than their total savings on separate expenses both exceeding the original amount.synergy: a) There is no real need to use both skills together—the setup is faulty.clarity: a) Ambiguity in partitioning savings, and confusing use of improper fractions greater than 1. | P28: 8.7780323 | Q28: 'NA
A29: TD | B29: Question 28 | C29: 0 | D29: 0 | E29: 'NA | F29: 'NA | G29: 'NA | H29: 'NA | I29: 'NA | J29: 'NA | K29: 'NA | L29: 'NA | M29: 1 | N29: 'NA | O29: A: Problem contains insufficient, unclear, or conflicting information. The relationships between budget, brushes, and paints are unclear for the required calculation; not enough information to find the actual fraction of budget used for brushes.* P: The requirement asks for 'fraction of her total budget used for brushes', but the only usable brush money is '6/5' of some amount, conflicting with real expenses. Calculation of brush spending out of total is unclear; multiplication of two improper fractions is not required to answer. G: The problem involves complicated ratio reasoning and multiple relationships, which is above Primary 5 standard for fractions and proportionality. S: The synergy is missing; the intended primary KC (multiplying two improper fractions) is not required to answer the question. CL: Ambiguity and lack of clarity regarding what '6/5 of the money she spent on brushes was actually used' refers to, and unclear steps to determine the answer. CR: Not all information is relevant or necessary, especially the difference between money set aside, spent, and used—it is not clear what to do with all quantities. | P29: 3.8203835 | Q29: 'NA
A30: TD | B30: Question 29 | C30: 0 | D30: 1 | E30: 1 | F30: 1 | G30: 0 | H30: 1 | I30: 1 | J30: 1 | K30: 1 | L30: 1 | M30: 1 | N30: 1 | O30: D- The topic is not aligned. The problem is about baking and using ingredients, but does NOT relate to the intended topic of household finance (income, bills, savings, etc.), although it could loosely connect if, for example, chocolate cost or income from sales were included, but as currently written it does not satisfy the specified finance context. | P30: 2.4234817
A31: TD | B31: Question 30 | C31: 0 | D31: 1 | E31: 0 | F31: 1 | G31: 1 | H31: 'NA | I31: 1 | J31: 'NA | K31: 1 | L31: 1 | M31: 1 | N31: 1 | O31: Primary KC Alignment: The core decimal multiplication required is $3.75 [FORMULA] 0.174 [FORMULA] 100$, but multiplying by 0.174 is not multiplying by 10, 100, 1000 or their multiples. The intended KC specifically requests multiplying decimals by those round numbers only, not by a general decimal. Thus, the word problem does not necessitate applying the intended decimal-multiplication-by-10/100/1000 skill as required. | P31: 2.1560471
A32: TD | B32: Question 31 | C32: 0 | D32: 0 | E32: 'NA | F32: 'NA | G32: 'NA | H32: 'NA | I32: 'NA | J32: 'NA | K32: 'NA | L32: 'NA | M32: 1 | N32: 'NA | O32: answerability: - The problem asks Mr Lim to 'subtract' the service fee from his cost calculation, but in real-world context, a service fee is added, not subtracted. This introduces a contradiction, making the intended solution unanswerable or misleading. primary_kc_alignment: - The multiplication is between 73.245 and 0.15, but this is not a multiplication by 10, 100, 1000 or their multiples. Instead, it is a multiplication of decimals by decimals (not specifically aligned with the intended primary KC). synergy: - The use of subtraction is not logically or procedurally dependent on the prior multiplication step because the problem incorrectly asks for subtraction of a fee rather than addition—steps cannot be used in tandem to reach a valid answer. | P32: 5.2156894 | Q32: 'NA
A33: TD | B33: Question 32 | C33: 0 | D33: 1 | E33: 1 | F33: 1 | G33: 1 | H33: 1 | I33: 1 | J33: 1 | K33: 1 | L33: 1 | M33: 1 | N33: 1 | P33: 1.3387184
A34: TD | B34: Question 33 | C34: 0 | D34: 1 | E34: 1 | F34: 1 | G34: 1 | H34: 1 | I34: 1 | J34: 1 | K34: 1 | L34: 1 | M34: 1 | N34: 1 | P34: 2.0605581
A35: TD | B35: Question 34 | C35: 0 | D35: 1 | E35: 1 | F35: 1 | G35: 1 | H35: 1 | I35: 1 | J35: 1 | K35: 1 | L35: 1 | M35: 1 | N35: 1 | P35: 1.2560349
A36: TD | B36: Question 35 | C36: 0 | D36: 1 | E36: 1 | F36: 1 | G36: 1 | H36: 1 | I36: 1 | J36: 1 | K36: 1 | L36: 1 | M36: 1 | N36: 1 | P36: 1.1417625
A37: TD | B37: Question 36 | C37: 0 | D37: 1 | E37: 1 | F37: 1 | G37: 1 | H37: 1 | I37: 1 | J37: 1 | K37: 1 | L37: 1 | M37: 1 | N37: 1 | P37: 1.2070439
A38: TD | B38: Question 37 | C38: 0 | D38: 1 | E38: 1 | F38: 1 | G38: 1 | H38: 1 | I38: 1 | J38: 1 | K38: 1 | L38: 1 | M38: 1 | N38: 1 | P38: 1.5221553
A39: TD | B39: Question 38 | C39: 0 | D39: 1 | E39: 1 | F39: 1 | G39: 0 | H39: 1 | I39: 1 | J39: 1 | K39: 1 | L39: 1 | M39: 1 | N39: 1 | O39: 4: The problem involves dividing trays of cookies for a fundraiser, which is not related to household finance topics like income, bills, savings, etc. The scenario is about charity and food distribution, not finance. | P39: 1.6308589
A40: TD | B40: Question 39 | C40: 0 | D40: 1 | E40: 0 | F40: 1 | G40: 1 | H40: 'NA | I40: 1 | J40: 'NA | K40: 1 | L40: 1 | M40: 1 | N40: 1 | O40: Primary KC Alignment: The main calculation for 'how many months of utility bills can Mrs Tan pay' (120 ÷ (3/4 * 120)) actually reduces to multiplication/division of whole numbers, not division by a proper fraction (it's division by a whole number using a fraction as a rate). The other calculation (money left after 2 months) is a subtraction of amounts, not fractions. Synergy: The questions are not dependent on each other—each can be solved independently; the result of one question is not needed as input for the other. | P40: 7.747385
...

Sheet householdfinance_v4_5
A1: Evaluator | B1: Question | C1: status | D1: answerability | E1: primary_kc_alignment | F1: secondary_kc_alignment | G1: topic_alignment | H1: grade_alignment | I1: real_world_feasibility | J1: synergy | K1: clarity | L1: conciseness_and_relevance | M1: language_quality | N1: content_appropriateness | O1: explanation | P1: response_time | Q1: language_quality1
A2: TD | B2: Question 1 | C2: 0 | D2: 1 | E2: 1 | F2: 1 | G2: 1 | H2: 1 | I2: 1 | J2: 1 | K2: 1 | L2: 1 | M2: 1 | N2: 1 | P2: 1.1985626
A3: TD | B3: Question 2 | C3: 0 | D3: 1 | E3: 1 | F3: 0 | G3: 1 | H3: 1 | I3: 1 | J3: 'NA | K3: 1 | L3: 1 | M3: 1 | N3: 1 | O3: 3: The solution only requires subtraction (450-215) to find the amount spent before receiving the extra money. The intended secondary knowledge component, addition, is not necessary for this problem. 7: There is no need to combine subtraction and addition in tandem, as the question focuses solely on the spending before the new amount was added. | P3: 8.184953
A4: TD | B4: Question 3 | C4: 0 | D4: 1 | E4: 1 | F4: 1 | G4: 0 | H4: 1 | I4: 1 | J4: 1 | K4: 1 | L4: 1 | M4: 1 | N4: 1 | O4: 4- The context is about sharing candies among children, not a household finance scenario such as money, bills, or planning. While it is set in a household, it does not fit the intended topic of 'household finance' as defined in the examples. | P4: 3.5693607
A5: TD | B5: Question 4 | C5: 0 | D5: 1 | E5: 1 | F5: 1 | G5: 1 | H5: 1 | I5: 1 | J5: 1 | K5: 1 | L5: 1 | M5: 1 | N5: 1 | P5: 1.1780415
A6: TD | B6: Question 5 | C6: 0 | D6: 1 | E6: 1 | F6: 1 | G6: 1 | H6: 1 | I6: 1 | J6: 1 | K6: 1 | L6: 1 | M6: 1 | N6: 1 | P6: 1.191191
A7: TD | B7: Question 6 | C7: 0 | D7: 1 | E7: 1 | F7: 1 | G7: 1 | H7: 1 | I7: 1 | J7: 1 | K7: 1 | L7: 1 | M7: 1 | N7: 1 | P7: 1.4485931
A8: TD | B8: Question 7 | C8: 0 | D8: 1 | E8: 1 | F8: 1 | G8: 0 | H8: 1 | I8: 1 | J8: 1 | K8: 1 | L8: 1 | M8: 1 | N8: 1 | O8: 4- The context of buying light bulbs for a new house does not specifically fall under the specified household finance topics such as income, utility bills, money, interest, savings, instalment, mortgage, or financial planning. It is more related to purchasing goods rather than explicit finance topics. | P8: 4.9530828
A9: TD | B9: Question 8 | C9: 0 | D9: 1 | E9: 1 | F9: 1 | G9: 1 | H9: 1 | I9: 1 | J9: 1 | K9: 1 | L9: 1 | M9: 1 | N9: 1 | P9: 1.5795407
A10: TD | B10: Question 9 | C10: 0 | D10: 1 | E10: 1 | F10: 0 | G10: 1 | H10: 1 | I10: 1 | J10: 'NA | K10: 1 | L10: 1 | M10: 1 | N10: 1 | O10: Secondary KC Alignment=0: The problem can be solved directly by division (3872-320=3552, then 3552 divided by 4 is not required; rather, the way it's structured currently, the 320 leftover makes the correct process division first, then check the remainder, but only division is necessary as posed. Synergy=0: Subtraction is not required for the solution; the question only asks how much each child received, making only division needed. | P10: 2.5088558
A11: TD | B11: Question 10 | C11: 0 | D11: 1 | E11: 1 | F11: 1 | G11: 1 | H11: 1 | I11: 1 | J11: 1 | K11: 1 | L11: 1 | M11: 1 | N11: 1 | P11: 1.5113101
A12: TD | B12: Question 11 | C12: 0 | D12: 1 | E12: 1 | F12: 1 | G12: 1 | H12: 1 | I12: 1 | J12: 1 | K12: 1 | L12: 1 | M12: 1 | N12: 1 | P12: 1.6401429
A13: TD | B13: Question 12 | C13: 0 | D13: 1 | E13: 1 | F13: 1 | G13: 1 | H13: 1 | I13: 1 | J13: 1 | K13: 1 | L13: 1 | M13: 1 | N13: 1 | P13: 2.8631728
A14: TD | B14: Question 13 | C14: 0 | D14: 1 | E14: 0 | F14: 1 | G14: 1 | H14: 'NA | I14: 0 | J14: 'NA | K14: 1 | L14: 1 | M14: 1 | N14: 1 | O14: Primary KC Alignment: The second bill in part (b) uses 3 decimal places ($45.605), but the addition in (a) is only up to 2 decimal places, which matches the KC. However, (b) asks for comparison between 2- and 3-decimal numbers, focusing more on secondary KC. Part (a) could be done at lower skill. / Grade Alignment: Primary 4 students in Singapore typically deal with decimals only up to 2 decimal places, especially around money. The use of $45.605 is not grade-appropriate. / Real-World Feasibility: Household utility bills do not reasonably have 3 decimal places in currency; bills are always given to 2 decimal places for cents. / Synergy: The parts are independent; solving (a) does not help (b), which instead simply compares June's 2-decimal electricity bill with July's improper 3-decimal one. | P14: 3.5787127
A15: TD | B15: Question 14 | C15: 0 | D15: 1 | E15: 1 | F15: 1 | G15: 1 | H15: 1 | I15: 1 | J15: 1 | K15: 1 | L15: 1 | M15: 1 | N15: 1 | P15: 2.0902917
A16: TD | B16: Question 15 | C16: 0 | D16: 1 | E16: 1 | F16: 1 | G16: 1 | H16: 1 | I16: 1 | J16: 1 | K16: 1 | L16: 1 | M16: 1 | N16: 1 | P16: 1.583555
A17: TD | B17: Question 16 | C17: 0 | D17: 1 | E17: 1 | F17: 1 | G17: 1 | H17: 1 | I17: 1 | J17: 1 | K17: 1 | L17: 1 | M17: 1 | N17: 1 | P17: 1.4827096
A18: TD | B18: Question 17 | C18: 0 | D18: 1 | E18: 1 | F18: 1 | G18: 1 | H18: 1 | I18: 1 | J18: 1 | K18: 1 | L18: 1 | M18: 1 | N18: 1 | P18: 1.6765738
